<?xml version="1.0" ?>


<sdf version="1.6">
  <model name="strawb_plant">
    <static>true</static>

    <link name="dirt_link">
      <inertial>
        <mass>10</mass>
        <inertia>
          <ixx>1</ixx>
          <ixy>0</ixy>
          <ixz>0</ixz>
          <iyy>1</iyy>
          <iyz>0</iyz>
          <izz>1</izz>
        </inertia>
      </inertial>
    </link>

    <joint name="fixed to ground" type="revolute">
      <parent>world</parent>
      <child>dirt_link</child>
      <axis>
        <xyz>0 1 0</xyz>
      </axis>
    </joint>


    <link name= leaf_stem_link_1 >
      <pose>0 0 0 0 -0.29870514137892035 -2.677930257248432 </pose>
      <inertial>
        <mass>1</mass>
        <inertia> <!-- Modeled as slender rod -->
          <ixx>1e-3</ixx>
          <ixy>0</ixy>
          <ixz>0</ixz>
          <iyy>8.333e-2</iyy>
          <iyz>0</iyz>
          <izz>8.333e-2</izz>
        </inertia>
      </inertial>
      <visual name="visual">
        <geometry>
          <mesh>
            <uri>model://random_strawberry_plant/meshes/leaf_stem1.stl</uri>
            <scale> 0.19631106860476222 0.19631106860476222 0.19631106860476222</scale>
          </mesh>
        </geometry>
        <material> <!-- Green -->
          <ambient>0.0 0.5 0.0 1.0</ambient>
          <diffuse>0.0 0.5 0.0 1.0</diffuse>
          <specular>0.1 0.1 0.1 1.0</specular>
        </material>
      </visual>
    </link>

    <link name= leaf_link_1_0 >
      <pose> -0.10068568806154458
             -0.05034470513648084
             0.034662598297326944 0
             0 -4.078507103487995  </pose>
      <inertial>
        <mass>0.018</mass>
        <inertia>
          <ixx>8.82e-6</ixx>
          <ixy>0</ixy>
          <ixz>0</ixz>
          <iyy>8.82e-6</iyy>
          <iyz>0</iyz>
          <izz>8.82e-6</izz>
        </inertia>
      </inertial>
      <visual name="visual">
        <geometry>
          <mesh>
            <uri>model://random_strawberry_plant/meshes/leaf1.dae</uri>
            <scale> 0.43661297402258253 0.43661297402258253 0.43661297402258253</scale>
          </mesh>
        </geometry>
      </visual>
    </link>

    <link name= leaf_link_1_1 >
      <pose> -0.10068568806154458
             -0.05034470513648084
             0.034662598297326944 0
             0 -2.637861431201853  </pose>
      <inertial>
        <mass>0.018</mass>
        <inertia>
          <ixx>8.82e-6</ixx>
          <ixy>0</ixy>
          <ixz>0</ixz>
          <iyy>8.82e-6</iyy>
          <iyz>0</iyz>
          <izz>8.82e-6</izz>
        </inertia>
      </inertial>
      <visual name="visual">
        <geometry>
          <mesh>
            <uri>model://random_strawberry_plant/meshes/leaf5.dae</uri>
            <scale> 0.43661297402258253 0.43661297402258253 0.43661297402258253</scale>
          </mesh>
        </geometry>
      </visual>
    </link>

    <link name= leaf_link_1_2 >
      <pose> -0.10068568806154458
             -0.05034470513648084
             0.034662598297326944 0
             0 -1.0406251109081894  </pose>
      <inertial>
        <mass>0.018</mass>
        <inertia>
          <ixx>8.82e-6</ixx>
          <ixy>0</ixy>
          <ixz>0</ixz>
          <iyy>8.82e-6</iyy>
          <iyz>0</iyz>
          <izz>8.82e-6</izz>
        </inertia>
      </inertial>
      <visual name="visual">
        <geometry>
          <mesh>
            <uri>model://random_strawberry_plant/meshes/leaf5.dae</uri>
            <scale> 0.43661297402258253 0.43661297402258253 0.43661297402258253</scale>
          </mesh>
        </geometry>
      </visual>
    </link>


    <joint name=leaf_dirt_joint_1 type="revolute">
      <parent>dirt_link</parent>
      <child>leaf_stem_link_1</child>
      <axis>
        <xyz>0 1 0</xyz>
      </axis>
    </joint>

    <link name= leaf_stem_link_2 >
      <pose>0 0 0 0 -0.6958215896522484 -0.3423745792068349 </pose>
      <inertial>
        <mass>1</mass>
        <inertia> <!-- Modeled as slender rod -->
          <ixx>1e-3</ixx>
          <ixy>0</ixy>
          <ixz>0</ixz>
          <iyy>8.333e-2</iyy>
          <iyz>0</iyz>
          <izz>8.333e-2</izz>
        </inertia>
      </inertial>
      <visual name="visual">
        <geometry>
          <mesh>
            <uri>model://random_strawberry_plant/meshes/leaf_stem1.stl</uri>
            <scale> 0.32122528520903293 0.32122528520903293 0.32122528520903293</scale>
          </mesh>
        </geometry>
        <material> <!-- Green -->
          <ambient>0.0 0.5 0.0 1.0</ambient>
          <diffuse>0.0 0.5 0.0 1.0</diffuse>
          <specular>0.1 0.1 0.1 1.0</specular>
        </material>
      </visual>
    </link>

    <link name= leaf_link_2_0 >
      <pose> 0.1393436958505264
             -0.04966360353441272
             0.12354637631042642 0
             0 -1.8587870520987548  </pose>
      <inertial>
        <mass>0.018</mass>
        <inertia>
          <ixx>8.82e-6</ixx>
          <ixy>0</ixy>
          <ixz>0</ixz>
          <iyy>8.82e-6</iyy>
          <iyz>0</iyz>
          <izz>8.82e-6</izz>
        </inertia>
      </inertial>
      <visual name="visual">
        <geometry>
          <mesh>
            <uri>model://random_strawberry_plant/meshes/leaf5.dae</uri>
            <scale> 0.5763750839833917 0.5763750839833917 0.5763750839833917</scale>
          </mesh>
        </geometry>
      </visual>
    </link>

    <link name= leaf_link_2_1 >
      <pose> 0.1393436958505264
             -0.04966360353441272
             0.12354637631042642 0
             0 -0.30129000195690336  </pose>
      <inertial>
        <mass>0.018</mass>
        <inertia>
          <ixx>8.82e-6</ixx>
          <ixy>0</ixy>
          <ixz>0</ixz>
          <iyy>8.82e-6</iyy>
          <iyz>0</iyz>
          <izz>8.82e-6</izz>
        </inertia>
      </inertial>
      <visual name="visual">
        <geometry>
          <mesh>
            <uri>model://random_strawberry_plant/meshes/leaf1.dae</uri>
            <scale> 0.5763750839833917 0.5763750839833917 0.5763750839833917</scale>
          </mesh>
        </geometry>
      </visual>
    </link>

    <link name= leaf_link_2_2 >
      <pose> 0.1393436958505264
             -0.04966360353441272
             0.12354637631042642 0
             0 1.3305568382979829  </pose>
      <inertial>
        <mass>0.018</mass>
        <inertia>
          <ixx>8.82e-6</ixx>
          <ixy>0</ixy>
          <ixz>0</ixz>
          <iyy>8.82e-6</iyy>
          <iyz>0</iyz>
          <izz>8.82e-6</izz>
        </inertia>
      </inertial>
      <visual name="visual">
        <geometry>
          <mesh>
            <uri>model://random_strawberry_plant/meshes/leaf5.dae</uri>
            <scale> 0.5763750839833917 0.5763750839833917 0.5763750839833917</scale>
          </mesh>
        </geometry>
      </visual>
    </link>


    <joint name=leaf_dirt_joint_2 type="revolute">
      <parent>dirt_link</parent>
      <child>leaf_stem_link_2</child>
      <axis>
        <xyz>0 1 0</xyz>
      </axis>
    </joint>

    <link name= leaf_stem_link_3 >
      <pose>0 0 0 0 -0.37669252061533076 -3.1012553944681125 </pose>
      <inertial>
        <mass>1</mass>
        <inertia> <!-- Modeled as slender rod -->
          <ixx>1e-3</ixx>
          <ixy>0</ixy>
          <ixz>0</ixz>
          <iyy>8.333e-2</iyy>
          <iyz>0</iyz>
          <izz>8.333e-2</izz>
        </inertia>
      </inertial>
      <visual name="visual">
        <geometry>
          <mesh>
            <uri>model://random_strawberry_plant/meshes/leaf_stem1.stl</uri>
            <scale> 0.3040713424997209 0.3040713424997209 0.3040713424997209</scale>
          </mesh>
        </geometry>
        <material> <!-- Green -->
          <ambient>0.0 0.5 0.0 1.0</ambient>
          <diffuse>0.0 0.5 0.0 1.0</diffuse>
          <specular>0.1 0.1 0.1 1.0</specular>
        </material>
      </visual>
    </link>

    <link name= leaf_link_3_0 >
      <pose> -0.1695130768885
             -0.006841403846316451
             0.06711102171666597 0
             0 -4.6665270852565985  </pose>
      <inertial>
        <mass>0.018</mass>
        <inertia>
          <ixx>8.82e-6</ixx>
          <ixy>0</ixy>
          <ixz>0</ixz>
          <iyy>8.82e-6</iyy>
          <iyz>0</iyz>
          <izz>8.82e-6</izz>
        </inertia>
      </inertial>
      <visual name="visual">
        <geometry>
          <mesh>
            <uri>model://random_strawberry_plant/meshes/leaf5.dae</uri>
            <scale> 0.5248861526486486 0.5248861526486486 0.5248861526486486</scale>
          </mesh>
        </geometry>
      </visual>
    </link>

    <link name= leaf_link_3_1 >
      <pose> -0.1695130768885
             -0.006841403846316451
             0.06711102171666597 0
             0 -3.0116249346617585  </pose>
      <inertial>
        <mass>0.018</mass>
        <inertia>
          <ixx>8.82e-6</ixx>
          <ixy>0</ixy>
          <ixz>0</ixz>
          <iyy>8.82e-6</iyy>
          <iyz>0</iyz>
          <izz>8.82e-6</izz>
        </inertia>
      </inertial>
      <visual name="visual">
        <geometry>
          <mesh>
            <uri>model://random_strawberry_plant/meshes/leaf4.dae</uri>
            <scale> 0.5248861526486486 0.5248861526486486 0.5248861526486486</scale>
          </mesh>
        </geometry>
      </visual>
    </link>

    <link name= leaf_link_3_2 >
      <pose> -0.1695130768885
             -0.006841403846316451
             0.06711102171666597 0
             0 -1.6411883712953546  </pose>
      <inertial>
        <mass>0.018</mass>
        <inertia>
          <ixx>8.82e-6</ixx>
          <ixy>0</ixy>
          <ixz>0</ixz>
          <iyy>8.82e-6</iyy>
          <iyz>0</iyz>
          <izz>8.82e-6</izz>
        </inertia>
      </inertial>
      <visual name="visual">
        <geometry>
          <mesh>
            <uri>model://random_strawberry_plant/meshes/leaf4.dae</uri>
            <scale> 0.5248861526486486 0.5248861526486486 0.5248861526486486</scale>
          </mesh>
        </geometry>
      </visual>
    </link>


    <joint name=leaf_dirt_joint_3 type="revolute">
      <parent>dirt_link</parent>
      <child>leaf_stem_link_3</child>
      <axis>
        <xyz>0 1 0</xyz>
      </axis>
    </joint>

    <link name= leaf_stem_link_4 >
      <pose>0 0 0 0 -1.0850138383922632 -0.436785061516352 </pose>
      <inertial>
        <mass>1</mass>
        <inertia> <!-- Modeled as slender rod -->
          <ixx>1e-3</ixx>
          <ixy>0</ixy>
          <ixz>0</ixz>
          <iyy>8.333e-2</iyy>
          <iyz>0</iyz>
          <izz>8.333e-2</izz>
        </inertia>
      </inertial>
      <visual name="visual">
        <geometry>
          <mesh>
            <uri>model://random_strawberry_plant/meshes/leaf_stem2.stl</uri>
            <scale> 0.3157458301506417 0.3157458301506417 0.3157458301506417</scale>
          </mesh>
        </geometry>
        <material> <!-- Green -->
          <ambient>0.0 0.5 0.0 1.0</ambient>
          <diffuse>0.0 0.5 0.0 1.0</diffuse>
          <specular>0.1 0.1 0.1 1.0</specular>
        </material>
      </visual>
    </link>

    <link name= leaf_link_4_0 >
      <pose> 0.08014882303395349
             -0.03741819697021665
             0.16753029348292958 0
             0 -2.0131240471030614  </pose>
      <inertial>
        <mass>0.018</mass>
        <inertia>
          <ixx>8.82e-6</ixx>
          <ixy>0</ixy>
          <ixz>0</ixz>
          <iyy>8.82e-6</iyy>
          <iyz>0</iyz>
          <izz>8.82e-6</izz>
        </inertia>
      </inertial>
      <visual name="visual">
        <geometry>
          <mesh>
            <uri>model://random_strawberry_plant/meshes/leaf2.dae</uri>
            <scale> 0.5638242328393558 0.5638242328393558 0.5638242328393558</scale>
          </mesh>
        </geometry>
      </visual>
    </link>

    <link name= leaf_link_4_1 >
      <pose> 0.08014882303395349
             -0.03741819697021665
             0.16753029348292958 0
             0 -0.430051034065639  </pose>
      <inertial>
        <mass>0.018</mass>
        <inertia>
          <ixx>8.82e-6</ixx>
          <ixy>0</ixy>
          <ixz>0</ixz>
          <iyy>8.82e-6</iyy>
          <iyz>0</iyz>
          <izz>8.82e-6</izz>
        </inertia>
      </inertial>
      <visual name="visual">
        <geometry>
          <mesh>
            <uri>model://random_strawberry_plant/meshes/leaf5.dae</uri>
            <scale> 0.5638242328393558 0.5638242328393558 0.5638242328393558</scale>
          </mesh>
        </geometry>
      </visual>
    </link>

    <link name= leaf_link_4_2 >
      <pose> 0.08014882303395349
             -0.03741819697021665
             0.16753029348292958 0
             0 0.9696169429320152  </pose>
      <inertial>
        <mass>0.018</mass>
        <inertia>
          <ixx>8.82e-6</ixx>
          <ixy>0</ixy>
          <ixz>0</ixz>
          <iyy>8.82e-6</iyy>
          <iyz>0</iyz>
          <izz>8.82e-6</izz>
        </inertia>
      </inertial>
      <visual name="visual">
        <geometry>
          <mesh>
            <uri>model://random_strawberry_plant/meshes/leaf3.dae</uri>
            <scale> 0.5638242328393558 0.5638242328393558 0.5638242328393558</scale>
          </mesh>
        </geometry>
      </visual>
    </link>


    <joint name=leaf_dirt_joint_4 type="revolute">
      <parent>dirt_link</parent>
      <child>leaf_stem_link_4</child>
      <axis>
        <xyz>0 1 0</xyz>
      </axis>
    </joint>

    <link name= leaf_stem_link_5 >
      <pose>0 0 0 0 -0.9479641706049635 -1.1363083116912405 </pose>
      <inertial>
        <mass>1</mass>
        <inertia> <!-- Modeled as slender rod -->
          <ixx>1e-3</ixx>
          <ixy>0</ixy>
          <ixz>0</ixz>
          <iyy>8.333e-2</iyy>
          <iyz>0</iyz>
          <izz>8.333e-2</izz>
        </inertia>
      </inertial>
      <visual name="visual">
        <geometry>
          <mesh>
            <uri>model://random_strawberry_plant/meshes/leaf_stem2.stl</uri>
            <scale> 0.152714797526026 0.152714797526026 0.152714797526026</scale>
          </mesh>
        </geometry>
        <material> <!-- Green -->
          <ambient>0.0 0.5 0.0 1.0</ambient>
          <diffuse>0.0 0.5 0.0 1.0</diffuse>
          <specular>0.1 0.1 0.1 1.0</specular>
        </material>
      </visual>
    </link>

    <link name= leaf_link_5_0 >
      <pose> 0.022499815895235278
             -0.04848426811933119
             0.07442368848453271 0
             0 -2.826367600551048  </pose>
      <inertial>
        <mass>0.018</mass>
        <inertia>
          <ixx>8.82e-6</ixx>
          <ixy>0</ixy>
          <ixz>0</ixz>
          <iyy>8.82e-6</iyy>
          <iyz>0</iyz>
          <izz>8.82e-6</izz>
        </inertia>
      </inertial>
      <visual name="visual">
        <geometry>
          <mesh>
            <uri>model://random_strawberry_plant/meshes/leaf2.dae</uri>
            <scale> 0.6882987482405885 0.6882987482405885 0.6882987482405885</scale>
          </mesh>
        </geometry>
      </visual>
    </link>

    <link name= leaf_link_5_1 >
      <pose> 0.022499815895235278
             -0.04848426811933119
             0.07442368848453271 0
             0 -1.1033831265648255  </pose>
      <inertial>
        <mass>0.018</mass>
        <inertia>
          <ixx>8.82e-6</ixx>
          <ixy>0</ixy>
          <ixz>0</ixz>
          <iyy>8.82e-6</iyy>
          <iyz>0</iyz>
          <izz>8.82e-6</izz>
        </inertia>
      </inertial>
      <visual name="visual">
        <geometry>
          <mesh>
            <uri>model://random_strawberry_plant/meshes/leaf2.dae</uri>
            <scale> 0.6882987482405885 0.6882987482405885 0.6882987482405885</scale>
          </mesh>
        </geometry>
      </visual>
    </link>

    <link name= leaf_link_5_2 >
      <pose> 0.022499815895235278
             -0.04848426811933119
             0.07442368848453271 0
             0 0.2390618613815243  </pose>
      <inertial>
        <mass>0.018</mass>
        <inertia>
          <ixx>8.82e-6</ixx>
          <ixy>0</ixy>
          <ixz>0</ixz>
          <iyy>8.82e-6</iyy>
          <iyz>0</iyz>
          <izz>8.82e-6</izz>
        </inertia>
      </inertial>
      <visual name="visual">
        <geometry>
          <mesh>
            <uri>model://random_strawberry_plant/meshes/leaf1.dae</uri>
            <scale> 0.6882987482405885 0.6882987482405885 0.6882987482405885</scale>
          </mesh>
        </geometry>
      </visual>
    </link>


    <joint name=leaf_dirt_joint_5 type="revolute">
      <parent>dirt_link</parent>
      <child>leaf_stem_link_5</child>
      <axis>
        <xyz>0 1 0</xyz>
      </axis>
    </joint>

    <link name= leaf_stem_link_6 >
      <pose>0 0 0 0 -1.0837104583388772 0.1594507584891769 </pose>
      <inertial>
        <mass>1</mass>
        <inertia> <!-- Modeled as slender rod -->
          <ixx>1e-3</ixx>
          <ixy>0</ixy>
          <ixz>0</ixz>
          <iyy>8.333e-2</iyy>
          <iyz>0</iyz>
          <izz>8.333e-2</izz>
        </inertia>
      </inertial>
      <visual name="visual">
        <geometry>
          <mesh>
            <uri>model://random_strawberry_plant/meshes/leaf_stem2.stl</uri>
            <scale> 0.24145503901231039 0.24145503901231039 0.24145503901231039</scale>
          </mesh>
        </geometry>
        <material> <!-- Green -->
          <ambient>0.0 0.5 0.0 1.0</ambient>
          <diffuse>0.0 0.5 0.0 1.0</diffuse>
          <specular>0.1 0.1 0.1 1.0</specular>
        </material>
      </visual>
    </link>

    <link name= leaf_link_6_0 >
      <pose> 0.06694803232305285
             0.010766312425279121
             0.12802437422627705 0
             0 -1.5256263631866513  </pose>
      <inertial>
        <mass>0.018</mass>
        <inertia>
          <ixx>8.82e-6</ixx>
          <ixy>0</ixy>
          <ixz>0</ixz>
          <iyy>8.82e-6</iyy>
          <iyz>0</iyz>
          <izz>8.82e-6</izz>
        </inertia>
      </inertial>
      <visual name="visual">
        <geometry>
          <mesh>
            <uri>model://random_strawberry_plant/meshes/leaf1.dae</uri>
            <scale> 0.4768967278266758 0.4768967278266758 0.4768967278266758</scale>
          </mesh>
        </geometry>
      </visual>
    </link>

    <link name= leaf_link_6_1 >
      <pose> 0.06694803232305285
             0.010766312425279121
             0.12802437422627705 0
             0 0.08636394982251885  </pose>
      <inertial>
        <mass>0.018</mass>
        <inertia>
          <ixx>8.82e-6</ixx>
          <ixy>0</ixy>
          <ixz>0</ixz>
          <iyy>8.82e-6</iyy>
          <iyz>0</iyz>
          <izz>8.82e-6</izz>
        </inertia>
      </inertial>
      <visual name="visual">
        <geometry>
          <mesh>
            <uri>model://random_strawberry_plant/meshes/leaf4.dae</uri>
            <scale> 0.4768967278266758 0.4768967278266758 0.4768967278266758</scale>
          </mesh>
        </geometry>
      </visual>
    </link>

    <link name= leaf_link_6_2 >
      <pose> 0.06694803232305285
             0.010766312425279121
             0.12802437422627705 0
             0 1.6797041197539062  </pose>
      <inertial>
        <mass>0.018</mass>
        <inertia>
          <ixx>8.82e-6</ixx>
          <ixy>0</ixy>
          <ixz>0</ixz>
          <iyy>8.82e-6</iyy>
          <iyz>0</iyz>
          <izz>8.82e-6</izz>
        </inertia>
      </inertial>
      <visual name="visual">
        <geometry>
          <mesh>
            <uri>model://random_strawberry_plant/meshes/leaf4.dae</uri>
            <scale> 0.4768967278266758 0.4768967278266758 0.4768967278266758</scale>
          </mesh>
        </geometry>
      </visual>
    </link>


    <joint name=leaf_dirt_joint_6 type="revolute">
      <parent>dirt_link</parent>
      <child>leaf_stem_link_6</child>
      <axis>
        <xyz>0 1 0</xyz>
      </axis>
    </joint>

    <link name= leaf_stem_link_7 >
      <pose>0 0 0 0 -0.8041120581520664 -0.5241477081877419 </pose>
      <inertial>
        <mass>1</mass>
        <inertia> <!-- Modeled as slender rod -->
          <ixx>1e-3</ixx>
          <ixy>0</ixy>
          <ixz>0</ixz>
          <iyy>8.333e-2</iyy>
          <iyz>0</iyz>
          <izz>8.333e-2</izz>
        </inertia>
      </inertial>
      <visual name="visual">
        <geometry>
          <mesh>
            <uri>model://random_strawberry_plant/meshes/leaf_stem2.stl</uri>
            <scale> 0.37923182803683775 0.37923182803683775 0.37923182803683775</scale>
          </mesh>
        </geometry>
        <material> <!-- Green -->
          <ambient>0.0 0.5 0.0 1.0</ambient>
          <diffuse>0.0 0.5 0.0 1.0</diffuse>
          <specular>0.1 0.1 0.1 1.0</specular>
        </material>
      </visual>
    </link>

    <link name= leaf_link_7_0 >
      <pose> 0.13666350913137007
             -0.07900277091145444
             0.16387705160525182 0
             0 -2.140685513797288  </pose>
      <inertial>
        <mass>0.018</mass>
        <inertia>
          <ixx>8.82e-6</ixx>
          <ixy>0</ixy>
          <ixz>0</ixz>
          <iyy>8.82e-6</iyy>
          <iyz>0</iyz>
          <izz>8.82e-6</izz>
        </inertia>
      </inertial>
      <visual name="visual">
        <geometry>
          <mesh>
            <uri>model://random_strawberry_plant/meshes/leaf3.dae</uri>
            <scale> 0.5108085631812613 0.5108085631812613 0.5108085631812613</scale>
          </mesh>
        </geometry>
      </visual>
    </link>

    <link name= leaf_link_7_1 >
      <pose> 0.13666350913137007
             -0.07900277091145444
             0.16387705160525182 0
             0 -0.5933592306484852  </pose>
      <inertial>
        <mass>0.018</mass>
        <inertia>
          <ixx>8.82e-6</ixx>
          <ixy>0</ixy>
          <ixz>0</ixz>
          <iyy>8.82e-6</iyy>
          <iyz>0</iyz>
          <izz>8.82e-6</izz>
        </inertia>
      </inertial>
      <visual name="visual">
        <geometry>
          <mesh>
            <uri>model://random_strawberry_plant/meshes/leaf4.dae</uri>
            <scale> 0.5108085631812613 0.5108085631812613 0.5108085631812613</scale>
          </mesh>
        </geometry>
      </visual>
    </link>

    <link name= leaf_link_7_2 >
      <pose> 0.13666350913137007
             -0.07900277091145444
             0.16387705160525182 0
             0 1.190680523157633  </pose>
      <inertial>
        <mass>0.018</mass>
        <inertia>
          <ixx>8.82e-6</ixx>
          <ixy>0</ixy>
          <ixz>0</ixz>
          <iyy>8.82e-6</iyy>
          <iyz>0</iyz>
          <izz>8.82e-6</izz>
        </inertia>
      </inertial>
      <visual name="visual">
        <geometry>
          <mesh>
            <uri>model://random_strawberry_plant/meshes/leaf5.dae</uri>
            <scale> 0.5108085631812613 0.5108085631812613 0.5108085631812613</scale>
          </mesh>
        </geometry>
      </visual>
    </link>


    <joint name=leaf_dirt_joint_7 type="revolute">
      <parent>dirt_link</parent>
      <child>leaf_stem_link_7</child>
      <axis>
        <xyz>0 1 0</xyz>
      </axis>
    </joint>

    <link name= leaf_stem_link_8 >
      <pose>0 0 0 0 -0.8630388046186832 -2.288124938014514 </pose>
      <inertial>
        <mass>1</mass>
        <inertia> <!-- Modeled as slender rod -->
          <ixx>1e-3</ixx>
          <ixy>0</ixy>
          <ixz>0</ixz>
          <iyy>8.333e-2</iyy>
          <iyz>0</iyz>
          <izz>8.333e-2</izz>
        </inertia>
      </inertial>
      <visual name="visual">
        <geometry>
          <mesh>
            <uri>model://random_strawberry_plant/meshes/leaf_stem2.stl</uri>
            <scale> 0.3865063560708972 0.3865063560708972 0.3865063560708972</scale>
          </mesh>
        </geometry>
        <material> <!-- Green -->
          <ambient>0.0 0.5 0.0 1.0</ambient>
          <diffuse>0.0 0.5 0.0 1.0</diffuse>
          <specular>0.1 0.1 0.1 1.0</specular>
        </material>
      </visual>
    </link>

    <link name= leaf_link_8_0 >
      <pose> -0.09911094330900147
             -0.11361339987896342
             0.17620554777388758 0
             0 -3.891778865964829  </pose>
      <inertial>
        <mass>0.018</mass>
        <inertia>
          <ixx>8.82e-6</ixx>
          <ixy>0</ixy>
          <ixz>0</ixz>
          <iyy>8.82e-6</iyy>
          <iyz>0</iyz>
          <izz>8.82e-6</izz>
        </inertia>
      </inertial>
      <visual name="visual">
        <geometry>
          <mesh>
            <uri>model://random_strawberry_plant/meshes/leaf3.dae</uri>
            <scale> 0.5402983930656294 0.5402983930656294 0.5402983930656294</scale>
          </mesh>
        </geometry>
      </visual>
    </link>

    <link name= leaf_link_8_1 >
      <pose> -0.09911094330900147
             -0.11361339987896342
             0.17620554777388758 0
             0 -2.4126742035519815  </pose>
      <inertial>
        <mass>0.018</mass>
        <inertia>
          <ixx>8.82e-6</ixx>
          <ixy>0</ixy>
          <ixz>0</ixz>
          <iyy>8.82e-6</iyy>
          <iyz>0</iyz>
          <izz>8.82e-6</izz>
        </inertia>
      </inertial>
      <visual name="visual">
        <geometry>
          <mesh>
            <uri>model://random_strawberry_plant/meshes/leaf4.dae</uri>
            <scale> 0.5402983930656294 0.5402983930656294 0.5402983930656294</scale>
          </mesh>
        </geometry>
      </visual>
    </link>

    <link name= leaf_link_8_2 >
      <pose> -0.09911094330900147
             -0.11361339987896342
             0.17620554777388758 0
             0 -0.4869955570001161  </pose>
      <inertial>
        <mass>0.018</mass>
        <inertia>
          <ixx>8.82e-6</ixx>
          <ixy>0</ixy>
          <ixz>0</ixz>
          <iyy>8.82e-6</iyy>
          <iyz>0</iyz>
          <izz>8.82e-6</izz>
        </inertia>
      </inertial>
      <visual name="visual">
        <geometry>
          <mesh>
            <uri>model://random_strawberry_plant/meshes/leaf3.dae</uri>
            <scale> 0.5402983930656294 0.5402983930656294 0.5402983930656294</scale>
          </mesh>
        </geometry>
      </visual>
    </link>


    <joint name=leaf_dirt_joint_8 type="revolute">
      <parent>dirt_link</parent>
      <child>leaf_stem_link_8</child>
      <axis>
        <xyz>0 1 0</xyz>
      </axis>
    </joint>

    <link name= leaf_stem_link_9 >
      <pose>0 0 0 0 -1.1133129409365055 0.35400472716877207 </pose>
      <inertial>
        <mass>1</mass>
        <inertia> <!-- Modeled as slender rod -->
          <ixx>1e-3</ixx>
          <ixy>0</ixy>
          <ixz>0</ixz>
          <iyy>8.333e-2</iyy>
          <iyz>0</iyz>
          <izz>8.333e-2</izz>
        </inertia>
      </inertial>
      <visual name="visual">
        <geometry>
          <mesh>
            <uri>model://random_strawberry_plant/meshes/leaf_stem2.stl</uri>
            <scale> 0.2818700664730991 0.2818700664730991 0.2818700664730991</scale>
          </mesh>
        </geometry>
        <material> <!-- Green -->
          <ambient>0.0 0.5 0.0 1.0</ambient>
          <diffuse>0.0 0.5 0.0 1.0</diffuse>
          <specular>0.1 0.1 0.1 1.0</specular>
        </material>
      </visual>
    </link>

    <link name= leaf_link_9_0 >
      <pose> 0.07006781154331108
             0.025895206591375116
             0.15173069707741674 0
             0 -0.9759422902851265  </pose>
      <inertial>
        <mass>0.018</mass>
        <inertia>
          <ixx>8.82e-6</ixx>
          <ixy>0</ixy>
          <ixz>0</ixz>
          <iyy>8.82e-6</iyy>
          <iyz>0</iyz>
          <izz>8.82e-6</izz>
        </inertia>
      </inertial>
      <visual name="visual">
        <geometry>
          <mesh>
            <uri>model://random_strawberry_plant/meshes/leaf2.dae</uri>
            <scale> 0.5352703213330978 0.5352703213330978 0.5352703213330978</scale>
          </mesh>
        </geometry>
      </visual>
    </link>

    <link name= leaf_link_9_1 >
      <pose> 0.07006781154331108
             0.025895206591375116
             0.15173069707741674 0
             0 0.46477301850757896  </pose>
      <inertial>
        <mass>0.018</mass>
        <inertia>
          <ixx>8.82e-6</ixx>
          <ixy>0</ixy>
          <ixz>0</ixz>
          <iyy>8.82e-6</iyy>
          <iyz>0</iyz>
          <izz>8.82e-6</izz>
        </inertia>
      </inertial>
      <visual name="visual">
        <geometry>
          <mesh>
            <uri>model://random_strawberry_plant/meshes/leaf3.dae</uri>
            <scale> 0.5352703213330978 0.5352703213330978 0.5352703213330978</scale>
          </mesh>
        </geometry>
      </visual>
    </link>

    <link name= leaf_link_9_2 >
      <pose> 0.07006781154331108
             0.025895206591375116
             0.15173069707741674 0
             0 1.9030853534177665  </pose>
      <inertial>
        <mass>0.018</mass>
        <inertia>
          <ixx>8.82e-6</ixx>
          <ixy>0</ixy>
          <ixz>0</ixz>
          <iyy>8.82e-6</iyy>
          <iyz>0</iyz>
          <izz>8.82e-6</izz>
        </inertia>
      </inertial>
      <visual name="visual">
        <geometry>
          <mesh>
            <uri>model://random_strawberry_plant/meshes/leaf1.dae</uri>
            <scale> 0.5352703213330978 0.5352703213330978 0.5352703213330978</scale>
          </mesh>
        </geometry>
      </visual>
    </link>


    <joint name=leaf_dirt_joint_9 type="revolute">
      <parent>dirt_link</parent>
      <child>leaf_stem_link_9</child>
      <axis>
        <xyz>0 1 0</xyz>
      </axis>
    </joint>

    <link name= leaf_stem_link_10 >
      <pose>0 0 0 0 -0.9545025481140232 0.06533924903610044 </pose>
      <inertial>
        <mass>1</mass>
        <inertia> <!-- Modeled as slender rod -->
          <ixx>1e-3</ixx>
          <ixy>0</ixy>
          <ixz>0</ixz>
          <iyy>8.333e-2</iyy>
          <iyz>0</iyz>
          <izz>8.333e-2</izz>
        </inertia>
      </inertial>
      <visual name="visual">
        <geometry>
          <mesh>
            <uri>model://random_strawberry_plant/meshes/leaf_stem2.stl</uri>
            <scale> 0.33518585347568575 0.33518585347568575 0.33518585347568575</scale>
          </mesh>
        </geometry>
        <material> <!-- Green -->
          <ambient>0.0 0.5 0.0 1.0</ambient>
          <diffuse>0.0 0.5 0.0 1.0</diffuse>
          <specular>0.1 0.1 0.1 1.0</specular>
        </material>
      </visual>
    </link>

    <link name= leaf_link_10_0 >
      <pose> 0.11599737280464457
             0.007589985404030319
             0.16411228448007023 0
             0 -1.595174527046313  </pose>
      <inertial>
        <mass>0.018</mass>
        <inertia>
          <ixx>8.82e-6</ixx>
          <ixy>0</ixy>
          <ixz>0</ixz>
          <iyy>8.82e-6</iyy>
          <iyz>0</iyz>
          <izz>8.82e-6</izz>
        </inertia>
      </inertial>
      <visual name="visual">
        <geometry>
          <mesh>
            <uri>model://random_strawberry_plant/meshes/leaf3.dae</uri>
            <scale> 0.6779593019640788 0.6779593019640788 0.6779593019640788</scale>
          </mesh>
        </geometry>
      </visual>
    </link>

    <link name= leaf_link_10_1 >
      <pose> 0.11599737280464457
             0.007589985404030319
             0.16411228448007023 0
             0 0.009972691750179868  </pose>
      <inertial>
        <mass>0.018</mass>
        <inertia>
          <ixx>8.82e-6</ixx>
          <ixy>0</ixy>
          <ixz>0</ixz>
          <iyy>8.82e-6</iyy>
          <iyz>0</iyz>
          <izz>8.82e-6</izz>
        </inertia>
      </inertial>
      <visual name="visual">
        <geometry>
          <mesh>
            <uri>model://random_strawberry_plant/meshes/leaf1.dae</uri>
            <scale> 0.6779593019640788 0.6779593019640788 0.6779593019640788</scale>
          </mesh>
        </geometry>
      </visual>
    </link>

    <link name= leaf_link_10_2 >
      <pose> 0.11599737280464457
             0.007589985404030319
             0.16411228448007023 0
             0 1.6238354660870644  </pose>
      <inertial>
        <mass>0.018</mass>
        <inertia>
          <ixx>8.82e-6</ixx>
          <ixy>0</ixy>
          <ixz>0</ixz>
          <iyy>8.82e-6</iyy>
          <iyz>0</iyz>
          <izz>8.82e-6</izz>
        </inertia>
      </inertial>
      <visual name="visual">
        <geometry>
          <mesh>
            <uri>model://random_strawberry_plant/meshes/leaf1.dae</uri>
            <scale> 0.6779593019640788 0.6779593019640788 0.6779593019640788</scale>
          </mesh>
        </geometry>
      </visual>
    </link>


    <joint name=leaf_dirt_joint_10 type="revolute">
      <parent>dirt_link</parent>
      <child>leaf_stem_link_10</child>
      <axis>
        <xyz>0 1 0</xyz>
      </axis>
    </joint>

    <link name= leaf_stem_link_11 >
      <pose>0 0 0 0 -0.6506904805951031 1.92404655457349 </pose>
      <inertial>
        <mass>1</mass>
        <inertia> <!-- Modeled as slender rod -->
          <ixx>1e-3</ixx>
          <ixy>0</ixy>
          <ixz>0</ixz>
          <iyy>8.333e-2</iyy>
          <iyz>0</iyz>
          <izz>8.333e-2</izz>
        </inertia>
      </inertial>
      <visual name="visual">
        <geometry>
          <mesh>
            <uri>model://random_strawberry_plant/meshes/leaf_stem1.stl</uri>
            <scale> 0.24762125875347987 0.24762125875347987 0.24762125875347987</scale>
          </mesh>
        </geometry>
        <material> <!-- Green -->
          <ambient>0.0 0.5 0.0 1.0</ambient>
          <diffuse>0.0 0.5 0.0 1.0</diffuse>
          <specular>0.1 0.1 0.1 1.0</specular>
        </material>
      </visual>
    </link>

    <link name= leaf_link_11_0 >
      <pose> -0.040896121617674384
             0.11091490617779695
             0.08999585783467869 0
             0 0.3336286835864355  </pose>
      <inertial>
        <mass>0.018</mass>
        <inertia>
          <ixx>8.82e-6</ixx>
          <ixy>0</ixy>
          <ixz>0</ixz>
          <iyy>8.82e-6</iyy>
          <iyz>0</iyz>
          <izz>8.82e-6</izz>
        </inertia>
      </inertial>
      <visual name="visual">
        <geometry>
          <mesh>
            <uri>model://random_strawberry_plant/meshes/leaf2.dae</uri>
            <scale> 0.47821435243142146 0.47821435243142146 0.47821435243142146</scale>
          </mesh>
        </geometry>
      </visual>
    </link>

    <link name= leaf_link_11_1 >
      <pose> -0.040896121617674384
             0.11091490617779695
             0.08999585783467869 0
             0 1.9993377194094306  </pose>
      <inertial>
        <mass>0.018</mass>
        <inertia>
          <ixx>8.82e-6</ixx>
          <ixy>0</ixy>
          <ixz>0</ixz>
          <iyy>8.82e-6</iyy>
          <iyz>0</iyz>
          <izz>8.82e-6</izz>
        </inertia>
      </inertial>
      <visual name="visual">
        <geometry>
          <mesh>
            <uri>model://random_strawberry_plant/meshes/leaf4.dae</uri>
            <scale> 0.47821435243142146 0.47821435243142146 0.47821435243142146</scale>
          </mesh>
        </geometry>
      </visual>
    </link>

    <link name= leaf_link_11_2 >
      <pose> -0.040896121617674384
             0.11091490617779695
             0.08999585783467869 0
             0 3.5846704145741004  </pose>
      <inertial>
        <mass>0.018</mass>
        <inertia>
          <ixx>8.82e-6</ixx>
          <ixy>0</ixy>
          <ixz>0</ixz>
          <iyy>8.82e-6</iyy>
          <iyz>0</iyz>
          <izz>8.82e-6</izz>
        </inertia>
      </inertial>
      <visual name="visual">
        <geometry>
          <mesh>
            <uri>model://random_strawberry_plant/meshes/leaf4.dae</uri>
            <scale> 0.47821435243142146 0.47821435243142146 0.47821435243142146</scale>
          </mesh>
        </geometry>
      </visual>
    </link>


    <joint name=leaf_dirt_joint_11 type="revolute">
      <parent>dirt_link</parent>
      <child>leaf_stem_link_11</child>
      <axis>
        <xyz>0 1 0</xyz>
      </axis>
    </joint>

    <link name= leaf_stem_link_12 >
      <pose>0 0 0 0 -0.7723598817963848 -1.2137573586644297 </pose>
      <inertial>
        <mass>1</mass>
        <inertia> <!-- Modeled as slender rod -->
          <ixx>1e-3</ixx>
          <ixy>0</ixy>
          <ixz>0</ixz>
          <iyy>8.333e-2</iyy>
          <iyz>0</iyz>
          <izz>8.333e-2</izz>
        </inertia>
      </inertial>
      <visual name="visual">
        <geometry>
          <mesh>
            <uri>model://random_strawberry_plant/meshes/leaf_stem1.stl</uri>
            <scale> 0.3637169121881607 0.3637169121881607 0.3637169121881607</scale>
          </mesh>
        </geometry>
        <material> <!-- Green -->
          <ambient>0.0 0.5 0.0 1.0</ambient>
          <diffuse>0.0 0.5 0.0 1.0</diffuse>
          <specular>0.1 0.1 0.1 1.0</specular>
        </material>
      </visual>
    </link>

    <link name= leaf_link_12_0 >
      <pose> 0.054630857405573566
             -0.146453193715431
             0.15228699440822516 0
             0 -2.8898964386805313  </pose>
      <inertial>
        <mass>0.018</mass>
        <inertia>
          <ixx>8.82e-6</ixx>
          <ixy>0</ixy>
          <ixz>0</ixz>
          <iyy>8.82e-6</iyy>
          <iyz>0</iyz>
          <izz>8.82e-6</izz>
        </inertia>
      </inertial>
      <visual name="visual">
        <geometry>
          <mesh>
            <uri>model://random_strawberry_plant/meshes/leaf3.dae</uri>
            <scale> 0.6096899534690521 0.6096899534690521 0.6096899534690521</scale>
          </mesh>
        </geometry>
      </visual>
    </link>

    <link name= leaf_link_12_1 >
      <pose> 0.054630857405573566
             -0.146453193715431
             0.15228699440822516 0
             0 -1.2768193634890603  </pose>
      <inertial>
        <mass>0.018</mass>
        <inertia>
          <ixx>8.82e-6</ixx>
          <ixy>0</ixy>
          <ixz>0</ixz>
          <iyy>8.82e-6</iyy>
          <iyz>0</iyz>
          <izz>8.82e-6</izz>
        </inertia>
      </inertial>
      <visual name="visual">
        <geometry>
          <mesh>
            <uri>model://random_strawberry_plant/meshes/leaf5.dae</uri>
            <scale> 0.6096899534690521 0.6096899534690521 0.6096899534690521</scale>
          </mesh>
        </geometry>
      </visual>
    </link>

    <link name= leaf_link_12_2 >
      <pose> 0.054630857405573566
             -0.146453193715431
             0.15228699440822516 0
             0 0.45808499255266666  </pose>
      <inertial>
        <mass>0.018</mass>
        <inertia>
          <ixx>8.82e-6</ixx>
          <ixy>0</ixy>
          <ixz>0</ixz>
          <iyy>8.82e-6</iyy>
          <iyz>0</iyz>
          <izz>8.82e-6</izz>
        </inertia>
      </inertial>
      <visual name="visual">
        <geometry>
          <mesh>
            <uri>model://random_strawberry_plant/meshes/leaf5.dae</uri>
            <scale> 0.6096899534690521 0.6096899534690521 0.6096899534690521</scale>
          </mesh>
        </geometry>
      </visual>
    </link>


    <joint name=leaf_dirt_joint_12 type="revolute">
      <parent>dirt_link</parent>
      <child>leaf_stem_link_12</child>
      <axis>
        <xyz>0 1 0</xyz>
      </axis>
    </joint>

    <link name= leaf_stem_link_13 >
      <pose>0 0 0 0 -0.8641395243225288 -0.7618480812941404 </pose>
      <inertial>
        <mass>1</mass>
        <inertia> <!-- Modeled as slender rod -->
          <ixx>1e-3</ixx>
          <ixy>0</ixy>
          <ixz>0</ixz>
          <iyy>8.333e-2</iyy>
          <iyz>0</iyz>
          <izz>8.333e-2</izz>
        </inertia>
      </inertial>
      <visual name="visual">
        <geometry>
          <mesh>
            <uri>model://random_strawberry_plant/meshes/leaf_stem2.stl</uri>
            <scale> 0.2186058818976514 0.2186058818976514 0.2186058818976514</scale>
          </mesh>
        </geometry>
        <material> <!-- Green -->
          <ambient>0.0 0.5 0.0 1.0</ambient>
          <diffuse>0.0 0.5 0.0 1.0</diffuse>
          <specular>0.1 0.1 0.1 1.0</specular>
        </material>
      </visual>
    </link>

    <link name= leaf_link_13_0 >
      <pose> 0.06162125078988468
             -0.05878514593460276
             0.09975469635374347 0
             0 -2.347094144360245  </pose>
      <inertial>
        <mass>0.018</mass>
        <inertia>
          <ixx>8.82e-6</ixx>
          <ixy>0</ixy>
          <ixz>0</ixz>
          <iyy>8.82e-6</iyy>
          <iyz>0</iyz>
          <izz>8.82e-6</izz>
        </inertia>
      </inertial>
      <visual name="visual">
        <geometry>
          <mesh>
            <uri>model://random_strawberry_plant/meshes/leaf1.dae</uri>
            <scale> 0.5981637911573462 0.5981637911573462 0.5981637911573462</scale>
          </mesh>
        </geometry>
      </visual>
    </link>

    <link name= leaf_link_13_1 >
      <pose> 0.06162125078988468
             -0.05878514593460276
             0.09975469635374347 0
             0 -0.7996832786361577  </pose>
      <inertial>
        <mass>0.018</mass>
        <inertia>
          <ixx>8.82e-6</ixx>
          <ixy>0</ixy>
          <ixz>0</ixz>
          <iyy>8.82e-6</iyy>
          <iyz>0</iyz>
          <izz>8.82e-6</izz>
        </inertia>
      </inertial>
      <visual name="visual">
        <geometry>
          <mesh>
            <uri>model://random_strawberry_plant/meshes/leaf3.dae</uri>
            <scale> 0.5981637911573462 0.5981637911573462 0.5981637911573462</scale>
          </mesh>
        </geometry>
      </visual>
    </link>

    <link name= leaf_link_13_2 >
      <pose> 0.06162125078988468
             -0.05878514593460276
             0.09975469635374347 0
             0 0.8155249559532474  </pose>
      <inertial>
        <mass>0.018</mass>
        <inertia>
          <ixx>8.82e-6</ixx>
          <ixy>0</ixy>
          <ixz>0</ixz>
          <iyy>8.82e-6</iyy>
          <iyz>0</iyz>
          <izz>8.82e-6</izz>
        </inertia>
      </inertial>
      <visual name="visual">
        <geometry>
          <mesh>
            <uri>model://random_strawberry_plant/meshes/leaf3.dae</uri>
            <scale> 0.5981637911573462 0.5981637911573462 0.5981637911573462</scale>
          </mesh>
        </geometry>
      </visual>
    </link>


    <joint name=leaf_dirt_joint_13 type="revolute">
      <parent>dirt_link</parent>
      <child>leaf_stem_link_13</child>
      <axis>
        <xyz>0 1 0</xyz>
      </axis>
    </joint>

    <link name= leaf_stem_link_14 >
      <pose>0 0 0 0 -0.9826447846882158 -0.7331655962777663 </pose>
      <inertial>
        <mass>1</mass>
        <inertia> <!-- Modeled as slender rod -->
          <ixx>1e-3</ixx>
          <ixy>0</ixy>
          <ixz>0</ixz>
          <iyy>8.333e-2</iyy>
          <iyz>0</iyz>
          <izz>8.333e-2</izz>
        </inertia>
      </inertial>
      <visual name="visual">
        <geometry>
          <mesh>
            <uri>model://random_strawberry_plant/meshes/leaf_stem2.stl</uri>
            <scale> 0.31925699720586725 0.31925699720586725 0.31925699720586725</scale>
          </mesh>
        </geometry>
        <material> <!-- Green -->
          <ambient>0.0 0.5 0.0 1.0</ambient>
          <diffuse>0.0 0.5 0.0 1.0</diffuse>
          <specular>0.1 0.1 0.1 1.0</specular>
        </material>
      </visual>
    </link>

    <link name= leaf_link_14_0 >
      <pose> 0.07897155175843125
             -0.07112451155304145
             0.1593668998398766 0
             0 -2.5154588719809823  </pose>
      <inertial>
        <mass>0.018</mass>
        <inertia>
          <ixx>8.82e-6</ixx>
          <ixy>0</ixy>
          <ixz>0</ixz>
          <iyy>8.82e-6</iyy>
          <iyz>0</iyz>
          <izz>8.82e-6</izz>
        </inertia>
      </inertial>
      <visual name="visual">
        <geometry>
          <mesh>
            <uri>model://random_strawberry_plant/meshes/leaf4.dae</uri>
            <scale> 0.42586324919437246 0.42586324919437246 0.42586324919437246</scale>
          </mesh>
        </geometry>
      </visual>
    </link>

    <link name= leaf_link_14_1 >
      <pose> 0.07897155175843125
             -0.07112451155304145
             0.1593668998398766 0
             0 -0.8026494106279134  </pose>
      <inertial>
        <mass>0.018</mass>
        <inertia>
          <ixx>8.82e-6</ixx>
          <ixy>0</ixy>
          <ixz>0</ixz>
          <iyy>8.82e-6</iyy>
          <iyz>0</iyz>
          <izz>8.82e-6</izz>
        </inertia>
      </inertial>
      <visual name="visual">
        <geometry>
          <mesh>
            <uri>model://random_strawberry_plant/meshes/leaf1.dae</uri>
            <scale> 0.42586324919437246 0.42586324919437246 0.42586324919437246</scale>
          </mesh>
        </geometry>
      </visual>
    </link>

    <link name= leaf_link_14_2 >
      <pose> 0.07897155175843125
             -0.07112451155304145
             0.1593668998398766 0
             0 0.8898239606107152  </pose>
      <inertial>
        <mass>0.018</mass>
        <inertia>
          <ixx>8.82e-6</ixx>
          <ixy>0</ixy>
          <ixz>0</ixz>
          <iyy>8.82e-6</iyy>
          <iyz>0</iyz>
          <izz>8.82e-6</izz>
        </inertia>
      </inertial>
      <visual name="visual">
        <geometry>
          <mesh>
            <uri>model://random_strawberry_plant/meshes/leaf4.dae</uri>
            <scale> 0.42586324919437246 0.42586324919437246 0.42586324919437246</scale>
          </mesh>
        </geometry>
      </visual>
    </link>


    <joint name=leaf_dirt_joint_14 type="revolute">
      <parent>dirt_link</parent>
      <child>leaf_stem_link_14</child>
      <axis>
        <xyz>0 1 0</xyz>
      </axis>
    </joint>

    <link name= leaf_stem_link_15 >
      <pose>0 0 0 0 -0.6478650714954657 -2.257509018298003 </pose>
      <inertial>
        <mass>1</mass>
        <inertia> <!-- Modeled as slender rod -->
          <ixx>1e-3</ixx>
          <ixy>0</ixy>
          <ixz>0</ixz>
          <iyy>8.333e-2</iyy>
          <iyz>0</iyz>
          <izz>8.333e-2</izz>
        </inertia>
      </inertial>
      <visual name="visual">
        <geometry>
          <mesh>
            <uri>model://random_strawberry_plant/meshes/leaf_stem1.stl</uri>
            <scale> 0.28882046014142054 0.28882046014142054 0.28882046014142054</scale>
          </mesh>
        </geometry>
        <material> <!-- Green -->
          <ambient>0.0 0.5 0.0 1.0</ambient>
          <diffuse>0.0 0.5 0.0 1.0</diffuse>
          <specular>0.1 0.1 0.1 1.0</specular>
        </material>
      </visual>
    </link>

    <link name= leaf_link_15_0 >
      <pose> -0.08760511453758256
             -0.10685837805878134
             0.1045793664934545 0
             0 -3.8364265752687645  </pose>
      <inertial>
        <mass>0.018</mass>
        <inertia>
          <ixx>8.82e-6</ixx>
          <ixy>0</ixy>
          <ixz>0</ixz>
          <iyy>8.82e-6</iyy>
          <iyz>0</iyz>
          <izz>8.82e-6</izz>
        </inertia>
      </inertial>
      <visual name="visual">
        <geometry>
          <mesh>
            <uri>model://random_strawberry_plant/meshes/leaf3.dae</uri>
            <scale> 0.5351830596366407 0.5351830596366407 0.5351830596366407</scale>
          </mesh>
        </geometry>
      </visual>
    </link>

    <link name= leaf_link_15_1 >
      <pose> -0.08760511453758256
             -0.10685837805878134
             0.1045793664934545 0
             0 -2.2649455182633287  </pose>
      <inertial>
        <mass>0.018</mass>
        <inertia>
          <ixx>8.82e-6</ixx>
          <ixy>0</ixy>
          <ixz>0</ixz>
          <iyy>8.82e-6</iyy>
          <iyz>0</iyz>
          <izz>8.82e-6</izz>
        </inertia>
      </inertial>
      <visual name="visual">
        <geometry>
          <mesh>
            <uri>model://random_strawberry_plant/meshes/leaf1.dae</uri>
            <scale> 0.5351830596366407 0.5351830596366407 0.5351830596366407</scale>
          </mesh>
        </geometry>
      </visual>
    </link>

    <link name= leaf_link_15_2 >
      <pose> -0.08760511453758256
             -0.10685837805878134
             0.1045793664934545 0
             0 -0.7995469768021988  </pose>
      <inertial>
        <mass>0.018</mass>
        <inertia>
          <ixx>8.82e-6</ixx>
          <ixy>0</ixy>
          <ixz>0</ixz>
          <iyy>8.82e-6</iyy>
          <iyz>0</iyz>
          <izz>8.82e-6</izz>
        </inertia>
      </inertial>
      <visual name="visual">
        <geometry>
          <mesh>
            <uri>model://random_strawberry_plant/meshes/leaf2.dae</uri>
            <scale> 0.5351830596366407 0.5351830596366407 0.5351830596366407</scale>
          </mesh>
        </geometry>
      </visual>
    </link>


    <joint name=leaf_dirt_joint_15 type="revolute">
      <parent>dirt_link</parent>
      <child>leaf_stem_link_15</child>
      <axis>
        <xyz>0 1 0</xyz>
      </axis>
    </joint>

    <link name= leaf_stem_link_16 >
      <pose>0 0 0 0 -0.41562697501338564 -0.5706623813435994 </pose>
      <inertial>
        <mass>1</mass>
        <inertia> <!-- Modeled as slender rod -->
          <ixx>1e-3</ixx>
          <ixy>0</ixy>
          <ixz>0</ixz>
          <iyy>8.333e-2</iyy>
          <iyz>0</iyz>
          <izz>8.333e-2</izz>
        </inertia>
      </inertial>
      <visual name="visual">
        <geometry>
          <mesh>
            <uri>model://random_strawberry_plant/meshes/leaf_stem1.stl</uri>
            <scale> 0.35872796037132587 0.35872796037132587 0.35872796037132587</scale>
          </mesh>
        </geometry>
        <material> <!-- Green -->
          <ambient>0.0 0.5 0.0 1.0</ambient>
          <diffuse>0.0 0.5 0.0 1.0</diffuse>
          <specular>0.1 0.1 0.1 1.0</specular>
        </material>
      </visual>
    </link>

    <link name= leaf_link_16_0 >
      <pose> 0.1657101843181645
             -0.10636994122242963
             0.08690477694786723 0
             0 -2.0397341463219503  </pose>
      <inertial>
        <mass>0.018</mass>
        <inertia>
          <ixx>8.82e-6</ixx>
          <ixy>0</ixy>
          <ixz>0</ixz>
          <iyy>8.82e-6</iyy>
          <iyz>0</iyz>
          <izz>8.82e-6</izz>
        </inertia>
      </inertial>
      <visual name="visual">
        <geometry>
          <mesh>
            <uri>model://random_strawberry_plant/meshes/leaf5.dae</uri>
            <scale> 0.5407238255603626 0.5407238255603626 0.5407238255603626</scale>
          </mesh>
        </geometry>
      </visual>
    </link>

    <link name= leaf_link_16_1 >
      <pose> 0.1657101843181645
             -0.10636994122242963
             0.08690477694786723 0
             0 -0.5020228500786633  </pose>
      <inertial>
        <mass>0.018</mass>
        <inertia>
          <ixx>8.82e-6</ixx>
          <ixy>0</ixy>
          <ixz>0</ixz>
          <iyy>8.82e-6</iyy>
          <iyz>0</iyz>
          <izz>8.82e-6</izz>
        </inertia>
      </inertial>
      <visual name="visual">
        <geometry>
          <mesh>
            <uri>model://random_strawberry_plant/meshes/leaf3.dae</uri>
            <scale> 0.5407238255603626 0.5407238255603626 0.5407238255603626</scale>
          </mesh>
        </geometry>
      </visual>
    </link>

    <link name= leaf_link_16_2 >
      <pose> 0.1657101843181645
             -0.10636994122242963
             0.08690477694786723 0
             0 0.8726329699201685  </pose>
      <inertial>
        <mass>0.018</mass>
        <inertia>
          <ixx>8.82e-6</ixx>
          <ixy>0</ixy>
          <ixz>0</ixz>
          <iyy>8.82e-6</iyy>
          <iyz>0</iyz>
          <izz>8.82e-6</izz>
        </inertia>
      </inertial>
      <visual name="visual">
        <geometry>
          <mesh>
            <uri>model://random_strawberry_plant/meshes/leaf1.dae</uri>
            <scale> 0.5407238255603626 0.5407238255603626 0.5407238255603626</scale>
          </mesh>
        </geometry>
      </visual>
    </link>


    <joint name=leaf_dirt_joint_16 type="revolute">
      <parent>dirt_link</parent>
      <child>leaf_stem_link_16</child>
      <axis>
        <xyz>0 1 0</xyz>
      </axis>
    </joint>

    <link name= leaf_stem_link_17 >
      <pose>0 0 0 0 -0.5718574611986739 3.013776167233801 </pose>
      <inertial>
        <mass>1</mass>
        <inertia> <!-- Modeled as slender rod -->
          <ixx>1e-3</ixx>
          <ixy>0</ixy>
          <ixz>0</ixz>
          <iyy>8.333e-2</iyy>
          <iyz>0</iyz>
          <izz>8.333e-2</izz>
        </inertia>
      </inertial>
      <visual name="visual">
        <geometry>
          <mesh>
            <uri>model://random_strawberry_plant/meshes/leaf_stem1.stl</uri>
            <scale> 0.21087097046263503 0.21087097046263503 0.21087097046263503</scale>
          </mesh>
        </geometry>
        <material> <!-- Green -->
          <ambient>0.0 0.5 0.0 1.0</ambient>
          <diffuse>0.0 0.5 0.0 1.0</diffuse>
          <specular>0.1 0.1 0.1 1.0</specular>
        </material>
      </visual>
    </link>

    <link name= leaf_link_17_0 >
      <pose> -0.1055245950165314
             0.013561716351980498
             0.06847337820184364 0
             0 1.5235555267567855  </pose>
      <inertial>
        <mass>0.018</mass>
        <inertia>
          <ixx>8.82e-6</ixx>
          <ixy>0</ixy>
          <ixz>0</ixz>
          <iyy>8.82e-6</iyy>
          <iyz>0</iyz>
          <izz>8.82e-6</izz>
        </inertia>
      </inertial>
      <visual name="visual">
        <geometry>
          <mesh>
            <uri>model://random_strawberry_plant/meshes/leaf1.dae</uri>
            <scale> 0.7085791112664566 0.7085791112664566 0.7085791112664566</scale>
          </mesh>
        </geometry>
      </visual>
    </link>

    <link name= leaf_link_17_1 >
      <pose> -0.1055245950165314
             0.013561716351980498
             0.06847337820184364 0
             0 2.9710188756743845  </pose>
      <inertial>
        <mass>0.018</mass>
        <inertia>
          <ixx>8.82e-6</ixx>
          <ixy>0</ixy>
          <ixz>0</ixz>
          <iyy>8.82e-6</iyy>
          <iyz>0</iyz>
          <izz>8.82e-6</izz>
        </inertia>
      </inertial>
      <visual name="visual">
        <geometry>
          <mesh>
            <uri>model://random_strawberry_plant/meshes/leaf3.dae</uri>
            <scale> 0.7085791112664566 0.7085791112664566 0.7085791112664566</scale>
          </mesh>
        </geometry>
      </visual>
    </link>

    <link name= leaf_link_17_2 >
      <pose> -0.1055245950165314
             0.013561716351980498
             0.06847337820184364 0
             0 4.568267235162955  </pose>
      <inertial>
        <mass>0.018</mass>
        <inertia>
          <ixx>8.82e-6</ixx>
          <ixy>0</ixy>
          <ixz>0</ixz>
          <iyy>8.82e-6</iyy>
          <iyz>0</iyz>
          <izz>8.82e-6</izz>
        </inertia>
      </inertial>
      <visual name="visual">
        <geometry>
          <mesh>
            <uri>model://random_strawberry_plant/meshes/leaf2.dae</uri>
            <scale> 0.7085791112664566 0.7085791112664566 0.7085791112664566</scale>
          </mesh>
        </geometry>
      </visual>
    </link>


    <joint name=leaf_dirt_joint_17 type="revolute">
      <parent>dirt_link</parent>
      <child>leaf_stem_link_17</child>
      <axis>
        <xyz>0 1 0</xyz>
      </axis>
    </joint>

    <link name= leaf_stem_link_18 >
      <pose>0 0 0 0 -0.6119157098571455 2.6689878369211417 </pose>
      <inertial>
        <mass>1</mass>
        <inertia> <!-- Modeled as slender rod -->
          <ixx>1e-3</ixx>
          <ixy>0</ixy>
          <ixz>0</ixz>
          <iyy>8.333e-2</iyy>
          <iyz>0</iyz>
          <izz>8.333e-2</izz>
        </inertia>
      </inertial>
      <visual name="visual">
        <geometry>
          <mesh>
            <uri>model://random_strawberry_plant/meshes/leaf_stem1.stl</uri>
            <scale> 0.3579602651877291 0.3579602651877291 0.3579602651877291</scale>
          </mesh>
        </geometry>
        <material> <!-- Green -->
          <ambient>0.0 0.5 0.0 1.0</ambient>
          <diffuse>0.0 0.5 0.0 1.0</diffuse>
          <specular>0.1 0.1 0.1 1.0</specular>
        </material>
      </visual>
    </link>

    <link name= leaf_link_18_0 >
      <pose> -0.15653408054336088
             0.08002760757290919
             0.1233752899805225 0
             0 1.145506368050905  </pose>
      <inertial>
        <mass>0.018</mass>
        <inertia>
          <ixx>8.82e-6</ixx>
          <ixy>0</ixy>
          <ixz>0</ixz>
          <iyy>8.82e-6</iyy>
          <iyz>0</iyz>
          <izz>8.82e-6</izz>
        </inertia>
      </inertial>
      <visual name="visual">
        <geometry>
          <mesh>
            <uri>model://random_strawberry_plant/meshes/leaf5.dae</uri>
            <scale> 0.5797433866765063 0.5797433866765063 0.5797433866765063</scale>
          </mesh>
        </geometry>
      </visual>
    </link>

    <link name= leaf_link_18_1 >
      <pose> -0.15653408054336088
             0.08002760757290919
             0.1233752899805225 0
             0 2.610938312567507  </pose>
      <inertial>
        <mass>0.018</mass>
        <inertia>
          <ixx>8.82e-6</ixx>
          <ixy>0</ixy>
          <ixz>0</ixz>
          <iyy>8.82e-6</iyy>
          <iyz>0</iyz>
          <izz>8.82e-6</izz>
        </inertia>
      </inertial>
      <visual name="visual">
        <geometry>
          <mesh>
            <uri>model://random_strawberry_plant/meshes/leaf3.dae</uri>
            <scale> 0.5797433866765063 0.5797433866765063 0.5797433866765063</scale>
          </mesh>
        </geometry>
      </visual>
    </link>

    <link name= leaf_link_18_2 >
      <pose> -0.15653408054336088
             0.08002760757290919
             0.1233752899805225 0
             0 4.230969771620442  </pose>
      <inertial>
        <mass>0.018</mass>
        <inertia>
          <ixx>8.82e-6</ixx>
          <ixy>0</ixy>
          <ixz>0</ixz>
          <iyy>8.82e-6</iyy>
          <iyz>0</iyz>
          <izz>8.82e-6</izz>
        </inertia>
      </inertial>
      <visual name="visual">
        <geometry>
          <mesh>
            <uri>model://random_strawberry_plant/meshes/leaf1.dae</uri>
            <scale> 0.5797433866765063 0.5797433866765063 0.5797433866765063</scale>
          </mesh>
        </geometry>
      </visual>
    </link>


    <joint name=leaf_dirt_joint_18 type="revolute">
      <parent>dirt_link</parent>
      <child>leaf_stem_link_18</child>
      <axis>
        <xyz>0 1 0</xyz>
      </axis>
    </joint>

    <link name= leaf_stem_link_19 >
      <pose>0 0 0 0 -1.1990371883642879 -0.8389304458832978 </pose>
      <inertial>
        <mass>1</mass>
        <inertia> <!-- Modeled as slender rod -->
          <ixx>1e-3</ixx>
          <ixy>0</ixy>
          <ixz>0</ixz>
          <iyy>8.333e-2</iyy>
          <iyz>0</iyz>
          <izz>8.333e-2</izz>
        </inertia>
      </inertial>
      <visual name="visual">
        <geometry>
          <mesh>
            <uri>model://random_strawberry_plant/meshes/leaf_stem2.stl</uri>
            <scale> 0.16808342077942132 0.16808342077942132 0.16808342077942132</scale>
          </mesh>
        </geometry>
        <material> <!-- Green -->
          <ambient>0.0 0.5 0.0 1.0</ambient>
          <diffuse>0.0 0.5 0.0 1.0</diffuse>
          <specular>0.1 0.1 0.1 1.0</specular>
        </material>
      </visual>
    </link>

    <link name= leaf_link_19_0 >
      <pose> 0.02448118441051738
             -0.02725329785551039
             0.09396096236515138 0
             0 -2.411743626787988  </pose>
      <inertial>
        <mass>0.018</mass>
        <inertia>
          <ixx>8.82e-6</ixx>
          <ixy>0</ixy>
          <ixz>0</ixz>
          <iyy>8.82e-6</iyy>
          <iyz>0</iyz>
          <izz>8.82e-6</izz>
        </inertia>
      </inertial>
      <visual name="visual">
        <geometry>
          <mesh>
            <uri>model://random_strawberry_plant/meshes/leaf5.dae</uri>
            <scale> 0.8290777679860881 0.8290777679860881 0.8290777679860881</scale>
          </mesh>
        </geometry>
      </visual>
    </link>

    <link name= leaf_link_19_1 >
      <pose> 0.02448118441051738
             -0.02725329785551039
             0.09396096236515138 0
             0 -0.7849237448042414  </pose>
      <inertial>
        <mass>0.018</mass>
        <inertia>
          <ixx>8.82e-6</ixx>
          <ixy>0</ixy>
          <ixz>0</ixz>
          <iyy>8.82e-6</iyy>
          <iyz>0</iyz>
          <izz>8.82e-6</izz>
        </inertia>
      </inertial>
      <visual name="visual">
        <geometry>
          <mesh>
            <uri>model://random_strawberry_plant/meshes/leaf4.dae</uri>
            <scale> 0.8290777679860881 0.8290777679860881 0.8290777679860881</scale>
          </mesh>
        </geometry>
      </visual>
    </link>

    <link name= leaf_link_19_2 >
      <pose> 0.02448118441051738
             -0.02725329785551039
             0.09396096236515138 0
             0 0.5148099986088073  </pose>
      <inertial>
        <mass>0.018</mass>
        <inertia>
          <ixx>8.82e-6</ixx>
          <ixy>0</ixy>
          <ixz>0</ixz>
          <iyy>8.82e-6</iyy>
          <iyz>0</iyz>
          <izz>8.82e-6</izz>
        </inertia>
      </inertial>
      <visual name="visual">
        <geometry>
          <mesh>
            <uri>model://random_strawberry_plant/meshes/leaf2.dae</uri>
            <scale> 0.8290777679860881 0.8290777679860881 0.8290777679860881</scale>
          </mesh>
        </geometry>
      </visual>
    </link>


    <joint name=leaf_dirt_joint_19 type="revolute">
      <parent>dirt_link</parent>
      <child>leaf_stem_link_19</child>
      <axis>
        <xyz>0 1 0</xyz>
      </axis>
    </joint>

    <link name= leaf_stem_link_20 >
      <pose>0 0 0 0 -0.32688544800420427 -2.1894151847296586 </pose>
      <inertial>
        <mass>1</mass>
        <inertia> <!-- Modeled as slender rod -->
          <ixx>1e-3</ixx>
          <ixy>0</ixy>
          <ixz>0</ixz>
          <iyy>8.333e-2</iyy>
          <iyz>0</iyz>
          <izz>8.333e-2</izz>
        </inertia>
      </inertial>
      <visual name="visual">
        <geometry>
          <mesh>
            <uri>model://random_strawberry_plant/meshes/leaf_stem1.stl</uri>
            <scale> 0.29918648445732576 0.29918648445732576 0.29918648445732576</scale>
          </mesh>
        </geometry>
        <material> <!-- Green -->
          <ambient>0.0 0.5 0.0 1.0</ambient>
          <diffuse>0.0 0.5 0.0 1.0</diffuse>
          <specular>0.1 0.1 0.1 1.0</specular>
        </material>
      </visual>
    </link>

    <link name= leaf_link_20_0 >
      <pose> -0.09858838348627422
             -0.13850067861454443
             0.057640363968057315 0
             0 -3.6812827142595603  </pose>
      <inertial>
        <mass>0.018</mass>
        <inertia>
          <ixx>8.82e-6</ixx>
          <ixy>0</ixy>
          <ixz>0</ixz>
          <iyy>8.82e-6</iyy>
          <iyz>0</iyz>
          <izz>8.82e-6</izz>
        </inertia>
      </inertial>
      <visual name="visual">
        <geometry>
          <mesh>
            <uri>model://random_strawberry_plant/meshes/leaf3.dae</uri>
            <scale> 0.5135967930446085 0.5135967930446085 0.5135967930446085</scale>
          </mesh>
        </geometry>
      </visual>
    </link>

    <link name= leaf_link_20_1 >
      <pose> -0.09858838348627422
             -0.13850067861454443
             0.057640363968057315 0
             0 -2.1195188856154465  </pose>
      <inertial>
        <mass>0.018</mass>
        <inertia>
          <ixx>8.82e-6</ixx>
          <ixy>0</ixy>
          <ixz>0</ixz>
          <iyy>8.82e-6</iyy>
          <iyz>0</iyz>
          <izz>8.82e-6</izz>
        </inertia>
      </inertial>
      <visual name="visual">
        <geometry>
          <mesh>
            <uri>model://random_strawberry_plant/meshes/leaf1.dae</uri>
            <scale> 0.5135967930446085 0.5135967930446085 0.5135967930446085</scale>
          </mesh>
        </geometry>
      </visual>
    </link>

    <link name= leaf_link_20_2 >
      <pose> -0.09858838348627422
             -0.13850067861454443
             0.057640363968057315 0
             0 -0.5809773490402064  </pose>
      <inertial>
        <mass>0.018</mass>
        <inertia>
          <ixx>8.82e-6</ixx>
          <ixy>0</ixy>
          <ixz>0</ixz>
          <iyy>8.82e-6</iyy>
          <iyz>0</iyz>
          <izz>8.82e-6</izz>
        </inertia>
      </inertial>
      <visual name="visual">
        <geometry>
          <mesh>
            <uri>model://random_strawberry_plant/meshes/leaf4.dae</uri>
            <scale> 0.5135967930446085 0.5135967930446085 0.5135967930446085</scale>
          </mesh>
        </geometry>
      </visual>
    </link>


    <joint name=leaf_dirt_joint_20 type="revolute">
      <parent>dirt_link</parent>
      <child>leaf_stem_link_20</child>
      <axis>
        <xyz>0 1 0</xyz>
      </axis>
    </joint>

    <link name= leaf_stem_link_21 >
      <pose>0 0 0 0 -0.4985098564072087 -0.8772151449515007 </pose>
      <inertial>
        <mass>1</mass>
        <inertia> <!-- Modeled as slender rod -->
          <ixx>1e-3</ixx>
          <ixy>0</ixy>
          <ixz>0</ixz>
          <iyy>8.333e-2</iyy>
          <iyz>0</iyz>
          <izz>8.333e-2</izz>
        </inertia>
      </inertial>
      <visual name="visual">
        <geometry>
          <mesh>
            <uri>model://random_strawberry_plant/meshes/leaf_stem1.stl</uri>
            <scale> 0.34022615149268404 0.34022615149268404 0.34022615149268404</scale>
          </mesh>
        </geometry>
        <material> <!-- Green -->
          <ambient>0.0 0.5 0.0 1.0</ambient>
          <diffuse>0.0 0.5 0.0 1.0</diffuse>
          <specular>0.1 0.1 0.1 1.0</specular>
        </material>
      </visual>
    </link>

    <link name= leaf_link_21_0 >
      <pose> 0.11462021034167458
             -0.13786831092568105
             0.09760080184690195 0
             0 -2.385137144067707  </pose>
      <inertial>
        <mass>0.018</mass>
        <inertia>
          <ixx>8.82e-6</ixx>
          <ixy>0</ixy>
          <ixz>0</ixz>
          <iyy>8.82e-6</iyy>
          <iyz>0</iyz>
          <izz>8.82e-6</izz>
        </inertia>
      </inertial>
      <visual name="visual">
        <geometry>
          <mesh>
            <uri>model://random_strawberry_plant/meshes/leaf4.dae</uri>
            <scale> 0.5171173033750196 0.5171173033750196 0.5171173033750196</scale>
          </mesh>
        </geometry>
      </visual>
    </link>

    <link name= leaf_link_21_1 >
      <pose> 0.11462021034167458
             -0.13786831092568105
             0.09760080184690195 0
             0 -0.7748978965827055  </pose>
      <inertial>
        <mass>0.018</mass>
        <inertia>
          <ixx>8.82e-6</ixx>
          <ixy>0</ixy>
          <ixz>0</ixz>
          <iyy>8.82e-6</iyy>
          <iyz>0</iyz>
          <izz>8.82e-6</izz>
        </inertia>
      </inertial>
      <visual name="visual">
        <geometry>
          <mesh>
            <uri>model://random_strawberry_plant/meshes/leaf3.dae</uri>
            <scale> 0.5171173033750196 0.5171173033750196 0.5171173033750196</scale>
          </mesh>
        </geometry>
      </visual>
    </link>

    <link name= leaf_link_21_2 >
      <pose> 0.11462021034167458
             -0.13786831092568105
             0.09760080184690195 0
             0 0.7967120687818097  </pose>
      <inertial>
        <mass>0.018</mass>
        <inertia>
          <ixx>8.82e-6</ixx>
          <ixy>0</ixy>
          <ixz>0</ixz>
          <iyy>8.82e-6</iyy>
          <iyz>0</iyz>
          <izz>8.82e-6</izz>
        </inertia>
      </inertial>
      <visual name="visual">
        <geometry>
          <mesh>
            <uri>model://random_strawberry_plant/meshes/leaf1.dae</uri>
            <scale> 0.5171173033750196 0.5171173033750196 0.5171173033750196</scale>
          </mesh>
        </geometry>
      </visual>
    </link>


    <joint name=leaf_dirt_joint_21 type="revolute">
      <parent>dirt_link</parent>
      <child>leaf_stem_link_21</child>
      <axis>
        <xyz>0 1 0</xyz>
      </axis>
    </joint>

    <link name= leaf_stem_link_22 >
      <pose>0 0 0 0 -1.04807818220782 -2.279656227711879 </pose>
      <inertial>
        <mass>1</mass>
        <inertia> <!-- Modeled as slender rod -->
          <ixx>1e-3</ixx>
          <ixy>0</ixy>
          <ixz>0</ixz>
          <iyy>8.333e-2</iyy>
          <iyz>0</iyz>
          <izz>8.333e-2</izz>
        </inertia>
      </inertial>
      <visual name="visual">
        <geometry>
          <mesh>
            <uri>model://random_strawberry_plant/meshes/leaf_stem2.stl</uri>
            <scale> 0.12276220264524729 0.12276220264524729 0.12276220264524729</scale>
          </mesh>
        </geometry>
        <material> <!-- Green -->
          <ambient>0.0 0.5 0.0 1.0</ambient>
          <diffuse>0.0 0.5 0.0 1.0</diffuse>
          <specular>0.1 0.1 0.1 1.0</specular>
        </material>
      </visual>
    </link>

    <link name= leaf_link_22_0 >
      <pose> -0.023937729663256125
             -0.02791415025677451
             0.06382151939121848 0
             0 -3.8062259714937143  </pose>
      <inertial>
        <mass>0.018</mass>
        <inertia>
          <ixx>8.82e-6</ixx>
          <ixy>0</ixy>
          <ixz>0</ixz>
          <iyy>8.82e-6</iyy>
          <iyz>0</iyz>
          <izz>8.82e-6</izz>
        </inertia>
      </inertial>
      <visual name="visual">
        <geometry>
          <mesh>
            <uri>model://random_strawberry_plant/meshes/leaf4.dae</uri>
            <scale> 0.4444204603386976 0.4444204603386976 0.4444204603386976</scale>
          </mesh>
        </geometry>
      </visual>
    </link>

    <link name= leaf_link_22_1 >
      <pose> -0.023937729663256125
             -0.02791415025677451
             0.06382151939121848 0
             0 -2.3006124157350296  </pose>
      <inertial>
        <mass>0.018</mass>
        <inertia>
          <ixx>8.82e-6</ixx>
          <ixy>0</ixy>
          <ixz>0</ixz>
          <iyy>8.82e-6</iyy>
          <iyz>0</iyz>
          <izz>8.82e-6</izz>
        </inertia>
      </inertial>
      <visual name="visual">
        <geometry>
          <mesh>
            <uri>model://random_strawberry_plant/meshes/leaf3.dae</uri>
            <scale> 0.4444204603386976 0.4444204603386976 0.4444204603386976</scale>
          </mesh>
        </geometry>
      </visual>
    </link>

    <link name= leaf_link_22_2 >
      <pose> -0.023937729663256125
             -0.02791415025677451
             0.06382151939121848 0
             0 -0.708546351634791  </pose>
      <inertial>
        <mass>0.018</mass>
        <inertia>
          <ixx>8.82e-6</ixx>
          <ixy>0</ixy>
          <ixz>0</ixz>
          <iyy>8.82e-6</iyy>
          <iyz>0</iyz>
          <izz>8.82e-6</izz>
        </inertia>
      </inertial>
      <visual name="visual">
        <geometry>
          <mesh>
            <uri>model://random_strawberry_plant/meshes/leaf2.dae</uri>
            <scale> 0.4444204603386976 0.4444204603386976 0.4444204603386976</scale>
          </mesh>
        </geometry>
      </visual>
    </link>


    <joint name=leaf_dirt_joint_22 type="revolute">
      <parent>dirt_link</parent>
      <child>leaf_stem_link_22</child>
      <axis>
        <xyz>0 1 0</xyz>
      </axis>
    </joint>

    <link name= leaf_stem_link_23 >
      <pose>0 0 0 0 -0.4350313571347345 1.1957205415750405 </pose>
      <inertial>
        <mass>1</mass>
        <inertia> <!-- Modeled as slender rod -->
          <ixx>1e-3</ixx>
          <ixy>0</ixy>
          <ixz>0</ixz>
          <iyy>8.333e-2</iyy>
          <iyz>0</iyz>
          <izz>8.333e-2</izz>
        </inertia>
      </inertial>
      <visual name="visual">
        <geometry>
          <mesh>
            <uri>model://random_strawberry_plant/meshes/leaf_stem1.stl</uri>
            <scale> 0.4058052511822324 0.4058052511822324 0.4058052511822324</scale>
          </mesh>
        </geometry>
        <material> <!-- Green -->
          <ambient>0.0 0.5 0.0 1.0</ambient>
          <diffuse>0.0 0.5 0.0 1.0</diffuse>
          <specular>0.1 0.1 0.1 1.0</specular>
        </material>
      </visual>
    </link>

    <link name= leaf_link_23_0 >
      <pose> 0.08089014111320383
             0.20545400804259484
             0.10261325610887818 0
             0 -0.2819518031945647  </pose>
      <inertial>
        <mass>0.018</mass>
        <inertia>
          <ixx>8.82e-6</ixx>
          <ixy>0</ixy>
          <ixz>0</ixz>
          <iyy>8.82e-6</iyy>
          <iyz>0</iyz>
          <izz>8.82e-6</izz>
        </inertia>
      </inertial>
      <visual name="visual">
        <geometry>
          <mesh>
            <uri>model://random_strawberry_plant/meshes/leaf2.dae</uri>
            <scale> 0.6066752687461969 0.6066752687461969 0.6066752687461969</scale>
          </mesh>
        </geometry>
      </visual>
    </link>

    <link name= leaf_link_23_1 >
      <pose> 0.08089014111320383
             0.20545400804259484
             0.10261325610887818 0
             0 1.1457214433030807  </pose>
      <inertial>
        <mass>0.018</mass>
        <inertia>
          <ixx>8.82e-6</ixx>
          <ixy>0</ixy>
          <ixz>0</ixz>
          <iyy>8.82e-6</iyy>
          <iyz>0</iyz>
          <izz>8.82e-6</izz>
        </inertia>
      </inertial>
      <visual name="visual">
        <geometry>
          <mesh>
            <uri>model://random_strawberry_plant/meshes/leaf3.dae</uri>
            <scale> 0.6066752687461969 0.6066752687461969 0.6066752687461969</scale>
          </mesh>
        </geometry>
      </visual>
    </link>

    <link name= leaf_link_23_2 >
      <pose> 0.08089014111320383
             0.20545400804259484
             0.10261325610887818 0
             0 2.983277887331333  </pose>
      <inertial>
        <mass>0.018</mass>
        <inertia>
          <ixx>8.82e-6</ixx>
          <ixy>0</ixy>
          <ixz>0</ixz>
          <iyy>8.82e-6</iyy>
          <iyz>0</iyz>
          <izz>8.82e-6</izz>
        </inertia>
      </inertial>
      <visual name="visual">
        <geometry>
          <mesh>
            <uri>model://random_strawberry_plant/meshes/leaf4.dae</uri>
            <scale> 0.6066752687461969 0.6066752687461969 0.6066752687461969</scale>
          </mesh>
        </geometry>
      </visual>
    </link>


    <joint name=leaf_dirt_joint_23 type="revolute">
      <parent>dirt_link</parent>
      <child>leaf_stem_link_23</child>
      <axis>
        <xyz>0 1 0</xyz>
      </axis>
    </joint>

    <link name= leaf_stem_link_24 >
      <pose>0 0 0 0 -0.5034537575027581 0.7246440495860171 </pose>
      <inertial>
        <mass>1</mass>
        <inertia> <!-- Modeled as slender rod -->
          <ixx>1e-3</ixx>
          <ixy>0</ixy>
          <ixz>0</ixz>
          <iyy>8.333e-2</iyy>
          <iyz>0</iyz>
          <izz>8.333e-2</izz>
        </inertia>
      </inertial>
      <visual name="visual">
        <geometry>
          <mesh>
            <uri>model://random_strawberry_plant/meshes/leaf_stem1.stl</uri>
            <scale> 0.38206590466444235 0.38206590466444235 0.38206590466444235</scale>
          </mesh>
        </geometry>
        <material> <!-- Green -->
          <ambient>0.0 0.5 0.0 1.0</ambient>
          <diffuse>0.0 0.5 0.0 1.0</diffuse>
          <specular>0.1 0.1 0.1 1.0</specular>
        </material>
      </visual>
    </link>

    <link name= leaf_link_24_0 >
      <pose> 0.1503429622869077
             0.13310133656810533
             0.11059744968634018 0
             0 -0.883926279731744  </pose>
      <inertial>
        <mass>0.018</mass>
        <inertia>
          <ixx>8.82e-6</ixx>
          <ixy>0</ixy>
          <ixz>0</ixz>
          <iyy>8.82e-6</iyy>
          <iyz>0</iyz>
          <izz>8.82e-6</izz>
        </inertia>
      </inertial>
      <visual name="visual">
        <geometry>
          <mesh>
            <uri>model://random_strawberry_plant/meshes/leaf2.dae</uri>
            <scale> 0.5150697665338696 0.5150697665338696 0.5150697665338696</scale>
          </mesh>
        </geometry>
      </visual>
    </link>

    <link name= leaf_link_24_1 >
      <pose> 0.1503429622869077
             0.13310133656810533
             0.11059744968634018 0
             0 0.8467940222054123  </pose>
      <inertial>
        <mass>0.018</mass>
        <inertia>
          <ixx>8.82e-6</ixx>
          <ixy>0</ixy>
          <ixz>0</ixz>
          <iyy>8.82e-6</iyy>
          <iyz>0</iyz>
          <izz>8.82e-6</izz>
        </inertia>
      </inertial>
      <visual name="visual">
        <geometry>
          <mesh>
            <uri>model://random_strawberry_plant/meshes/leaf4.dae</uri>
            <scale> 0.5150697665338696 0.5150697665338696 0.5150697665338696</scale>
          </mesh>
        </geometry>
      </visual>
    </link>

    <link name= leaf_link_24_2 >
      <pose> 0.1503429622869077
             0.13310133656810533
             0.11059744968634018 0
             0 2.2985960174673616  </pose>
      <inertial>
        <mass>0.018</mass>
        <inertia>
          <ixx>8.82e-6</ixx>
          <ixy>0</ixy>
          <ixz>0</ixz>
          <iyy>8.82e-6</iyy>
          <iyz>0</iyz>
          <izz>8.82e-6</izz>
        </inertia>
      </inertial>
      <visual name="visual">
        <geometry>
          <mesh>
            <uri>model://random_strawberry_plant/meshes/leaf1.dae</uri>
            <scale> 0.5150697665338696 0.5150697665338696 0.5150697665338696</scale>
          </mesh>
        </geometry>
      </visual>
    </link>


    <joint name=leaf_dirt_joint_24 type="revolute">
      <parent>dirt_link</parent>
      <child>leaf_stem_link_24</child>
      <axis>
        <xyz>0 1 0</xyz>
      </axis>
    </joint>

    <link name= leaf_stem_link_25 >
      <pose>0 0 0 0 -0.7228577794286863 -3.054341465721873 </pose>
      <inertial>
        <mass>1</mass>
        <inertia> <!-- Modeled as slender rod -->
          <ixx>1e-3</ixx>
          <ixy>0</ixy>
          <ixz>0</ixz>
          <iyy>8.333e-2</iyy>
          <iyz>0</iyz>
          <izz>8.333e-2</izz>
        </inertia>
      </inertial>
      <visual name="visual">
        <geometry>
          <mesh>
            <uri>model://random_strawberry_plant/meshes/leaf_stem1.stl</uri>
            <scale> 0.26663757992990106 0.26663757992990106 0.26663757992990106</scale>
          </mesh>
        </geometry>
        <material> <!-- Green -->
          <ambient>0.0 0.5 0.0 1.0</ambient>
          <diffuse>0.0 0.5 0.0 1.0</diffuse>
          <specular>0.1 0.1 0.1 1.0</specular>
        </material>
      </visual>
    </link>

    <link name= leaf_link_25_0 >
      <pose> -0.1195174611513974
             -0.010454583375834684
             0.10583333037128097 0
             0 -4.712737452239361  </pose>
      <inertial>
        <mass>0.018</mass>
        <inertia>
          <ixx>8.82e-6</ixx>
          <ixy>0</ixy>
          <ixz>0</ixz>
          <iyy>8.82e-6</iyy>
          <iyz>0</iyz>
          <izz>8.82e-6</izz>
        </inertia>
      </inertial>
      <visual name="visual">
        <geometry>
          <mesh>
            <uri>model://random_strawberry_plant/meshes/leaf5.dae</uri>
            <scale> 0.4754678734477521 0.4754678734477521 0.4754678734477521</scale>
          </mesh>
        </geometry>
      </visual>
    </link>

    <link name= leaf_link_25_1 >
      <pose> -0.1195174611513974
             -0.010454583375834684
             0.10583333037128097 0
             0 -3.1087298706209556  </pose>
      <inertial>
        <mass>0.018</mass>
        <inertia>
          <ixx>8.82e-6</ixx>
          <ixy>0</ixy>
          <ixz>0</ixz>
          <iyy>8.82e-6</iyy>
          <iyz>0</iyz>
          <izz>8.82e-6</izz>
        </inertia>
      </inertial>
      <visual name="visual">
        <geometry>
          <mesh>
            <uri>model://random_strawberry_plant/meshes/leaf3.dae</uri>
            <scale> 0.4754678734477521 0.4754678734477521 0.4754678734477521</scale>
          </mesh>
        </geometry>
      </visual>
    </link>

    <link name= leaf_link_25_2 >
      <pose> -0.1195174611513974
             -0.010454583375834684
             0.10583333037128097 0
             0 -1.4693009648167756  </pose>
      <inertial>
        <mass>0.018</mass>
        <inertia>
          <ixx>8.82e-6</ixx>
          <ixy>0</ixy>
          <ixz>0</ixz>
          <iyy>8.82e-6</iyy>
          <iyz>0</iyz>
          <izz>8.82e-6</izz>
        </inertia>
      </inertial>
      <visual name="visual">
        <geometry>
          <mesh>
            <uri>model://random_strawberry_plant/meshes/leaf1.dae</uri>
            <scale> 0.4754678734477521 0.4754678734477521 0.4754678734477521</scale>
          </mesh>
        </geometry>
      </visual>
    </link>


    <joint name=leaf_dirt_joint_25 type="revolute">
      <parent>dirt_link</parent>
      <child>leaf_stem_link_25</child>
      <axis>
        <xyz>0 1 0</xyz>
      </axis>
    </joint>

    <link name= leaf_stem_link_26 >
      <pose>0 0 0 0 -1.2430102974392436 2.211199285358145 </pose>
      <inertial>
        <mass>1</mass>
        <inertia> <!-- Modeled as slender rod -->
          <ixx>1e-3</ixx>
          <ixy>0</ixy>
          <ixz>0</ixz>
          <iyy>8.333e-2</iyy>
          <iyz>0</iyz>
          <izz>8.333e-2</izz>
        </inertia>
      </inertial>
      <visual name="visual">
        <geometry>
          <mesh>
            <uri>model://random_strawberry_plant/meshes/leaf_stem2.stl</uri>
            <scale> 0.24952304569763384 0.24952304569763384 0.24952304569763384</scale>
          </mesh>
        </geometry>
        <material> <!-- Green -->
          <ambient>0.0 0.5 0.0 1.0</ambient>
          <diffuse>0.0 0.5 0.0 1.0</diffuse>
          <specular>0.1 0.1 0.1 1.0</specular>
        </material>
      </visual>
    </link>

    <link name= leaf_link_26_0 >
      <pose> -0.028800412427101133
             0.03864943437549857
             0.14174268089324174 0
             0 0.7897222449020995  </pose>
      <inertial>
        <mass>0.018</mass>
        <inertia>
          <ixx>8.82e-6</ixx>
          <ixy>0</ixy>
          <ixz>0</ixz>
          <iyy>8.82e-6</iyy>
          <iyz>0</iyz>
          <izz>8.82e-6</izz>
        </inertia>
      </inertial>
      <visual name="visual">
        <geometry>
          <mesh>
            <uri>model://random_strawberry_plant/meshes/leaf3.dae</uri>
            <scale> 0.5564473189812633 0.5564473189812633 0.5564473189812633</scale>
          </mesh>
        </geometry>
      </visual>
    </link>

    <link name= leaf_link_26_1 >
      <pose> -0.028800412427101133
             0.03864943437549857
             0.14174268089324174 0
             0 2.1616336116435546  </pose>
      <inertial>
        <mass>0.018</mass>
        <inertia>
          <ixx>8.82e-6</ixx>
          <ixy>0</ixy>
          <ixz>0</ixz>
          <iyy>8.82e-6</iyy>
          <iyz>0</iyz>
          <izz>8.82e-6</izz>
        </inertia>
      </inertial>
      <visual name="visual">
        <geometry>
          <mesh>
            <uri>model://random_strawberry_plant/meshes/leaf2.dae</uri>
            <scale> 0.5564473189812633 0.5564473189812633 0.5564473189812633</scale>
          </mesh>
        </geometry>
      </visual>
    </link>

    <link name= leaf_link_26_2 >
      <pose> -0.028800412427101133
             0.03864943437549857
             0.14174268089324174 0
             0 3.704624814886842  </pose>
      <inertial>
        <mass>0.018</mass>
        <inertia>
          <ixx>8.82e-6</ixx>
          <ixy>0</ixy>
          <ixz>0</ixz>
          <iyy>8.82e-6</iyy>
          <iyz>0</iyz>
          <izz>8.82e-6</izz>
        </inertia>
      </inertial>
      <visual name="visual">
        <geometry>
          <mesh>
            <uri>model://random_strawberry_plant/meshes/leaf2.dae</uri>
            <scale> 0.5564473189812633 0.5564473189812633 0.5564473189812633</scale>
          </mesh>
        </geometry>
      </visual>
    </link>


    <joint name=leaf_dirt_joint_26 type="revolute">
      <parent>dirt_link</parent>
      <child>leaf_stem_link_26</child>
      <axis>
        <xyz>0 1 0</xyz>
      </axis>
    </joint>

    <link name= leaf_stem_link_27 >
      <pose>0 0 0 0 -0.6547797516842956 2.706516717085405 </pose>
      <inertial>
        <mass>1</mass>
        <inertia> <!-- Modeled as slender rod -->
          <ixx>1e-3</ixx>
          <ixy>0</ixy>
          <ixz>0</ixz>
          <iyy>8.333e-2</iyy>
          <iyz>0</iyz>
          <izz>8.333e-2</izz>
        </inertia>
      </inertial>
      <visual name="visual">
        <geometry>
          <mesh>
            <uri>model://random_strawberry_plant/meshes/leaf_stem1.stl</uri>
            <scale> 0.3017691916565606 0.3017691916565606 0.3017691916565606</scale>
          </mesh>
        </geometry>
        <material> <!-- Green -->
          <ambient>0.0 0.5 0.0 1.0</ambient>
          <diffuse>0.0 0.5 0.0 1.0</diffuse>
          <specular>0.1 0.1 0.1 1.0</specular>
        </material>
      </visual>
    </link>

    <link name= leaf_link_27_0 >
      <pose> -0.13023531666082114
             0.060530638468236184
             0.11026366723804698 0
             0 1.042503396651373  </pose>
      <inertial>
        <mass>0.018</mass>
        <inertia>
          <ixx>8.82e-6</ixx>
          <ixy>0</ixy>
          <ixz>0</ixz>
          <iyy>8.82e-6</iyy>
          <iyz>0</iyz>
          <izz>8.82e-6</izz>
        </inertia>
      </inertial>
      <visual name="visual">
        <geometry>
          <mesh>
            <uri>model://random_strawberry_plant/meshes/leaf2.dae</uri>
            <scale> 0.3493591715901507 0.3493591715901507 0.3493591715901507</scale>
          </mesh>
        </geometry>
      </visual>
    </link>

    <link name= leaf_link_27_1 >
      <pose> -0.13023531666082114
             0.060530638468236184
             0.11026366723804698 0
             0 2.778896009599424  </pose>
      <inertial>
        <mass>0.018</mass>
        <inertia>
          <ixx>8.82e-6</ixx>
          <ixy>0</ixy>
          <ixz>0</ixz>
          <iyy>8.82e-6</iyy>
          <iyz>0</iyz>
          <izz>8.82e-6</izz>
        </inertia>
      </inertial>
      <visual name="visual">
        <geometry>
          <mesh>
            <uri>model://random_strawberry_plant/meshes/leaf1.dae</uri>
            <scale> 0.3493591715901507 0.3493591715901507 0.3493591715901507</scale>
          </mesh>
        </geometry>
      </visual>
    </link>

    <link name= leaf_link_27_2 >
      <pose> -0.13023531666082114
             0.060530638468236184
             0.11026366723804698 0
             0 4.124586043069165  </pose>
      <inertial>
        <mass>0.018</mass>
        <inertia>
          <ixx>8.82e-6</ixx>
          <ixy>0</ixy>
          <ixz>0</ixz>
          <iyy>8.82e-6</iyy>
          <iyz>0</iyz>
          <izz>8.82e-6</izz>
        </inertia>
      </inertial>
      <visual name="visual">
        <geometry>
          <mesh>
            <uri>model://random_strawberry_plant/meshes/leaf4.dae</uri>
            <scale> 0.3493591715901507 0.3493591715901507 0.3493591715901507</scale>
          </mesh>
        </geometry>
      </visual>
    </link>


    <joint name=leaf_dirt_joint_27 type="revolute">
      <parent>dirt_link</parent>
      <child>leaf_stem_link_27</child>
      <axis>
        <xyz>0 1 0</xyz>
      </axis>
    </joint>

    <link name= leaf_stem_link_28 >
      <pose>0 0 0 0 -1.120072333854679 -0.7123726618417892 </pose>
      <inertial>
        <mass>1</mass>
        <inertia> <!-- Modeled as slender rod -->
          <ixx>1e-3</ixx>
          <ixy>0</ixy>
          <ixz>0</ixz>
          <iyy>8.333e-2</iyy>
          <iyz>0</iyz>
          <izz>8.333e-2</izz>
        </inertia>
      </inertial>
      <visual name="visual">
        <geometry>
          <mesh>
            <uri>model://random_strawberry_plant/meshes/leaf_stem2.stl</uri>
            <scale> 0.19130481769071864 0.19130481769071864 0.19130481769071864</scale>
          </mesh>
        </geometry>
        <material> <!-- Green -->
          <ambient>0.0 0.5 0.0 1.0</ambient>
          <diffuse>0.0 0.5 0.0 1.0</diffuse>
          <specular>0.1 0.1 0.1 1.0</specular>
        </material>
      </visual>
    </link>

    <link name= leaf_link_28_0 >
      <pose> 0.037841730633075325
             -0.032682489862052445
             0.10331974766188252 0
             0 -2.3602486859216203  </pose>
      <inertial>
        <mass>0.018</mass>
        <inertia>
          <ixx>8.82e-6</ixx>
          <ixy>0</ixy>
          <ixz>0</ixz>
          <iyy>8.82e-6</iyy>
          <iyz>0</iyz>
          <izz>8.82e-6</izz>
        </inertia>
      </inertial>
      <visual name="visual">
        <geometry>
          <mesh>
            <uri>model://random_strawberry_plant/meshes/leaf4.dae</uri>
            <scale> 0.7876320781802414 0.7876320781802414 0.7876320781802414</scale>
          </mesh>
        </geometry>
      </visual>
    </link>

    <link name= leaf_link_28_1 >
      <pose> 0.037841730633075325
             -0.032682489862052445
             0.10331974766188252 0
             0 -0.5621531797519049  </pose>
      <inertial>
        <mass>0.018</mass>
        <inertia>
          <ixx>8.82e-6</ixx>
          <ixy>0</ixy>
          <ixz>0</ixz>
          <iyy>8.82e-6</iyy>
          <iyz>0</iyz>
          <izz>8.82e-6</izz>
        </inertia>
      </inertial>
      <visual name="visual">
        <geometry>
          <mesh>
            <uri>model://random_strawberry_plant/meshes/leaf1.dae</uri>
            <scale> 0.7876320781802414 0.7876320781802414 0.7876320781802414</scale>
          </mesh>
        </geometry>
      </visual>
    </link>

    <link name= leaf_link_28_2 >
      <pose> 0.037841730633075325
             -0.032682489862052445
             0.10331974766188252 0
             0 0.782680289229335  </pose>
      <inertial>
        <mass>0.018</mass>
        <inertia>
          <ixx>8.82e-6</ixx>
          <ixy>0</ixy>
          <ixz>0</ixz>
          <iyy>8.82e-6</iyy>
          <iyz>0</iyz>
          <izz>8.82e-6</izz>
        </inertia>
      </inertial>
      <visual name="visual">
        <geometry>
          <mesh>
            <uri>model://random_strawberry_plant/meshes/leaf3.dae</uri>
            <scale> 0.7876320781802414 0.7876320781802414 0.7876320781802414</scale>
          </mesh>
        </geometry>
      </visual>
    </link>


    <joint name=leaf_dirt_joint_28 type="revolute">
      <parent>dirt_link</parent>
      <child>leaf_stem_link_28</child>
      <axis>
        <xyz>0 1 0</xyz>
      </axis>
    </joint>

    <link name= leaf_stem_link_29 >
      <pose>0 0 0 0 -0.6392883510947126 1.0099368235357957 </pose>
      <inertial>
        <mass>1</mass>
        <inertia> <!-- Modeled as slender rod -->
          <ixx>1e-3</ixx>
          <ixy>0</ixy>
          <ixz>0</ixz>
          <iyy>8.333e-2</iyy>
          <iyz>0</iyz>
          <izz>8.333e-2</izz>
        </inertia>
      </inertial>
      <visual name="visual">
        <geometry>
          <mesh>
            <uri>model://random_strawberry_plant/meshes/leaf_stem1.stl</uri>
            <scale> 0.33091717300569873 0.33091717300569873 0.33091717300569873</scale>
          </mesh>
        </geometry>
        <material> <!-- Green -->
          <ambient>0.0 0.5 0.0 1.0</ambient>
          <diffuse>0.0 0.5 0.0 1.0</diffuse>
          <specular>0.1 0.1 0.1 1.0</specular>
        </material>
      </visual>
    </link>

    <link name= leaf_link_29_0 >
      <pose> 0.08475558346556349
             0.13492942347846243
             0.11845997168500304 0
             0 -0.7355665899153627  </pose>
      <inertial>
        <mass>0.018</mass>
        <inertia>
          <ixx>8.82e-6</ixx>
          <ixy>0</ixy>
          <ixz>0</ixz>
          <iyy>8.82e-6</iyy>
          <iyz>0</iyz>
          <izz>8.82e-6</izz>
        </inertia>
      </inertial>
      <visual name="visual">
        <geometry>
          <mesh>
            <uri>model://random_strawberry_plant/meshes/leaf4.dae</uri>
            <scale> 0.47511153441030696 0.47511153441030696 0.47511153441030696</scale>
          </mesh>
        </geometry>
      </visual>
    </link>

    <link name= leaf_link_29_1 >
      <pose> 0.08475558346556349
             0.13492942347846243
             0.11845997168500304 0
             0 1.0625469002818473  </pose>
      <inertial>
        <mass>0.018</mass>
        <inertia>
          <ixx>8.82e-6</ixx>
          <ixy>0</ixy>
          <ixz>0</ixz>
          <iyy>8.82e-6</iyy>
          <iyz>0</iyz>
          <izz>8.82e-6</izz>
        </inertia>
      </inertial>
      <visual name="visual">
        <geometry>
          <mesh>
            <uri>model://random_strawberry_plant/meshes/leaf4.dae</uri>
            <scale> 0.47511153441030696 0.47511153441030696 0.47511153441030696</scale>
          </mesh>
        </geometry>
      </visual>
    </link>

    <link name= leaf_link_29_2 >
      <pose> 0.08475558346556349
             0.13492942347846243
             0.11845997168500304 0
             0 2.5325712166013843  </pose>
      <inertial>
        <mass>0.018</mass>
        <inertia>
          <ixx>8.82e-6</ixx>
          <ixy>0</ixy>
          <ixz>0</ixz>
          <iyy>8.82e-6</iyy>
          <iyz>0</iyz>
          <izz>8.82e-6</izz>
        </inertia>
      </inertial>
      <visual name="visual">
        <geometry>
          <mesh>
            <uri>model://random_strawberry_plant/meshes/leaf1.dae</uri>
            <scale> 0.47511153441030696 0.47511153441030696 0.47511153441030696</scale>
          </mesh>
        </geometry>
      </visual>
    </link>


    <joint name=leaf_dirt_joint_29 type="revolute">
      <parent>dirt_link</parent>
      <child>leaf_stem_link_29</child>
      <axis>
        <xyz>0 1 0</xyz>
      </axis>
    </joint>

    <link name= leaf_stem_link_30 >
      <pose>0 0 0 0 -0.6939313474736266 1.453806089430306 </pose>
      <inertial>
        <mass>1</mass>
        <inertia> <!-- Modeled as slender rod -->
          <ixx>1e-3</ixx>
          <ixy>0</ixy>
          <ixz>0</ixz>
          <iyy>8.333e-2</iyy>
          <iyz>0</iyz>
          <izz>8.333e-2</izz>
        </inertia>
      </inertial>
      <visual name="visual">
        <geometry>
          <mesh>
            <uri>model://random_strawberry_plant/meshes/leaf_stem1.stl</uri>
            <scale> 0.33398030402633283 0.33398030402633283 0.33398030402633283</scale>
          </mesh>
        </geometry>
        <material> <!-- Green -->
          <ambient>0.0 0.5 0.0 1.0</ambient>
          <diffuse>0.0 0.5 0.0 1.0</diffuse>
          <specular>0.1 0.1 0.1 1.0</specular>
        </material>
      </visual>
    </link>

    <link name= leaf_link_30_0 >
      <pose> 0.017980788348760643
             0.1529929433264092
             0.12816112591026593 0
             0 -0.1879723731231404  </pose>
      <inertial>
        <mass>0.018</mass>
        <inertia>
          <ixx>8.82e-6</ixx>
          <ixy>0</ixy>
          <ixz>0</ixz>
          <iyy>8.82e-6</iyy>
          <iyz>0</iyz>
          <izz>8.82e-6</izz>
        </inertia>
      </inertial>
      <visual name="visual">
        <geometry>
          <mesh>
            <uri>model://random_strawberry_plant/meshes/leaf3.dae</uri>
            <scale> 0.6778650389214158 0.6778650389214158 0.6778650389214158</scale>
          </mesh>
        </geometry>
      </visual>
    </link>

    <link name= leaf_link_30_1 >
      <pose> 0.017980788348760643
             0.1529929433264092
             0.12816112591026593 0
             0 1.501802879846759  </pose>
      <inertial>
        <mass>0.018</mass>
        <inertia>
          <ixx>8.82e-6</ixx>
          <ixy>0</ixy>
          <ixz>0</ixz>
          <iyy>8.82e-6</iyy>
          <iyz>0</iyz>
          <izz>8.82e-6</izz>
        </inertia>
      </inertial>
      <visual name="visual">
        <geometry>
          <mesh>
            <uri>model://random_strawberry_plant/meshes/leaf5.dae</uri>
            <scale> 0.6778650389214158 0.6778650389214158 0.6778650389214158</scale>
          </mesh>
        </geometry>
      </visual>
    </link>

    <link name= leaf_link_30_2 >
      <pose> 0.017980788348760643
             0.1529929433264092
             0.12816112591026593 0
             0 3.131239247710193  </pose>
      <inertial>
        <mass>0.018</mass>
        <inertia>
          <ixx>8.82e-6</ixx>
          <ixy>0</ixy>
          <ixz>0</ixz>
          <iyy>8.82e-6</iyy>
          <iyz>0</iyz>
          <izz>8.82e-6</izz>
        </inertia>
      </inertial>
      <visual name="visual">
        <geometry>
          <mesh>
            <uri>model://random_strawberry_plant/meshes/leaf2.dae</uri>
            <scale> 0.6778650389214158 0.6778650389214158 0.6778650389214158</scale>
          </mesh>
        </geometry>
      </visual>
    </link>


    <joint name=leaf_dirt_joint_30 type="revolute">
      <parent>dirt_link</parent>
      <child>leaf_stem_link_30</child>
      <axis>
        <xyz>0 1 0</xyz>
      </axis>
    </joint>

    <link name= leaf_stem_link_31 >
      <pose>0 0 0 0 -1.244429143055559 -0.23939439863172796 </pose>
      <inertial>
        <mass>1</mass>
        <inertia> <!-- Modeled as slender rod -->
          <ixx>1e-3</ixx>
          <ixy>0</ixy>
          <ixz>0</ixz>
          <iyy>8.333e-2</iyy>
          <iyz>0</iyz>
          <izz>8.333e-2</izz>
        </inertia>
      </inertial>
      <visual name="visual">
        <geometry>
          <mesh>
            <uri>model://random_strawberry_plant/meshes/leaf_stem2.stl</uri>
            <scale> 0.2946090932039555 0.2946090932039555 0.2946090932039555</scale>
          </mesh>
        </geometry>
        <material> <!-- Green -->
          <ambient>0.0 0.5 0.0 1.0</ambient>
          <diffuse>0.0 0.5 0.0 1.0</diffuse>
          <specular>0.1 0.1 0.1 1.0</specular>
        </material>
      </visual>
    </link>

    <link name= leaf_link_31_0 >
      <pose> 0.05505555127917249
             -0.013437679779170753
             0.16743458855010623 0
             0 -1.8601520083852758  </pose>
      <inertial>
        <mass>0.018</mass>
        <inertia>
          <ixx>8.82e-6</ixx>
          <ixy>0</ixy>
          <ixz>0</ixz>
          <iyy>8.82e-6</iyy>
          <iyz>0</iyz>
          <izz>8.82e-6</izz>
        </inertia>
      </inertial>
      <visual name="visual">
        <geometry>
          <mesh>
            <uri>model://random_strawberry_plant/meshes/leaf5.dae</uri>
            <scale> 0.6383861107684645 0.6383861107684645 0.6383861107684645</scale>
          </mesh>
        </geometry>
      </visual>
    </link>

    <link name= leaf_link_31_1 >
      <pose> 0.05505555127917249
             -0.013437679779170753
             0.16743458855010623 0
             0 -0.321665139292355  </pose>
      <inertial>
        <mass>0.018</mass>
        <inertia>
          <ixx>8.82e-6</ixx>
          <ixy>0</ixy>
          <ixz>0</ixz>
          <iyy>8.82e-6</iyy>
          <iyz>0</iyz>
          <izz>8.82e-6</izz>
        </inertia>
      </inertial>
      <visual name="visual">
        <geometry>
          <mesh>
            <uri>model://random_strawberry_plant/meshes/leaf3.dae</uri>
            <scale> 0.6383861107684645 0.6383861107684645 0.6383861107684645</scale>
          </mesh>
        </geometry>
      </visual>
    </link>

    <link name= leaf_link_31_2 >
      <pose> 0.05505555127917249
             -0.013437679779170753
             0.16743458855010623 0
             0 1.3638130375678472  </pose>
      <inertial>
        <mass>0.018</mass>
        <inertia>
          <ixx>8.82e-6</ixx>
          <ixy>0</ixy>
          <ixz>0</ixz>
          <iyy>8.82e-6</iyy>
          <iyz>0</iyz>
          <izz>8.82e-6</izz>
        </inertia>
      </inertial>
      <visual name="visual">
        <geometry>
          <mesh>
            <uri>model://random_strawberry_plant/meshes/leaf2.dae</uri>
            <scale> 0.6383861107684645 0.6383861107684645 0.6383861107684645</scale>
          </mesh>
        </geometry>
      </visual>
    </link>


    <joint name=leaf_dirt_joint_31 type="revolute">
      <parent>dirt_link</parent>
      <child>leaf_stem_link_31</child>
      <axis>
        <xyz>0 1 0</xyz>
      </axis>
    </joint>


    <link name= berry_stem_link_1 >
      <pose>0 0 0 0 -0.08058372380636433 -0.7276378734645874</pose>
      <inertial>
        <mass>1</mass>
        <inertia> <!-- Modeled as slender rod -->
          <ixx>1e-3</ixx>
          <ixy>0</ixy>
          <ixz>0</ixz>
          <iyy>8.333e-2</iyy>
          <iyz>0</iyz>
          <izz>8.333e-2</izz>
        </inertia>
      </inertial>
      <visual name="visual">
        <geometry>
          <mesh>
            <uri>model://random_strawberry_plant/meshes/strawb_stem1.stl</uri>
            <scale>0.3281992529558887 0.3281992529558887 0.3281992529558887</scale>
          </mesh>
        </geometry>
        <material> <!-- Green -->
          <ambient>0.0 0.5 0.0 1.0</ambient>
          <diffuse>0.0 0.5 0.0 1.0</diffuse>
          <specular>0.1 0.1 0.1 1.0</specular>
        </material>
      </visual>
    </link>

    <link name= berry_link_1 >
      <pose> 0.15532351393796273 -0.1383423971456737 0.016629884954964588
             0 -1.5607963267948965  -0.7276378734645874</pose>
      <inertial>
        <mass>0.018</mass>
        <inertia>
          <ixx>8.82e-6</ixx>
          <ixy>0</ixy>
          <ixz>0</ixz>
          <iyy>8.82e-6</iyy>
          <iyz>0</iyz>
          <izz>8.82e-6</izz>
        </inertia>
      </inertial>
      <collision name="collision">
        <geometry>
          <sphere>
            <radius>0.016797860762964772</radius>
          </sphere>
        </geometry>
      </collision>
      <visual name="visual">
        <geometry>
          <mesh>
            <uri>model://random_strawberry_plant/meshes/1002r1.dae</uri>
            <scale>0.33595721525929545 0.33595721525929545 0.33595721525929545</scale>
          </mesh>
        </geometry>
      </visual>
    </link>

    <link name= calyx_link_1 >
      <pose> 0.15532351393796273 -0.1383423971456737 0.016629884954964588
             0 -1.5607963267948965 -0.7276378734645874 </pose>
      <inertial>
        <mass>0.018</mass>
        <inertia>
          <ixx>8.82e-6</ixx>
          <ixy>0</ixy>
          <ixz>0</ixz>
          <iyy>8.82e-6</iyy>
          <iyz>0</iyz>
          <izz>8.82e-6</izz>
        </inertia>
      </inertial>
      <visual name="visual">
        <geometry>
          <mesh>
            <uri>model://random_strawberry_plant/meshes/calyx1_1002.dae</uri>
            <scale>0.33595721525929545 0.33595721525929545 0.33595721525929545</scale>
          </mesh>
        </geometry>
      </visual>
    </link>

    <joint name=berry_dirt_joint_1 type="revolute">
      <parent>dirt_link</parent>
      <child>berry_stem_link_1</child>
      <axis>
        <xyz>0 1 0</xyz>
      </axis>
    </joint>

    <joint name=stem_to_calyx_joint_1 type="ball">
      <parent> berry_link_1 </parent>
      <child> calyx_link_1 </child>
    </joint>

    <joint name=stem_to_berry_joint_1 type="ball">
      <parent> berry_stem_link_1 </parent>
      <child> berry_link_1 </child>
    </joint>

    <link name= berry_stem_link_2 >
      <pose>0 0 0 0 -0.0543770328823164 -1.7611419791483998</pose>
      <inertial>
        <mass>1</mass>
        <inertia> <!-- Modeled as slender rod -->
          <ixx>1e-3</ixx>
          <ixy>0</ixy>
          <ixz>0</ixz>
          <iyy>8.333e-2</iyy>
          <iyz>0</iyz>
          <izz>8.333e-2</izz>
        </inertia>
      </inertial>
      <visual name="visual">
        <geometry>
          <mesh>
            <uri>model://random_strawberry_plant/meshes/strawb_stem1.stl</uri>
            <scale>0.46618185964677616 0.46618185964677616 0.46618185964677616</scale>
          </mesh>
        </geometry>
        <material> <!-- Green -->
          <ambient>0.0 0.5 0.0 1.0</ambient>
          <diffuse>0.0 0.5 0.0 1.0</diffuse>
          <specular>0.1 0.1 0.1 1.0</specular>
        </material>
      </visual>
    </link>

    <link name= berry_link_2 >
      <pose> -0.054932027991845815 -0.2850971202107115 0.015645471932917175
             0 -1.5607963267948965  -1.7611419791483998</pose>
      <inertial>
        <mass>0.018</mass>
        <inertia>
          <ixx>8.82e-6</ixx>
          <ixy>0</ixy>
          <ixz>0</ixz>
          <iyy>8.82e-6</iyy>
          <iyz>0</iyz>
          <izz>8.82e-6</izz>
        </inertia>
      </inertial>
      <collision name="collision">
        <geometry>
          <sphere>
            <radius>0.015803504342437328</radius>
          </sphere>
        </geometry>
      </collision>
      <visual name="visual">
        <geometry>
          <mesh>
            <uri>model://random_strawberry_plant/meshes/1003r0.dae</uri>
            <scale>0.31607008684874655 0.31607008684874655 0.31607008684874655</scale>
          </mesh>
        </geometry>
      </visual>
    </link>

    <link name= calyx_link_2 >
      <pose> -0.054932027991845815 -0.2850971202107115 0.015645471932917175
             0 -1.5607963267948965 -1.7611419791483998 </pose>
      <inertial>
        <mass>0.018</mass>
        <inertia>
          <ixx>8.82e-6</ixx>
          <ixy>0</ixy>
          <ixz>0</ixz>
          <iyy>8.82e-6</iyy>
          <iyz>0</iyz>
          <izz>8.82e-6</izz>
        </inertia>
      </inertial>
      <visual name="visual">
        <geometry>
          <mesh>
            <uri>model://random_strawberry_plant/meshes/calyx2_1003.dae</uri>
            <scale>0.31607008684874655 0.31607008684874655 0.31607008684874655</scale>
          </mesh>
        </geometry>
      </visual>
    </link>

    <joint name=berry_dirt_joint_2 type="revolute">
      <parent>dirt_link</parent>
      <child>berry_stem_link_2</child>
      <axis>
        <xyz>0 1 0</xyz>
      </axis>
    </joint>

    <joint name=stem_to_calyx_joint_2 type="ball">
      <parent> berry_link_2 </parent>
      <child> calyx_link_2 </child>
    </joint>

    <joint name=stem_to_berry_joint_2 type="ball">
      <parent> berry_stem_link_2 </parent>
      <child> berry_link_2 </child>
    </joint>

    <link name= berry_stem_link_3 >
      <pose>0 0 0 0 -0.1104792150698146 2.873758527084277</pose>
      <inertial>
        <mass>1</mass>
        <inertia> <!-- Modeled as slender rod -->
          <ixx>1e-3</ixx>
          <ixy>0</ixy>
          <ixz>0</ixz>
          <iyy>8.333e-2</iyy>
          <iyz>0</iyz>
          <izz>8.333e-2</izz>
        </inertia>
      </inertial>
      <visual name="visual">
        <geometry>
          <mesh>
            <uri>model://random_strawberry_plant/meshes/strawb_stem1.stl</uri>
            <scale>0.2558867616256185 0.2558867616256185 0.2558867616256185</scale>
          </mesh>
        </geometry>
        <material> <!-- Green -->
          <ambient>0.0 0.5 0.0 1.0</ambient>
          <diffuse>0.0 0.5 0.0 1.0</diffuse>
          <specular>0.1 0.1 0.1 1.0</specular>
        </material>
      </visual>
    </link>

    <link name= berry_link_3 >
      <pose> -0.15946156767698685 0.043760680886633395 0.018159891436956663
             0 -1.5607963267948965  2.873758527084277</pose>
      <inertial>
        <mass>0.018</mass>
        <inertia>
          <ixx>8.82e-6</ixx>
          <ixy>0</ixy>
          <ixz>0</ixz>
          <iyy>8.82e-6</iyy>
          <iyz>0</iyz>
          <izz>8.82e-6</izz>
        </inertia>
      </inertial>
      <collision name="collision">
        <geometry>
          <sphere>
            <radius>0.01834332159570877</radius>
          </sphere>
        </geometry>
      </collision>
      <visual name="visual">
        <geometry>
          <mesh>
            <uri>model://random_strawberry_plant/meshes/1004r0.dae</uri>
            <scale>0.3668664319141754 0.3668664319141754 0.3668664319141754</scale>
          </mesh>
        </geometry>
      </visual>
    </link>

    <link name= calyx_link_3 >
      <pose> -0.15946156767698685 0.043760680886633395 0.018159891436956663
             0 -1.5607963267948965 2.873758527084277 </pose>
      <inertial>
        <mass>0.018</mass>
        <inertia>
          <ixx>8.82e-6</ixx>
          <ixy>0</ixy>
          <ixz>0</ixz>
          <iyy>8.82e-6</iyy>
          <iyz>0</iyz>
          <izz>8.82e-6</izz>
        </inertia>
      </inertial>
      <visual name="visual">
        <geometry>
          <mesh>
            <uri>model://random_strawberry_plant/meshes/calyx2_1004.dae</uri>
            <scale>0.3668664319141754 0.3668664319141754 0.3668664319141754</scale>
          </mesh>
        </geometry>
      </visual>
    </link>

    <joint name=berry_dirt_joint_3 type="revolute">
      <parent>dirt_link</parent>
      <child>berry_stem_link_3</child>
      <axis>
        <xyz>0 1 0</xyz>
      </axis>
    </joint>

    <joint name=stem_to_calyx_joint_3 type="ball">
      <parent> berry_link_3 </parent>
      <child> calyx_link_3 </child>
    </joint>

    <joint name=stem_to_berry_joint_3 type="ball">
      <parent> berry_stem_link_3 </parent>
      <child> berry_link_3 </child>
    </joint>

    <link name= berry_stem_link_4 >
      <pose>0 0 0 0 -0.07992579704837291 -2.4101040163531375</pose>
      <inertial>
        <mass>1</mass>
        <inertia> <!-- Modeled as slender rod -->
          <ixx>1e-3</ixx>
          <ixy>0</ixy>
          <ixz>0</ixz>
          <iyy>8.333e-2</iyy>
          <iyz>0</iyz>
          <izz>8.333e-2</izz>
        </inertia>
      </inertial>
      <visual name="visual">
        <geometry>
          <mesh>
            <uri>model://random_strawberry_plant/meshes/strawb_stem1.stl</uri>
            <scale>0.29769222739262186 0.29769222739262186 0.29769222739262186</scale>
          </mesh>
        </geometry>
        <material> <!-- Green -->
          <ambient>0.0 0.5 0.0 1.0</ambient>
          <diffuse>0.0 0.5 0.0 1.0</diffuse>
          <specular>0.1 0.1 0.1 1.0</specular>
        </material>
      </visual>
    </link>

    <link name= berry_link_4 >
      <pose> -0.14034067748690135 -0.12597006726153143 0.01495392572905966
             0 -1.5607963267948965  -2.4101040163531375</pose>
      <inertial>
        <mass>0.018</mass>
        <inertia>
          <ixx>8.82e-6</ixx>
          <ixy>0</ixy>
          <ixz>0</ixz>
          <iyy>8.82e-6</iyy>
          <iyz>0</iyz>
          <izz>8.82e-6</izz>
        </inertia>
      </inertial>
      <collision name="collision">
        <geometry>
          <sphere>
            <radius>0.015104972940986623</radius>
          </sphere>
        </geometry>
      </collision>
      <visual name="visual">
        <geometry>
          <mesh>
            <uri>model://random_strawberry_plant/meshes/1004r1.dae</uri>
            <scale>0.30209945881973244 0.30209945881973244 0.30209945881973244</scale>
          </mesh>
        </geometry>
      </visual>
    </link>

    <link name= calyx_link_4 >
      <pose> -0.14034067748690135 -0.12597006726153143 0.01495392572905966
             0 -1.5607963267948965 -2.4101040163531375 </pose>
      <inertial>
        <mass>0.018</mass>
        <inertia>
          <ixx>8.82e-6</ixx>
          <ixy>0</ixy>
          <ixz>0</ixz>
          <iyy>8.82e-6</iyy>
          <iyz>0</iyz>
          <izz>8.82e-6</izz>
        </inertia>
      </inertial>
      <visual name="visual">
        <geometry>
          <mesh>
            <uri>model://random_strawberry_plant/meshes/calyx5_1004.dae</uri>
            <scale>0.30209945881973244 0.30209945881973244 0.30209945881973244</scale>
          </mesh>
        </geometry>
      </visual>
    </link>

    <joint name=berry_dirt_joint_4 type="revolute">
      <parent>dirt_link</parent>
      <child>berry_stem_link_4</child>
      <axis>
        <xyz>0 1 0</xyz>
      </axis>
    </joint>

    <joint name=stem_to_calyx_joint_4 type="ball">
      <parent> berry_link_4 </parent>
      <child> calyx_link_4 </child>
    </joint>

    <joint name=stem_to_berry_joint_4 type="ball">
      <parent> berry_stem_link_4 </parent>
      <child> berry_link_4 </child>
    </joint>

    <link name= berry_stem_link_5 >
      <pose>0 0 0 0 -0.08270336342585743 2.749687178170106</pose>
      <inertial>
        <mass>1</mass>
        <inertia> <!-- Modeled as slender rod -->
          <ixx>1e-3</ixx>
          <ixy>0</ixy>
          <ixz>0</ixz>
          <iyy>8.333e-2</iyy>
          <iyz>0</iyz>
          <izz>8.333e-2</izz>
        </inertia>
      </inertial>
      <visual name="visual">
        <geometry>
          <mesh>
            <uri>model://random_strawberry_plant/meshes/strawb_stem2.stl</uri>
            <scale>0.30453997096883717 0.30453997096883717 0.30453997096883717</scale>
          </mesh>
        </geometry>
        <material> <!-- Green -->
          <ambient>0.0 0.5 0.0 1.0</ambient>
          <diffuse>0.0 0.5 0.0 1.0</diffuse>
          <specular>0.1 0.1 0.1 1.0</specular>
        </material>
      </visual>
    </link>

    <link name= berry_link_5 >
      <pose> -0.17651177378466196 0.07294950958970069 0.013150553848308807
             0 -1.3636567858907152  2.749687178170106</pose>
      <inertial>
        <mass>0.018</mass>
        <inertia>
          <ixx>8.82e-6</ixx>
          <ixy>0</ixy>
          <ixz>0</ixz>
          <iyy>8.82e-6</iyy>
          <iyz>0</iyz>
          <izz>8.82e-6</izz>
        </inertia>
      </inertial>
      <collision name="collision">
        <geometry>
          <sphere>
            <radius>0.013150553848308807</radius>
          </sphere>
        </geometry>
      </collision>
      <visual name="visual">
        <geometry>
          <mesh>
            <uri>model://random_strawberry_plant/meshes/1003r0.dae</uri>
            <scale>0.26301107696617615 0.26301107696617615 0.26301107696617615</scale>
          </mesh>
        </geometry>
      </visual>
    </link>

    <link name= calyx_link_5 >
      <pose> -0.17651177378466196 0.07294950958970069 0.013150553848308807
             0 -1.3636567858907152 2.749687178170106 </pose>
      <inertial>
        <mass>0.018</mass>
        <inertia>
          <ixx>8.82e-6</ixx>
          <ixy>0</ixy>
          <ixz>0</ixz>
          <iyy>8.82e-6</iyy>
          <iyz>0</iyz>
          <izz>8.82e-6</izz>
        </inertia>
      </inertial>
      <visual name="visual">
        <geometry>
          <mesh>
            <uri>model://random_strawberry_plant/meshes/calyx1_1003.dae</uri>
            <scale>0.26301107696617615 0.26301107696617615 0.26301107696617615</scale>
          </mesh>
        </geometry>
      </visual>
    </link>

    <joint name=berry_dirt_joint_5 type="revolute">
      <parent>dirt_link</parent>
      <child>berry_stem_link_5</child>
      <axis>
        <xyz>0 1 0</xyz>
      </axis>
    </joint>

    <joint name=stem_to_calyx_joint_5 type="ball">
      <parent> berry_link_5 </parent>
      <child> calyx_link_5 </child>
    </joint>

    <joint name=stem_to_berry_joint_5 type="ball">
      <parent> berry_stem_link_5 </parent>
      <child> berry_link_5 </child>
    </joint>

    <link name= berry_stem_link_6 >
      <pose>0 0 0 0 -0.09921406496624907 -1.187859965473306</pose>
      <inertial>
        <mass>1</mass>
        <inertia> <!-- Modeled as slender rod -->
          <ixx>1e-3</ixx>
          <ixy>0</ixy>
          <ixz>0</ixz>
          <iyy>8.333e-2</iyy>
          <iyz>0</iyz>
          <izz>8.333e-2</izz>
        </inertia>
      </inertial>
      <visual name="visual">
        <geometry>
          <mesh>
            <uri>model://random_strawberry_plant/meshes/strawb_stem1.stl</uri>
            <scale>0.24245491644296072 0.24245491644296072 0.24245491644296072</scale>
          </mesh>
        </geometry>
        <material> <!-- Green -->
          <ambient>0.0 0.5 0.0 1.0</ambient>
          <diffuse>0.0 0.5 0.0 1.0</diffuse>
          <specular>0.1 0.1 0.1 1.0</specular>
        </material>
      </visual>
    </link>

    <link name= berry_link_6 >
      <pose> 0.058117406098131444 -0.14427581895851685 0.015327986178871886
             0 -1.5607963267948965  -1.187859965473306</pose>
      <inertial>
        <mass>0.018</mass>
        <inertia>
          <ixx>8.82e-6</ixx>
          <ixy>0</ixy>
          <ixz>0</ixz>
          <iyy>8.82e-6</iyy>
          <iyz>0</iyz>
          <izz>8.82e-6</izz>
        </inertia>
      </inertial>
      <collision name="collision">
        <geometry>
          <sphere>
            <radius>0.015482811715571887</radius>
          </sphere>
        </geometry>
      </collision>
      <visual name="visual">
        <geometry>
          <mesh>
            <uri>model://random_strawberry_plant/meshes/1002u1.dae</uri>
            <scale>0.30965623431143774 0.30965623431143774 0.30965623431143774</scale>
          </mesh>
        </geometry>
      </visual>
    </link>

    <link name= calyx_link_6 >
      <pose> 0.058117406098131444 -0.14427581895851685 0.015327986178871886
             0 -1.5607963267948965 -1.187859965473306 </pose>
      <inertial>
        <mass>0.018</mass>
        <inertia>
          <ixx>8.82e-6</ixx>
          <ixy>0</ixy>
          <ixz>0</ixz>
          <iyy>8.82e-6</iyy>
          <iyz>0</iyz>
          <izz>8.82e-6</izz>
        </inertia>
      </inertial>
      <visual name="visual">
        <geometry>
          <mesh>
            <uri>model://random_strawberry_plant/meshes/calyx4_1002.dae</uri>
            <scale>0.30965623431143774 0.30965623431143774 0.30965623431143774</scale>
          </mesh>
        </geometry>
      </visual>
    </link>

    <joint name=berry_dirt_joint_6 type="revolute">
      <parent>dirt_link</parent>
      <child>berry_stem_link_6</child>
      <axis>
        <xyz>0 1 0</xyz>
      </axis>
    </joint>

    <joint name=stem_to_calyx_joint_6 type="ball">
      <parent> berry_link_6 </parent>
      <child> calyx_link_6 </child>
    </joint>

    <joint name=stem_to_berry_joint_6 type="ball">
      <parent> berry_stem_link_6 </parent>
      <child> berry_link_6 </child>
    </joint>

    <link name= berry_stem_link_7 >
      <pose>0 0 0 0 -0.0869648105073936 2.249611473515965</pose>
      <inertial>
        <mass>1</mass>
        <inertia> <!-- Modeled as slender rod -->
          <ixx>1e-3</ixx>
          <ixy>0</ixy>
          <ixz>0</ixz>
          <iyy>8.333e-2</iyy>
          <iyz>0</iyz>
          <izz>8.333e-2</izz>
        </inertia>
      </inertial>
      <visual name="visual">
        <geometry>
          <mesh>
            <uri>model://random_strawberry_plant/meshes/strawb_stem1.stl</uri>
            <scale>0.29226096107047217 0.29226096107047217 0.29226096107047217</scale>
          </mesh>
        </geometry>
        <material> <!-- Green -->
          <ambient>0.0 0.5 0.0 1.0</ambient>
          <diffuse>0.0 0.5 0.0 1.0</diffuse>
          <specular>0.1 0.1 0.1 1.0</specular>
        </material>
      </visual>
    </link>

    <link name= berry_link_7 >
      <pose> -0.11678518277320557 0.14476839498014554 0.016054420064884622
             0 -1.5607963267948965  2.249611473515965</pose>
      <inertial>
        <mass>0.018</mass>
        <inertia>
          <ixx>8.82e-6</ixx>
          <ixy>0</ixy>
          <ixz>0</ixz>
          <iyy>8.82e-6</iyy>
          <iyz>0</iyz>
          <izz>8.82e-6</izz>
        </inertia>
      </inertial>
      <collision name="collision">
        <geometry>
          <sphere>
            <radius>0.01621658319407502</radius>
          </sphere>
        </geometry>
      </collision>
      <visual name="visual">
        <geometry>
          <mesh>
            <uri>model://random_strawberry_plant/meshes/1001u0.dae</uri>
            <scale>0.32433166388150036 0.32433166388150036 0.32433166388150036</scale>
          </mesh>
        </geometry>
      </visual>
    </link>

    <link name= calyx_link_7 >
      <pose> -0.11678518277320557 0.14476839498014554 0.016054420064884622
             0 -1.5607963267948965 2.249611473515965 </pose>
      <inertial>
        <mass>0.018</mass>
        <inertia>
          <ixx>8.82e-6</ixx>
          <ixy>0</ixy>
          <ixz>0</ixz>
          <iyy>8.82e-6</iyy>
          <iyz>0</iyz>
          <izz>8.82e-6</izz>
        </inertia>
      </inertial>
      <visual name="visual">
        <geometry>
          <mesh>
            <uri>model://random_strawberry_plant/meshes/calyx6_1001.dae</uri>
            <scale>0.32433166388150036 0.32433166388150036 0.32433166388150036</scale>
          </mesh>
        </geometry>
      </visual>
    </link>

    <joint name=berry_dirt_joint_7 type="revolute">
      <parent>dirt_link</parent>
      <child>berry_stem_link_7</child>
      <axis>
        <xyz>0 1 0</xyz>
      </axis>
    </joint>

    <joint name=stem_to_calyx_joint_7 type="ball">
      <parent> berry_link_7 </parent>
      <child> calyx_link_7 </child>
    </joint>

    <joint name=stem_to_berry_joint_7 type="ball">
      <parent> berry_stem_link_7 </parent>
      <child> berry_link_7 </child>
    </joint>

    <link name= berry_stem_link_8 >
      <pose>0 0 0 0 -0.0996520144256064 1.8635597780104858</pose>
      <inertial>
        <mass>1</mass>
        <inertia> <!-- Modeled as slender rod -->
          <ixx>1e-3</ixx>
          <ixy>0</ixy>
          <ixz>0</ixz>
          <iyy>8.333e-2</iyy>
          <iyz>0</iyz>
          <izz>8.333e-2</izz>
        </inertia>
      </inertial>
      <visual name="visual">
        <geometry>
          <mesh>
            <uri>model://random_strawberry_plant/meshes/strawb_stem3.stl</uri>
            <scale>0.26763109205556185 0.26763109205556185 0.26763109205556185</scale>
          </mesh>
        </geometry>
        <material> <!-- Green -->
          <ambient>0.0 0.5 0.0 1.0</ambient>
          <diffuse>0.0 0.5 0.0 1.0</diffuse>
          <specular>0.1 0.1 0.1 1.0</specular>
        </material>
      </visual>
    </link>

    <link name= berry_link_8 >
      <pose> -0.045873174676210444 0.15218778403852998 0.013428388525495986
             0 0.0  1.8635597780104858</pose>
      <inertial>
        <mass>0.018</mass>
        <inertia>
          <ixx>8.82e-6</ixx>
          <ixy>0</ixy>
          <ixz>0</ixz>
          <iyy>8.82e-6</iyy>
          <iyz>0</iyz>
          <izz>8.82e-6</izz>
        </inertia>
      </inertial>
      <collision name="collision">
        <geometry>
          <sphere>
            <radius>0.005000000000000001</radius>
          </sphere>
        </geometry>
      </collision>
      <visual name="visual">
        <geometry>
          <mesh>
            <uri>model://random_strawberry_plant/meshes/1003g.dae</uri>
            <scale>0.1 0.1 0.1</scale>
          </mesh>
        </geometry>
      </visual>
    </link>

    <link name= calyx_link_8 >
      <pose> -0.045873174676210444 0.15218778403852998 0.013428388525495986
             0 0.0 1.8635597780104858 </pose>
      <inertial>
        <mass>0.018</mass>
        <inertia>
          <ixx>8.82e-6</ixx>
          <ixy>0</ixy>
          <ixz>0</ixz>
          <iyy>8.82e-6</iyy>
          <iyz>0</iyz>
          <izz>8.82e-6</izz>
        </inertia>
      </inertial>
      <visual name="visual">
        <geometry>
          <mesh>
            <uri>model://random_strawberry_plant/meshes/calyx9_1003.dae</uri>
            <scale>0.1 0.1 0.1</scale>
          </mesh>
        </geometry>
      </visual>
    </link>

    <joint name=berry_dirt_joint_8 type="revolute">
      <parent>dirt_link</parent>
      <child>berry_stem_link_8</child>
      <axis>
        <xyz>0 1 0</xyz>
      </axis>
    </joint>

    <joint name=stem_to_calyx_joint_8 type="ball">
      <parent> berry_link_8 </parent>
      <child> calyx_link_8 </child>
    </joint>

    <joint name=stem_to_berry_joint_8 type="ball">
      <parent> berry_stem_link_8 </parent>
      <child> berry_link_8 </child>
    </joint>

    <link name= berry_stem_link_9 >
      <pose>0 0 0 0 -0.0487960277634725 1.4985617673537028</pose>
      <inertial>
        <mass>1</mass>
        <inertia> <!-- Modeled as slender rod -->
          <ixx>1e-3</ixx>
          <ixy>0</ixy>
          <ixz>0</ixz>
          <iyy>8.333e-2</iyy>
          <iyz>0</iyz>
          <izz>8.333e-2</izz>
        </inertia>
      </inertial>
      <visual name="visual">
        <geometry>
          <mesh>
            <uri>model://random_strawberry_plant/meshes/strawb_stem2.stl</uri>
            <scale>0.23259145266302433 0.23259145266302433 0.23259145266302433</scale>
          </mesh>
        </geometry>
        <material> <!-- Green -->
          <ambient>0.0 0.5 0.0 1.0</ambient>
          <diffuse>0.0 0.5 0.0 1.0</diffuse>
          <specular>0.1 0.1 0.1 1.0</specular>
        </material>
      </visual>
    </link>

    <link name= berry_link_9 >
      <pose> 0.01015857191915631 0.1403884411560546 0.0039398770196829745
             0 -0.7046042039921605  1.4985617673537028</pose>
      <inertial>
        <mass>0.018</mass>
        <inertia>
          <ixx>8.82e-6</ixx>
          <ixy>0</ixy>
          <ixz>0</ixz>
          <iyy>8.82e-6</iyy>
          <iyz>0</iyz>
          <izz>8.82e-6</izz>
        </inertia>
      </inertial>
      <collision name="collision">
        <geometry>
          <sphere>
            <radius>0.005000000000000001</radius>
          </sphere>
        </geometry>
      </collision>
      <visual name="visual">
        <geometry>
          <mesh>
            <uri>model://random_strawberry_plant/meshes/1001g.dae</uri>
            <scale>0.1 0.1 0.1</scale>
          </mesh>
        </geometry>
      </visual>
    </link>

    <link name= calyx_link_9 >
      <pose> 0.01015857191915631 0.1403884411560546 0.0039398770196829745
             0 -0.7046042039921605 1.4985617673537028 </pose>
      <inertial>
        <mass>0.018</mass>
        <inertia>
          <ixx>8.82e-6</ixx>
          <ixy>0</ixy>
          <ixz>0</ixz>
          <iyy>8.82e-6</iyy>
          <iyz>0</iyz>
          <izz>8.82e-6</izz>
        </inertia>
      </inertial>
      <visual name="visual">
        <geometry>
          <mesh>
            <uri>model://random_strawberry_plant/meshes/calyx9_1001.dae</uri>
            <scale>0.1 0.1 0.1</scale>
          </mesh>
        </geometry>
      </visual>
    </link>

    <joint name=berry_dirt_joint_9 type="revolute">
      <parent>dirt_link</parent>
      <child>berry_stem_link_9</child>
      <axis>
        <xyz>0 1 0</xyz>
      </axis>
    </joint>

    <joint name=stem_to_calyx_joint_9 type="ball">
      <parent> berry_link_9 </parent>
      <child> calyx_link_9 </child>
    </joint>

    <joint name=stem_to_berry_joint_9 type="ball">
      <parent> berry_stem_link_9 </parent>
      <child> berry_link_9 </child>
    </joint>

  </model>
</sdf>
