<?xml version="1.0" ?>


<sdf version="1.6">
  <model name="strawb_plant">
    <static>true</static>

    <link name="dirt_link">
      <inertial>
        <mass>10</mass>
        <inertia>
          <ixx>1</ixx>
          <ixy>0</ixy>
          <ixz>0</ixz>
          <iyy>1</iyy>
          <iyz>0</iyz>
          <izz>1</izz>
        </inertia>
      </inertial>
    </link>

    <joint name="fixed to ground" type="revolute">
      <parent>world</parent>
      <child>dirt_link</child>
      <axis>
        <xyz>0 1 0</xyz>
      </axis>
    </joint>


    <link name= leaf_stem_link_1 >
      <pose>0 0 0 0 -0.6857043043458946 -0.77162598317733 </pose>
      <inertial>
        <mass>1</mass>
        <inertia> <!-- Modeled as slender rod -->
          <ixx>1e-3</ixx>
          <ixy>0</ixy>
          <ixz>0</ixz>
          <iyy>8.333e-2</iyy>
          <iyz>0</iyz>
          <izz>8.333e-2</izz>
        </inertia>
      </inertial>
      <visual name="visual">
        <geometry>
          <mesh>
            <uri>model://random_strawberry_plant/meshes/leaf_stem1.stl</uri>
            <scale> 0.28916292641103836 0.28916292641103836 0.28916292641103836</scale>
          </mesh>
        </geometry>
        <material> <!-- Green -->
          <ambient>0.0 0.5 0.0 1.0</ambient>
          <diffuse>0.0 0.5 0.0 1.0</diffuse>
          <specular>0.1 0.1 0.1 1.0</specular>
        </material>
      </visual>
    </link>

    <link name= leaf_link_1_0 >
      <pose> 0.09625080594868088
             -0.09363549227470819
             0.10986195075874469 0
             0 -2.212319072814471  </pose>
      <inertial>
        <mass>0.018</mass>
        <inertia>
          <ixx>8.82e-6</ixx>
          <ixy>0</ixy>
          <ixz>0</ixz>
          <iyy>8.82e-6</iyy>
          <iyz>0</iyz>
          <izz>8.82e-6</izz>
        </inertia>
      </inertial>
      <visual name="visual">
        <geometry>
          <mesh>
            <uri>model://random_strawberry_plant/meshes/leaf2.dae</uri>
            <scale> 0.6660629642369813 0.6660629642369813 0.6660629642369813</scale>
          </mesh>
        </geometry>
      </visual>
    </link>

    <link name= leaf_link_1_1 >
      <pose> 0.09625080594868088
             -0.09363549227470819
             0.10986195075874469 0
             0 -0.7508734177728529  </pose>
      <inertial>
        <mass>0.018</mass>
        <inertia>
          <ixx>8.82e-6</ixx>
          <ixy>0</ixy>
          <ixz>0</ixz>
          <iyy>8.82e-6</iyy>
          <iyz>0</iyz>
          <izz>8.82e-6</izz>
        </inertia>
      </inertial>
      <visual name="visual">
        <geometry>
          <mesh>
            <uri>model://random_strawberry_plant/meshes/leaf4.dae</uri>
            <scale> 0.6660629642369813 0.6660629642369813 0.6660629642369813</scale>
          </mesh>
        </geometry>
      </visual>
    </link>

    <link name= leaf_link_1_2 >
      <pose> 0.09625080594868088
             -0.09363549227470819
             0.10986195075874469 0
             0 0.8423936738283426  </pose>
      <inertial>
        <mass>0.018</mass>
        <inertia>
          <ixx>8.82e-6</ixx>
          <ixy>0</ixy>
          <ixz>0</ixz>
          <iyy>8.82e-6</iyy>
          <iyz>0</iyz>
          <izz>8.82e-6</izz>
        </inertia>
      </inertial>
      <visual name="visual">
        <geometry>
          <mesh>
            <uri>model://random_strawberry_plant/meshes/leaf2.dae</uri>
            <scale> 0.6660629642369813 0.6660629642369813 0.6660629642369813</scale>
          </mesh>
        </geometry>
      </visual>
    </link>


    <joint name=leaf_dirt_joint_1 type="revolute">
      <parent>dirt_link</parent>
      <child>leaf_stem_link_1</child>
      <axis>
        <xyz>0 1 0</xyz>
      </axis>
    </joint>

    <link name= leaf_stem_link_2 >
      <pose>0 0 0 0 -0.8603213619224737 -1.86438914924681 </pose>
      <inertial>
        <mass>1</mass>
        <inertia> <!-- Modeled as slender rod -->
          <ixx>1e-3</ixx>
          <ixy>0</ixy>
          <ixz>0</ixz>
          <iyy>8.333e-2</iyy>
          <iyz>0</iyz>
          <izz>8.333e-2</izz>
        </inertia>
      </inertial>
      <visual name="visual">
        <geometry>
          <mesh>
            <uri>model://random_strawberry_plant/meshes/leaf_stem2.stl</uri>
            <scale> 0.37498679363847004 0.37498679363847004 0.37498679363847004</scale>
          </mesh>
        </geometry>
        <material> <!-- Green -->
          <ambient>0.0 0.5 0.0 1.0</ambient>
          <diffuse>0.0 0.5 0.0 1.0</diffuse>
          <specular>0.1 0.1 0.1 1.0</specular>
        </material>
      </visual>
    </link>

    <link name= leaf_link_2_0 >
      <pose> -0.04246510784763158
             -0.14045956596776565
             0.17055573660481105 0
             0 -3.411366219239224  </pose>
      <inertial>
        <mass>0.018</mass>
        <inertia>
          <ixx>8.82e-6</ixx>
          <ixy>0</ixy>
          <ixz>0</ixz>
          <iyy>8.82e-6</iyy>
          <iyz>0</iyz>
          <izz>8.82e-6</izz>
        </inertia>
      </inertial>
      <visual name="visual">
        <geometry>
          <mesh>
            <uri>model://random_strawberry_plant/meshes/leaf2.dae</uri>
            <scale> 0.762476455528019 0.762476455528019 0.762476455528019</scale>
          </mesh>
        </geometry>
      </visual>
    </link>

    <link name= leaf_link_2_1 >
      <pose> -0.04246510784763158
             -0.14045956596776565
             0.17055573660481105 0
             0 -1.7139659949858834  </pose>
      <inertial>
        <mass>0.018</mass>
        <inertia>
          <ixx>8.82e-6</ixx>
          <ixy>0</ixy>
          <ixz>0</ixz>
          <iyy>8.82e-6</iyy>
          <iyz>0</iyz>
          <izz>8.82e-6</izz>
        </inertia>
      </inertial>
      <visual name="visual">
        <geometry>
          <mesh>
            <uri>model://random_strawberry_plant/meshes/leaf5.dae</uri>
            <scale> 0.762476455528019 0.762476455528019 0.762476455528019</scale>
          </mesh>
        </geometry>
      </visual>
    </link>

    <link name= leaf_link_2_2 >
      <pose> -0.04246510784763158
             -0.14045956596776565
             0.17055573660481105 0
             0 -0.33380837138222974  </pose>
      <inertial>
        <mass>0.018</mass>
        <inertia>
          <ixx>8.82e-6</ixx>
          <ixy>0</ixy>
          <ixz>0</ixz>
          <iyy>8.82e-6</iyy>
          <iyz>0</iyz>
          <izz>8.82e-6</izz>
        </inertia>
      </inertial>
      <visual name="visual">
        <geometry>
          <mesh>
            <uri>model://random_strawberry_plant/meshes/leaf3.dae</uri>
            <scale> 0.762476455528019 0.762476455528019 0.762476455528019</scale>
          </mesh>
        </geometry>
      </visual>
    </link>


    <joint name=leaf_dirt_joint_2 type="revolute">
      <parent>dirt_link</parent>
      <child>leaf_stem_link_2</child>
      <axis>
        <xyz>0 1 0</xyz>
      </axis>
    </joint>

    <link name= leaf_stem_link_3 >
      <pose>0 0 0 0 -1.0712210182648105 2.116216997600926 </pose>
      <inertial>
        <mass>1</mass>
        <inertia> <!-- Modeled as slender rod -->
          <ixx>1e-3</ixx>
          <ixy>0</ixy>
          <ixz>0</ixz>
          <iyy>8.333e-2</iyy>
          <iyz>0</iyz>
          <izz>8.333e-2</izz>
        </inertia>
      </inertial>
      <visual name="visual">
        <geometry>
          <mesh>
            <uri>model://random_strawberry_plant/meshes/leaf_stem2.stl</uri>
            <scale> 0.1944808106369637 0.1944808106369637 0.1944808106369637</scale>
          </mesh>
        </geometry>
        <material> <!-- Green -->
          <ambient>0.0 0.5 0.0 1.0</ambient>
          <diffuse>0.0 0.5 0.0 1.0</diffuse>
          <specular>0.1 0.1 0.1 1.0</specular>
        </material>
      </visual>
    </link>

    <link name= leaf_link_3_0 >
      <pose> -0.028999649101247273
             0.04778937376787917
             0.10242753028869855 0
             0 0.46844946833553447  </pose>
      <inertial>
        <mass>0.018</mass>
        <inertia>
          <ixx>8.82e-6</ixx>
          <ixy>0</ixy>
          <ixz>0</ixz>
          <iyy>8.82e-6</iyy>
          <iyz>0</iyz>
          <izz>8.82e-6</izz>
        </inertia>
      </inertial>
      <visual name="visual">
        <geometry>
          <mesh>
            <uri>model://random_strawberry_plant/meshes/leaf1.dae</uri>
            <scale> 0.6838594634815987 0.6838594634815987 0.6838594634815987</scale>
          </mesh>
        </geometry>
      </visual>
    </link>

    <link name= leaf_link_3_1 >
      <pose> -0.028999649101247273
             0.04778937376787917
             0.10242753028869855 0
             0 2.117778878217512  </pose>
      <inertial>
        <mass>0.018</mass>
        <inertia>
          <ixx>8.82e-6</ixx>
          <ixy>0</ixy>
          <ixz>0</ixz>
          <iyy>8.82e-6</iyy>
          <iyz>0</iyz>
          <izz>8.82e-6</izz>
        </inertia>
      </inertial>
      <visual name="visual">
        <geometry>
          <mesh>
            <uri>model://random_strawberry_plant/meshes/leaf3.dae</uri>
            <scale> 0.6838594634815987 0.6838594634815987 0.6838594634815987</scale>
          </mesh>
        </geometry>
      </visual>
    </link>

    <link name= leaf_link_3_2 >
      <pose> -0.028999649101247273
             0.04778937376787917
             0.10242753028869855 0
             0 3.6510612342720608  </pose>
      <inertial>
        <mass>0.018</mass>
        <inertia>
          <ixx>8.82e-6</ixx>
          <ixy>0</ixy>
          <ixz>0</ixz>
          <iyy>8.82e-6</iyy>
          <iyz>0</iyz>
          <izz>8.82e-6</izz>
        </inertia>
      </inertial>
      <visual name="visual">
        <geometry>
          <mesh>
            <uri>model://random_strawberry_plant/meshes/leaf3.dae</uri>
            <scale> 0.6838594634815987 0.6838594634815987 0.6838594634815987</scale>
          </mesh>
        </geometry>
      </visual>
    </link>


    <joint name=leaf_dirt_joint_3 type="revolute">
      <parent>dirt_link</parent>
      <child>leaf_stem_link_3</child>
      <axis>
        <xyz>0 1 0</xyz>
      </axis>
    </joint>

    <link name= leaf_stem_link_4 >
      <pose>0 0 0 0 -1.1304963415152827 -2.1045938018304993 </pose>
      <inertial>
        <mass>1</mass>
        <inertia> <!-- Modeled as slender rod -->
          <ixx>1e-3</ixx>
          <ixy>0</ixy>
          <ixz>0</ixz>
          <iyy>8.333e-2</iyy>
          <iyz>0</iyz>
          <izz>8.333e-2</izz>
        </inertia>
      </inertial>
      <visual name="visual">
        <geometry>
          <mesh>
            <uri>model://random_strawberry_plant/meshes/leaf_stem2.stl</uri>
            <scale> 0.24878694012517089 0.24878694012517089 0.24878694012517089</scale>
          </mesh>
        </geometry>
        <material> <!-- Green -->
          <ambient>0.0 0.5 0.0 1.0</ambient>
          <diffuse>0.0 0.5 0.0 1.0</diffuse>
          <specular>0.1 0.1 0.1 1.0</specular>
        </material>
      </visual>
    </link>

    <link name= leaf_link_4_0 >
      <pose> -0.03237096999999341
             -0.05477047580441634
             0.13503515930705492 0
             0 -3.7644796691600373  </pose>
      <inertial>
        <mass>0.018</mass>
        <inertia>
          <ixx>8.82e-6</ixx>
          <ixy>0</ixy>
          <ixz>0</ixz>
          <iyy>8.82e-6</iyy>
          <iyz>0</iyz>
          <izz>8.82e-6</izz>
        </inertia>
      </inertial>
      <visual name="visual">
        <geometry>
          <mesh>
            <uri>model://random_strawberry_plant/meshes/leaf4.dae</uri>
            <scale> 0.6865356904632061 0.6865356904632061 0.6865356904632061</scale>
          </mesh>
        </geometry>
      </visual>
    </link>

    <link name= leaf_link_4_1 >
      <pose> -0.03237096999999341
             -0.05477047580441634
             0.13503515930705492 0
             0 -2.0702550079575968  </pose>
      <inertial>
        <mass>0.018</mass>
        <inertia>
          <ixx>8.82e-6</ixx>
          <ixy>0</ixy>
          <ixz>0</ixz>
          <iyy>8.82e-6</iyy>
          <iyz>0</iyz>
          <izz>8.82e-6</izz>
        </inertia>
      </inertial>
      <visual name="visual">
        <geometry>
          <mesh>
            <uri>model://random_strawberry_plant/meshes/leaf4.dae</uri>
            <scale> 0.6865356904632061 0.6865356904632061 0.6865356904632061</scale>
          </mesh>
        </geometry>
      </visual>
    </link>

    <link name= leaf_link_4_2 >
      <pose> -0.03237096999999341
             -0.05477047580441634
             0.13503515930705492 0
             0 -0.36102591756681046  </pose>
      <inertial>
        <mass>0.018</mass>
        <inertia>
          <ixx>8.82e-6</ixx>
          <ixy>0</ixy>
          <ixz>0</ixz>
          <iyy>8.82e-6</iyy>
          <iyz>0</iyz>
          <izz>8.82e-6</izz>
        </inertia>
      </inertial>
      <visual name="visual">
        <geometry>
          <mesh>
            <uri>model://random_strawberry_plant/meshes/leaf2.dae</uri>
            <scale> 0.6865356904632061 0.6865356904632061 0.6865356904632061</scale>
          </mesh>
        </geometry>
      </visual>
    </link>


    <joint name=leaf_dirt_joint_4 type="revolute">
      <parent>dirt_link</parent>
      <child>leaf_stem_link_4</child>
      <axis>
        <xyz>0 1 0</xyz>
      </axis>
    </joint>

    <link name= leaf_stem_link_5 >
      <pose>0 0 0 0 -0.8933584127415886 -0.6860882893703293 </pose>
      <inertial>
        <mass>1</mass>
        <inertia> <!-- Modeled as slender rod -->
          <ixx>1e-3</ixx>
          <ixy>0</ixy>
          <ixz>0</ixz>
          <iyy>8.333e-2</iyy>
          <iyz>0</iyz>
          <izz>8.333e-2</izz>
        </inertia>
      </inertial>
      <visual name="visual">
        <geometry>
          <mesh>
            <uri>model://random_strawberry_plant/meshes/leaf_stem2.stl</uri>
            <scale> 0.35483656796566415 0.35483656796566415 0.35483656796566415</scale>
          </mesh>
        </geometry>
        <material> <!-- Green -->
          <ambient>0.0 0.5 0.0 1.0</ambient>
          <diffuse>0.0 0.5 0.0 1.0</diffuse>
          <specular>0.1 0.1 0.1 1.0</specular>
        </material>
      </visual>
    </link>

    <link name= leaf_link_5_0 >
      <pose> 0.10325170060498455
             -0.08454052515491092
             0.1658891868578088 0
             0 -2.373808733233946  </pose>
      <inertial>
        <mass>0.018</mass>
        <inertia>
          <ixx>8.82e-6</ixx>
          <ixy>0</ixy>
          <ixz>0</ixz>
          <iyy>8.82e-6</iyy>
          <iyz>0</iyz>
          <izz>8.82e-6</izz>
        </inertia>
      </inertial>
      <visual name="visual">
        <geometry>
          <mesh>
            <uri>model://random_strawberry_plant/meshes/leaf2.dae</uri>
            <scale> 0.44505118781463165 0.44505118781463165 0.44505118781463165</scale>
          </mesh>
        </geometry>
      </visual>
    </link>

    <link name= leaf_link_5_1 >
      <pose> 0.10325170060498455
             -0.08454052515491092
             0.1658891868578088 0
             0 -0.6601017818341238  </pose>
      <inertial>
        <mass>0.018</mass>
        <inertia>
          <ixx>8.82e-6</ixx>
          <ixy>0</ixy>
          <ixz>0</ixz>
          <iyy>8.82e-6</iyy>
          <iyz>0</iyz>
          <izz>8.82e-6</izz>
        </inertia>
      </inertial>
      <visual name="visual">
        <geometry>
          <mesh>
            <uri>model://random_strawberry_plant/meshes/leaf2.dae</uri>
            <scale> 0.44505118781463165 0.44505118781463165 0.44505118781463165</scale>
          </mesh>
        </geometry>
      </visual>
    </link>

    <link name= leaf_link_5_2 >
      <pose> 0.10325170060498455
             -0.08454052515491092
             0.1658891868578088 0
             0 0.8959942661787346  </pose>
      <inertial>
        <mass>0.018</mass>
        <inertia>
          <ixx>8.82e-6</ixx>
          <ixy>0</ixy>
          <ixz>0</ixz>
          <iyy>8.82e-6</iyy>
          <iyz>0</iyz>
          <izz>8.82e-6</izz>
        </inertia>
      </inertial>
      <visual name="visual">
        <geometry>
          <mesh>
            <uri>model://random_strawberry_plant/meshes/leaf5.dae</uri>
            <scale> 0.44505118781463165 0.44505118781463165 0.44505118781463165</scale>
          </mesh>
        </geometry>
      </visual>
    </link>


    <joint name=leaf_dirt_joint_5 type="revolute">
      <parent>dirt_link</parent>
      <child>leaf_stem_link_5</child>
      <axis>
        <xyz>0 1 0</xyz>
      </axis>
    </joint>

    <link name= leaf_stem_link_6 >
      <pose>0 0 0 0 -0.3515678031127568 2.052506575891825 </pose>
      <inertial>
        <mass>1</mass>
        <inertia> <!-- Modeled as slender rod -->
          <ixx>1e-3</ixx>
          <ixy>0</ixy>
          <ixz>0</ixz>
          <iyy>8.333e-2</iyy>
          <iyz>0</iyz>
          <izz>8.333e-2</izz>
        </inertia>
      </inertial>
      <visual name="visual">
        <geometry>
          <mesh>
            <uri>model://random_strawberry_plant/meshes/leaf_stem1.stl</uri>
            <scale> 0.289256736819999 0.289256736819999 0.289256736819999</scale>
          </mesh>
        </geometry>
        <material> <!-- Green -->
          <ambient>0.0 0.5 0.0 1.0</ambient>
          <diffuse>0.0 0.5 0.0 1.0</diffuse>
          <specular>0.1 0.1 0.1 1.0</specular>
        </material>
      </visual>
    </link>

    <link name= leaf_link_6_0 >
      <pose> -0.07548863796226808
             0.14439666612648008
             0.05976682923353847 0
             0 0.5039094213659678  </pose>
      <inertial>
        <mass>0.018</mass>
        <inertia>
          <ixx>8.82e-6</ixx>
          <ixy>0</ixy>
          <ixz>0</ixz>
          <iyy>8.82e-6</iyy>
          <iyz>0</iyz>
          <izz>8.82e-6</izz>
        </inertia>
      </inertial>
      <visual name="visual">
        <geometry>
          <mesh>
            <uri>model://random_strawberry_plant/meshes/leaf1.dae</uri>
            <scale> 0.7224081403184927 0.7224081403184927 0.7224081403184927</scale>
          </mesh>
        </geometry>
      </visual>
    </link>

    <link name= leaf_link_6_1 >
      <pose> -0.07548863796226808
             0.14439666612648008
             0.05976682923353847 0
             0 1.9737417228667686  </pose>
      <inertial>
        <mass>0.018</mass>
        <inertia>
          <ixx>8.82e-6</ixx>
          <ixy>0</ixy>
          <ixz>0</ixz>
          <iyy>8.82e-6</iyy>
          <iyz>0</iyz>
          <izz>8.82e-6</izz>
        </inertia>
      </inertial>
      <visual name="visual">
        <geometry>
          <mesh>
            <uri>model://random_strawberry_plant/meshes/leaf5.dae</uri>
            <scale> 0.7224081403184927 0.7224081403184927 0.7224081403184927</scale>
          </mesh>
        </geometry>
      </visual>
    </link>

    <link name= leaf_link_6_2 >
      <pose> -0.07548863796226808
             0.14439666612648008
             0.05976682923353847 0
             0 3.4842488242281364  </pose>
      <inertial>
        <mass>0.018</mass>
        <inertia>
          <ixx>8.82e-6</ixx>
          <ixy>0</ixy>
          <ixz>0</ixz>
          <iyy>8.82e-6</iyy>
          <iyz>0</iyz>
          <izz>8.82e-6</izz>
        </inertia>
      </inertial>
      <visual name="visual">
        <geometry>
          <mesh>
            <uri>model://random_strawberry_plant/meshes/leaf1.dae</uri>
            <scale> 0.7224081403184927 0.7224081403184927 0.7224081403184927</scale>
          </mesh>
        </geometry>
      </visual>
    </link>


    <joint name=leaf_dirt_joint_6 type="revolute">
      <parent>dirt_link</parent>
      <child>leaf_stem_link_6</child>
      <axis>
        <xyz>0 1 0</xyz>
      </axis>
    </joint>

    <link name= leaf_stem_link_7 >
      <pose>0 0 0 0 -0.5781038148290133 -2.376048792621388 </pose>
      <inertial>
        <mass>1</mass>
        <inertia> <!-- Modeled as slender rod -->
          <ixx>1e-3</ixx>
          <ixy>0</ixy>
          <ixz>0</ixz>
          <iyy>8.333e-2</iyy>
          <iyz>0</iyz>
          <izz>8.333e-2</izz>
        </inertia>
      </inertial>
      <visual name="visual">
        <geometry>
          <mesh>
            <uri>model://random_strawberry_plant/meshes/leaf_stem1.stl</uri>
            <scale> 0.40237152314938607 0.40237152314938607 0.40237152314938607</scale>
          </mesh>
        </geometry>
        <material> <!-- Green -->
          <ambient>0.0 0.5 0.0 1.0</ambient>
          <diffuse>0.0 0.5 0.0 1.0</diffuse>
          <specular>0.1 0.1 0.1 1.0</specular>
        </material>
      </visual>
    </link>

    <link name= leaf_link_7_0 >
      <pose> -0.14578139472884563
             -0.1401045821436508
             0.13192238007338258 0
             0 -3.8126383239020853  </pose>
      <inertial>
        <mass>0.018</mass>
        <inertia>
          <ixx>8.82e-6</ixx>
          <ixy>0</ixy>
          <ixz>0</ixz>
          <iyy>8.82e-6</iyy>
          <iyz>0</iyz>
          <izz>8.82e-6</izz>
        </inertia>
      </inertial>
      <visual name="visual">
        <geometry>
          <mesh>
            <uri>model://random_strawberry_plant/meshes/leaf2.dae</uri>
            <scale> 0.6623177289042832 0.6623177289042832 0.6623177289042832</scale>
          </mesh>
        </geometry>
      </visual>
    </link>

    <link name= leaf_link_7_1 >
      <pose> -0.14578139472884563
             -0.1401045821436508
             0.13192238007338258 0
             0 -2.373673931171498  </pose>
      <inertial>
        <mass>0.018</mass>
        <inertia>
          <ixx>8.82e-6</ixx>
          <ixy>0</ixy>
          <ixz>0</ixz>
          <iyy>8.82e-6</iyy>
          <iyz>0</iyz>
          <izz>8.82e-6</izz>
        </inertia>
      </inertial>
      <visual name="visual">
        <geometry>
          <mesh>
            <uri>model://random_strawberry_plant/meshes/leaf4.dae</uri>
            <scale> 0.6623177289042832 0.6623177289042832 0.6623177289042832</scale>
          </mesh>
        </geometry>
      </visual>
    </link>

    <link name= leaf_link_7_2 >
      <pose> -0.14578139472884563
             -0.1401045821436508
             0.13192238007338258 0
             0 -0.9300359842466839  </pose>
      <inertial>
        <mass>0.018</mass>
        <inertia>
          <ixx>8.82e-6</ixx>
          <ixy>0</ixy>
          <ixz>0</ixz>
          <iyy>8.82e-6</iyy>
          <iyz>0</iyz>
          <izz>8.82e-6</izz>
        </inertia>
      </inertial>
      <visual name="visual">
        <geometry>
          <mesh>
            <uri>model://random_strawberry_plant/meshes/leaf3.dae</uri>
            <scale> 0.6623177289042832 0.6623177289042832 0.6623177289042832</scale>
          </mesh>
        </geometry>
      </visual>
    </link>


    <joint name=leaf_dirt_joint_7 type="revolute">
      <parent>dirt_link</parent>
      <child>leaf_stem_link_7</child>
      <axis>
        <xyz>0 1 0</xyz>
      </axis>
    </joint>

    <link name= leaf_stem_link_8 >
      <pose>0 0 0 0 -0.6967403489960441 2.7179196197655733 </pose>
      <inertial>
        <mass>1</mass>
        <inertia> <!-- Modeled as slender rod -->
          <ixx>1e-3</ixx>
          <ixy>0</ixy>
          <ixz>0</ixz>
          <iyy>8.333e-2</iyy>
          <iyz>0</iyz>
          <izz>8.333e-2</izz>
        </inertia>
      </inertial>
      <visual name="visual">
        <geometry>
          <mesh>
            <uri>model://random_strawberry_plant/meshes/leaf_stem1.stl</uri>
            <scale> 0.3640088406777513 0.3640088406777513 0.3640088406777513</scale>
          </mesh>
        </geometry>
        <material> <!-- Green -->
          <ambient>0.0 0.5 0.0 1.0</ambient>
          <diffuse>0.0 0.5 0.0 1.0</diffuse>
          <specular>0.1 0.1 0.1 1.0</specular>
        </material>
      </visual>
    </link>

    <link name= leaf_link_8_0 >
      <pose> -0.15269354075986202
             0.06886254845861924
             0.1401553032281064 0
             0 1.1504204716409934  </pose>
      <inertial>
        <mass>0.018</mass>
        <inertia>
          <ixx>8.82e-6</ixx>
          <ixy>0</ixy>
          <ixz>0</ixz>
          <iyy>8.82e-6</iyy>
          <iyz>0</iyz>
          <izz>8.82e-6</izz>
        </inertia>
      </inertial>
      <visual name="visual">
        <geometry>
          <mesh>
            <uri>model://random_strawberry_plant/meshes/leaf3.dae</uri>
            <scale> 0.5658877939361553 0.5658877939361553 0.5658877939361553</scale>
          </mesh>
        </geometry>
      </visual>
    </link>

    <link name= leaf_link_8_1 >
      <pose> -0.15269354075986202
             0.06886254845861924
             0.1401553032281064 0
             0 2.5370167086845044  </pose>
      <inertial>
        <mass>0.018</mass>
        <inertia>
          <ixx>8.82e-6</ixx>
          <ixy>0</ixy>
          <ixz>0</ixz>
          <iyy>8.82e-6</iyy>
          <iyz>0</iyz>
          <izz>8.82e-6</izz>
        </inertia>
      </inertial>
      <visual name="visual">
        <geometry>
          <mesh>
            <uri>model://random_strawberry_plant/meshes/leaf3.dae</uri>
            <scale> 0.5658877939361553 0.5658877939361553 0.5658877939361553</scale>
          </mesh>
        </geometry>
      </visual>
    </link>

    <link name= leaf_link_8_2 >
      <pose> -0.15269354075986202
             0.06886254845861924
             0.1401553032281064 0
             0 4.194322951617435  </pose>
      <inertial>
        <mass>0.018</mass>
        <inertia>
          <ixx>8.82e-6</ixx>
          <ixy>0</ixy>
          <ixz>0</ixz>
          <iyy>8.82e-6</iyy>
          <iyz>0</iyz>
          <izz>8.82e-6</izz>
        </inertia>
      </inertial>
      <visual name="visual">
        <geometry>
          <mesh>
            <uri>model://random_strawberry_plant/meshes/leaf5.dae</uri>
            <scale> 0.5658877939361553 0.5658877939361553 0.5658877939361553</scale>
          </mesh>
        </geometry>
      </visual>
    </link>


    <joint name=leaf_dirt_joint_8 type="revolute">
      <parent>dirt_link</parent>
      <child>leaf_stem_link_8</child>
      <axis>
        <xyz>0 1 0</xyz>
      </axis>
    </joint>

    <link name= leaf_stem_link_9 >
      <pose>0 0 0 0 -0.8931908853847328 -2.3850972952172205 </pose>
      <inertial>
        <mass>1</mass>
        <inertia> <!-- Modeled as slender rod -->
          <ixx>1e-3</ixx>
          <ixy>0</ixy>
          <ixz>0</ixz>
          <iyy>8.333e-2</iyy>
          <iyz>0</iyz>
          <izz>8.333e-2</izz>
        </inertia>
      </inertial>
      <visual name="visual">
        <geometry>
          <mesh>
            <uri>model://random_strawberry_plant/meshes/leaf_stem2.stl</uri>
            <scale> 0.1852133379896718 0.1852133379896718 0.1852133379896718</scale>
          </mesh>
        </geometry>
        <material> <!-- Green -->
          <ambient>0.0 0.5 0.0 1.0</ambient>
          <diffuse>0.0 0.5 0.0 1.0</diffuse>
          <specular>0.1 0.1 0.1 1.0</specular>
        </material>
      </visual>
    </link>

    <link name= leaf_link_9_0 >
      <pose> -0.05066678996564168
             -0.047819467953393334
             0.08657717877230374 0
             0 -3.8586914400217847  </pose>
      <inertial>
        <mass>0.018</mass>
        <inertia>
          <ixx>8.82e-6</ixx>
          <ixy>0</ixy>
          <ixz>0</ixz>
          <iyy>8.82e-6</iyy>
          <iyz>0</iyz>
          <izz>8.82e-6</izz>
        </inertia>
      </inertial>
      <visual name="visual">
        <geometry>
          <mesh>
            <uri>model://random_strawberry_plant/meshes/leaf1.dae</uri>
            <scale> 0.4860194481031754 0.4860194481031754 0.4860194481031754</scale>
          </mesh>
        </geometry>
      </visual>
    </link>

    <link name= leaf_link_9_1 >
      <pose> -0.05066678996564168
             -0.047819467953393334
             0.08657717877230374 0
             0 -2.3651855881851396  </pose>
      <inertial>
        <mass>0.018</mass>
        <inertia>
          <ixx>8.82e-6</ixx>
          <ixy>0</ixy>
          <ixz>0</ixz>
          <iyy>8.82e-6</iyy>
          <iyz>0</iyz>
          <izz>8.82e-6</izz>
        </inertia>
      </inertial>
      <visual name="visual">
        <geometry>
          <mesh>
            <uri>model://random_strawberry_plant/meshes/leaf3.dae</uri>
            <scale> 0.4860194481031754 0.4860194481031754 0.4860194481031754</scale>
          </mesh>
        </geometry>
      </visual>
    </link>

    <link name= leaf_link_9_2 >
      <pose> -0.05066678996564168
             -0.047819467953393334
             0.08657717877230374 0
             0 -0.9515581756988356  </pose>
      <inertial>
        <mass>0.018</mass>
        <inertia>
          <ixx>8.82e-6</ixx>
          <ixy>0</ixy>
          <ixz>0</ixz>
          <iyy>8.82e-6</iyy>
          <iyz>0</iyz>
          <izz>8.82e-6</izz>
        </inertia>
      </inertial>
      <visual name="visual">
        <geometry>
          <mesh>
            <uri>model://random_strawberry_plant/meshes/leaf4.dae</uri>
            <scale> 0.4860194481031754 0.4860194481031754 0.4860194481031754</scale>
          </mesh>
        </geometry>
      </visual>
    </link>


    <joint name=leaf_dirt_joint_9 type="revolute">
      <parent>dirt_link</parent>
      <child>leaf_stem_link_9</child>
      <axis>
        <xyz>0 1 0</xyz>
      </axis>
    </joint>

    <link name= leaf_stem_link_10 >
      <pose>0 0 0 0 -1.0919520204756425 -3.1063277763713644 </pose>
      <inertial>
        <mass>1</mass>
        <inertia> <!-- Modeled as slender rod -->
          <ixx>1e-3</ixx>
          <ixy>0</ixy>
          <ixz>0</ixz>
          <iyy>8.333e-2</iyy>
          <iyz>0</iyz>
          <izz>8.333e-2</izz>
        </inertia>
      </inertial>
      <visual name="visual">
        <geometry>
          <mesh>
            <uri>model://random_strawberry_plant/meshes/leaf_stem2.stl</uri>
            <scale> 0.33998390591458383 0.33998390591458383 0.33998390591458383</scale>
          </mesh>
        </geometry>
        <material> <!-- Green -->
          <ambient>0.0 0.5 0.0 1.0</ambient>
          <diffuse>0.0 0.5 0.0 1.0</diffuse>
          <specular>0.1 0.1 0.1 1.0</specular>
        </material>
      </visual>
    </link>

    <link name= leaf_link_10_0 >
      <pose> -0.09393088339100544
             -0.003313834891505231
             0.1810471427690433 0
             0 -4.724219147569538  </pose>
      <inertial>
        <mass>0.018</mass>
        <inertia>
          <ixx>8.82e-6</ixx>
          <ixy>0</ixy>
          <ixz>0</ixz>
          <iyy>8.82e-6</iyy>
          <iyz>0</iyz>
          <izz>8.82e-6</izz>
        </inertia>
      </inertial>
      <visual name="visual">
        <geometry>
          <mesh>
            <uri>model://random_strawberry_plant/meshes/leaf2.dae</uri>
            <scale> 0.4537761773587087 0.4537761773587087 0.4537761773587087</scale>
          </mesh>
        </geometry>
      </visual>
    </link>

    <link name= leaf_link_10_1 >
      <pose> -0.09393088339100544
             -0.003313834891505231
             0.1810471427690433 0
             0 -3.0152827073605697  </pose>
      <inertial>
        <mass>0.018</mass>
        <inertia>
          <ixx>8.82e-6</ixx>
          <ixy>0</ixy>
          <ixz>0</ixz>
          <iyy>8.82e-6</iyy>
          <iyz>0</iyz>
          <izz>8.82e-6</izz>
        </inertia>
      </inertial>
      <visual name="visual">
        <geometry>
          <mesh>
            <uri>model://random_strawberry_plant/meshes/leaf1.dae</uri>
            <scale> 0.4537761773587087 0.4537761773587087 0.4537761773587087</scale>
          </mesh>
        </geometry>
      </visual>
    </link>

    <link name= leaf_link_10_2 >
      <pose> -0.09393088339100544
             -0.003313834891505231
             0.1810471427690433 0
             0 -1.6195624692425203  </pose>
      <inertial>
        <mass>0.018</mass>
        <inertia>
          <ixx>8.82e-6</ixx>
          <ixy>0</ixy>
          <ixz>0</ixz>
          <iyy>8.82e-6</iyy>
          <iyz>0</iyz>
          <izz>8.82e-6</izz>
        </inertia>
      </inertial>
      <visual name="visual">
        <geometry>
          <mesh>
            <uri>model://random_strawberry_plant/meshes/leaf2.dae</uri>
            <scale> 0.4537761773587087 0.4537761773587087 0.4537761773587087</scale>
          </mesh>
        </geometry>
      </visual>
    </link>


    <joint name=leaf_dirt_joint_10 type="revolute">
      <parent>dirt_link</parent>
      <child>leaf_stem_link_10</child>
      <axis>
        <xyz>0 1 0</xyz>
      </axis>
    </joint>

    <link name= leaf_stem_link_11 >
      <pose>0 0 0 0 -0.5158891479411046 -0.6943463536769956 </pose>
      <inertial>
        <mass>1</mass>
        <inertia> <!-- Modeled as slender rod -->
          <ixx>1e-3</ixx>
          <ixy>0</ixy>
          <ixz>0</ixz>
          <iyy>8.333e-2</iyy>
          <iyz>0</iyz>
          <izz>8.333e-2</izz>
        </inertia>
      </inertial>
      <visual name="visual">
        <geometry>
          <mesh>
            <uri>model://random_strawberry_plant/meshes/leaf_stem1.stl</uri>
            <scale> 0.3588900694612933 0.3588900694612933 0.3588900694612933</scale>
          </mesh>
        </geometry>
        <material> <!-- Green -->
          <ambient>0.0 0.5 0.0 1.0</ambient>
          <diffuse>0.0 0.5 0.0 1.0</diffuse>
          <specular>0.1 0.1 0.1 1.0</specular>
        </material>
      </visual>
    </link>

    <link name= leaf_link_11_0 >
      <pose> 0.14394195447288438
             -0.11985606938509255
             0.10622610733213117 0
             0 -2.47422552900405  </pose>
      <inertial>
        <mass>0.018</mass>
        <inertia>
          <ixx>8.82e-6</ixx>
          <ixy>0</ixy>
          <ixz>0</ixz>
          <iyy>8.82e-6</iyy>
          <iyz>0</iyz>
          <izz>8.82e-6</izz>
        </inertia>
      </inertial>
      <visual name="visual">
        <geometry>
          <mesh>
            <uri>model://random_strawberry_plant/meshes/leaf5.dae</uri>
            <scale> 0.5332978005222669 0.5332978005222669 0.5332978005222669</scale>
          </mesh>
        </geometry>
      </visual>
    </link>

    <link name= leaf_link_11_1 >
      <pose> 0.14394195447288438
             -0.11985606938509255
             0.10622610733213117 0
             0 -0.7424695460943812  </pose>
      <inertial>
        <mass>0.018</mass>
        <inertia>
          <ixx>8.82e-6</ixx>
          <ixy>0</ixy>
          <ixz>0</ixz>
          <iyy>8.82e-6</iyy>
          <iyz>0</iyz>
          <izz>8.82e-6</izz>
        </inertia>
      </inertial>
      <visual name="visual">
        <geometry>
          <mesh>
            <uri>model://random_strawberry_plant/meshes/leaf1.dae</uri>
            <scale> 0.5332978005222669 0.5332978005222669 0.5332978005222669</scale>
          </mesh>
        </geometry>
      </visual>
    </link>

    <link name= leaf_link_11_2 >
      <pose> 0.14394195447288438
             -0.11985606938509255
             0.10622610733213117 0
             0 0.9216271762709951  </pose>
      <inertial>
        <mass>0.018</mass>
        <inertia>
          <ixx>8.82e-6</ixx>
          <ixy>0</ixy>
          <ixz>0</ixz>
          <iyy>8.82e-6</iyy>
          <iyz>0</iyz>
          <izz>8.82e-6</izz>
        </inertia>
      </inertial>
      <visual name="visual">
        <geometry>
          <mesh>
            <uri>model://random_strawberry_plant/meshes/leaf2.dae</uri>
            <scale> 0.5332978005222669 0.5332978005222669 0.5332978005222669</scale>
          </mesh>
        </geometry>
      </visual>
    </link>


    <joint name=leaf_dirt_joint_11 type="revolute">
      <parent>dirt_link</parent>
      <child>leaf_stem_link_11</child>
      <axis>
        <xyz>0 1 0</xyz>
      </axis>
    </joint>

    <link name= leaf_stem_link_12 >
      <pose>0 0 0 0 -1.1980126016733288 0.4908451526763451 </pose>
      <inertial>
        <mass>1</mass>
        <inertia> <!-- Modeled as slender rod -->
          <ixx>1e-3</ixx>
          <ixy>0</ixy>
          <ixz>0</ixz>
          <iyy>8.333e-2</iyy>
          <iyz>0</iyz>
          <izz>8.333e-2</izz>
        </inertia>
      </inertial>
      <visual name="visual">
        <geometry>
          <mesh>
            <uri>model://random_strawberry_plant/meshes/leaf_stem2.stl</uri>
            <scale> 0.32453419908676595 0.32453419908676595 0.32453419908676595</scale>
          </mesh>
        </geometry>
        <material> <!-- Green -->
          <ambient>0.0 0.5 0.0 1.0</ambient>
          <diffuse>0.0 0.5 0.0 1.0</diffuse>
          <specular>0.1 0.1 0.1 1.0</specular>
        </material>
      </visual>
    </link>

    <link name= leaf_link_12_0 >
      <pose> 0.06254596693129919
             0.03342920798905309
             0.18134654882167833 0
             0 -1.022664209809035  </pose>
      <inertial>
        <mass>0.018</mass>
        <inertia>
          <ixx>8.82e-6</ixx>
          <ixy>0</ixy>
          <ixz>0</ixz>
          <iyy>8.82e-6</iyy>
          <iyz>0</iyz>
          <izz>8.82e-6</izz>
        </inertia>
      </inertial>
      <visual name="visual">
        <geometry>
          <mesh>
            <uri>model://random_strawberry_plant/meshes/leaf2.dae</uri>
            <scale> 0.6356870499224001 0.6356870499224001 0.6356870499224001</scale>
          </mesh>
        </geometry>
      </visual>
    </link>

    <link name= leaf_link_12_1 >
      <pose> 0.06254596693129919
             0.03342920798905309
             0.18134654882167833 0
             0 0.3533343168876461  </pose>
      <inertial>
        <mass>0.018</mass>
        <inertia>
          <ixx>8.82e-6</ixx>
          <ixy>0</ixy>
          <ixz>0</ixz>
          <iyy>8.82e-6</iyy>
          <iyz>0</iyz>
          <izz>8.82e-6</izz>
        </inertia>
      </inertial>
      <visual name="visual">
        <geometry>
          <mesh>
            <uri>model://random_strawberry_plant/meshes/leaf3.dae</uri>
            <scale> 0.6356870499224001 0.6356870499224001 0.6356870499224001</scale>
          </mesh>
        </geometry>
      </visual>
    </link>

    <link name= leaf_link_12_2 >
      <pose> 0.06254596693129919
             0.03342920798905309
             0.18134654882167833 0
             0 2.017795019373931  </pose>
      <inertial>
        <mass>0.018</mass>
        <inertia>
          <ixx>8.82e-6</ixx>
          <ixy>0</ixy>
          <ixz>0</ixz>
          <iyy>8.82e-6</iyy>
          <iyz>0</iyz>
          <izz>8.82e-6</izz>
        </inertia>
      </inertial>
      <visual name="visual">
        <geometry>
          <mesh>
            <uri>model://random_strawberry_plant/meshes/leaf5.dae</uri>
            <scale> 0.6356870499224001 0.6356870499224001 0.6356870499224001</scale>
          </mesh>
        </geometry>
      </visual>
    </link>


    <joint name=leaf_dirt_joint_12 type="revolute">
      <parent>dirt_link</parent>
      <child>leaf_stem_link_12</child>
      <axis>
        <xyz>0 1 0</xyz>
      </axis>
    </joint>

    <link name= leaf_stem_link_13 >
      <pose>0 0 0 0 -0.9988337544638761 2.162070918118414 </pose>
      <inertial>
        <mass>1</mass>
        <inertia> <!-- Modeled as slender rod -->
          <ixx>1e-3</ixx>
          <ixy>0</ixy>
          <ixz>0</ixz>
          <iyy>8.333e-2</iyy>
          <iyz>0</iyz>
          <izz>8.333e-2</izz>
        </inertia>
      </inertial>
      <visual name="visual">
        <geometry>
          <mesh>
            <uri>model://random_strawberry_plant/meshes/leaf_stem2.stl</uri>
            <scale> 0.28286602174272524 0.28286602174272524 0.28286602174272524</scale>
          </mesh>
        </geometry>
        <material> <!-- Green -->
          <ambient>0.0 0.5 0.0 1.0</ambient>
          <diffuse>0.0 0.5 0.0 1.0</diffuse>
          <specular>0.1 0.1 0.1 1.0</specular>
        </material>
      </visual>
    </link>

    <link name= leaf_link_13_0 >
      <pose> -0.05120813499886684
             0.07627031486589084
             0.14270708823515327 0
             0 0.5805314339722567  </pose>
      <inertial>
        <mass>0.018</mass>
        <inertia>
          <ixx>8.82e-6</ixx>
          <ixy>0</ixy>
          <ixz>0</ixz>
          <iyy>8.82e-6</iyy>
          <iyz>0</iyz>
          <izz>8.82e-6</izz>
        </inertia>
      </inertial>
      <visual name="visual">
        <geometry>
          <mesh>
            <uri>model://random_strawberry_plant/meshes/leaf2.dae</uri>
            <scale> 0.6136721398770822 0.6136721398770822 0.6136721398770822</scale>
          </mesh>
        </geometry>
      </visual>
    </link>

    <link name= leaf_link_13_1 >
      <pose> -0.05120813499886684
             0.07627031486589084
             0.14270708823515327 0
             0 2.2163979701603855  </pose>
      <inertial>
        <mass>0.018</mass>
        <inertia>
          <ixx>8.82e-6</ixx>
          <ixy>0</ixy>
          <ixz>0</ixz>
          <iyy>8.82e-6</iyy>
          <iyz>0</iyz>
          <izz>8.82e-6</izz>
        </inertia>
      </inertial>
      <visual name="visual">
        <geometry>
          <mesh>
            <uri>model://random_strawberry_plant/meshes/leaf4.dae</uri>
            <scale> 0.6136721398770822 0.6136721398770822 0.6136721398770822</scale>
          </mesh>
        </geometry>
      </visual>
    </link>

    <link name= leaf_link_13_2 >
      <pose> -0.05120813499886684
             0.07627031486589084
             0.14270708823515327 0
             0 3.7814770731923675  </pose>
      <inertial>
        <mass>0.018</mass>
        <inertia>
          <ixx>8.82e-6</ixx>
          <ixy>0</ixy>
          <ixz>0</ixz>
          <iyy>8.82e-6</iyy>
          <iyz>0</iyz>
          <izz>8.82e-6</izz>
        </inertia>
      </inertial>
      <visual name="visual">
        <geometry>
          <mesh>
            <uri>model://random_strawberry_plant/meshes/leaf5.dae</uri>
            <scale> 0.6136721398770822 0.6136721398770822 0.6136721398770822</scale>
          </mesh>
        </geometry>
      </visual>
    </link>


    <joint name=leaf_dirt_joint_13 type="revolute">
      <parent>dirt_link</parent>
      <child>leaf_stem_link_13</child>
      <axis>
        <xyz>0 1 0</xyz>
      </axis>
    </joint>

    <link name= leaf_stem_link_14 >
      <pose>0 0 0 0 -0.5765312531397392 -0.9799051560599192 </pose>
      <inertial>
        <mass>1</mass>
        <inertia> <!-- Modeled as slender rod -->
          <ixx>1e-3</ixx>
          <ixy>0</ixy>
          <ixz>0</ixz>
          <iyy>8.333e-2</iyy>
          <iyz>0</iyz>
          <izz>8.333e-2</izz>
        </inertia>
      </inertial>
      <visual name="visual">
        <geometry>
          <mesh>
            <uri>model://random_strawberry_plant/meshes/leaf_stem1.stl</uri>
            <scale> 0.3401147028680329 0.3401147028680329 0.3401147028680329</scale>
          </mesh>
        </geometry>
        <material> <!-- Green -->
          <ambient>0.0 0.5 0.0 1.0</ambient>
          <diffuse>0.0 0.5 0.0 1.0</diffuse>
          <specular>0.1 0.1 0.1 1.0</specular>
        </material>
      </visual>
    </link>

    <link name= leaf_link_14_0 >
      <pose> 0.0953104777250747
             -0.14207481442055625
             0.11124182640403858 0
             0 -2.44174895484085  </pose>
      <inertial>
        <mass>0.018</mass>
        <inertia>
          <ixx>8.82e-6</ixx>
          <ixy>0</ixy>
          <ixz>0</ixz>
          <iyy>8.82e-6</iyy>
          <iyz>0</iyz>
          <izz>8.82e-6</izz>
        </inertia>
      </inertial>
      <visual name="visual">
        <geometry>
          <mesh>
            <uri>model://random_strawberry_plant/meshes/leaf1.dae</uri>
            <scale> 0.5229901319135449 0.5229901319135449 0.5229901319135449</scale>
          </mesh>
        </geometry>
      </visual>
    </link>

    <link name= leaf_link_14_1 >
      <pose> 0.0953104777250747
             -0.14207481442055625
             0.11124182640403858 0
             0 -1.0132280824577953  </pose>
      <inertial>
        <mass>0.018</mass>
        <inertia>
          <ixx>8.82e-6</ixx>
          <ixy>0</ixy>
          <ixz>0</ixz>
          <iyy>8.82e-6</iyy>
          <iyz>0</iyz>
          <izz>8.82e-6</izz>
        </inertia>
      </inertial>
      <visual name="visual">
        <geometry>
          <mesh>
            <uri>model://random_strawberry_plant/meshes/leaf2.dae</uri>
            <scale> 0.5229901319135449 0.5229901319135449 0.5229901319135449</scale>
          </mesh>
        </geometry>
      </visual>
    </link>

    <link name= leaf_link_14_2 >
      <pose> 0.0953104777250747
             -0.14207481442055625
             0.11124182640403858 0
             0 0.4550100693679675  </pose>
      <inertial>
        <mass>0.018</mass>
        <inertia>
          <ixx>8.82e-6</ixx>
          <ixy>0</ixy>
          <ixz>0</ixz>
          <iyy>8.82e-6</iyy>
          <iyz>0</iyz>
          <izz>8.82e-6</izz>
        </inertia>
      </inertial>
      <visual name="visual">
        <geometry>
          <mesh>
            <uri>model://random_strawberry_plant/meshes/leaf3.dae</uri>
            <scale> 0.5229901319135449 0.5229901319135449 0.5229901319135449</scale>
          </mesh>
        </geometry>
      </visual>
    </link>


    <joint name=leaf_dirt_joint_14 type="revolute">
      <parent>dirt_link</parent>
      <child>leaf_stem_link_14</child>
      <axis>
        <xyz>0 1 0</xyz>
      </axis>
    </joint>

    <link name= leaf_stem_link_15 >
      <pose>0 0 0 0 -0.7520503130195376 1.6385060283484805 </pose>
      <inertial>
        <mass>1</mass>
        <inertia> <!-- Modeled as slender rod -->
          <ixx>1e-3</ixx>
          <ixy>0</ixy>
          <ixz>0</ixz>
          <iyy>8.333e-2</iyy>
          <iyz>0</iyz>
          <izz>8.333e-2</izz>
        </inertia>
      </inertial>
      <visual name="visual">
        <geometry>
          <mesh>
            <uri>model://random_strawberry_plant/meshes/leaf_stem1.stl</uri>
            <scale> 0.30323591030412317 0.30323591030412317 0.30323591030412317</scale>
          </mesh>
        </geometry>
        <material> <!-- Green -->
          <ambient>0.0 0.5 0.0 1.0</ambient>
          <diffuse>0.0 0.5 0.0 1.0</diffuse>
          <specular>0.1 0.1 0.1 1.0</specular>
        </material>
      </visual>
    </link>

    <link name= leaf_link_15_0 >
      <pose> -0.008989718565554278
             0.1325655860223823
             0.12429109618119785 0
             0 0.09811599338160826  </pose>
      <inertial>
        <mass>0.018</mass>
        <inertia>
          <ixx>8.82e-6</ixx>
          <ixy>0</ixy>
          <ixz>0</ixz>
          <iyy>8.82e-6</iyy>
          <iyz>0</iyz>
          <izz>8.82e-6</izz>
        </inertia>
      </inertial>
      <visual name="visual">
        <geometry>
          <mesh>
            <uri>model://random_strawberry_plant/meshes/leaf1.dae</uri>
            <scale> 0.735152457187673 0.735152457187673 0.735152457187673</scale>
          </mesh>
        </geometry>
      </visual>
    </link>

    <link name= leaf_link_15_1 >
      <pose> -0.008989718565554278
             0.1325655860223823
             0.12429109618119785 0
             0 1.8484578543709582  </pose>
      <inertial>
        <mass>0.018</mass>
        <inertia>
          <ixx>8.82e-6</ixx>
          <ixy>0</ixy>
          <ixz>0</ixz>
          <iyy>8.82e-6</iyy>
          <iyz>0</iyz>
          <izz>8.82e-6</izz>
        </inertia>
      </inertial>
      <visual name="visual">
        <geometry>
          <mesh>
            <uri>model://random_strawberry_plant/meshes/leaf5.dae</uri>
            <scale> 0.735152457187673 0.735152457187673 0.735152457187673</scale>
          </mesh>
        </geometry>
      </visual>
    </link>

    <link name= leaf_link_15_2 >
      <pose> -0.008989718565554278
             0.1325655860223823
             0.12429109618119785 0
             0 3.188951708819917  </pose>
      <inertial>
        <mass>0.018</mass>
        <inertia>
          <ixx>8.82e-6</ixx>
          <ixy>0</ixy>
          <ixz>0</ixz>
          <iyy>8.82e-6</iyy>
          <iyz>0</iyz>
          <izz>8.82e-6</izz>
        </inertia>
      </inertial>
      <visual name="visual">
        <geometry>
          <mesh>
            <uri>model://random_strawberry_plant/meshes/leaf3.dae</uri>
            <scale> 0.735152457187673 0.735152457187673 0.735152457187673</scale>
          </mesh>
        </geometry>
      </visual>
    </link>


    <joint name=leaf_dirt_joint_15 type="revolute">
      <parent>dirt_link</parent>
      <child>leaf_stem_link_15</child>
      <axis>
        <xyz>0 1 0</xyz>
      </axis>
    </joint>

    <link name= leaf_stem_link_16 >
      <pose>0 0 0 0 -0.572282012439568 2.0083560658151836 </pose>
      <inertial>
        <mass>1</mass>
        <inertia> <!-- Modeled as slender rod -->
          <ixx>1e-3</ixx>
          <ixy>0</ixy>
          <ixz>0</ixz>
          <iyy>8.333e-2</iyy>
          <iyz>0</iyz>
          <izz>8.333e-2</izz>
        </inertia>
      </inertial>
      <visual name="visual">
        <geometry>
          <mesh>
            <uri>model://random_strawberry_plant/meshes/leaf_stem1.stl</uri>
            <scale> 0.2622080703132537 0.2622080703132537 0.2622080703132537</scale>
          </mesh>
        </geometry>
        <material> <!-- Green -->
          <ambient>0.0 0.5 0.0 1.0</ambient>
          <diffuse>0.0 0.5 0.0 1.0</diffuse>
          <specular>0.1 0.1 0.1 1.0</specular>
        </material>
      </visual>
    </link>

    <link name= leaf_link_16_0 >
      <pose> -0.056041670165610596
             0.1197976281660642
             0.08519956255931373 0
             0 0.3157237405173776  </pose>
      <inertial>
        <mass>0.018</mass>
        <inertia>
          <ixx>8.82e-6</ixx>
          <ixy>0</ixy>
          <ixz>0</ixz>
          <iyy>8.82e-6</iyy>
          <iyz>0</iyz>
          <izz>8.82e-6</izz>
        </inertia>
      </inertial>
      <visual name="visual">
        <geometry>
          <mesh>
            <uri>model://random_strawberry_plant/meshes/leaf1.dae</uri>
            <scale> 0.6079714878463869 0.6079714878463869 0.6079714878463869</scale>
          </mesh>
        </geometry>
      </visual>
    </link>

    <link name= leaf_link_16_1 >
      <pose> -0.056041670165610596
             0.1197976281660642
             0.08519956255931373 0
             0 2.1102777184978145  </pose>
      <inertial>
        <mass>0.018</mass>
        <inertia>
          <ixx>8.82e-6</ixx>
          <ixy>0</ixy>
          <ixz>0</ixz>
          <iyy>8.82e-6</iyy>
          <iyz>0</iyz>
          <izz>8.82e-6</izz>
        </inertia>
      </inertial>
      <visual name="visual">
        <geometry>
          <mesh>
            <uri>model://random_strawberry_plant/meshes/leaf3.dae</uri>
            <scale> 0.6079714878463869 0.6079714878463869 0.6079714878463869</scale>
          </mesh>
        </geometry>
      </visual>
    </link>

    <link name= leaf_link_16_2 >
      <pose> -0.056041670165610596
             0.1197976281660642
             0.08519956255931373 0
             0 3.6684345673737804  </pose>
      <inertial>
        <mass>0.018</mass>
        <inertia>
          <ixx>8.82e-6</ixx>
          <ixy>0</ixy>
          <ixz>0</ixz>
          <iyy>8.82e-6</iyy>
          <iyz>0</iyz>
          <izz>8.82e-6</izz>
        </inertia>
      </inertial>
      <visual name="visual">
        <geometry>
          <mesh>
            <uri>model://random_strawberry_plant/meshes/leaf2.dae</uri>
            <scale> 0.6079714878463869 0.6079714878463869 0.6079714878463869</scale>
          </mesh>
        </geometry>
      </visual>
    </link>


    <joint name=leaf_dirt_joint_16 type="revolute">
      <parent>dirt_link</parent>
      <child>leaf_stem_link_16</child>
      <axis>
        <xyz>0 1 0</xyz>
      </axis>
    </joint>

    <link name= leaf_stem_link_17 >
      <pose>0 0 0 0 -0.41054462617575804 -3.000820817749868 </pose>
      <inertial>
        <mass>1</mass>
        <inertia> <!-- Modeled as slender rod -->
          <ixx>1e-3</ixx>
          <ixy>0</ixy>
          <ixz>0</ixz>
          <iyy>8.333e-2</iyy>
          <iyz>0</iyz>
          <izz>8.333e-2</izz>
        </inertia>
      </inertial>
      <visual name="visual">
        <geometry>
          <mesh>
            <uri>model://random_strawberry_plant/meshes/leaf_stem1.stl</uri>
            <scale> 0.4149440834527071 0.4149440834527071 0.4149440834527071</scale>
          </mesh>
        </geometry>
        <material> <!-- Green -->
          <ambient>0.0 0.5 0.0 1.0</ambient>
          <diffuse>0.0 0.5 0.0 1.0</diffuse>
          <specular>0.1 0.1 0.1 1.0</specular>
        </material>
      </visual>
    </link>

    <link name= leaf_link_17_0 >
      <pose> -0.22602010380293813
             -0.0320291155487591
             0.09936469038516592 0
             0 -4.542699286892354  </pose>
      <inertial>
        <mass>0.018</mass>
        <inertia>
          <ixx>8.82e-6</ixx>
          <ixy>0</ixy>
          <ixz>0</ixz>
          <iyy>8.82e-6</iyy>
          <iyz>0</iyz>
          <izz>8.82e-6</izz>
        </inertia>
      </inertial>
      <visual name="visual">
        <geometry>
          <mesh>
            <uri>model://random_strawberry_plant/meshes/leaf4.dae</uri>
            <scale> 0.58940878031501 0.58940878031501 0.58940878031501</scale>
          </mesh>
        </geometry>
      </visual>
    </link>

    <link name= leaf_link_17_1 >
      <pose> -0.22602010380293813
             -0.0320291155487591
             0.09936469038516592 0
             0 -2.8823066791096115  </pose>
      <inertial>
        <mass>0.018</mass>
        <inertia>
          <ixx>8.82e-6</ixx>
          <ixy>0</ixy>
          <ixz>0</ixz>
          <iyy>8.82e-6</iyy>
          <iyz>0</iyz>
          <izz>8.82e-6</izz>
        </inertia>
      </inertial>
      <visual name="visual">
        <geometry>
          <mesh>
            <uri>model://random_strawberry_plant/meshes/leaf3.dae</uri>
            <scale> 0.58940878031501 0.58940878031501 0.58940878031501</scale>
          </mesh>
        </geometry>
      </visual>
    </link>

    <link name= leaf_link_17_2 >
      <pose> -0.22602010380293813
             -0.0320291155487591
             0.09936469038516592 0
             0 -1.5025511868684633  </pose>
      <inertial>
        <mass>0.018</mass>
        <inertia>
          <ixx>8.82e-6</ixx>
          <ixy>0</ixy>
          <ixz>0</ixz>
          <iyy>8.82e-6</iyy>
          <iyz>0</iyz>
          <izz>8.82e-6</izz>
        </inertia>
      </inertial>
      <visual name="visual">
        <geometry>
          <mesh>
            <uri>model://random_strawberry_plant/meshes/leaf3.dae</uri>
            <scale> 0.58940878031501 0.58940878031501 0.58940878031501</scale>
          </mesh>
        </geometry>
      </visual>
    </link>


    <joint name=leaf_dirt_joint_17 type="revolute">
      <parent>dirt_link</parent>
      <child>leaf_stem_link_17</child>
      <axis>
        <xyz>0 1 0</xyz>
      </axis>
    </joint>

    <link name= leaf_stem_link_18 >
      <pose>0 0 0 0 -0.6995448315364039 -1.5829261459470756 </pose>
      <inertial>
        <mass>1</mass>
        <inertia> <!-- Modeled as slender rod -->
          <ixx>1e-3</ixx>
          <ixy>0</ixy>
          <ixz>0</ixz>
          <iyy>8.333e-2</iyy>
          <iyz>0</iyz>
          <izz>8.333e-2</izz>
        </inertia>
      </inertial>
      <visual name="visual">
        <geometry>
          <mesh>
            <uri>model://random_strawberry_plant/meshes/leaf_stem1.stl</uri>
            <scale> 0.11093731929817835 0.11093731929817835 0.11093731929817835</scale>
          </mesh>
        </geometry>
        <material> <!-- Green -->
          <ambient>0.0 0.5 0.0 1.0</ambient>
          <diffuse>0.0 0.5 0.0 1.0</diffuse>
          <specular>0.1 0.1 0.1 1.0</specular>
        </material>
      </visual>
    </link>

    <link name= leaf_link_18_0 >
      <pose> -0.0006177472956076651
             -0.050925491192965314
             0.0428574930174145 0
             0 -3.3043338041156654  </pose>
      <inertial>
        <mass>0.018</mass>
        <inertia>
          <ixx>8.82e-6</ixx>
          <ixy>0</ixy>
          <ixz>0</ixz>
          <iyy>8.82e-6</iyy>
          <iyz>0</iyz>
          <izz>8.82e-6</izz>
        </inertia>
      </inertial>
      <visual name="visual">
        <geometry>
          <mesh>
            <uri>model://random_strawberry_plant/meshes/leaf5.dae</uri>
            <scale> 0.5686481370059915 0.5686481370059915 0.5686481370059915</scale>
          </mesh>
        </geometry>
      </visual>
    </link>

    <link name= leaf_link_18_1 >
      <pose> -0.0006177472956076651
             -0.050925491192965314
             0.0428574930174145 0
             0 -1.5378904154131388  </pose>
      <inertial>
        <mass>0.018</mass>
        <inertia>
          <ixx>8.82e-6</ixx>
          <ixy>0</ixy>
          <ixz>0</ixz>
          <iyy>8.82e-6</iyy>
          <iyz>0</iyz>
          <izz>8.82e-6</izz>
        </inertia>
      </inertial>
      <visual name="visual">
        <geometry>
          <mesh>
            <uri>model://random_strawberry_plant/meshes/leaf3.dae</uri>
            <scale> 0.5686481370059915 0.5686481370059915 0.5686481370059915</scale>
          </mesh>
        </geometry>
      </visual>
    </link>

    <link name= leaf_link_18_2 >
      <pose> -0.0006177472956076651
             -0.050925491192965314
             0.0428574930174145 0
             0 -0.074571110665405  </pose>
      <inertial>
        <mass>0.018</mass>
        <inertia>
          <ixx>8.82e-6</ixx>
          <ixy>0</ixy>
          <ixz>0</ixz>
          <iyy>8.82e-6</iyy>
          <iyz>0</iyz>
          <izz>8.82e-6</izz>
        </inertia>
      </inertial>
      <visual name="visual">
        <geometry>
          <mesh>
            <uri>model://random_strawberry_plant/meshes/leaf3.dae</uri>
            <scale> 0.5686481370059915 0.5686481370059915 0.5686481370059915</scale>
          </mesh>
        </geometry>
      </visual>
    </link>


    <joint name=leaf_dirt_joint_18 type="revolute">
      <parent>dirt_link</parent>
      <child>leaf_stem_link_18</child>
      <axis>
        <xyz>0 1 0</xyz>
      </axis>
    </joint>

    <link name= leaf_stem_link_19 >
      <pose>0 0 0 0 -0.9153156360898844 -2.6187410355254293 </pose>
      <inertial>
        <mass>1</mass>
        <inertia> <!-- Modeled as slender rod -->
          <ixx>1e-3</ixx>
          <ixy>0</ixy>
          <ixz>0</ixz>
          <iyy>8.333e-2</iyy>
          <iyz>0</iyz>
          <izz>8.333e-2</izz>
        </inertia>
      </inertial>
      <visual name="visual">
        <geometry>
          <mesh>
            <uri>model://random_strawberry_plant/meshes/leaf_stem2.stl</uri>
            <scale> 0.33047810301627567 0.33047810301627567 0.33047810301627567</scale>
          </mesh>
        </geometry>
        <material> <!-- Green -->
          <ambient>0.0 0.5 0.0 1.0</ambient>
          <diffuse>0.0 0.5 0.0 1.0</diffuse>
          <specular>0.1 0.1 0.1 1.0</specular>
        </material>
      </visual>
    </link>

    <link name= leaf_link_19_0 >
      <pose> -0.10471628730076643
             -0.06035370220596133
             0.15719290496184132 0
             0 -4.277529648938813  </pose>
      <inertial>
        <mass>0.018</mass>
        <inertia>
          <ixx>8.82e-6</ixx>
          <ixy>0</ixy>
          <ixz>0</ixz>
          <iyy>8.82e-6</iyy>
          <iyz>0</iyz>
          <izz>8.82e-6</izz>
        </inertia>
      </inertial>
      <visual name="visual">
        <geometry>
          <mesh>
            <uri>model://random_strawberry_plant/meshes/leaf4.dae</uri>
            <scale> 0.6220791583347713 0.6220791583347713 0.6220791583347713</scale>
          </mesh>
        </geometry>
      </visual>
    </link>

    <link name= leaf_link_19_1 >
      <pose> -0.10471628730076643
             -0.06035370220596133
             0.15719290496184132 0
             0 -2.599382460704513  </pose>
      <inertial>
        <mass>0.018</mass>
        <inertia>
          <ixx>8.82e-6</ixx>
          <ixy>0</ixy>
          <ixz>0</ixz>
          <iyy>8.82e-6</iyy>
          <iyz>0</iyz>
          <izz>8.82e-6</izz>
        </inertia>
      </inertial>
      <visual name="visual">
        <geometry>
          <mesh>
            <uri>model://random_strawberry_plant/meshes/leaf3.dae</uri>
            <scale> 0.6220791583347713 0.6220791583347713 0.6220791583347713</scale>
          </mesh>
        </geometry>
      </visual>
    </link>

    <link name= leaf_link_19_2 >
      <pose> -0.10471628730076643
             -0.06035370220596133
             0.15719290496184132 0
             0 -0.848725010691525  </pose>
      <inertial>
        <mass>0.018</mass>
        <inertia>
          <ixx>8.82e-6</ixx>
          <ixy>0</ixy>
          <ixz>0</ixz>
          <iyy>8.82e-6</iyy>
          <iyz>0</iyz>
          <izz>8.82e-6</izz>
        </inertia>
      </inertial>
      <visual name="visual">
        <geometry>
          <mesh>
            <uri>model://random_strawberry_plant/meshes/leaf5.dae</uri>
            <scale> 0.6220791583347713 0.6220791583347713 0.6220791583347713</scale>
          </mesh>
        </geometry>
      </visual>
    </link>


    <joint name=leaf_dirt_joint_19 type="revolute">
      <parent>dirt_link</parent>
      <child>leaf_stem_link_19</child>
      <axis>
        <xyz>0 1 0</xyz>
      </axis>
    </joint>

    <link name= leaf_stem_link_20 >
      <pose>0 0 0 0 -0.7436742932468579 2.64663723204695 </pose>
      <inertial>
        <mass>1</mass>
        <inertia> <!-- Modeled as slender rod -->
          <ixx>1e-3</ixx>
          <ixy>0</ixy>
          <ixz>0</ixz>
          <iyy>8.333e-2</iyy>
          <iyz>0</iyz>
          <izz>8.333e-2</izz>
        </inertia>
      </inertial>
      <visual name="visual">
        <geometry>
          <mesh>
            <uri>model://random_strawberry_plant/meshes/leaf_stem1.stl</uri>
            <scale> 0.30710747160687746 0.30710747160687746 0.30710747160687746</scale>
          </mesh>
        </geometry>
        <material> <!-- Green -->
          <ambient>0.0 0.5 0.0 1.0</ambient>
          <diffuse>0.0 0.5 0.0 1.0</diffuse>
          <specular>0.1 0.1 0.1 1.0</specular>
        </material>
      </visual>
    </link>

    <link name= leaf_link_20_0 >
      <pose> -0.11934078622813359
             0.06441661454130765
             0.1247464476268738 0
             0 0.9546814731767208  </pose>
      <inertial>
        <mass>0.018</mass>
        <inertia>
          <ixx>8.82e-6</ixx>
          <ixy>0</ixy>
          <ixz>0</ixz>
          <iyy>8.82e-6</iyy>
          <iyz>0</iyz>
          <izz>8.82e-6</izz>
        </inertia>
      </inertial>
      <visual name="visual">
        <geometry>
          <mesh>
            <uri>model://random_strawberry_plant/meshes/leaf1.dae</uri>
            <scale> 0.6821477022931178 0.6821477022931178 0.6821477022931178</scale>
          </mesh>
        </geometry>
      </visual>
    </link>

    <link name= leaf_link_20_1 >
      <pose> -0.11934078622813359
             0.06441661454130765
             0.1247464476268738 0
             0 2.610424249216629  </pose>
      <inertial>
        <mass>0.018</mass>
        <inertia>
          <ixx>8.82e-6</ixx>
          <ixy>0</ixy>
          <ixz>0</ixz>
          <iyy>8.82e-6</iyy>
          <iyz>0</iyz>
          <izz>8.82e-6</izz>
        </inertia>
      </inertial>
      <visual name="visual">
        <geometry>
          <mesh>
            <uri>model://random_strawberry_plant/meshes/leaf5.dae</uri>
            <scale> 0.6821477022931178 0.6821477022931178 0.6821477022931178</scale>
          </mesh>
        </geometry>
      </visual>
    </link>

    <link name= leaf_link_20_2 >
      <pose> -0.11934078622813359
             0.06441661454130765
             0.1247464476268738 0
             0 4.14354585515244  </pose>
      <inertial>
        <mass>0.018</mass>
        <inertia>
          <ixx>8.82e-6</ixx>
          <ixy>0</ixy>
          <ixz>0</ixz>
          <iyy>8.82e-6</iyy>
          <iyz>0</iyz>
          <izz>8.82e-6</izz>
        </inertia>
      </inertial>
      <visual name="visual">
        <geometry>
          <mesh>
            <uri>model://random_strawberry_plant/meshes/leaf1.dae</uri>
            <scale> 0.6821477022931178 0.6821477022931178 0.6821477022931178</scale>
          </mesh>
        </geometry>
      </visual>
    </link>


    <joint name=leaf_dirt_joint_20 type="revolute">
      <parent>dirt_link</parent>
      <child>leaf_stem_link_20</child>
      <axis>
        <xyz>0 1 0</xyz>
      </axis>
    </joint>

    <link name= leaf_stem_link_21 >
      <pose>0 0 0 0 -0.4069763925079215 0.5762854443885788 </pose>
      <inertial>
        <mass>1</mass>
        <inertia> <!-- Modeled as slender rod -->
          <ixx>1e-3</ixx>
          <ixy>0</ixy>
          <ixz>0</ixz>
          <iyy>8.333e-2</iyy>
          <iyz>0</iyz>
          <izz>8.333e-2</izz>
        </inertia>
      </inertial>
      <visual name="visual">
        <geometry>
          <mesh>
            <uri>model://random_strawberry_plant/meshes/leaf_stem1.stl</uri>
            <scale> 0.4956361153717137 0.4956361153717137 0.4956361153717137</scale>
          </mesh>
        </geometry>
        <material> <!-- Green -->
          <ambient>0.0 0.5 0.0 1.0</ambient>
          <diffuse>0.0 0.5 0.0 1.0</diffuse>
          <specular>0.1 0.1 0.1 1.0</specular>
        </material>
      </visual>
    </link>

    <link name= leaf_link_21_0 >
      <pose> 0.22898567988510177
             0.14881145063793405
             0.11771392337555484 0
             0 -0.9344006929544584  </pose>
      <inertial>
        <mass>0.018</mass>
        <inertia>
          <ixx>8.82e-6</ixx>
          <ixy>0</ixy>
          <ixz>0</ixz>
          <iyy>8.82e-6</iyy>
          <iyz>0</iyz>
          <izz>8.82e-6</izz>
        </inertia>
      </inertial>
      <visual name="visual">
        <geometry>
          <mesh>
            <uri>model://random_strawberry_plant/meshes/leaf2.dae</uri>
            <scale> 0.4290613778153782 0.4290613778153782 0.4290613778153782</scale>
          </mesh>
        </geometry>
      </visual>
    </link>

    <link name= leaf_link_21_1 >
      <pose> 0.22898567988510177
             0.14881145063793405
             0.11771392337555484 0
             0 0.5876497794234326  </pose>
      <inertial>
        <mass>0.018</mass>
        <inertia>
          <ixx>8.82e-6</ixx>
          <ixy>0</ixy>
          <ixz>0</ixz>
          <iyy>8.82e-6</iyy>
          <iyz>0</iyz>
          <izz>8.82e-6</izz>
        </inertia>
      </inertial>
      <visual name="visual">
        <geometry>
          <mesh>
            <uri>model://random_strawberry_plant/meshes/leaf5.dae</uri>
            <scale> 0.4290613778153782 0.4290613778153782 0.4290613778153782</scale>
          </mesh>
        </geometry>
      </visual>
    </link>

    <link name= leaf_link_21_2 >
      <pose> 0.22898567988510177
             0.14881145063793405
             0.11771392337555484 0
             0 2.1353925284515576  </pose>
      <inertial>
        <mass>0.018</mass>
        <inertia>
          <ixx>8.82e-6</ixx>
          <ixy>0</ixy>
          <ixz>0</ixz>
          <iyy>8.82e-6</iyy>
          <iyz>0</iyz>
          <izz>8.82e-6</izz>
        </inertia>
      </inertial>
      <visual name="visual">
        <geometry>
          <mesh>
            <uri>model://random_strawberry_plant/meshes/leaf4.dae</uri>
            <scale> 0.4290613778153782 0.4290613778153782 0.4290613778153782</scale>
          </mesh>
        </geometry>
      </visual>
    </link>


    <joint name=leaf_dirt_joint_21 type="revolute">
      <parent>dirt_link</parent>
      <child>leaf_stem_link_21</child>
      <axis>
        <xyz>0 1 0</xyz>
      </axis>
    </joint>

    <link name= leaf_stem_link_22 >
      <pose>0 0 0 0 -1.1732267874337765 2.811373636467372 </pose>
      <inertial>
        <mass>1</mass>
        <inertia> <!-- Modeled as slender rod -->
          <ixx>1e-3</ixx>
          <ixy>0</ixy>
          <ixz>0</ixz>
          <iyy>8.333e-2</iyy>
          <iyz>0</iyz>
          <izz>8.333e-2</izz>
        </inertia>
      </inertial>
      <visual name="visual">
        <geometry>
          <mesh>
            <uri>model://random_strawberry_plant/meshes/leaf_stem2.stl</uri>
            <scale> 0.3376671985637323 0.3376671985637323 0.3376671985637323</scale>
          </mesh>
        </geometry>
        <material> <!-- Green -->
          <ambient>0.0 0.5 0.0 1.0</ambient>
          <diffuse>0.0 0.5 0.0 1.0</diffuse>
          <specular>0.1 0.1 0.1 1.0</specular>
        </material>
      </visual>
    </link>

    <link name= leaf_link_22_0 >
      <pose> -0.07420436354482693
             0.025434999923255833
             0.1867984542889142 0
             0 1.1436483574707987  </pose>
      <inertial>
        <mass>0.018</mass>
        <inertia>
          <ixx>8.82e-6</ixx>
          <ixy>0</ixy>
          <ixz>0</ixz>
          <iyy>8.82e-6</iyy>
          <iyz>0</iyz>
          <izz>8.82e-6</izz>
        </inertia>
      </inertial>
      <visual name="visual">
        <geometry>
          <mesh>
            <uri>model://random_strawberry_plant/meshes/leaf4.dae</uri>
            <scale> 0.5031496958262336 0.5031496958262336 0.5031496958262336</scale>
          </mesh>
        </geometry>
      </visual>
    </link>

    <link name= leaf_link_22_1 >
      <pose> -0.07420436354482693
             0.025434999923255833
             0.1867984542889142 0
             0 2.7841613211442877  </pose>
      <inertial>
        <mass>0.018</mass>
        <inertia>
          <ixx>8.82e-6</ixx>
          <ixy>0</ixy>
          <ixz>0</ixz>
          <iyy>8.82e-6</iyy>
          <iyz>0</iyz>
          <izz>8.82e-6</izz>
        </inertia>
      </inertial>
      <visual name="visual">
        <geometry>
          <mesh>
            <uri>model://random_strawberry_plant/meshes/leaf5.dae</uri>
            <scale> 0.5031496958262336 0.5031496958262336 0.5031496958262336</scale>
          </mesh>
        </geometry>
      </visual>
    </link>

    <link name= leaf_link_22_2 >
      <pose> -0.07420436354482693
             0.025434999923255833
             0.1867984542889142 0
             0 4.136317321189557  </pose>
      <inertial>
        <mass>0.018</mass>
        <inertia>
          <ixx>8.82e-6</ixx>
          <ixy>0</ixy>
          <ixz>0</ixz>
          <iyy>8.82e-6</iyy>
          <iyz>0</iyz>
          <izz>8.82e-6</izz>
        </inertia>
      </inertial>
      <visual name="visual">
        <geometry>
          <mesh>
            <uri>model://random_strawberry_plant/meshes/leaf1.dae</uri>
            <scale> 0.5031496958262336 0.5031496958262336 0.5031496958262336</scale>
          </mesh>
        </geometry>
      </visual>
    </link>


    <joint name=leaf_dirt_joint_22 type="revolute">
      <parent>dirt_link</parent>
      <child>leaf_stem_link_22</child>
      <axis>
        <xyz>0 1 0</xyz>
      </axis>
    </joint>

    <link name= leaf_stem_link_23 >
      <pose>0 0 0 0 -1.0416174634366413 -1.2525034651610398 </pose>
      <inertial>
        <mass>1</mass>
        <inertia> <!-- Modeled as slender rod -->
          <ixx>1e-3</ixx>
          <ixy>0</ixy>
          <ixz>0</ixz>
          <iyy>8.333e-2</iyy>
          <iyz>0</iyz>
          <izz>8.333e-2</izz>
        </inertia>
      </inertial>
      <visual name="visual">
        <geometry>
          <mesh>
            <uri>model://random_strawberry_plant/meshes/leaf_stem2.stl</uri>
            <scale> 0.18820814476814535 0.18820814476814535 0.18820814476814535</scale>
          </mesh>
        </geometry>
        <material> <!-- Green -->
          <ambient>0.0 0.5 0.0 1.0</ambient>
          <diffuse>0.0 0.5 0.0 1.0</diffuse>
          <specular>0.1 0.1 0.1 1.0</specular>
        </material>
      </visual>
    </link>

    <link name= leaf_link_23_0 >
      <pose> 0.017840176099539928
             -0.05414385507805608
             0.09747923443774083 0
             0 -2.9703906441994254  </pose>
      <inertial>
        <mass>0.018</mass>
        <inertia>
          <ixx>8.82e-6</ixx>
          <ixy>0</ixy>
          <ixz>0</ixz>
          <iyy>8.82e-6</iyy>
          <iyz>0</iyz>
          <izz>8.82e-6</izz>
        </inertia>
      </inertial>
      <visual name="visual">
        <geometry>
          <mesh>
            <uri>model://random_strawberry_plant/meshes/leaf3.dae</uri>
            <scale> 0.48663718950908114 0.48663718950908114 0.48663718950908114</scale>
          </mesh>
        </geometry>
      </visual>
    </link>

    <link name= leaf_link_23_1 >
      <pose> 0.017840176099539928
             -0.05414385507805608
             0.09747923443774083 0
             0 -1.4423322657845992  </pose>
      <inertial>
        <mass>0.018</mass>
        <inertia>
          <ixx>8.82e-6</ixx>
          <ixy>0</ixy>
          <ixz>0</ixz>
          <iyy>8.82e-6</iyy>
          <iyz>0</iyz>
          <izz>8.82e-6</izz>
        </inertia>
      </inertial>
      <visual name="visual">
        <geometry>
          <mesh>
            <uri>model://random_strawberry_plant/meshes/leaf1.dae</uri>
            <scale> 0.48663718950908114 0.48663718950908114 0.48663718950908114</scale>
          </mesh>
        </geometry>
      </visual>
    </link>

    <link name= leaf_link_23_2 >
      <pose> 0.017840176099539928
             -0.05414385507805608
             0.09747923443774083 0
             0 0.3817526334314556  </pose>
      <inertial>
        <mass>0.018</mass>
        <inertia>
          <ixx>8.82e-6</ixx>
          <ixy>0</ixy>
          <ixz>0</ixz>
          <iyy>8.82e-6</iyy>
          <iyz>0</iyz>
          <izz>8.82e-6</izz>
        </inertia>
      </inertial>
      <visual name="visual">
        <geometry>
          <mesh>
            <uri>model://random_strawberry_plant/meshes/leaf4.dae</uri>
            <scale> 0.48663718950908114 0.48663718950908114 0.48663718950908114</scale>
          </mesh>
        </geometry>
      </visual>
    </link>


    <joint name=leaf_dirt_joint_23 type="revolute">
      <parent>dirt_link</parent>
      <child>leaf_stem_link_23</child>
      <axis>
        <xyz>0 1 0</xyz>
      </axis>
    </joint>

    <link name= leaf_stem_link_24 >
      <pose>0 0 0 0 -0.46058455358438244 -2.8571711556828645 </pose>
      <inertial>
        <mass>1</mass>
        <inertia> <!-- Modeled as slender rod -->
          <ixx>1e-3</ixx>
          <ixy>0</ixy>
          <ixz>0</ixz>
          <iyy>8.333e-2</iyy>
          <iyz>0</iyz>
          <izz>8.333e-2</izz>
        </inertia>
      </inertial>
      <visual name="visual">
        <geometry>
          <mesh>
            <uri>model://random_strawberry_plant/meshes/leaf_stem1.stl</uri>
            <scale> 0.24907503239445894 0.24907503239445894 0.24907503239445894</scale>
          </mesh>
        </geometry>
        <material> <!-- Green -->
          <ambient>0.0 0.5 0.0 1.0</ambient>
          <diffuse>0.0 0.5 0.0 1.0</diffuse>
          <specular>0.1 0.1 0.1 1.0</specular>
        </material>
      </visual>
    </link>

    <link name= leaf_link_24_0 >
      <pose> -0.12849336385321092
             -0.037564720326617014
             0.06642410004582425 0
             0 -4.234269236278767  </pose>
      <inertial>
        <mass>0.018</mass>
        <inertia>
          <ixx>8.82e-6</ixx>
          <ixy>0</ixy>
          <ixz>0</ixz>
          <iyy>8.82e-6</iyy>
          <iyz>0</iyz>
          <izz>8.82e-6</izz>
        </inertia>
      </inertial>
      <visual name="visual">
        <geometry>
          <mesh>
            <uri>model://random_strawberry_plant/meshes/leaf4.dae</uri>
            <scale> 0.5159307226875116 0.5159307226875116 0.5159307226875116</scale>
          </mesh>
        </geometry>
      </visual>
    </link>

    <link name= leaf_link_24_1 >
      <pose> -0.12849336385321092
             -0.037564720326617014
             0.06642410004582425 0
             0 -3.0062367978273192  </pose>
      <inertial>
        <mass>0.018</mass>
        <inertia>
          <ixx>8.82e-6</ixx>
          <ixy>0</ixy>
          <ixz>0</ixz>
          <iyy>8.82e-6</iyy>
          <iyz>0</iyz>
          <izz>8.82e-6</izz>
        </inertia>
      </inertial>
      <visual name="visual">
        <geometry>
          <mesh>
            <uri>model://random_strawberry_plant/meshes/leaf3.dae</uri>
            <scale> 0.5159307226875116 0.5159307226875116 0.5159307226875116</scale>
          </mesh>
        </geometry>
      </visual>
    </link>

    <link name= leaf_link_24_2 >
      <pose> -0.12849336385321092
             -0.037564720326617014
             0.06642410004582425 0
             0 -1.2792679281931423  </pose>
      <inertial>
        <mass>0.018</mass>
        <inertia>
          <ixx>8.82e-6</ixx>
          <ixy>0</ixy>
          <ixz>0</ixz>
          <iyy>8.82e-6</iyy>
          <iyz>0</iyz>
          <izz>8.82e-6</izz>
        </inertia>
      </inertial>
      <visual name="visual">
        <geometry>
          <mesh>
            <uri>model://random_strawberry_plant/meshes/leaf3.dae</uri>
            <scale> 0.5159307226875116 0.5159307226875116 0.5159307226875116</scale>
          </mesh>
        </geometry>
      </visual>
    </link>


    <joint name=leaf_dirt_joint_24 type="revolute">
      <parent>dirt_link</parent>
      <child>leaf_stem_link_24</child>
      <axis>
        <xyz>0 1 0</xyz>
      </axis>
    </joint>

    <link name= leaf_stem_link_25 >
      <pose>0 0 0 0 -0.606471560190873 2.0881338710479085 </pose>
      <inertial>
        <mass>1</mass>
        <inertia> <!-- Modeled as slender rod -->
          <ixx>1e-3</ixx>
          <ixy>0</ixy>
          <ixz>0</ixz>
          <iyy>8.333e-2</iyy>
          <iyz>0</iyz>
          <izz>8.333e-2</izz>
        </inertia>
      </inertial>
      <visual name="visual">
        <geometry>
          <mesh>
            <uri>model://random_strawberry_plant/meshes/leaf_stem1.stl</uri>
            <scale> 0.26119641244767783 0.26119641244767783 0.26119641244767783</scale>
          </mesh>
        </geometry>
        <material> <!-- Green -->
          <ambient>0.0 0.5 0.0 1.0</ambient>
          <diffuse>0.0 0.5 0.0 1.0</diffuse>
          <specular>0.1 0.1 0.1 1.0</specular>
        </material>
      </visual>
    </link>

    <link name= leaf_link_25_0 >
      <pose> -0.06368523043436365
             0.11191855491395791
             0.08932475695845392 0
             0 0.5328583482744487  </pose>
      <inertial>
        <mass>0.018</mass>
        <inertia>
          <ixx>8.82e-6</ixx>
          <ixy>0</ixy>
          <ixz>0</ixz>
          <iyy>8.82e-6</iyy>
          <iyz>0</iyz>
          <izz>8.82e-6</izz>
        </inertia>
      </inertial>
      <visual name="visual">
        <geometry>
          <mesh>
            <uri>model://random_strawberry_plant/meshes/leaf3.dae</uri>
            <scale> 0.35147379354601305 0.35147379354601305 0.35147379354601305</scale>
          </mesh>
        </geometry>
      </visual>
    </link>

    <link name= leaf_link_25_1 >
      <pose> -0.06368523043436365
             0.11191855491395791
             0.08932475695845392 0
             0 2.2534085628442595  </pose>
      <inertial>
        <mass>0.018</mass>
        <inertia>
          <ixx>8.82e-6</ixx>
          <ixy>0</ixy>
          <ixz>0</ixz>
          <iyy>8.82e-6</iyy>
          <iyz>0</iyz>
          <izz>8.82e-6</izz>
        </inertia>
      </inertial>
      <visual name="visual">
        <geometry>
          <mesh>
            <uri>model://random_strawberry_plant/meshes/leaf1.dae</uri>
            <scale> 0.35147379354601305 0.35147379354601305 0.35147379354601305</scale>
          </mesh>
        </geometry>
      </visual>
    </link>

    <link name= leaf_link_25_2 >
      <pose> -0.06368523043436365
             0.11191855491395791
             0.08932475695845392 0
             0 3.6518310835777386  </pose>
      <inertial>
        <mass>0.018</mass>
        <inertia>
          <ixx>8.82e-6</ixx>
          <ixy>0</ixy>
          <ixz>0</ixz>
          <iyy>8.82e-6</iyy>
          <iyz>0</iyz>
          <izz>8.82e-6</izz>
        </inertia>
      </inertial>
      <visual name="visual">
        <geometry>
          <mesh>
            <uri>model://random_strawberry_plant/meshes/leaf4.dae</uri>
            <scale> 0.35147379354601305 0.35147379354601305 0.35147379354601305</scale>
          </mesh>
        </geometry>
      </visual>
    </link>


    <joint name=leaf_dirt_joint_25 type="revolute">
      <parent>dirt_link</parent>
      <child>leaf_stem_link_25</child>
      <axis>
        <xyz>0 1 0</xyz>
      </axis>
    </joint>

    <link name= leaf_stem_link_26 >
      <pose>0 0 0 0 -1.009301717146049 -2.093868041088131 </pose>
      <inertial>
        <mass>1</mass>
        <inertia> <!-- Modeled as slender rod -->
          <ixx>1e-3</ixx>
          <ixy>0</ixy>
          <ixz>0</ixz>
          <iyy>8.333e-2</iyy>
          <iyz>0</iyz>
          <izz>8.333e-2</izz>
        </inertia>
      </inertial>
      <visual name="visual">
        <geometry>
          <mesh>
            <uri>model://random_strawberry_plant/meshes/leaf_stem2.stl</uri>
            <scale> 0.27184858151022545 0.27184858151022545 0.27184858151022545</scale>
          </mesh>
        </geometry>
        <material> <!-- Green -->
          <ambient>0.0 0.5 0.0 1.0</ambient>
          <diffuse>0.0 0.5 0.0 1.0</diffuse>
          <specular>0.1 0.1 0.1 1.0</specular>
        </material>
      </visual>
    </link>

    <link name= leaf_link_26_0 >
      <pose> -0.04338424217083397
             -0.07523525989150183
             0.1380654107921474 0
             0 -3.5344831448110297  </pose>
      <inertial>
        <mass>0.018</mass>
        <inertia>
          <ixx>8.82e-6</ixx>
          <ixy>0</ixy>
          <ixz>0</ixz>
          <iyy>8.82e-6</iyy>
          <iyz>0</iyz>
          <izz>8.82e-6</izz>
        </inertia>
      </inertial>
      <visual name="visual">
        <geometry>
          <mesh>
            <uri>model://random_strawberry_plant/meshes/leaf3.dae</uri>
            <scale> 0.3516933531549701 0.3516933531549701 0.3516933531549701</scale>
          </mesh>
        </geometry>
      </visual>
    </link>

    <link name= leaf_link_26_1 >
      <pose> -0.04338424217083397
             -0.07523525989150183
             0.1380654107921474 0
             0 -2.132207565216725  </pose>
      <inertial>
        <mass>0.018</mass>
        <inertia>
          <ixx>8.82e-6</ixx>
          <ixy>0</ixy>
          <ixz>0</ixz>
          <iyy>8.82e-6</iyy>
          <iyz>0</iyz>
          <izz>8.82e-6</izz>
        </inertia>
      </inertial>
      <visual name="visual">
        <geometry>
          <mesh>
            <uri>model://random_strawberry_plant/meshes/leaf4.dae</uri>
            <scale> 0.3516933531549701 0.3516933531549701 0.3516933531549701</scale>
          </mesh>
        </geometry>
      </visual>
    </link>

    <link name= leaf_link_26_2 >
      <pose> -0.04338424217083397
             -0.07523525989150183
             0.1380654107921474 0
             0 -0.43300829901904225  </pose>
      <inertial>
        <mass>0.018</mass>
        <inertia>
          <ixx>8.82e-6</ixx>
          <ixy>0</ixy>
          <ixz>0</ixz>
          <iyy>8.82e-6</iyy>
          <iyz>0</iyz>
          <izz>8.82e-6</izz>
        </inertia>
      </inertial>
      <visual name="visual">
        <geometry>
          <mesh>
            <uri>model://random_strawberry_plant/meshes/leaf4.dae</uri>
            <scale> 0.3516933531549701 0.3516933531549701 0.3516933531549701</scale>
          </mesh>
        </geometry>
      </visual>
    </link>


    <joint name=leaf_dirt_joint_26 type="revolute">
      <parent>dirt_link</parent>
      <child>leaf_stem_link_26</child>
      <axis>
        <xyz>0 1 0</xyz>
      </axis>
    </joint>

    <link name= leaf_stem_link_27 >
      <pose>0 0 0 0 -0.68595283877746 -2.403882595367177 </pose>
      <inertial>
        <mass>1</mass>
        <inertia> <!-- Modeled as slender rod -->
          <ixx>1e-3</ixx>
          <ixy>0</ixy>
          <ixz>0</ixz>
          <iyy>8.333e-2</iyy>
          <iyz>0</iyz>
          <izz>8.333e-2</izz>
        </inertia>
      </inertial>
      <visual name="visual">
        <geometry>
          <mesh>
            <uri>model://random_strawberry_plant/meshes/leaf_stem1.stl</uri>
            <scale> 0.36239260926685263 0.36239260926685263 0.36239260926685263</scale>
          </mesh>
        </geometry>
        <material> <!-- Green -->
          <ambient>0.0 0.5 0.0 1.0</ambient>
          <diffuse>0.0 0.5 0.0 1.0</diffuse>
          <specular>0.1 0.1 0.1 1.0</specular>
        </material>
      </visual>
    </link>

    <link name= leaf_link_27_0 >
      <pose> -0.1245105665560388
             -0.11316754774389508
             0.13772599654376452 0
             0 -3.900290833821275  </pose>
      <inertial>
        <mass>0.018</mass>
        <inertia>
          <ixx>8.82e-6</ixx>
          <ixy>0</ixy>
          <ixz>0</ixz>
          <iyy>8.82e-6</iyy>
          <iyz>0</iyz>
          <izz>8.82e-6</izz>
        </inertia>
      </inertial>
      <visual name="visual">
        <geometry>
          <mesh>
            <uri>model://random_strawberry_plant/meshes/leaf4.dae</uri>
            <scale> 0.4927732063098333 0.4927732063098333 0.4927732063098333</scale>
          </mesh>
        </geometry>
      </visual>
    </link>

    <link name= leaf_link_27_1 >
      <pose> -0.1245105665560388
             -0.11316754774389508
             0.13772599654376452 0
             0 -2.339074969356748  </pose>
      <inertial>
        <mass>0.018</mass>
        <inertia>
          <ixx>8.82e-6</ixx>
          <ixy>0</ixy>
          <ixz>0</ixz>
          <iyy>8.82e-6</iyy>
          <iyz>0</iyz>
          <izz>8.82e-6</izz>
        </inertia>
      </inertial>
      <visual name="visual">
        <geometry>
          <mesh>
            <uri>model://random_strawberry_plant/meshes/leaf3.dae</uri>
            <scale> 0.4927732063098333 0.4927732063098333 0.4927732063098333</scale>
          </mesh>
        </geometry>
      </visual>
    </link>

    <link name= leaf_link_27_2 >
      <pose> -0.1245105665560388
             -0.11316754774389508
             0.13772599654376452 0
             0 -0.7210759730787926  </pose>
      <inertial>
        <mass>0.018</mass>
        <inertia>
          <ixx>8.82e-6</ixx>
          <ixy>0</ixy>
          <ixz>0</ixz>
          <iyy>8.82e-6</iyy>
          <iyz>0</iyz>
          <izz>8.82e-6</izz>
        </inertia>
      </inertial>
      <visual name="visual">
        <geometry>
          <mesh>
            <uri>model://random_strawberry_plant/meshes/leaf1.dae</uri>
            <scale> 0.4927732063098333 0.4927732063098333 0.4927732063098333</scale>
          </mesh>
        </geometry>
      </visual>
    </link>


    <joint name=leaf_dirt_joint_27 type="revolute">
      <parent>dirt_link</parent>
      <child>leaf_stem_link_27</child>
      <axis>
        <xyz>0 1 0</xyz>
      </axis>
    </joint>


    <link name= berry_stem_link_1 >
      <pose>0 0 0 0 -0.09643579906269086 1.8555025153030664</pose>
      <inertial>
        <mass>1</mass>
        <inertia> <!-- Modeled as slender rod -->
          <ixx>1e-3</ixx>
          <ixy>0</ixy>
          <ixz>0</ixz>
          <iyy>8.333e-2</iyy>
          <iyz>0</iyz>
          <izz>8.333e-2</izz>
        </inertia>
      </inertial>
      <visual name="visual">
        <geometry>
          <mesh>
            <uri>model://random_strawberry_plant/meshes/strawb_stem3.stl</uri>
            <scale>0.4914662712193896 0.4914662712193896 0.4914662712193896</scale>
          </mesh>
        </geometry>
        <material> <!-- Green -->
          <ambient>0.0 0.5 0.0 1.0</ambient>
          <diffuse>0.0 0.5 0.0 1.0</diffuse>
          <specular>0.1 0.1 0.1 1.0</specular>
        </material>
      </visual>
    </link>

    <link name= berry_link_1 >
      <pose> -0.0813440948915352 0.27795065952564735 0.016397441095064823
             0 0.0  1.8555025153030664</pose>
      <inertial>
        <mass>0.018</mass>
        <inertia>
          <ixx>8.82e-6</ixx>
          <ixy>0</ixy>
          <ixz>0</ixz>
          <iyy>8.82e-6</iyy>
          <iyz>0</iyz>
          <izz>8.82e-6</izz>
        </inertia>
      </inertial>
      <collision name="collision">
        <geometry>
          <sphere>
            <radius>0.01286240019788376</radius>
          </sphere>
        </geometry>
      </collision>
      <visual name="visual">
        <geometry>
          <mesh>
            <uri>model://random_strawberry_plant/meshes/1003r1.dae</uri>
            <scale>0.25724800395767516 0.25724800395767516 0.25724800395767516</scale>
          </mesh>
        </geometry>
      </visual>
    </link>

    <link name= calyx_link_1 >
      <pose> -0.0813440948915352 0.27795065952564735 0.016397441095064823
             0 0.0 1.8555025153030664 </pose>
      <inertial>
        <mass>0.018</mass>
        <inertia>
          <ixx>8.82e-6</ixx>
          <ixy>0</ixy>
          <ixz>0</ixz>
          <iyy>8.82e-6</iyy>
          <iyz>0</iyz>
          <izz>8.82e-6</izz>
        </inertia>
      </inertial>
      <visual name="visual">
        <geometry>
          <mesh>
            <uri>model://random_strawberry_plant/meshes/calyx5_1003.dae</uri>
            <scale>0.25724800395767516 0.25724800395767516 0.25724800395767516</scale>
          </mesh>
        </geometry>
      </visual>
    </link>

    <joint name=berry_dirt_joint_1 type="revolute">
      <parent>dirt_link</parent>
      <child>berry_stem_link_1</child>
      <axis>
        <xyz>0 1 0</xyz>
      </axis>
    </joint>

    <joint name=stem_to_calyx_joint_1 type="ball">
      <parent> berry_link_1 </parent>
      <child> calyx_link_1 </child>
    </joint>

    <joint name=stem_to_berry_joint_1 type="ball">
      <parent> berry_stem_link_1 </parent>
      <child> berry_link_1 </child>
    </joint>

    <link name= berry_stem_link_2 >
      <pose>0 0 0 0 -0.07445428075958571 -0.5714631019646528</pose>
      <inertial>
        <mass>1</mass>
        <inertia> <!-- Modeled as slender rod -->
          <ixx>1e-3</ixx>
          <ixy>0</ixy>
          <ixz>0</ixz>
          <iyy>8.333e-2</iyy>
          <iyz>0</iyz>
          <izz>8.333e-2</izz>
        </inertia>
      </inertial>
      <visual name="visual">
        <geometry>
          <mesh>
            <uri>model://random_strawberry_plant/meshes/strawb_stem1.stl</uri>
            <scale>0.2634807291131802 0.2634807291131802 0.2634807291131802</scale>
          </mesh>
        </geometry>
        <material> <!-- Green -->
          <ambient>0.0 0.5 0.0 1.0</ambient>
          <diffuse>0.0 0.5 0.0 1.0</diffuse>
          <specular>0.1 0.1 0.1 1.0</specular>
        </material>
      </visual>
    </link>

    <link name= berry_link_2 >
      <pose> 0.13988475015370863 -0.08995074759374147 0.012281386312738531
             0 -1.5607963267948965  -0.5714631019646528</pose>
      <inertial>
        <mass>0.018</mass>
        <inertia>
          <ixx>8.82e-6</ixx>
          <ixy>0</ixy>
          <ixz>0</ixz>
          <iyy>8.82e-6</iyy>
          <iyz>0</iyz>
          <izz>8.82e-6</izz>
        </inertia>
      </inertial>
      <collision name="collision">
        <geometry>
          <sphere>
            <radius>0.01240543863149067</radius>
          </sphere>
        </geometry>
      </collision>
      <visual name="visual">
        <geometry>
          <mesh>
            <uri>model://random_strawberry_plant/meshes/1001r1.dae</uri>
            <scale>0.2481087726298134 0.2481087726298134 0.2481087726298134</scale>
          </mesh>
        </geometry>
      </visual>
    </link>

    <link name= calyx_link_2 >
      <pose> 0.13988475015370863 -0.08995074759374147 0.012281386312738531
             0 -1.5607963267948965 -0.5714631019646528 </pose>
      <inertial>
        <mass>0.018</mass>
        <inertia>
          <ixx>8.82e-6</ixx>
          <ixy>0</ixy>
          <ixz>0</ixz>
          <iyy>8.82e-6</iyy>
          <iyz>0</iyz>
          <izz>8.82e-6</izz>
        </inertia>
      </inertial>
      <visual name="visual">
        <geometry>
          <mesh>
            <uri>model://random_strawberry_plant/meshes/calyx1_1001.dae</uri>
            <scale>0.2481087726298134 0.2481087726298134 0.2481087726298134</scale>
          </mesh>
        </geometry>
      </visual>
    </link>

    <joint name=berry_dirt_joint_2 type="revolute">
      <parent>dirt_link</parent>
      <child>berry_stem_link_2</child>
      <axis>
        <xyz>0 1 0</xyz>
      </axis>
    </joint>

    <joint name=stem_to_calyx_joint_2 type="ball">
      <parent> berry_link_2 </parent>
      <child> calyx_link_2 </child>
    </joint>

    <joint name=stem_to_berry_joint_2 type="ball">
      <parent> berry_stem_link_2 </parent>
      <child> berry_link_2 </child>
    </joint>

    <link name= berry_stem_link_3 >
      <pose>0 0 0 0 -0.08670860042409109 -2.0709251286012087</pose>
      <inertial>
        <mass>1</mass>
        <inertia> <!-- Modeled as slender rod -->
          <ixx>1e-3</ixx>
          <ixy>0</ixy>
          <ixz>0</ixz>
          <iyy>8.333e-2</iyy>
          <iyz>0</iyz>
          <izz>8.333e-2</izz>
        </inertia>
      </inertial>
      <visual name="visual">
        <geometry>
          <mesh>
            <uri>model://random_strawberry_plant/meshes/strawb_stem1.stl</uri>
            <scale>0.31910649311600303 0.31910649311600303 0.31910649311600303</scale>
          </mesh>
        </geometry>
        <material> <!-- Green -->
          <ambient>0.0 0.5 0.0 1.0</ambient>
          <diffuse>0.0 0.5 0.0 1.0</diffuse>
          <specular>0.1 0.1 0.1 1.0</specular>
        </material>
      </visual>
    </link>

    <link name= berry_link_3 >
      <pose> -0.09737166323822714 -0.17818308210634506 0.01747425575218785
             0 -1.5607963267948965  -2.0709251286012087</pose>
      <inertial>
        <mass>0.018</mass>
        <inertia>
          <ixx>8.82e-6</ixx>
          <ixy>0</ixy>
          <ixz>0</ixz>
          <iyy>8.82e-6</iyy>
          <iyz>0</iyz>
          <izz>8.82e-6</izz>
        </inertia>
      </inertial>
      <collision name="collision">
        <geometry>
          <sphere>
            <radius>0.017650760414554705</radius>
          </sphere>
        </geometry>
      </collision>
      <visual name="visual">
        <geometry>
          <mesh>
            <uri>model://random_strawberry_plant/meshes/1000r1.dae</uri>
            <scale>0.35301520829109406 0.35301520829109406 0.35301520829109406</scale>
          </mesh>
        </geometry>
      </visual>
    </link>

    <link name= calyx_link_3 >
      <pose> -0.09737166323822714 -0.17818308210634506 0.01747425575218785
             0 -1.5607963267948965 -2.0709251286012087 </pose>
      <inertial>
        <mass>0.018</mass>
        <inertia>
          <ixx>8.82e-6</ixx>
          <ixy>0</ixy>
          <ixz>0</ixz>
          <iyy>8.82e-6</iyy>
          <iyz>0</iyz>
          <izz>8.82e-6</izz>
        </inertia>
      </inertial>
      <visual name="visual">
        <geometry>
          <mesh>
            <uri>model://random_strawberry_plant/meshes/calyx2_1000.dae</uri>
            <scale>0.35301520829109406 0.35301520829109406 0.35301520829109406</scale>
          </mesh>
        </geometry>
      </visual>
    </link>

    <joint name=berry_dirt_joint_3 type="revolute">
      <parent>dirt_link</parent>
      <child>berry_stem_link_3</child>
      <axis>
        <xyz>0 1 0</xyz>
      </axis>
    </joint>

    <joint name=stem_to_calyx_joint_3 type="ball">
      <parent> berry_link_3 </parent>
      <child> calyx_link_3 </child>
    </joint>

    <joint name=stem_to_berry_joint_3 type="ball">
      <parent> berry_stem_link_3 </parent>
      <child> berry_link_3 </child>
    </joint>

    <link name= berry_stem_link_4 >
      <pose>0 0 0 0 -0.1630926793451033 -0.3610122634483539</pose>
      <inertial>
        <mass>1</mass>
        <inertia> <!-- Modeled as slender rod -->
          <ixx>1e-3</ixx>
          <ixy>0</ixy>
          <ixz>0</ixz>
          <iyy>8.333e-2</iyy>
          <iyz>0</iyz>
          <izz>8.333e-2</izz>
        </inertia>
      </inertial>
      <visual name="visual">
        <geometry>
          <mesh>
            <uri>model://random_strawberry_plant/meshes/strawb_stem1.stl</uri>
            <scale>0.15279351043464895 0.15279351043464895 0.15279351043464895</scale>
          </mesh>
        </geometry>
        <material> <!-- Green -->
          <ambient>0.0 0.5 0.0 1.0</ambient>
          <diffuse>0.0 0.5 0.0 1.0</diffuse>
          <specular>0.1 0.1 0.1 1.0</specular>
        </material>
      </visual>
    </link>

    <link name= berry_link_4 >
      <pose> 0.09548001239900876 -0.036049335382365606 0.016626400637173272
             0 -1.5607963267948965  -0.3610122634483539</pose>
      <inertial>
        <mass>0.018</mass>
        <inertia>
          <ixx>8.82e-6</ixx>
          <ixy>0</ixy>
          <ixz>0</ixz>
          <iyy>8.82e-6</iyy>
          <iyz>0</iyz>
          <izz>8.82e-6</izz>
        </inertia>
      </inertial>
      <collision name="collision">
        <geometry>
          <sphere>
            <radius>0.01679434125063676</radius>
          </sphere>
        </geometry>
      </collision>
      <visual name="visual">
        <geometry>
          <mesh>
            <uri>model://random_strawberry_plant/meshes/1003r0.dae</uri>
            <scale>0.33588682501273515 0.33588682501273515 0.33588682501273515</scale>
          </mesh>
        </geometry>
      </visual>
    </link>

    <link name= calyx_link_4 >
      <pose> 0.09548001239900876 -0.036049335382365606 0.016626400637173272
             0 -1.5607963267948965 -0.3610122634483539 </pose>
      <inertial>
        <mass>0.018</mass>
        <inertia>
          <ixx>8.82e-6</ixx>
          <ixy>0</ixy>
          <ixz>0</ixz>
          <iyy>8.82e-6</iyy>
          <iyz>0</iyz>
          <izz>8.82e-6</izz>
        </inertia>
      </inertial>
      <visual name="visual">
        <geometry>
          <mesh>
            <uri>model://random_strawberry_plant/meshes/calyx6_1003.dae</uri>
            <scale>0.33588682501273515 0.33588682501273515 0.33588682501273515</scale>
          </mesh>
        </geometry>
      </visual>
    </link>

    <joint name=berry_dirt_joint_4 type="revolute">
      <parent>dirt_link</parent>
      <child>berry_stem_link_4</child>
      <axis>
        <xyz>0 1 0</xyz>
      </axis>
    </joint>

    <joint name=stem_to_calyx_joint_4 type="ball">
      <parent> berry_link_4 </parent>
      <child> calyx_link_4 </child>
    </joint>

    <joint name=stem_to_berry_joint_4 type="ball">
      <parent> berry_stem_link_4 </parent>
      <child> berry_link_4 </child>
    </joint>

    <link name= berry_stem_link_5 >
      <pose>0 0 0 0 -0.0793652607346268 -0.8269103807690064</pose>
      <inertial>
        <mass>1</mass>
        <inertia> <!-- Modeled as slender rod -->
          <ixx>1e-3</ixx>
          <ixy>0</ixy>
          <ixz>0</ixz>
          <iyy>8.333e-2</iyy>
          <iyz>0</iyz>
          <izz>8.333e-2</izz>
        </inertia>
      </inertial>
      <visual name="visual">
        <geometry>
          <mesh>
            <uri>model://random_strawberry_plant/meshes/strawb_stem1.stl</uri>
            <scale>0.30148115406066806 0.30148115406066806 0.30148115406066806</scale>
          </mesh>
        </geometry>
        <material> <!-- Green -->
          <ambient>0.0 0.5 0.0 1.0</ambient>
          <diffuse>0.0 0.5 0.0 1.0</diffuse>
          <specular>0.1 0.1 0.1 1.0</specular>
        </material>
      </visual>
    </link>

    <link name= berry_link_5 >
      <pose> 0.12927774604172884 -0.14048253027788188 0.015032040782091291
             0 -1.5607963267948965  -0.8269103807690064</pose>
      <inertial>
        <mass>0.018</mass>
        <inertia>
          <ixx>8.82e-6</ixx>
          <ixy>0</ixy>
          <ixz>0</ixz>
          <iyy>8.82e-6</iyy>
          <iyz>0</iyz>
          <izz>8.82e-6</izz>
        </inertia>
      </inertial>
      <collision name="collision">
        <geometry>
          <sphere>
            <radius>0.01518387702167452</radius>
          </sphere>
        </geometry>
      </collision>
      <visual name="visual">
        <geometry>
          <mesh>
            <uri>model://random_strawberry_plant/meshes/1003r0.dae</uri>
            <scale>0.3036775404334904 0.3036775404334904 0.3036775404334904</scale>
          </mesh>
        </geometry>
      </visual>
    </link>

    <link name= calyx_link_5 >
      <pose> 0.12927774604172884 -0.14048253027788188 0.015032040782091291
             0 -1.5607963267948965 -0.8269103807690064 </pose>
      <inertial>
        <mass>0.018</mass>
        <inertia>
          <ixx>8.82e-6</ixx>
          <ixy>0</ixy>
          <ixz>0</ixz>
          <iyy>8.82e-6</iyy>
          <iyz>0</iyz>
          <izz>8.82e-6</izz>
        </inertia>
      </inertial>
      <visual name="visual">
        <geometry>
          <mesh>
            <uri>model://random_strawberry_plant/meshes/calyx2_1003.dae</uri>
            <scale>0.3036775404334904 0.3036775404334904 0.3036775404334904</scale>
          </mesh>
        </geometry>
      </visual>
    </link>

    <joint name=berry_dirt_joint_5 type="revolute">
      <parent>dirt_link</parent>
      <child>berry_stem_link_5</child>
      <axis>
        <xyz>0 1 0</xyz>
      </axis>
    </joint>

    <joint name=stem_to_calyx_joint_5 type="ball">
      <parent> berry_link_5 </parent>
      <child> calyx_link_5 </child>
    </joint>

    <joint name=stem_to_berry_joint_5 type="ball">
      <parent> berry_stem_link_5 </parent>
      <child> berry_link_5 </child>
    </joint>

    <link name= berry_stem_link_6 >
      <pose>0 0 0 0 -0.09565208956349251 0.1580261589604035</pose>
      <inertial>
        <mass>1</mass>
        <inertia> <!-- Modeled as slender rod -->
          <ixx>1e-3</ixx>
          <ixy>0</ixy>
          <ixz>0</ixz>
          <iyy>8.333e-2</iyy>
          <iyz>0</iyz>
          <izz>8.333e-2</izz>
        </inertia>
      </inertial>
      <visual name="visual">
        <geometry>
          <mesh>
            <uri>model://random_strawberry_plant/meshes/strawb_stem2.stl</uri>
            <scale>0.2657733341829345 0.2657733341829345 0.2657733341829345</scale>
          </mesh>
        </geometry>
        <material> <!-- Green -->
          <ambient>0.0 0.5 0.0 1.0</ambient>
          <diffuse>0.0 0.5 0.0 1.0</diffuse>
          <specular>0.1 0.1 0.1 1.0</specular>
        </material>
      </visual>
    </link>

    <link name= berry_link_6 >
      <pose> 0.16454857831610778 0.026221615098696624 0.012210019940429608
             0 -1.25120819581519  0.1580261589604035</pose>
      <inertial>
        <mass>0.018</mass>
        <inertia>
          <ixx>8.82e-6</ixx>
          <ixy>0</ixy>
          <ixz>0</ixz>
          <iyy>8.82e-6</iyy>
          <iyz>0</iyz>
          <izz>8.82e-6</izz>
        </inertia>
      </inertial>
      <collision name="collision">
        <geometry>
          <sphere>
            <radius>0.012210019940429608</radius>
          </sphere>
        </geometry>
      </collision>
      <visual name="visual">
        <geometry>
          <mesh>
            <uri>model://random_strawberry_plant/meshes/1001u1.dae</uri>
            <scale>0.24420039880859215 0.24420039880859215 0.24420039880859215</scale>
          </mesh>
        </geometry>
      </visual>
    </link>

    <link name= calyx_link_6 >
      <pose> 0.16454857831610778 0.026221615098696624 0.012210019940429608
             0 -1.25120819581519 0.1580261589604035 </pose>
      <inertial>
        <mass>0.018</mass>
        <inertia>
          <ixx>8.82e-6</ixx>
          <ixy>0</ixy>
          <ixz>0</ixz>
          <iyy>8.82e-6</iyy>
          <iyz>0</iyz>
          <izz>8.82e-6</izz>
        </inertia>
      </inertial>
      <visual name="visual">
        <geometry>
          <mesh>
            <uri>model://random_strawberry_plant/meshes/calyx4_1001.dae</uri>
            <scale>0.24420039880859215 0.24420039880859215 0.24420039880859215</scale>
          </mesh>
        </geometry>
      </visual>
    </link>

    <joint name=berry_dirt_joint_6 type="revolute">
      <parent>dirt_link</parent>
      <child>berry_stem_link_6</child>
      <axis>
        <xyz>0 1 0</xyz>
      </axis>
    </joint>

    <joint name=stem_to_calyx_joint_6 type="ball">
      <parent> berry_link_6 </parent>
      <child> calyx_link_6 </child>
    </joint>

    <joint name=stem_to_berry_joint_6 type="ball">
      <parent> berry_stem_link_6 </parent>
      <child> berry_link_6 </child>
    </joint>

    <link name= berry_stem_link_7 >
      <pose>0 0 0 0 -0.09118679768952005 1.7293491583397698</pose>
      <inertial>
        <mass>1</mass>
        <inertia> <!-- Modeled as slender rod -->
          <ixx>1e-3</ixx>
          <ixy>0</ixy>
          <ixz>0</ixz>
          <iyy>8.333e-2</iyy>
          <iyz>0</iyz>
          <izz>8.333e-2</izz>
        </inertia>
      </inertial>
      <visual name="visual">
        <geometry>
          <mesh>
            <uri>model://random_strawberry_plant/meshes/strawb_stem2.stl</uri>
            <scale>0.335263419943294 0.335263419943294 0.335263419943294</scale>
          </mesh>
        </geometry>
        <material> <!-- Green -->
          <ambient>0.0 0.5 0.0 1.0</ambient>
          <diffuse>0.0 0.5 0.0 1.0</diffuse>
          <specular>0.1 0.1 0.1 1.0</specular>
        </material>
      </visual>
    </link>

    <link name= berry_link_7 >
      <pose> -0.03252989886627341 0.2034454440190036 0.011792369054868617
             0 -0.9057678934724764  1.7293491583397698</pose>
      <inertial>
        <mass>0.018</mass>
        <inertia>
          <ixx>8.82e-6</ixx>
          <ixy>0</ixy>
          <ixz>0</ixz>
          <iyy>8.82e-6</iyy>
          <iyz>0</iyz>
          <izz>8.82e-6</izz>
        </inertia>
      </inertial>
      <collision name="collision">
        <geometry>
          <sphere>
            <radius>0.011792369054868617</radius>
          </sphere>
        </geometry>
      </collision>
      <visual name="visual">
        <geometry>
          <mesh>
            <uri>model://random_strawberry_plant/meshes/1002u2.dae</uri>
            <scale>0.23584738109737233 0.23584738109737233 0.23584738109737233</scale>
          </mesh>
        </geometry>
      </visual>
    </link>

    <link name= calyx_link_7 >
      <pose> -0.03252989886627341 0.2034454440190036 0.011792369054868617
             0 -0.9057678934724764 1.7293491583397698 </pose>
      <inertial>
        <mass>0.018</mass>
        <inertia>
          <ixx>8.82e-6</ixx>
          <ixy>0</ixy>
          <ixz>0</ixz>
          <iyy>8.82e-6</iyy>
          <iyz>0</iyz>
          <izz>8.82e-6</izz>
        </inertia>
      </inertial>
      <visual name="visual">
        <geometry>
          <mesh>
            <uri>model://random_strawberry_plant/meshes/calyx6_1002.dae</uri>
            <scale>0.23584738109737233 0.23584738109737233 0.23584738109737233</scale>
          </mesh>
        </geometry>
      </visual>
    </link>

    <joint name=berry_dirt_joint_7 type="revolute">
      <parent>dirt_link</parent>
      <child>berry_stem_link_7</child>
      <axis>
        <xyz>0 1 0</xyz>
      </axis>
    </joint>

    <joint name=stem_to_calyx_joint_7 type="ball">
      <parent> berry_link_7 </parent>
      <child> calyx_link_7 </child>
    </joint>

    <joint name=stem_to_berry_joint_7 type="ball">
      <parent> berry_stem_link_7 </parent>
      <child> berry_link_7 </child>
    </joint>

    <link name= berry_stem_link_8 >
      <pose>0 0 0 0 -0.06998320366806707 0.22383221963279354</pose>
      <inertial>
        <mass>1</mass>
        <inertia> <!-- Modeled as slender rod -->
          <ixx>1e-3</ixx>
          <ixy>0</ixy>
          <ixz>0</ixz>
          <iyy>8.333e-2</iyy>
          <iyz>0</iyz>
          <izz>8.333e-2</izz>
        </inertia>
      </inertial>
      <visual name="visual">
        <geometry>
          <mesh>
            <uri>model://random_strawberry_plant/meshes/strawb_stem2.stl</uri>
            <scale>0.3616618116608594 0.3616618116608594 0.3616618116608594</scale>
          </mesh>
        </geometry>
        <material> <!-- Green -->
          <ambient>0.0 0.5 0.0 1.0</ambient>
          <diffuse>0.0 0.5 0.0 1.0</diffuse>
          <specular>0.1 0.1 0.1 1.0</specular>
        </material>
      </visual>
    </link>

    <link name= berry_link_8 >
      <pose> 0.21952091075545177 0.04997322073439116 0.0128944629948195
             0 -1.3431207519899977  0.22383221963279354</pose>
      <inertial>
        <mass>0.018</mass>
        <inertia>
          <ixx>8.82e-6</ixx>
          <ixy>0</ixy>
          <ixz>0</ixz>
          <iyy>8.82e-6</iyy>
          <iyz>0</iyz>
          <izz>8.82e-6</izz>
        </inertia>
      </inertial>
      <collision name="collision">
        <geometry>
          <sphere>
            <radius>0.0128944629948195</radius>
          </sphere>
        </geometry>
      </collision>
      <visual name="visual">
        <geometry>
          <mesh>
            <uri>model://random_strawberry_plant/meshes/1003u0.dae</uri>
            <scale>0.25788925989639 0.25788925989639 0.25788925989639</scale>
          </mesh>
        </geometry>
      </visual>
    </link>

    <link name= calyx_link_8 >
      <pose> 0.21952091075545177 0.04997322073439116 0.0128944629948195
             0 -1.3431207519899977 0.22383221963279354 </pose>
      <inertial>
        <mass>0.018</mass>
        <inertia>
          <ixx>8.82e-6</ixx>
          <ixy>0</ixy>
          <ixz>0</ixz>
          <iyy>8.82e-6</iyy>
          <iyz>0</iyz>
          <izz>8.82e-6</izz>
        </inertia>
      </inertial>
      <visual name="visual">
        <geometry>
          <mesh>
            <uri>model://random_strawberry_plant/meshes/calyx3_1003.dae</uri>
            <scale>0.25788925989639 0.25788925989639 0.25788925989639</scale>
          </mesh>
        </geometry>
      </visual>
    </link>

    <joint name=berry_dirt_joint_8 type="revolute">
      <parent>dirt_link</parent>
      <child>berry_stem_link_8</child>
      <axis>
        <xyz>0 1 0</xyz>
      </axis>
    </joint>

    <joint name=stem_to_calyx_joint_8 type="ball">
      <parent> berry_link_8 </parent>
      <child> calyx_link_8 </child>
    </joint>

    <joint name=stem_to_berry_joint_8 type="ball">
      <parent> berry_stem_link_8 </parent>
      <child> berry_link_8 </child>
    </joint>

    <link name= berry_stem_link_9 >
      <pose>0 0 0 0 -0.048013509847604274 1.4687439387977195</pose>
      <inertial>
        <mass>1</mass>
        <inertia> <!-- Modeled as slender rod -->
          <ixx>1e-3</ixx>
          <ixy>0</ixy>
          <ixz>0</ixz>
          <iyy>8.333e-2</iyy>
          <iyz>0</iyz>
          <izz>8.333e-2</izz>
        </inertia>
      </inertial>
      <visual name="visual">
        <geometry>
          <mesh>
            <uri>model://random_strawberry_plant/meshes/strawb_stem3.stl</uri>
            <scale>0.2636954879209642 0.2636954879209642 0.2636954879209642</scale>
          </mesh>
        </geometry>
        <material> <!-- Green -->
          <ambient>0.0 0.5 0.0 1.0</ambient>
          <diffuse>0.0 0.5 0.0 1.0</diffuse>
          <specular>0.1 0.1 0.1 1.0</specular>
        </material>
      </visual>
    </link>

    <link name= berry_link_9 >
      <pose> 0.016060068212935857 0.15682411979590258 0.006338628303366044
             0 0.0  1.4687439387977195</pose>
      <inertial>
        <mass>0.018</mass>
        <inertia>
          <ixx>8.82e-6</ixx>
          <ixy>0</ixy>
          <ixz>0</ixz>
          <iyy>8.82e-6</iyy>
          <iyz>0</iyz>
          <izz>8.82e-6</izz>
        </inertia>
      </inertial>
      <collision name="collision">
        <geometry>
          <sphere>
            <radius>0.005000000000000001</radius>
          </sphere>
        </geometry>
      </collision>
      <visual name="visual">
        <geometry>
          <mesh>
            <uri>model://random_strawberry_plant/meshes/1004g.dae</uri>
            <scale>0.1 0.1 0.1</scale>
          </mesh>
        </geometry>
      </visual>
    </link>

    <link name= calyx_link_9 >
      <pose> 0.016060068212935857 0.15682411979590258 0.006338628303366044
             0 0.0 1.4687439387977195 </pose>
      <inertial>
        <mass>0.018</mass>
        <inertia>
          <ixx>8.82e-6</ixx>
          <ixy>0</ixy>
          <ixz>0</ixz>
          <iyy>8.82e-6</iyy>
          <iyz>0</iyz>
          <izz>8.82e-6</izz>
        </inertia>
      </inertial>
      <visual name="visual">
        <geometry>
          <mesh>
            <uri>model://random_strawberry_plant/meshes/calyx7_1004.dae</uri>
            <scale>0.1 0.1 0.1</scale>
          </mesh>
        </geometry>
      </visual>
    </link>

    <joint name=berry_dirt_joint_9 type="revolute">
      <parent>dirt_link</parent>
      <child>berry_stem_link_9</child>
      <axis>
        <xyz>0 1 0</xyz>
      </axis>
    </joint>

    <joint name=stem_to_calyx_joint_9 type="ball">
      <parent> berry_link_9 </parent>
      <child> calyx_link_9 </child>
    </joint>

    <joint name=stem_to_berry_joint_9 type="ball">
      <parent> berry_stem_link_9 </parent>
      <child> berry_link_9 </child>
    </joint>

    <link name= berry_stem_link_10 >
      <pose>0 0 0 0 -0.09440975999743784 -1.4203139818276527</pose>
      <inertial>
        <mass>1</mass>
        <inertia> <!-- Modeled as slender rod -->
          <ixx>1e-3</ixx>
          <ixy>0</ixy>
          <ixz>0</ixz>
          <iyy>8.333e-2</iyy>
          <iyz>0</iyz>
          <izz>8.333e-2</izz>
        </inertia>
      </inertial>
      <visual name="visual">
        <geometry>
          <mesh>
            <uri>model://random_strawberry_plant/meshes/strawb_stem3.stl</uri>
            <scale>0.35109680162581486 0.35109680162581486 0.35109680162581486</scale>
          </mesh>
        </geometry>
        <material> <!-- Green -->
          <ambient>0.0 0.5 0.0 1.0</ambient>
          <diffuse>0.0 0.5 0.0 1.0</diffuse>
          <specular>0.1 0.1 0.1 1.0</specular>
        </material>
      </visual>
    </link>

    <link name= berry_link_10 >
      <pose> 0.031233523104295665 -0.20598699498166667 0.015611088160444785
             0 0.0  -1.4203139818276527</pose>
      <inertial>
        <mass>0.018</mass>
        <inertia>
          <ixx>8.82e-6</ixx>
          <ixy>0</ixy>
          <ixz>0</ixz>
          <iyy>8.82e-6</iyy>
          <iyz>0</iyz>
          <izz>8.82e-6</izz>
        </inertia>
      </inertial>
      <collision name="collision">
        <geometry>
          <sphere>
            <radius>0.005000000000000001</radius>
          </sphere>
        </geometry>
      </collision>
      <visual name="visual">
        <geometry>
          <mesh>
            <uri>model://random_strawberry_plant/meshes/1003g.dae</uri>
            <scale>0.1 0.1 0.1</scale>
          </mesh>
        </geometry>
      </visual>
    </link>

    <link name= calyx_link_10 >
      <pose> 0.031233523104295665 -0.20598699498166667 0.015611088160444785
             0 0.0 -1.4203139818276527 </pose>
      <inertial>
        <mass>0.018</mass>
        <inertia>
          <ixx>8.82e-6</ixx>
          <ixy>0</ixy>
          <ixz>0</ixz>
          <iyy>8.82e-6</iyy>
          <iyz>0</iyz>
          <izz>8.82e-6</izz>
        </inertia>
      </inertial>
      <visual name="visual">
        <geometry>
          <mesh>
            <uri>model://random_strawberry_plant/meshes/calyx10_1003.dae</uri>
            <scale>0.1 0.1 0.1</scale>
          </mesh>
        </geometry>
      </visual>
    </link>

    <joint name=berry_dirt_joint_10 type="revolute">
      <parent>dirt_link</parent>
      <child>berry_stem_link_10</child>
      <axis>
        <xyz>0 1 0</xyz>
      </axis>
    </joint>

    <joint name=stem_to_calyx_joint_10 type="ball">
      <parent> berry_link_10 </parent>
      <child> calyx_link_10 </child>
    </joint>

    <joint name=stem_to_berry_joint_10 type="ball">
      <parent> berry_stem_link_10 </parent>
      <child> berry_link_10 </child>
    </joint>

  </model>
</sdf>
