<?xml version="1.0" ?>


<sdf version="1.6">
  <model name="strawb_plant">
    <static>true</static>

    <link name="dirt_link">
      <inertial>
        <mass>10</mass>
        <inertia>
          <ixx>1</ixx>
          <ixy>0</ixy>
          <ixz>0</ixz>
          <iyy>1</iyy>
          <iyz>0</iyz>
          <izz>1</izz>
        </inertia>
      </inertial>
    </link>

    <joint name="fixed to ground" type="revolute">
      <parent>world</parent>
      <child>dirt_link</child>
      <axis>
        <xyz>0 1 0</xyz>
      </axis>
    </joint>


    <link name= leaf_stem_link_1 >
      <pose>0 0 0 0 -0.9717966997944004 0.10079429540484952 </pose>
      <inertial>
        <mass>1</mass>
        <inertia> <!-- Modeled as slender rod -->
          <ixx>1e-3</ixx>
          <ixy>0</ixy>
          <ixz>0</ixz>
          <iyy>8.333e-2</iyy>
          <iyz>0</iyz>
          <izz>8.333e-2</izz>
        </inertia>
      </inertial>
      <visual name="visual">
        <geometry>
          <mesh>
            <uri>model://random_strawberry_plant/meshes/leaf_stem2.stl</uri>
            <scale> 0.38590576895000284 0.38590576895000284 0.38590576895000284</scale>
          </mesh>
        </geometry>
        <material> <!-- Green -->
          <ambient>0.0 0.5 0.0 1.0</ambient>
          <diffuse>0.0 0.5 0.0 1.0</diffuse>
          <specular>0.1 0.1 0.1 1.0</specular>
        </material>
      </visual>
    </link>

    <link name= leaf_link_1_0 >
      <pose> 0.12988544551643103
             0.013136227915541542
             0.19123175746290322 0
             0 -1.3599184414881926  </pose>
      <inertial>
        <mass>0.018</mass>
        <inertia>
          <ixx>8.82e-6</ixx>
          <ixy>0</ixy>
          <ixz>0</ixz>
          <iyy>8.82e-6</iyy>
          <iyz>0</iyz>
          <izz>8.82e-6</izz>
        </inertia>
      </inertial>
      <visual name="visual">
        <geometry>
          <mesh>
            <uri>model://random_strawberry_plant/meshes/leaf5.dae</uri>
            <scale> 0.6168617015079061 0.6168617015079061 0.6168617015079061</scale>
          </mesh>
        </geometry>
      </visual>
    </link>

    <link name= leaf_link_1_1 >
      <pose> 0.12988544551643103
             0.013136227915541542
             0.19123175746290322 0
             0 0.015035270645115381  </pose>
      <inertial>
        <mass>0.018</mass>
        <inertia>
          <ixx>8.82e-6</ixx>
          <ixy>0</ixy>
          <ixz>0</ixz>
          <iyy>8.82e-6</iyy>
          <iyz>0</iyz>
          <izz>8.82e-6</izz>
        </inertia>
      </inertial>
      <visual name="visual">
        <geometry>
          <mesh>
            <uri>model://random_strawberry_plant/meshes/leaf2.dae</uri>
            <scale> 0.6168617015079061 0.6168617015079061 0.6168617015079061</scale>
          </mesh>
        </geometry>
      </visual>
    </link>

    <link name= leaf_link_1_2 >
      <pose> 0.12988544551643103
             0.013136227915541542
             0.19123175746290322 0
             0 1.8200959774690675  </pose>
      <inertial>
        <mass>0.018</mass>
        <inertia>
          <ixx>8.82e-6</ixx>
          <ixy>0</ixy>
          <ixz>0</ixz>
          <iyy>8.82e-6</iyy>
          <iyz>0</iyz>
          <izz>8.82e-6</izz>
        </inertia>
      </inertial>
      <visual name="visual">
        <geometry>
          <mesh>
            <uri>model://random_strawberry_plant/meshes/leaf3.dae</uri>
            <scale> 0.6168617015079061 0.6168617015079061 0.6168617015079061</scale>
          </mesh>
        </geometry>
      </visual>
    </link>


    <joint name=leaf_dirt_joint_1 type="revolute">
      <parent>dirt_link</parent>
      <child>leaf_stem_link_1</child>
      <axis>
        <xyz>0 1 0</xyz>
      </axis>
    </joint>

    <link name= leaf_stem_link_2 >
      <pose>0 0 0 0 -1.18042297158019 0.9855045229435708 </pose>
      <inertial>
        <mass>1</mass>
        <inertia> <!-- Modeled as slender rod -->
          <ixx>1e-3</ixx>
          <ixy>0</ixy>
          <ixz>0</ixz>
          <iyy>8.333e-2</iyy>
          <iyz>0</iyz>
          <izz>8.333e-2</izz>
        </inertia>
      </inertial>
      <visual name="visual">
        <geometry>
          <mesh>
            <uri>model://random_strawberry_plant/meshes/leaf_stem2.stl</uri>
            <scale> 0.3225389617072583 0.3225389617072583 0.3225389617072583</scale>
          </mesh>
        </geometry>
        <material> <!-- Green -->
          <ambient>0.0 0.5 0.0 1.0</ambient>
          <diffuse>0.0 0.5 0.0 1.0</diffuse>
          <specular>0.1 0.1 0.1 1.0</specular>
        </material>
      </visual>
    </link>

    <link name= leaf_link_2_0 >
      <pose> 0.04068307380748552
             0.06138449687008565
             0.1789640424903611 0
             0 -0.6148772428259353  </pose>
      <inertial>
        <mass>0.018</mass>
        <inertia>
          <ixx>8.82e-6</ixx>
          <ixy>0</ixy>
          <ixz>0</ixz>
          <iyy>8.82e-6</iyy>
          <iyz>0</iyz>
          <izz>8.82e-6</izz>
        </inertia>
      </inertial>
      <visual name="visual">
        <geometry>
          <mesh>
            <uri>model://random_strawberry_plant/meshes/leaf5.dae</uri>
            <scale> 0.6275553084340552 0.6275553084340552 0.6275553084340552</scale>
          </mesh>
        </geometry>
      </visual>
    </link>

    <link name= leaf_link_2_1 >
      <pose> 0.04068307380748552
             0.06138449687008565
             0.1789640424903611 0
             0 0.996142596877651  </pose>
      <inertial>
        <mass>0.018</mass>
        <inertia>
          <ixx>8.82e-6</ixx>
          <ixy>0</ixy>
          <ixz>0</ixz>
          <iyy>8.82e-6</iyy>
          <iyz>0</iyz>
          <izz>8.82e-6</izz>
        </inertia>
      </inertial>
      <visual name="visual">
        <geometry>
          <mesh>
            <uri>model://random_strawberry_plant/meshes/leaf4.dae</uri>
            <scale> 0.6275553084340552 0.6275553084340552 0.6275553084340552</scale>
          </mesh>
        </geometry>
      </visual>
    </link>

    <link name= leaf_link_2_2 >
      <pose> 0.04068307380748552
             0.06138449687008565
             0.1789640424903611 0
             0 2.5271727153063797  </pose>
      <inertial>
        <mass>0.018</mass>
        <inertia>
          <ixx>8.82e-6</ixx>
          <ixy>0</ixy>
          <ixz>0</ixz>
          <iyy>8.82e-6</iyy>
          <iyz>0</iyz>
          <izz>8.82e-6</izz>
        </inertia>
      </inertial>
      <visual name="visual">
        <geometry>
          <mesh>
            <uri>model://random_strawberry_plant/meshes/leaf5.dae</uri>
            <scale> 0.6275553084340552 0.6275553084340552 0.6275553084340552</scale>
          </mesh>
        </geometry>
      </visual>
    </link>


    <joint name=leaf_dirt_joint_2 type="revolute">
      <parent>dirt_link</parent>
      <child>leaf_stem_link_2</child>
      <axis>
        <xyz>0 1 0</xyz>
      </axis>
    </joint>

    <link name= leaf_stem_link_3 >
      <pose>0 0 0 0 -0.747550608160753 -0.8793134174298021 </pose>
      <inertial>
        <mass>1</mass>
        <inertia> <!-- Modeled as slender rod -->
          <ixx>1e-3</ixx>
          <ixy>0</ixy>
          <ixz>0</ixz>
          <iyy>8.333e-2</iyy>
          <iyz>0</iyz>
          <izz>8.333e-2</izz>
        </inertia>
      </inertial>
      <visual name="visual">
        <geometry>
          <mesh>
            <uri>model://random_strawberry_plant/meshes/leaf_stem1.stl</uri>
            <scale> 0.3084527456736193 0.3084527456736193 0.3084527456736193</scale>
          </mesh>
        </geometry>
        <material> <!-- Green -->
          <ambient>0.0 0.5 0.0 1.0</ambient>
          <diffuse>0.0 0.5 0.0 1.0</diffuse>
          <specular>0.1 0.1 0.1 1.0</specular>
        </material>
      </visual>
    </link>

    <link name= leaf_link_3_0 >
      <pose> 0.08654815490029072
             -0.1045479446045298
             0.1258199460944784 0
             0 -2.546201202982738  </pose>
      <inertial>
        <mass>0.018</mass>
        <inertia>
          <ixx>8.82e-6</ixx>
          <ixy>0</ixy>
          <ixz>0</ixz>
          <iyy>8.82e-6</iyy>
          <iyz>0</iyz>
          <izz>8.82e-6</izz>
        </inertia>
      </inertial>
      <visual name="visual">
        <geometry>
          <mesh>
            <uri>model://random_strawberry_plant/meshes/leaf3.dae</uri>
            <scale> 0.3568629359216921 0.3568629359216921 0.3568629359216921</scale>
          </mesh>
        </geometry>
      </visual>
    </link>

    <link name= leaf_link_3_1 >
      <pose> 0.08654815490029072
             -0.1045479446045298
             0.1258199460944784 0
             0 -0.9594873773874224  </pose>
      <inertial>
        <mass>0.018</mass>
        <inertia>
          <ixx>8.82e-6</ixx>
          <ixy>0</ixy>
          <ixz>0</ixz>
          <iyy>8.82e-6</iyy>
          <iyz>0</iyz>
          <izz>8.82e-6</izz>
        </inertia>
      </inertial>
      <visual name="visual">
        <geometry>
          <mesh>
            <uri>model://random_strawberry_plant/meshes/leaf3.dae</uri>
            <scale> 0.3568629359216921 0.3568629359216921 0.3568629359216921</scale>
          </mesh>
        </geometry>
      </visual>
    </link>

    <link name= leaf_link_3_2 >
      <pose> 0.08654815490029072
             -0.1045479446045298
             0.1258199460944784 0
             0 0.5900422178265288  </pose>
      <inertial>
        <mass>0.018</mass>
        <inertia>
          <ixx>8.82e-6</ixx>
          <ixy>0</ixy>
          <ixz>0</ixz>
          <iyy>8.82e-6</iyy>
          <iyz>0</iyz>
          <izz>8.82e-6</izz>
        </inertia>
      </inertial>
      <visual name="visual">
        <geometry>
          <mesh>
            <uri>model://random_strawberry_plant/meshes/leaf2.dae</uri>
            <scale> 0.3568629359216921 0.3568629359216921 0.3568629359216921</scale>
          </mesh>
        </geometry>
      </visual>
    </link>


    <joint name=leaf_dirt_joint_3 type="revolute">
      <parent>dirt_link</parent>
      <child>leaf_stem_link_3</child>
      <axis>
        <xyz>0 1 0</xyz>
      </axis>
    </joint>

    <link name= leaf_stem_link_4 >
      <pose>0 0 0 0 -1.1673785624227393 -1.6881017766395192 </pose>
      <inertial>
        <mass>1</mass>
        <inertia> <!-- Modeled as slender rod -->
          <ixx>1e-3</ixx>
          <ixy>0</ixy>
          <ixz>0</ixz>
          <iyy>8.333e-2</iyy>
          <iyz>0</iyz>
          <izz>8.333e-2</izz>
        </inertia>
      </inertial>
      <visual name="visual">
        <geometry>
          <mesh>
            <uri>model://random_strawberry_plant/meshes/leaf_stem2.stl</uri>
            <scale> 0.23423945780413358 0.23423945780413358 0.23423945780413358</scale>
          </mesh>
        </geometry>
        <material> <!-- Green -->
          <ambient>0.0 0.5 0.0 1.0</ambient>
          <diffuse>0.0 0.5 0.0 1.0</diffuse>
          <specular>0.1 0.1 0.1 1.0</specular>
        </material>
      </visual>
    </link>

    <link name= leaf_link_4_0 >
      <pose> -0.006457189294889858
             -0.054793224851785186
             0.129261485795292 0
             0 -3.202511181899894  </pose>
      <inertial>
        <mass>0.018</mass>
        <inertia>
          <ixx>8.82e-6</ixx>
          <ixy>0</ixy>
          <ixz>0</ixz>
          <iyy>8.82e-6</iyy>
          <iyz>0</iyz>
          <izz>8.82e-6</izz>
        </inertia>
      </inertial>
      <visual name="visual">
        <geometry>
          <mesh>
            <uri>model://random_strawberry_plant/meshes/leaf2.dae</uri>
            <scale> 0.5942696025323535 0.5942696025323535 0.5942696025323535</scale>
          </mesh>
        </geometry>
      </visual>
    </link>

    <link name= leaf_link_4_1 >
      <pose> -0.006457189294889858
             -0.054793224851785186
             0.129261485795292 0
             0 -1.664301120797005  </pose>
      <inertial>
        <mass>0.018</mass>
        <inertia>
          <ixx>8.82e-6</ixx>
          <ixy>0</ixy>
          <ixz>0</ixz>
          <iyy>8.82e-6</iyy>
          <iyz>0</iyz>
          <izz>8.82e-6</izz>
        </inertia>
      </inertial>
      <visual name="visual">
        <geometry>
          <mesh>
            <uri>model://random_strawberry_plant/meshes/leaf2.dae</uri>
            <scale> 0.5942696025323535 0.5942696025323535 0.5942696025323535</scale>
          </mesh>
        </geometry>
      </visual>
    </link>

    <link name= leaf_link_4_2 >
      <pose> -0.006457189294889858
             -0.054793224851785186
             0.129261485795292 0
             0 -0.24815918803909165  </pose>
      <inertial>
        <mass>0.018</mass>
        <inertia>
          <ixx>8.82e-6</ixx>
          <ixy>0</ixy>
          <ixz>0</ixz>
          <iyy>8.82e-6</iyy>
          <iyz>0</iyz>
          <izz>8.82e-6</izz>
        </inertia>
      </inertial>
      <visual name="visual">
        <geometry>
          <mesh>
            <uri>model://random_strawberry_plant/meshes/leaf3.dae</uri>
            <scale> 0.5942696025323535 0.5942696025323535 0.5942696025323535</scale>
          </mesh>
        </geometry>
      </visual>
    </link>


    <joint name=leaf_dirt_joint_4 type="revolute">
      <parent>dirt_link</parent>
      <child>leaf_stem_link_4</child>
      <axis>
        <xyz>0 1 0</xyz>
      </axis>
    </joint>

    <link name= leaf_stem_link_5 >
      <pose>0 0 0 0 -0.8629363685598641 1.2563071238697532 </pose>
      <inertial>
        <mass>1</mass>
        <inertia> <!-- Modeled as slender rod -->
          <ixx>1e-3</ixx>
          <ixy>0</ixy>
          <ixz>0</ixz>
          <iyy>8.333e-2</iyy>
          <iyz>0</iyz>
          <izz>8.333e-2</izz>
        </inertia>
      </inertial>
      <visual name="visual">
        <geometry>
          <mesh>
            <uri>model://random_strawberry_plant/meshes/leaf_stem2.stl</uri>
            <scale> 0.3396681349501832 0.3396681349501832 0.3396681349501832</scale>
          </mesh>
        </geometry>
        <material> <!-- Green -->
          <ambient>0.0 0.5 0.0 1.0</ambient>
          <diffuse>0.0 0.5 0.0 1.0</diffuse>
          <specular>0.1 0.1 0.1 1.0</specular>
        </material>
      </visual>
    </link>

    <link name= leaf_link_5_0 >
      <pose> 0.04099042185486607
             0.1260140620898012
             0.15483875663405708 0
             0 -0.4187828277323624  </pose>
      <inertial>
        <mass>0.018</mass>
        <inertia>
          <ixx>8.82e-6</ixx>
          <ixy>0</ixy>
          <ixz>0</ixz>
          <iyy>8.82e-6</iyy>
          <iyz>0</iyz>
          <izz>8.82e-6</izz>
        </inertia>
      </inertial>
      <visual name="visual">
        <geometry>
          <mesh>
            <uri>model://random_strawberry_plant/meshes/leaf3.dae</uri>
            <scale> 0.5376983248843891 0.5376983248843891 0.5376983248843891</scale>
          </mesh>
        </geometry>
      </visual>
    </link>

    <link name= leaf_link_5_1 >
      <pose> 0.04099042185486607
             0.1260140620898012
             0.15483875663405708 0
             0 1.3628694543286286  </pose>
      <inertial>
        <mass>0.018</mass>
        <inertia>
          <ixx>8.82e-6</ixx>
          <ixy>0</ixy>
          <ixz>0</ixz>
          <iyy>8.82e-6</iyy>
          <iyz>0</iyz>
          <izz>8.82e-6</izz>
        </inertia>
      </inertial>
      <visual name="visual">
        <geometry>
          <mesh>
            <uri>model://random_strawberry_plant/meshes/leaf4.dae</uri>
            <scale> 0.5376983248843891 0.5376983248843891 0.5376983248843891</scale>
          </mesh>
        </geometry>
      </visual>
    </link>

    <link name= leaf_link_5_2 >
      <pose> 0.04099042185486607
             0.1260140620898012
             0.15483875663405708 0
             0 2.9944361154871597  </pose>
      <inertial>
        <mass>0.018</mass>
        <inertia>
          <ixx>8.82e-6</ixx>
          <ixy>0</ixy>
          <ixz>0</ixz>
          <iyy>8.82e-6</iyy>
          <iyz>0</iyz>
          <izz>8.82e-6</izz>
        </inertia>
      </inertial>
      <visual name="visual">
        <geometry>
          <mesh>
            <uri>model://random_strawberry_plant/meshes/leaf5.dae</uri>
            <scale> 0.5376983248843891 0.5376983248843891 0.5376983248843891</scale>
          </mesh>
        </geometry>
      </visual>
    </link>


    <joint name=leaf_dirt_joint_5 type="revolute">
      <parent>dirt_link</parent>
      <child>leaf_stem_link_5</child>
      <axis>
        <xyz>0 1 0</xyz>
      </axis>
    </joint>

    <link name= leaf_stem_link_6 >
      <pose>0 0 0 0 -1.024989202360761 -0.9711796549944771 </pose>
      <inertial>
        <mass>1</mass>
        <inertia> <!-- Modeled as slender rod -->
          <ixx>1e-3</ixx>
          <ixy>0</ixy>
          <ixz>0</ixz>
          <iyy>8.333e-2</iyy>
          <iyz>0</iyz>
          <izz>8.333e-2</izz>
        </inertia>
      </inertial>
      <visual name="visual">
        <geometry>
          <mesh>
            <uri>model://random_strawberry_plant/meshes/leaf_stem2.stl</uri>
            <scale> 0.3821467162239263 0.3821467162239263 0.3821467162239263</scale>
          </mesh>
        </geometry>
        <material> <!-- Green -->
          <ambient>0.0 0.5 0.0 1.0</ambient>
          <diffuse>0.0 0.5 0.0 1.0</diffuse>
          <specular>0.1 0.1 0.1 1.0</specular>
        </material>
      </visual>
    </link>

    <link name= leaf_link_6_0 >
      <pose> 0.06716906535078955
             -0.09826155525397573
             0.19597444730993388 0
             0 -2.5033669862290524  </pose>
      <inertial>
        <mass>0.018</mass>
        <inertia>
          <ixx>8.82e-6</ixx>
          <ixy>0</ixy>
          <ixz>0</ixz>
          <iyy>8.82e-6</iyy>
          <iyz>0</iyz>
          <izz>8.82e-6</izz>
        </inertia>
      </inertial>
      <visual name="visual">
        <geometry>
          <mesh>
            <uri>model://random_strawberry_plant/meshes/leaf5.dae</uri>
            <scale> 0.5092577947848773 0.5092577947848773 0.5092577947848773</scale>
          </mesh>
        </geometry>
      </visual>
    </link>

    <link name= leaf_link_6_1 >
      <pose> 0.06716906535078955
             -0.09826155525397573
             0.19597444730993388 0
             0 -0.9964131907619181  </pose>
      <inertial>
        <mass>0.018</mass>
        <inertia>
          <ixx>8.82e-6</ixx>
          <ixy>0</ixy>
          <ixz>0</ixz>
          <iyy>8.82e-6</iyy>
          <iyz>0</iyz>
          <izz>8.82e-6</izz>
        </inertia>
      </inertial>
      <visual name="visual">
        <geometry>
          <mesh>
            <uri>model://random_strawberry_plant/meshes/leaf3.dae</uri>
            <scale> 0.5092577947848773 0.5092577947848773 0.5092577947848773</scale>
          </mesh>
        </geometry>
      </visual>
    </link>

    <link name= leaf_link_6_2 >
      <pose> 0.06716906535078955
             -0.09826155525397573
             0.19597444730993388 0
             0 0.5972098496568177  </pose>
      <inertial>
        <mass>0.018</mass>
        <inertia>
          <ixx>8.82e-6</ixx>
          <ixy>0</ixy>
          <ixz>0</ixz>
          <iyy>8.82e-6</iyy>
          <iyz>0</iyz>
          <izz>8.82e-6</izz>
        </inertia>
      </inertial>
      <visual name="visual">
        <geometry>
          <mesh>
            <uri>model://random_strawberry_plant/meshes/leaf2.dae</uri>
            <scale> 0.5092577947848773 0.5092577947848773 0.5092577947848773</scale>
          </mesh>
        </geometry>
      </visual>
    </link>


    <joint name=leaf_dirt_joint_6 type="revolute">
      <parent>dirt_link</parent>
      <child>leaf_stem_link_6</child>
      <axis>
        <xyz>0 1 0</xyz>
      </axis>
    </joint>

    <link name= leaf_stem_link_7 >
      <pose>0 0 0 0 -0.613509358150934 0.49015480707989534 </pose>
      <inertial>
        <mass>1</mass>
        <inertia> <!-- Modeled as slender rod -->
          <ixx>1e-3</ixx>
          <ixy>0</ixy>
          <ixz>0</ixz>
          <iyy>8.333e-2</iyy>
          <iyz>0</iyz>
          <izz>8.333e-2</izz>
        </inertia>
      </inertial>
      <visual name="visual">
        <geometry>
          <mesh>
            <uri>model://random_strawberry_plant/meshes/leaf_stem1.stl</uri>
            <scale> 0.3975793913539645 0.3975793913539645 0.3975793913539645</scale>
          </mesh>
        </geometry>
        <material> <!-- Green -->
          <ambient>0.0 0.5 0.0 1.0</ambient>
          <diffuse>0.0 0.5 0.0 1.0</diffuse>
          <specular>0.1 0.1 0.1 1.0</specular>
        </material>
      </visual>
    </link>

    <link name= leaf_link_7_0 >
      <pose> 0.1720797980027065
             0.09181954544919042
             0.13734150234882303 0
             0 -1.0823801208457664  </pose>
      <inertial>
        <mass>0.018</mass>
        <inertia>
          <ixx>8.82e-6</ixx>
          <ixy>0</ixy>
          <ixz>0</ixz>
          <iyy>8.82e-6</iyy>
          <iyz>0</iyz>
          <izz>8.82e-6</izz>
        </inertia>
      </inertial>
      <visual name="visual">
        <geometry>
          <mesh>
            <uri>model://random_strawberry_plant/meshes/leaf5.dae</uri>
            <scale> 0.5213387911106196 0.5213387911106196 0.5213387911106196</scale>
          </mesh>
        </geometry>
      </visual>
    </link>

    <link name= leaf_link_7_1 >
      <pose> 0.1720797980027065
             0.09181954544919042
             0.13734150234882303 0
             0 0.4781048195222435  </pose>
      <inertial>
        <mass>0.018</mass>
        <inertia>
          <ixx>8.82e-6</ixx>
          <ixy>0</ixy>
          <ixz>0</ixz>
          <iyy>8.82e-6</iyy>
          <iyz>0</iyz>
          <izz>8.82e-6</izz>
        </inertia>
      </inertial>
      <visual name="visual">
        <geometry>
          <mesh>
            <uri>model://random_strawberry_plant/meshes/leaf4.dae</uri>
            <scale> 0.5213387911106196 0.5213387911106196 0.5213387911106196</scale>
          </mesh>
        </geometry>
      </visual>
    </link>

    <link name= leaf_link_7_2 >
      <pose> 0.1720797980027065
             0.09181954544919042
             0.13734150234882303 0
             0 2.2014719857519425  </pose>
      <inertial>
        <mass>0.018</mass>
        <inertia>
          <ixx>8.82e-6</ixx>
          <ixy>0</ixy>
          <ixz>0</ixz>
          <iyy>8.82e-6</iyy>
          <iyz>0</iyz>
          <izz>8.82e-6</izz>
        </inertia>
      </inertial>
      <visual name="visual">
        <geometry>
          <mesh>
            <uri>model://random_strawberry_plant/meshes/leaf4.dae</uri>
            <scale> 0.5213387911106196 0.5213387911106196 0.5213387911106196</scale>
          </mesh>
        </geometry>
      </visual>
    </link>


    <joint name=leaf_dirt_joint_7 type="revolute">
      <parent>dirt_link</parent>
      <child>leaf_stem_link_7</child>
      <axis>
        <xyz>0 1 0</xyz>
      </axis>
    </joint>

    <link name= leaf_stem_link_8 >
      <pose>0 0 0 0 -0.48028422974094787 -2.266404205581199 </pose>
      <inertial>
        <mass>1</mass>
        <inertia> <!-- Modeled as slender rod -->
          <ixx>1e-3</ixx>
          <ixy>0</ixy>
          <ixz>0</ixz>
          <iyy>8.333e-2</iyy>
          <iyz>0</iyz>
          <izz>8.333e-2</izz>
        </inertia>
      </inertial>
      <visual name="visual">
        <geometry>
          <mesh>
            <uri>model://random_strawberry_plant/meshes/leaf_stem1.stl</uri>
            <scale> 0.3176508742661675 0.3176508742661675 0.3176508742661675</scale>
          </mesh>
        </geometry>
        <material> <!-- Green -->
          <ambient>0.0 0.5 0.0 1.0</ambient>
          <diffuse>0.0 0.5 0.0 1.0</diffuse>
          <specular>0.1 0.1 0.1 1.0</specular>
        </material>
      </visual>
    </link>

    <link name= leaf_link_8_0 >
      <pose> -0.10832184182792924
             -0.12975660916146267
             0.08805878158290797 0
             0 -3.655302738225476  </pose>
      <inertial>
        <mass>0.018</mass>
        <inertia>
          <ixx>8.82e-6</ixx>
          <ixy>0</ixy>
          <ixz>0</ixz>
          <iyy>8.82e-6</iyy>
          <iyz>0</iyz>
          <izz>8.82e-6</izz>
        </inertia>
      </inertial>
      <visual name="visual">
        <geometry>
          <mesh>
            <uri>model://random_strawberry_plant/meshes/leaf1.dae</uri>
            <scale> 0.511224209732805 0.511224209732805 0.511224209732805</scale>
          </mesh>
        </geometry>
      </visual>
    </link>

    <link name= leaf_link_8_1 >
      <pose> -0.10832184182792924
             -0.12975660916146267
             0.08805878158290797 0
             0 -2.321235389983669  </pose>
      <inertial>
        <mass>0.018</mass>
        <inertia>
          <ixx>8.82e-6</ixx>
          <ixy>0</ixy>
          <ixz>0</ixz>
          <iyy>8.82e-6</iyy>
          <iyz>0</iyz>
          <izz>8.82e-6</izz>
        </inertia>
      </inertial>
      <visual name="visual">
        <geometry>
          <mesh>
            <uri>model://random_strawberry_plant/meshes/leaf2.dae</uri>
            <scale> 0.511224209732805 0.511224209732805 0.511224209732805</scale>
          </mesh>
        </geometry>
      </visual>
    </link>

    <link name= leaf_link_8_2 >
      <pose> -0.10832184182792924
             -0.12975660916146267
             0.08805878158290797 0
             0 -0.7093669888518428  </pose>
      <inertial>
        <mass>0.018</mass>
        <inertia>
          <ixx>8.82e-6</ixx>
          <ixy>0</ixy>
          <ixz>0</ixz>
          <iyy>8.82e-6</iyy>
          <iyz>0</iyz>
          <izz>8.82e-6</izz>
        </inertia>
      </inertial>
      <visual name="visual">
        <geometry>
          <mesh>
            <uri>model://random_strawberry_plant/meshes/leaf2.dae</uri>
            <scale> 0.511224209732805 0.511224209732805 0.511224209732805</scale>
          </mesh>
        </geometry>
      </visual>
    </link>


    <joint name=leaf_dirt_joint_8 type="revolute">
      <parent>dirt_link</parent>
      <child>leaf_stem_link_8</child>
      <axis>
        <xyz>0 1 0</xyz>
      </axis>
    </joint>

    <link name= leaf_stem_link_9 >
      <pose>0 0 0 0 -0.3638207623928492 -1.7348826219617441 </pose>
      <inertial>
        <mass>1</mass>
        <inertia> <!-- Modeled as slender rod -->
          <ixx>1e-3</ixx>
          <ixy>0</ixy>
          <ixz>0</ixz>
          <iyy>8.333e-2</iyy>
          <iyz>0</iyz>
          <izz>8.333e-2</izz>
        </inertia>
      </inertial>
      <visual name="visual">
        <geometry>
          <mesh>
            <uri>model://random_strawberry_plant/meshes/leaf_stem1.stl</uri>
            <scale> 0.25785538165602684 0.25785538165602684 0.25785538165602684</scale>
          </mesh>
        </geometry>
        <material> <!-- Green -->
          <ambient>0.0 0.5 0.0 1.0</ambient>
          <diffuse>0.0 0.5 0.0 1.0</diffuse>
          <specular>0.1 0.1 0.1 1.0</specular>
        </material>
      </visual>
    </link>

    <link name= leaf_link_9_0 >
      <pose> -0.023618316215889827
             -0.14264424561244768
             0.055054314621226765 0
             0 -3.066773961245606  </pose>
      <inertial>
        <mass>0.018</mass>
        <inertia>
          <ixx>8.82e-6</ixx>
          <ixy>0</ixy>
          <ixz>0</ixz>
          <iyy>8.82e-6</iyy>
          <iyz>0</iyz>
          <izz>8.82e-6</izz>
        </inertia>
      </inertial>
      <visual name="visual">
        <geometry>
          <mesh>
            <uri>model://random_strawberry_plant/meshes/leaf1.dae</uri>
            <scale> 0.580898304142085 0.580898304142085 0.580898304142085</scale>
          </mesh>
        </geometry>
      </visual>
    </link>

    <link name= leaf_link_9_1 >
      <pose> -0.023618316215889827
             -0.14264424561244768
             0.055054314621226765 0
             0 -1.5870346866751426  </pose>
      <inertial>
        <mass>0.018</mass>
        <inertia>
          <ixx>8.82e-6</ixx>
          <ixy>0</ixy>
          <ixz>0</ixz>
          <iyy>8.82e-6</iyy>
          <iyz>0</iyz>
          <izz>8.82e-6</izz>
        </inertia>
      </inertial>
      <visual name="visual">
        <geometry>
          <mesh>
            <uri>model://random_strawberry_plant/meshes/leaf3.dae</uri>
            <scale> 0.580898304142085 0.580898304142085 0.580898304142085</scale>
          </mesh>
        </geometry>
      </visual>
    </link>

    <link name= leaf_link_9_2 >
      <pose> -0.023618316215889827
             -0.14264424561244768
             0.055054314621226765 0
             0 -0.04532614154020154  </pose>
      <inertial>
        <mass>0.018</mass>
        <inertia>
          <ixx>8.82e-6</ixx>
          <ixy>0</ixy>
          <ixz>0</ixz>
          <iyy>8.82e-6</iyy>
          <iyz>0</iyz>
          <izz>8.82e-6</izz>
        </inertia>
      </inertial>
      <visual name="visual">
        <geometry>
          <mesh>
            <uri>model://random_strawberry_plant/meshes/leaf4.dae</uri>
            <scale> 0.580898304142085 0.580898304142085 0.580898304142085</scale>
          </mesh>
        </geometry>
      </visual>
    </link>


    <joint name=leaf_dirt_joint_9 type="revolute">
      <parent>dirt_link</parent>
      <child>leaf_stem_link_9</child>
      <axis>
        <xyz>0 1 0</xyz>
      </axis>
    </joint>

    <link name= leaf_stem_link_10 >
      <pose>0 0 0 0 -0.6929546532246931 1.6117421068082152 </pose>
      <inertial>
        <mass>1</mass>
        <inertia> <!-- Modeled as slender rod -->
          <ixx>1e-3</ixx>
          <ixy>0</ixy>
          <ixz>0</ixz>
          <iyy>8.333e-2</iyy>
          <iyz>0</iyz>
          <izz>8.333e-2</izz>
        </inertia>
      </inertial>
      <visual name="visual">
        <geometry>
          <mesh>
            <uri>model://random_strawberry_plant/meshes/leaf_stem1.stl</uri>
            <scale> 0.2884390802911158 0.2884390802911158 0.2884390802911158</scale>
          </mesh>
        </geometry>
        <material> <!-- Green -->
          <ambient>0.0 0.5 0.0 1.0</ambient>
          <diffuse>0.0 0.5 0.0 1.0</diffuse>
          <specular>0.1 0.1 0.1 1.0</specular>
        </material>
      </visual>
    </link>

    <link name= leaf_link_10_0 >
      <pose> -0.005450342816372999
             0.13303682424612948
             0.11055520906675982 0
             0 -0.20148812027687701  </pose>
      <inertial>
        <mass>0.018</mass>
        <inertia>
          <ixx>8.82e-6</ixx>
          <ixy>0</ixy>
          <ixz>0</ixz>
          <iyy>8.82e-6</iyy>
          <iyz>0</iyz>
          <izz>8.82e-6</izz>
        </inertia>
      </inertial>
      <visual name="visual">
        <geometry>
          <mesh>
            <uri>model://random_strawberry_plant/meshes/leaf1.dae</uri>
            <scale> 0.549949722842864 0.549949722842864 0.549949722842864</scale>
          </mesh>
        </geometry>
      </visual>
    </link>

    <link name= leaf_link_10_1 >
      <pose> -0.005450342816372999
             0.13303682424612948
             0.11055520906675982 0
             0 1.531901612609001  </pose>
      <inertial>
        <mass>0.018</mass>
        <inertia>
          <ixx>8.82e-6</ixx>
          <ixy>0</ixy>
          <ixz>0</ixz>
          <iyy>8.82e-6</iyy>
          <iyz>0</iyz>
          <izz>8.82e-6</izz>
        </inertia>
      </inertial>
      <visual name="visual">
        <geometry>
          <mesh>
            <uri>model://random_strawberry_plant/meshes/leaf2.dae</uri>
            <scale> 0.549949722842864 0.549949722842864 0.549949722842864</scale>
          </mesh>
        </geometry>
      </visual>
    </link>

    <link name= leaf_link_10_2 >
      <pose> -0.005450342816372999
             0.13303682424612948
             0.11055520906675982 0
             0 3.2211993586948227  </pose>
      <inertial>
        <mass>0.018</mass>
        <inertia>
          <ixx>8.82e-6</ixx>
          <ixy>0</ixy>
          <ixz>0</ixz>
          <iyy>8.82e-6</iyy>
          <iyz>0</iyz>
          <izz>8.82e-6</izz>
        </inertia>
      </inertial>
      <visual name="visual">
        <geometry>
          <mesh>
            <uri>model://random_strawberry_plant/meshes/leaf2.dae</uri>
            <scale> 0.549949722842864 0.549949722842864 0.549949722842864</scale>
          </mesh>
        </geometry>
      </visual>
    </link>


    <joint name=leaf_dirt_joint_10 type="revolute">
      <parent>dirt_link</parent>
      <child>leaf_stem_link_10</child>
      <axis>
        <xyz>0 1 0</xyz>
      </axis>
    </joint>

    <link name= leaf_stem_link_11 >
      <pose>0 0 0 0 -1.1794487313420794 2.9839483063892995 </pose>
      <inertial>
        <mass>1</mass>
        <inertia> <!-- Modeled as slender rod -->
          <ixx>1e-3</ixx>
          <ixy>0</ixy>
          <ixz>0</ixz>
          <iyy>8.333e-2</iyy>
          <iyz>0</iyz>
          <izz>8.333e-2</izz>
        </inertia>
      </inertial>
      <visual name="visual">
        <geometry>
          <mesh>
            <uri>model://random_strawberry_plant/meshes/leaf_stem2.stl</uri>
            <scale> 0.3112589046847355 0.3112589046847355 0.3112589046847355</scale>
          </mesh>
        </geometry>
        <material> <!-- Green -->
          <ambient>0.0 0.5 0.0 1.0</ambient>
          <diffuse>0.0 0.5 0.0 1.0</diffuse>
          <specular>0.1 0.1 0.1 1.0</specular>
        </material>
      </visual>
    </link>

    <link name= leaf_link_11_0 >
      <pose> -0.07035160141021189
             0.011183327849648199
             0.17263586946408563 0
             0 1.740400951225608  </pose>
      <inertial>
        <mass>0.018</mass>
        <inertia>
          <ixx>8.82e-6</ixx>
          <ixy>0</ixy>
          <ixz>0</ixz>
          <iyy>8.82e-6</iyy>
          <iyz>0</iyz>
          <izz>8.82e-6</izz>
        </inertia>
      </inertial>
      <visual name="visual">
        <geometry>
          <mesh>
            <uri>model://random_strawberry_plant/meshes/leaf4.dae</uri>
            <scale> 0.6457693638216352 0.6457693638216352 0.6457693638216352</scale>
          </mesh>
        </geometry>
      </visual>
    </link>

    <link name= leaf_link_11_1 >
      <pose> -0.07035160141021189
             0.011183327849648199
             0.17263586946408563 0
             0 2.990793770331275  </pose>
      <inertial>
        <mass>0.018</mass>
        <inertia>
          <ixx>8.82e-6</ixx>
          <ixy>0</ixy>
          <ixz>0</ixz>
          <iyy>8.82e-6</iyy>
          <iyz>0</iyz>
          <izz>8.82e-6</izz>
        </inertia>
      </inertial>
      <visual name="visual">
        <geometry>
          <mesh>
            <uri>model://random_strawberry_plant/meshes/leaf1.dae</uri>
            <scale> 0.6457693638216352 0.6457693638216352 0.6457693638216352</scale>
          </mesh>
        </geometry>
      </visual>
    </link>

    <link name= leaf_link_11_2 >
      <pose> -0.07035160141021189
             0.011183327849648199
             0.17263586946408563 0
             0 4.559142024796841  </pose>
      <inertial>
        <mass>0.018</mass>
        <inertia>
          <ixx>8.82e-6</ixx>
          <ixy>0</ixy>
          <ixz>0</ixz>
          <iyy>8.82e-6</iyy>
          <iyz>0</iyz>
          <izz>8.82e-6</izz>
        </inertia>
      </inertial>
      <visual name="visual">
        <geometry>
          <mesh>
            <uri>model://random_strawberry_plant/meshes/leaf2.dae</uri>
            <scale> 0.6457693638216352 0.6457693638216352 0.6457693638216352</scale>
          </mesh>
        </geometry>
      </visual>
    </link>


    <joint name=leaf_dirt_joint_11 type="revolute">
      <parent>dirt_link</parent>
      <child>leaf_stem_link_11</child>
      <axis>
        <xyz>0 1 0</xyz>
      </axis>
    </joint>

    <link name= leaf_stem_link_12 >
      <pose>0 0 0 0 -0.476668697824993 -2.8677894401330235 </pose>
      <inertial>
        <mass>1</mass>
        <inertia> <!-- Modeled as slender rod -->
          <ixx>1e-3</ixx>
          <ixy>0</ixy>
          <ixz>0</ixz>
          <iyy>8.333e-2</iyy>
          <iyz>0</iyz>
          <izz>8.333e-2</izz>
        </inertia>
      </inertial>
      <visual name="visual">
        <geometry>
          <mesh>
            <uri>model://random_strawberry_plant/meshes/leaf_stem1.stl</uri>
            <scale> 0.22781216826006928 0.22781216826006928 0.22781216826006928</scale>
          </mesh>
        </geometry>
        <material> <!-- Green -->
          <ambient>0.0 0.5 0.0 1.0</ambient>
          <diffuse>0.0 0.5 0.0 1.0</diffuse>
          <specular>0.1 0.1 0.1 1.0</specular>
        </material>
      </visual>
    </link>

    <link name= leaf_link_12_0 >
      <pose> -0.11692644420253366
             -0.032839609265077896
             0.06271510944035952 0
             0 -4.334551593567788  </pose>
      <inertial>
        <mass>0.018</mass>
        <inertia>
          <ixx>8.82e-6</ixx>
          <ixy>0</ixy>
          <ixz>0</ixz>
          <iyy>8.82e-6</iyy>
          <iyz>0</iyz>
          <izz>8.82e-6</izz>
        </inertia>
      </inertial>
      <visual name="visual">
        <geometry>
          <mesh>
            <uri>model://random_strawberry_plant/meshes/leaf5.dae</uri>
            <scale> 0.561438846823816 0.561438846823816 0.561438846823816</scale>
          </mesh>
        </geometry>
      </visual>
    </link>

    <link name= leaf_link_12_1 >
      <pose> -0.11692644420253366
             -0.032839609265077896
             0.06271510944035952 0
             0 -2.8310932758063982  </pose>
      <inertial>
        <mass>0.018</mass>
        <inertia>
          <ixx>8.82e-6</ixx>
          <ixy>0</ixy>
          <ixz>0</ixz>
          <iyy>8.82e-6</iyy>
          <iyz>0</iyz>
          <izz>8.82e-6</izz>
        </inertia>
      </inertial>
      <visual name="visual">
        <geometry>
          <mesh>
            <uri>model://random_strawberry_plant/meshes/leaf3.dae</uri>
            <scale> 0.561438846823816 0.561438846823816 0.561438846823816</scale>
          </mesh>
        </geometry>
      </visual>
    </link>

    <link name= leaf_link_12_2 >
      <pose> -0.11692644420253366
             -0.032839609265077896
             0.06271510944035952 0
             0 -1.2283678976870473  </pose>
      <inertial>
        <mass>0.018</mass>
        <inertia>
          <ixx>8.82e-6</ixx>
          <ixy>0</ixy>
          <ixz>0</ixz>
          <iyy>8.82e-6</iyy>
          <iyz>0</iyz>
          <izz>8.82e-6</izz>
        </inertia>
      </inertial>
      <visual name="visual">
        <geometry>
          <mesh>
            <uri>model://random_strawberry_plant/meshes/leaf4.dae</uri>
            <scale> 0.561438846823816 0.561438846823816 0.561438846823816</scale>
          </mesh>
        </geometry>
      </visual>
    </link>


    <joint name=leaf_dirt_joint_12 type="revolute">
      <parent>dirt_link</parent>
      <child>leaf_stem_link_12</child>
      <axis>
        <xyz>0 1 0</xyz>
      </axis>
    </joint>

    <link name= leaf_stem_link_13 >
      <pose>0 0 0 0 -0.9546650751303878 -0.04390679158524291 </pose>
      <inertial>
        <mass>1</mass>
        <inertia> <!-- Modeled as slender rod -->
          <ixx>1e-3</ixx>
          <ixy>0</ixy>
          <ixz>0</ixz>
          <iyy>8.333e-2</iyy>
          <iyz>0</iyz>
          <izz>8.333e-2</izz>
        </inertia>
      </inertial>
      <visual name="visual">
        <geometry>
          <mesh>
            <uri>model://random_strawberry_plant/meshes/leaf_stem2.stl</uri>
            <scale> 0.19117462044431716 0.19117462044431716 0.19117462044431716</scale>
          </mesh>
        </geometry>
        <material> <!-- Green -->
          <ambient>0.0 0.5 0.0 1.0</ambient>
          <diffuse>0.0 0.5 0.0 1.0</diffuse>
          <specular>0.1 0.1 0.1 1.0</specular>
        </material>
      </visual>
    </link>

    <link name= leaf_link_13_0 >
      <pose> 0.06622195516488173
             -0.0029094634514908713
             0.09361288617116327 0
             0 -1.5219764294272538  </pose>
      <inertial>
        <mass>0.018</mass>
        <inertia>
          <ixx>8.82e-6</ixx>
          <ixy>0</ixy>
          <ixz>0</ixz>
          <iyy>8.82e-6</iyy>
          <iyz>0</iyz>
          <izz>8.82e-6</izz>
        </inertia>
      </inertial>
      <visual name="visual">
        <geometry>
          <mesh>
            <uri>model://random_strawberry_plant/meshes/leaf5.dae</uri>
            <scale> 0.5067628002353127 0.5067628002353127 0.5067628002353127</scale>
          </mesh>
        </geometry>
      </visual>
    </link>

    <link name= leaf_link_13_1 >
      <pose> 0.06622195516488173
             -0.0029094634514908713
             0.09361288617116327 0
             0 0.017670535444120943  </pose>
      <inertial>
        <mass>0.018</mass>
        <inertia>
          <ixx>8.82e-6</ixx>
          <ixy>0</ixy>
          <ixz>0</ixz>
          <iyy>8.82e-6</iyy>
          <iyz>0</iyz>
          <izz>8.82e-6</izz>
        </inertia>
      </inertial>
      <visual name="visual">
        <geometry>
          <mesh>
            <uri>model://random_strawberry_plant/meshes/leaf3.dae</uri>
            <scale> 0.5067628002353127 0.5067628002353127 0.5067628002353127</scale>
          </mesh>
        </geometry>
      </visual>
    </link>

    <link name= leaf_link_13_2 >
      <pose> 0.06622195516488173
             -0.0029094634514908713
             0.09361288617116327 0
             0 1.4132039661585498  </pose>
      <inertial>
        <mass>0.018</mass>
        <inertia>
          <ixx>8.82e-6</ixx>
          <ixy>0</ixy>
          <ixz>0</ixz>
          <iyy>8.82e-6</iyy>
          <iyz>0</iyz>
          <izz>8.82e-6</izz>
        </inertia>
      </inertial>
      <visual name="visual">
        <geometry>
          <mesh>
            <uri>model://random_strawberry_plant/meshes/leaf4.dae</uri>
            <scale> 0.5067628002353127 0.5067628002353127 0.5067628002353127</scale>
          </mesh>
        </geometry>
      </visual>
    </link>


    <joint name=leaf_dirt_joint_13 type="revolute">
      <parent>dirt_link</parent>
      <child>leaf_stem_link_13</child>
      <axis>
        <xyz>0 1 0</xyz>
      </axis>
    </joint>


    <link name= berry_stem_link_1 >
      <pose>0 0 0 0 -0.08696939523972652 -2.0472685900322167</pose>
      <inertial>
        <mass>1</mass>
        <inertia> <!-- Modeled as slender rod -->
          <ixx>1e-3</ixx>
          <ixy>0</ixy>
          <ixz>0</ixz>
          <iyy>8.333e-2</iyy>
          <iyz>0</iyz>
          <izz>8.333e-2</izz>
        </inertia>
      </inertial>
      <visual name="visual">
        <geometry>
          <mesh>
            <uri>model://random_strawberry_plant/meshes/strawb_stem1.stl</uri>
            <scale>0.38165887595776904 0.38165887595776904 0.38165887595776904</scale>
          </mesh>
        </geometry>
        <material> <!-- Green -->
          <ambient>0.0 0.5 0.0 1.0</ambient>
          <diffuse>0.0 0.5 0.0 1.0</diffuse>
          <specular>0.1 0.1 0.1 1.0</specular>
        </material>
      </visual>
    </link>

    <link name= berry_link_1 >
      <pose> -0.11140425126394689 -0.21584317156476845 0.020966382121346303
             0 -1.5607963267948965  -2.0472685900322167</pose>
      <inertial>
        <mass>0.018</mass>
        <inertia>
          <ixx>8.82e-6</ixx>
          <ixy>0</ixy>
          <ixz>0</ixz>
          <iyy>8.82e-6</iyy>
          <iyz>0</iyz>
          <izz>8.82e-6</izz>
        </inertia>
      </inertial>
      <collision name="collision">
        <geometry>
          <sphere>
            <radius>0.021178160193606653</radius>
          </sphere>
        </geometry>
      </collision>
      <visual name="visual">
        <geometry>
          <mesh>
            <uri>model://random_strawberry_plant/meshes/1002r1.dae</uri>
            <scale>0.42356320387213303 0.42356320387213303 0.42356320387213303</scale>
          </mesh>
        </geometry>
      </visual>
    </link>

    <link name= calyx_link_1 >
      <pose> -0.11140425126394689 -0.21584317156476845 0.020966382121346303
             0 -1.5607963267948965 -2.0472685900322167 </pose>
      <inertial>
        <mass>0.018</mass>
        <inertia>
          <ixx>8.82e-6</ixx>
          <ixy>0</ixy>
          <ixz>0</ixz>
          <iyy>8.82e-6</iyy>
          <iyz>0</iyz>
          <izz>8.82e-6</izz>
        </inertia>
      </inertial>
      <visual name="visual">
        <geometry>
          <mesh>
            <uri>model://random_strawberry_plant/meshes/calyx6_1002.dae</uri>
            <scale>0.42356320387213303 0.42356320387213303 0.42356320387213303</scale>
          </mesh>
        </geometry>
      </visual>
    </link>

    <joint name=berry_dirt_joint_1 type="revolute">
      <parent>dirt_link</parent>
      <child>berry_stem_link_1</child>
      <axis>
        <xyz>0 1 0</xyz>
      </axis>
    </joint>

    <joint name=stem_to_calyx_joint_1 type="ball">
      <parent> berry_link_1 </parent>
      <child> calyx_link_1 </child>
    </joint>

    <joint name=stem_to_berry_joint_1 type="ball">
      <parent> berry_stem_link_1 </parent>
      <child> berry_link_1 </child>
    </joint>

    <link name= berry_stem_link_2 >
      <pose>0 0 0 0 -0.09073826240626098 -0.4778577261507282</pose>
      <inertial>
        <mass>1</mass>
        <inertia> <!-- Modeled as slender rod -->
          <ixx>1e-3</ixx>
          <ixy>0</ixy>
          <ixz>0</ixz>
          <iyy>8.333e-2</iyy>
          <iyz>0</iyz>
          <izz>8.333e-2</izz>
        </inertia>
      </inertial>
      <visual name="visual">
        <geometry>
          <mesh>
            <uri>model://random_strawberry_plant/meshes/strawb_stem2.stl</uri>
            <scale>0.5354812284140049 0.5354812284140049 0.5354812284140049</scale>
          </mesh>
        </geometry>
        <material> <!-- Green -->
          <ambient>0.0 0.5 0.0 1.0</ambient>
          <diffuse>0.0 0.5 0.0 1.0</diffuse>
          <specular>0.1 0.1 0.1 1.0</specular>
        </material>
      </visual>
    </link>

    <link name= berry_link_2 >
      <pose> 0.29605404402264196 -0.15332371515739143 0.021838709945857574
             0 -1.1630623772411282  -0.4778577261507282</pose>
      <inertial>
        <mass>0.018</mass>
        <inertia>
          <ixx>8.82e-6</ixx>
          <ixy>0</ixy>
          <ixz>0</ixz>
          <iyy>8.82e-6</iyy>
          <iyz>0</iyz>
          <izz>8.82e-6</izz>
        </inertia>
      </inertial>
      <collision name="collision">
        <geometry>
          <sphere>
            <radius>0.021838709945857574</radius>
          </sphere>
        </geometry>
      </collision>
      <visual name="visual">
        <geometry>
          <mesh>
            <uri>model://random_strawberry_plant/meshes/1000r1.dae</uri>
            <scale>0.43677419891715147 0.43677419891715147 0.43677419891715147</scale>
          </mesh>
        </geometry>
      </visual>
    </link>

    <link name= calyx_link_2 >
      <pose> 0.29605404402264196 -0.15332371515739143 0.021838709945857574
             0 -1.1630623772411282 -0.4778577261507282 </pose>
      <inertial>
        <mass>0.018</mass>
        <inertia>
          <ixx>8.82e-6</ixx>
          <ixy>0</ixy>
          <ixz>0</ixz>
          <iyy>8.82e-6</iyy>
          <iyz>0</iyz>
          <izz>8.82e-6</izz>
        </inertia>
      </inertial>
      <visual name="visual">
        <geometry>
          <mesh>
            <uri>model://random_strawberry_plant/meshes/calyx2_1000.dae</uri>
            <scale>0.43677419891715147 0.43677419891715147 0.43677419891715147</scale>
          </mesh>
        </geometry>
      </visual>
    </link>

    <joint name=berry_dirt_joint_2 type="revolute">
      <parent>dirt_link</parent>
      <child>berry_stem_link_2</child>
      <axis>
        <xyz>0 1 0</xyz>
      </axis>
    </joint>

    <joint name=stem_to_calyx_joint_2 type="ball">
      <parent> berry_link_2 </parent>
      <child> calyx_link_2 </child>
    </joint>

    <joint name=stem_to_berry_joint_2 type="ball">
      <parent> berry_stem_link_2 </parent>
      <child> berry_link_2 </child>
    </joint>

    <link name= berry_stem_link_3 >
      <pose>0 0 0 0 -0.07212642054645048 -2.6395173364529043</pose>
      <inertial>
        <mass>1</mass>
        <inertia> <!-- Modeled as slender rod -->
          <ixx>1e-3</ixx>
          <ixy>0</ixy>
          <ixz>0</ixz>
          <iyy>8.333e-2</iyy>
          <iyz>0</iyz>
          <izz>8.333e-2</izz>
        </inertia>
      </inertial>
      <visual name="visual">
        <geometry>
          <mesh>
            <uri>model://random_strawberry_plant/meshes/strawb_stem1.stl</uri>
            <scale>0.3390590248697212 0.3390590248697212 0.3390590248697212</scale>
          </mesh>
        </geometry>
        <material> <!-- Green -->
          <ambient>0.0 0.5 0.0 1.0</ambient>
          <diffuse>0.0 0.5 0.0 1.0</diffuse>
          <specular>0.1 0.1 0.1 1.0</specular>
        </material>
      </visual>
    </link>

    <link name= berry_link_3 >
      <pose> -0.1873132508279964 -0.10283501973108189 0.015284785333342673
             0 -1.5607963267948965  -2.6395173364529043</pose>
      <inertial>
        <mass>0.018</mass>
        <inertia>
          <ixx>8.82e-6</ixx>
          <ixy>0</ixy>
          <ixz>0</ixz>
          <iyy>8.82e-6</iyy>
          <iyz>0</iyz>
          <izz>8.82e-6</izz>
        </inertia>
      </inertial>
      <collision name="collision">
        <geometry>
          <sphere>
            <radius>0.015439174505211907</radius>
          </sphere>
        </geometry>
      </collision>
      <visual name="visual">
        <geometry>
          <mesh>
            <uri>model://random_strawberry_plant/meshes/1004r0.dae</uri>
            <scale>0.3087834901042381 0.3087834901042381 0.3087834901042381</scale>
          </mesh>
        </geometry>
      </visual>
    </link>

    <link name= calyx_link_3 >
      <pose> -0.1873132508279964 -0.10283501973108189 0.015284785333342673
             0 -1.5607963267948965 -2.6395173364529043 </pose>
      <inertial>
        <mass>0.018</mass>
        <inertia>
          <ixx>8.82e-6</ixx>
          <ixy>0</ixy>
          <ixz>0</ixz>
          <iyy>8.82e-6</iyy>
          <iyz>0</iyz>
          <izz>8.82e-6</izz>
        </inertia>
      </inertial>
      <visual name="visual">
        <geometry>
          <mesh>
            <uri>model://random_strawberry_plant/meshes/calyx1_1004.dae</uri>
            <scale>0.3087834901042381 0.3087834901042381 0.3087834901042381</scale>
          </mesh>
        </geometry>
      </visual>
    </link>

    <joint name=berry_dirt_joint_3 type="revolute">
      <parent>dirt_link</parent>
      <child>berry_stem_link_3</child>
      <axis>
        <xyz>0 1 0</xyz>
      </axis>
    </joint>

    <joint name=stem_to_calyx_joint_3 type="ball">
      <parent> berry_link_3 </parent>
      <child> calyx_link_3 </child>
    </joint>

    <joint name=stem_to_berry_joint_3 type="ball">
      <parent> berry_stem_link_3 </parent>
      <child> berry_link_3 </child>
    </joint>

    <link name= berry_stem_link_4 >
      <pose>0 0 0 0 -0.1295803221331097 -2.6026787802582803</pose>
      <inertial>
        <mass>1</mass>
        <inertia> <!-- Modeled as slender rod -->
          <ixx>1e-3</ixx>
          <ixy>0</ixy>
          <ixz>0</ixz>
          <iyy>8.333e-2</iyy>
          <iyz>0</iyz>
          <izz>8.333e-2</izz>
        </inertia>
      </inertial>
      <visual name="visual">
        <geometry>
          <mesh>
            <uri>model://random_strawberry_plant/meshes/strawb_stem1.stl</uri>
            <scale>0.2578440758991039 0.2578440758991039 0.2578440758991039</scale>
          </mesh>
        </geometry>
        <material> <!-- Green -->
          <ambient>0.0 0.5 0.0 1.0</ambient>
          <diffuse>0.0 0.5 0.0 1.0</diffuse>
          <specular>0.1 0.1 0.1 1.0</specular>
        </material>
      </visual>
    </link>

    <link name= berry_link_4 >
      <pose> -0.14475916387674326 -0.0865593491527066 0.021759120341988174
             0 -1.5607963267948965  -2.6026787802582803</pose>
      <inertial>
        <mass>0.018</mass>
        <inertia>
          <ixx>8.82e-6</ixx>
          <ixy>0</ixy>
          <ixz>0</ixz>
          <iyy>8.82e-6</iyy>
          <iyz>0</iyz>
          <izz>8.82e-6</izz>
        </inertia>
      </inertial>
      <collision name="collision">
        <geometry>
          <sphere>
            <radius>0.021978905736217712</radius>
          </sphere>
        </geometry>
      </collision>
      <visual name="visual">
        <geometry>
          <mesh>
            <uri>model://random_strawberry_plant/meshes/1004u3.dae</uri>
            <scale>0.4395781147243542 0.4395781147243542 0.4395781147243542</scale>
          </mesh>
        </geometry>
      </visual>
    </link>

    <link name= calyx_link_4 >
      <pose> -0.14475916387674326 -0.0865593491527066 0.021759120341988174
             0 -1.5607963267948965 -2.6026787802582803 </pose>
      <inertial>
        <mass>0.018</mass>
        <inertia>
          <ixx>8.82e-6</ixx>
          <ixy>0</ixy>
          <ixz>0</ixz>
          <iyy>8.82e-6</iyy>
          <iyz>0</iyz>
          <izz>8.82e-6</izz>
        </inertia>
      </inertial>
      <visual name="visual">
        <geometry>
          <mesh>
            <uri>model://random_strawberry_plant/meshes/calyx6_1004.dae</uri>
            <scale>0.4395781147243542 0.4395781147243542 0.4395781147243542</scale>
          </mesh>
        </geometry>
      </visual>
    </link>

    <joint name=berry_dirt_joint_4 type="revolute">
      <parent>dirt_link</parent>
      <child>berry_stem_link_4</child>
      <axis>
        <xyz>0 1 0</xyz>
      </axis>
    </joint>

    <joint name=stem_to_calyx_joint_4 type="ball">
      <parent> berry_link_4 </parent>
      <child> calyx_link_4 </child>
    </joint>

    <joint name=stem_to_berry_joint_4 type="ball">
      <parent> berry_stem_link_4 </parent>
      <child> berry_link_4 </child>
    </joint>

    <link name= berry_stem_link_5 >
      <pose>0 0 0 0 -0.09731337276604365 1.0299376364787758</pose>
      <inertial>
        <mass>1</mass>
        <inertia> <!-- Modeled as slender rod -->
          <ixx>1e-3</ixx>
          <ixy>0</ixy>
          <ixz>0</ixz>
          <iyy>8.333e-2</iyy>
          <iyz>0</iyz>
          <izz>8.333e-2</izz>
        </inertia>
      </inertial>
      <visual name="visual">
        <geometry>
          <mesh>
            <uri>model://random_strawberry_plant/meshes/strawb_stem2.stl</uri>
            <scale>0.3490386780975521 0.3490386780975521 0.3490386780975521</scale>
          </mesh>
        </geometry>
        <material> <!-- Green -->
          <ambient>0.0 0.5 0.0 1.0</ambient>
          <diffuse>0.0 0.5 0.0 1.0</diffuse>
          <specular>0.1 0.1 0.1 1.0</specular>
        </material>
      </visual>
    </link>

    <link name= berry_link_5 >
      <pose> 0.10650685793020763 0.17733484695469265 0.01059822377156025
             0 -0.15564499445602542  1.0299376364787758</pose>
      <inertial>
        <mass>0.018</mass>
        <inertia>
          <ixx>8.82e-6</ixx>
          <ixy>0</ixy>
          <ixz>0</ixz>
          <iyy>8.82e-6</iyy>
          <iyz>0</iyz>
          <izz>8.82e-6</izz>
        </inertia>
      </inertial>
      <collision name="collision">
        <geometry>
          <sphere>
            <radius>0.01059822377156025</radius>
          </sphere>
        </geometry>
      </collision>
      <visual name="visual">
        <geometry>
          <mesh>
            <uri>model://random_strawberry_plant/meshes/1000u2.dae</uri>
            <scale>0.21196447543120497 0.21196447543120497 0.21196447543120497</scale>
          </mesh>
        </geometry>
      </visual>
    </link>

    <link name= calyx_link_5 >
      <pose> 0.10650685793020763 0.17733484695469265 0.01059822377156025
             0 -0.15564499445602542 1.0299376364787758 </pose>
      <inertial>
        <mass>0.018</mass>
        <inertia>
          <ixx>8.82e-6</ixx>
          <ixy>0</ixy>
          <ixz>0</ixz>
          <iyy>8.82e-6</iyy>
          <iyz>0</iyz>
          <izz>8.82e-6</izz>
        </inertia>
      </inertial>
      <visual name="visual">
        <geometry>
          <mesh>
            <uri>model://random_strawberry_plant/meshes/calyx1_1000.dae</uri>
            <scale>0.21196447543120497 0.21196447543120497 0.21196447543120497</scale>
          </mesh>
        </geometry>
      </visual>
    </link>

    <joint name=berry_dirt_joint_5 type="revolute">
      <parent>dirt_link</parent>
      <child>berry_stem_link_5</child>
      <axis>
        <xyz>0 1 0</xyz>
      </axis>
    </joint>

    <joint name=stem_to_calyx_joint_5 type="ball">
      <parent> berry_link_5 </parent>
      <child> calyx_link_5 </child>
    </joint>

    <joint name=stem_to_berry_joint_5 type="ball">
      <parent> berry_stem_link_5 </parent>
      <child> berry_link_5 </child>
    </joint>

    <link name= berry_stem_link_6 >
      <pose>0 0 0 0 -0.12358891643097555 -0.49931034969110444</pose>
      <inertial>
        <mass>1</mass>
        <inertia> <!-- Modeled as slender rod -->
          <ixx>1e-3</ixx>
          <ixy>0</ixy>
          <ixz>0</ixz>
          <iyy>8.333e-2</iyy>
          <iyz>0</iyz>
          <izz>8.333e-2</izz>
        </inertia>
      </inertial>
      <visual name="visual">
        <geometry>
          <mesh>
            <uri>model://random_strawberry_plant/meshes/strawb_stem1.stl</uri>
            <scale>0.20580145575025338 0.20580145575025338 0.20580145575025338</scale>
          </mesh>
        </geometry>
        <material> <!-- Green -->
          <ambient>0.0 0.5 0.0 1.0</ambient>
          <diffuse>0.0 0.5 0.0 1.0</diffuse>
          <specular>0.1 0.1 0.1 1.0</specular>
        </material>
      </visual>
    </link>

    <link name= berry_link_6 >
      <pose> 0.11773779365065047 -0.06421505838112357 0.016493050645253728
             0 -1.5607963267948965  -0.49931034969110444</pose>
      <inertial>
        <mass>0.018</mass>
        <inertia>
          <ixx>8.82e-6</ixx>
          <ixy>0</ixy>
          <ixz>0</ixz>
          <iyy>8.82e-6</iyy>
          <iyz>0</iyz>
          <izz>8.82e-6</izz>
        </inertia>
      </inertial>
      <collision name="collision">
        <geometry>
          <sphere>
            <radius>0.016659644311778004</radius>
          </sphere>
        </geometry>
      </collision>
      <visual name="visual">
        <geometry>
          <mesh>
            <uri>model://random_strawberry_plant/meshes/1003u3.dae</uri>
            <scale>0.33319288623556004 0.33319288623556004 0.33319288623556004</scale>
          </mesh>
        </geometry>
      </visual>
    </link>

    <link name= calyx_link_6 >
      <pose> 0.11773779365065047 -0.06421505838112357 0.016493050645253728
             0 -1.5607963267948965 -0.49931034969110444 </pose>
      <inertial>
        <mass>0.018</mass>
        <inertia>
          <ixx>8.82e-6</ixx>
          <ixy>0</ixy>
          <ixz>0</ixz>
          <iyy>8.82e-6</iyy>
          <iyz>0</iyz>
          <izz>8.82e-6</izz>
        </inertia>
      </inertial>
      <visual name="visual">
        <geometry>
          <mesh>
            <uri>model://random_strawberry_plant/meshes/calyx3_1003.dae</uri>
            <scale>0.33319288623556004 0.33319288623556004 0.33319288623556004</scale>
          </mesh>
        </geometry>
      </visual>
    </link>

    <joint name=berry_dirt_joint_6 type="revolute">
      <parent>dirt_link</parent>
      <child>berry_stem_link_6</child>
      <axis>
        <xyz>0 1 0</xyz>
      </axis>
    </joint>

    <joint name=stem_to_calyx_joint_6 type="ball">
      <parent> berry_link_6 </parent>
      <child> calyx_link_6 </child>
    </joint>

    <joint name=stem_to_berry_joint_6 type="ball">
      <parent> berry_stem_link_6 </parent>
      <child> berry_link_6 </child>
    </joint>

    <link name= berry_stem_link_7 >
      <pose>0 0 0 0 -0.05323806916164271 -2.977616973100963</pose>
      <inertial>
        <mass>1</mass>
        <inertia> <!-- Modeled as slender rod -->
          <ixx>1e-3</ixx>
          <ixy>0</ixy>
          <ixz>0</ixz>
          <iyy>8.333e-2</iyy>
          <iyz>0</iyz>
          <izz>8.333e-2</izz>
        </inertia>
      </inertial>
      <visual name="visual">
        <geometry>
          <mesh>
            <uri>model://random_strawberry_plant/meshes/strawb_stem3.stl</uri>
            <scale>0.22006944546913737 0.22006944546913737 0.22006944546913737</scale>
          </mesh>
        </geometry>
        <material> <!-- Green -->
          <ambient>0.0 0.5 0.0 1.0</ambient>
          <diffuse>0.0 0.5 0.0 1.0</diffuse>
          <specular>0.1 0.1 0.1 1.0</specular>
        </material>
      </visual>
    </link>

    <link name= berry_link_7 >
      <pose> -0.13066287391004805 -0.021619651799179795 0.008896912205674484
             0 0.0  -2.977616973100963</pose>
      <inertial>
        <mass>0.018</mass>
        <inertia>
          <ixx>8.82e-6</ixx>
          <ixy>0</ixy>
          <ixz>0</ixz>
          <iyy>8.82e-6</iyy>
          <iyz>0</iyz>
          <izz>8.82e-6</izz>
        </inertia>
      </inertial>
      <collision name="collision">
        <geometry>
          <sphere>
            <radius>0.005000000000000001</radius>
          </sphere>
        </geometry>
      </collision>
      <visual name="visual">
        <geometry>
          <mesh>
            <uri>model://random_strawberry_plant/meshes/1001g.dae</uri>
            <scale>0.1 0.1 0.1</scale>
          </mesh>
        </geometry>
      </visual>
    </link>

    <link name= calyx_link_7 >
      <pose> -0.13066287391004805 -0.021619651799179795 0.008896912205674484
             0 0.0 -2.977616973100963 </pose>
      <inertial>
        <mass>0.018</mass>
        <inertia>
          <ixx>8.82e-6</ixx>
          <ixy>0</ixy>
          <ixz>0</ixz>
          <iyy>8.82e-6</iyy>
          <iyz>0</iyz>
          <izz>8.82e-6</izz>
        </inertia>
      </inertial>
      <visual name="visual">
        <geometry>
          <mesh>
            <uri>model://random_strawberry_plant/meshes/calyx8_1001.dae</uri>
            <scale>0.1 0.1 0.1</scale>
          </mesh>
        </geometry>
      </visual>
    </link>

    <joint name=berry_dirt_joint_7 type="revolute">
      <parent>dirt_link</parent>
      <child>berry_stem_link_7</child>
      <axis>
        <xyz>0 1 0</xyz>
      </axis>
    </joint>

    <joint name=stem_to_calyx_joint_7 type="ball">
      <parent> berry_link_7 </parent>
      <child> calyx_link_7 </child>
    </joint>

    <joint name=stem_to_berry_joint_7 type="ball">
      <parent> berry_stem_link_7 </parent>
      <child> berry_link_7 </child>
    </joint>

    <link name= berry_stem_link_8 >
      <pose>0 0 0 0 -0.04746838074475134 -0.8322154239958284</pose>
      <inertial>
        <mass>1</mass>
        <inertia> <!-- Modeled as slender rod -->
          <ixx>1e-3</ixx>
          <ixy>0</ixy>
          <ixz>0</ixz>
          <iyy>8.333e-2</iyy>
          <iyz>0</iyz>
          <izz>8.333e-2</izz>
        </inertia>
      </inertial>
      <visual name="visual">
        <geometry>
          <mesh>
            <uri>model://random_strawberry_plant/meshes/strawb_stem3.stl</uri>
            <scale>0.38429795558585755 0.38429795558585755 0.38429795558585755</scale>
          </mesh>
        </geometry>
        <material> <!-- Green -->
          <ambient>0.0 0.5 0.0 1.0</ambient>
          <diffuse>0.0 0.5 0.0 1.0</diffuse>
          <specular>0.1 0.1 0.1 1.0</specular>
        </material>
      </visual>
    </link>

    <link name= berry_link_8 >
      <pose> 0.15440202905219624 -0.16958112453393798 0.007800639250199707
             0 0.0  -0.8322154239958284</pose>
      <inertial>
        <mass>0.018</mass>
        <inertia>
          <ixx>8.82e-6</ixx>
          <ixy>0</ixy>
          <ixz>0</ixz>
          <iyy>8.82e-6</iyy>
          <iyz>0</iyz>
          <izz>8.82e-6</izz>
        </inertia>
      </inertial>
      <collision name="collision">
        <geometry>
          <sphere>
            <radius>0.005000000000000001</radius>
          </sphere>
        </geometry>
      </collision>
      <visual name="visual">
        <geometry>
          <mesh>
            <uri>model://random_strawberry_plant/meshes/1000g.dae</uri>
            <scale>0.1 0.1 0.1</scale>
          </mesh>
        </geometry>
      </visual>
    </link>

    <link name= calyx_link_8 >
      <pose> 0.15440202905219624 -0.16958112453393798 0.007800639250199707
             0 0.0 -0.8322154239958284 </pose>
      <inertial>
        <mass>0.018</mass>
        <inertia>
          <ixx>8.82e-6</ixx>
          <ixy>0</ixy>
          <ixz>0</ixz>
          <iyy>8.82e-6</iyy>
          <iyz>0</iyz>
          <izz>8.82e-6</izz>
        </inertia>
      </inertial>
      <visual name="visual">
        <geometry>
          <mesh>
            <uri>model://random_strawberry_plant/meshes/calyx10_1000.dae</uri>
            <scale>0.1 0.1 0.1</scale>
          </mesh>
        </geometry>
      </visual>
    </link>

    <joint name=berry_dirt_joint_8 type="revolute">
      <parent>dirt_link</parent>
      <child>berry_stem_link_8</child>
      <axis>
        <xyz>0 1 0</xyz>
      </axis>
    </joint>

    <joint name=stem_to_calyx_joint_8 type="ball">
      <parent> berry_link_8 </parent>
      <child> calyx_link_8 </child>
    </joint>

    <joint name=stem_to_berry_joint_8 type="ball">
      <parent> berry_stem_link_8 </parent>
      <child> berry_link_8 </child>
    </joint>

    <link name= berry_stem_link_9 >
      <pose>0 0 0 0 -0.07652566611051445 0.0049093026732673906</pose>
      <inertial>
        <mass>1</mass>
        <inertia> <!-- Modeled as slender rod -->
          <ixx>1e-3</ixx>
          <ixy>0</ixy>
          <ixz>0</ixz>
          <iyy>8.333e-2</iyy>
          <iyz>0</iyz>
          <izz>8.333e-2</izz>
        </inertia>
      </inertial>
      <visual name="visual">
        <geometry>
          <mesh>
            <uri>model://random_strawberry_plant/meshes/strawb_stem3.stl</uri>
            <scale>0.3602533705930021 0.3602533705930021 0.3602533705930021</scale>
          </mesh>
        </geometry>
        <material> <!-- Green -->
          <ambient>0.0 0.5 0.0 1.0</ambient>
          <diffuse>0.0 0.5 0.0 1.0</diffuse>
          <specular>0.1 0.1 0.1 1.0</specular>
        </material>
      </visual>
    </link>

    <link name= berry_link_9 >
      <pose> 0.21435465355166144 0.0010523403279621307 0.012883282695907886
             0 0.0  0.0049093026732673906</pose>
      <inertial>
        <mass>0.018</mass>
        <inertia>
          <ixx>8.82e-6</ixx>
          <ixy>0</ixy>
          <ixz>0</ixz>
          <iyy>8.82e-6</iyy>
          <iyz>0</iyz>
          <izz>8.82e-6</izz>
        </inertia>
      </inertial>
      <collision name="collision">
        <geometry>
          <sphere>
            <radius>0.005000000000000001</radius>
          </sphere>
        </geometry>
      </collision>
      <visual name="visual">
        <geometry>
          <mesh>
            <uri>model://random_strawberry_plant/meshes/1000g.dae</uri>
            <scale>0.1 0.1 0.1</scale>
          </mesh>
        </geometry>
      </visual>
    </link>

    <link name= calyx_link_9 >
      <pose> 0.21435465355166144 0.0010523403279621307 0.012883282695907886
             0 0.0 0.0049093026732673906 </pose>
      <inertial>
        <mass>0.018</mass>
        <inertia>
          <ixx>8.82e-6</ixx>
          <ixy>0</ixy>
          <ixz>0</ixz>
          <iyy>8.82e-6</iyy>
          <iyz>0</iyz>
          <izz>8.82e-6</izz>
        </inertia>
      </inertial>
      <visual name="visual">
        <geometry>
          <mesh>
            <uri>model://random_strawberry_plant/meshes/calyx8_1000.dae</uri>
            <scale>0.1 0.1 0.1</scale>
          </mesh>
        </geometry>
      </visual>
    </link>

    <joint name=berry_dirt_joint_9 type="revolute">
      <parent>dirt_link</parent>
      <child>berry_stem_link_9</child>
      <axis>
        <xyz>0 1 0</xyz>
      </axis>
    </joint>

    <joint name=stem_to_calyx_joint_9 type="ball">
      <parent> berry_link_9 </parent>
      <child> calyx_link_9 </child>
    </joint>

    <joint name=stem_to_berry_joint_9 type="ball">
      <parent> berry_stem_link_9 </parent>
      <child> berry_link_9 </child>
    </joint>

  </model>
</sdf>
