<?xml version="1.0" ?>


<sdf version="1.6">
  <model name="strawb_plant">
    <static>true</static>

    <link name="dirt_link">
      <inertial>
        <mass>10</mass>
        <inertia>
          <ixx>1</ixx>
          <ixy>0</ixy>
          <ixz>0</ixz>
          <iyy>1</iyy>
          <iyz>0</iyz>
          <izz>1</izz>
        </inertia>
      </inertial>
    </link>

    <joint name="fixed to ground" type="revolute">
      <parent>world</parent>
      <child>dirt_link</child>
      <axis>
        <xyz>0 1 0</xyz>
      </axis>
    </joint>


    <link name= leaf_stem_link_1 >
      <pose>0 0 0 0 -1.2104058357903997 0.8927646736213601 </pose>
      <inertial>
        <mass>1</mass>
        <inertia> <!-- Modeled as slender rod -->
          <ixx>1e-3</ixx>
          <ixy>0</ixy>
          <ixz>0</ixz>
          <iyy>8.333e-2</iyy>
          <iyz>0</iyz>
          <izz>8.333e-2</izz>
        </inertia>
      </inertial>
      <visual name="visual">
        <geometry>
          <mesh>
            <uri>model://random_strawberry_plant/meshes/leaf_stem2.stl</uri>
            <scale> 0.4121822271060078 0.4121822271060078 0.4121822271060078</scale>
          </mesh>
        </geometry>
        <material> <!-- Green -->
          <ambient>0.0 0.5 0.0 1.0</ambient>
          <diffuse>0.0 0.5 0.0 1.0</diffuse>
          <specular>0.1 0.1 0.1 1.0</specular>
        </material>
      </visual>
    </link>

    <link name= leaf_link_1_0 >
      <pose> 0.054704134201985846
             0.06792076608992106
             0.23142198477697412 0
             0 -0.638622206878126  </pose>
      <inertial>
        <mass>0.018</mass>
        <inertia>
          <ixx>8.82e-6</ixx>
          <ixy>0</ixy>
          <ixz>0</ixz>
          <iyy>8.82e-6</iyy>
          <iyz>0</iyz>
          <izz>8.82e-6</izz>
        </inertia>
      </inertial>
      <visual name="visual">
        <geometry>
          <mesh>
            <uri>model://random_strawberry_plant/meshes/leaf4.dae</uri>
            <scale> 0.4891576309817093 0.4891576309817093 0.4891576309817093</scale>
          </mesh>
        </geometry>
      </visual>
    </link>

    <link name= leaf_link_1_1 >
      <pose> 0.054704134201985846
             0.06792076608992106
             0.23142198477697412 0
             0 0.9375750224525845  </pose>
      <inertial>
        <mass>0.018</mass>
        <inertia>
          <ixx>8.82e-6</ixx>
          <ixy>0</ixy>
          <ixz>0</ixz>
          <iyy>8.82e-6</iyy>
          <iyz>0</iyz>
          <izz>8.82e-6</izz>
        </inertia>
      </inertial>
      <visual name="visual">
        <geometry>
          <mesh>
            <uri>model://random_strawberry_plant/meshes/leaf3.dae</uri>
            <scale> 0.4891576309817093 0.4891576309817093 0.4891576309817093</scale>
          </mesh>
        </geometry>
      </visual>
    </link>

    <link name= leaf_link_1_2 >
      <pose> 0.054704134201985846
             0.06792076608992106
             0.23142198477697412 0
             0 2.447263977867541  </pose>
      <inertial>
        <mass>0.018</mass>
        <inertia>
          <ixx>8.82e-6</ixx>
          <ixy>0</ixy>
          <ixz>0</ixz>
          <iyy>8.82e-6</iyy>
          <iyz>0</iyz>
          <izz>8.82e-6</izz>
        </inertia>
      </inertial>
      <visual name="visual">
        <geometry>
          <mesh>
            <uri>model://random_strawberry_plant/meshes/leaf1.dae</uri>
            <scale> 0.4891576309817093 0.4891576309817093 0.4891576309817093</scale>
          </mesh>
        </geometry>
      </visual>
    </link>


    <joint name=leaf_dirt_joint_1 type="revolute">
      <parent>dirt_link</parent>
      <child>leaf_stem_link_1</child>
      <axis>
        <xyz>0 1 0</xyz>
      </axis>
    </joint>

    <link name= leaf_stem_link_2 >
      <pose>0 0 0 0 -0.423465125042499 -2.3073820993024445 </pose>
      <inertial>
        <mass>1</mass>
        <inertia> <!-- Modeled as slender rod -->
          <ixx>1e-3</ixx>
          <ixy>0</ixy>
          <ixz>0</ixz>
          <iyy>8.333e-2</iyy>
          <iyz>0</iyz>
          <izz>8.333e-2</izz>
        </inertia>
      </inertial>
      <visual name="visual">
        <geometry>
          <mesh>
            <uri>model://random_strawberry_plant/meshes/leaf_stem1.stl</uri>
            <scale> 0.3700306111319251 0.3700306111319251 0.3700306111319251</scale>
          </mesh>
        </geometry>
        <material> <!-- Green -->
          <ambient>0.0 0.5 0.0 1.0</ambient>
          <diffuse>0.0 0.5 0.0 1.0</diffuse>
          <specular>0.1 0.1 0.1 1.0</specular>
        </material>
      </visual>
    </link>

    <link name= leaf_link_2_0 >
      <pose> -0.13596987313349743
             -0.14993675364731884
             0.09123222374053801 0
             0 -3.768852782795893  </pose>
      <inertial>
        <mass>0.018</mass>
        <inertia>
          <ixx>8.82e-6</ixx>
          <ixy>0</ixy>
          <ixz>0</ixz>
          <iyy>8.82e-6</iyy>
          <iyz>0</iyz>
          <izz>8.82e-6</izz>
        </inertia>
      </inertial>
      <visual name="visual">
        <geometry>
          <mesh>
            <uri>model://random_strawberry_plant/meshes/leaf2.dae</uri>
            <scale> 0.5838859176595098 0.5838859176595098 0.5838859176595098</scale>
          </mesh>
        </geometry>
      </visual>
    </link>

    <link name= leaf_link_2_1 >
      <pose> -0.13596987313349743
             -0.14993675364731884
             0.09123222374053801 0
             0 -2.2202055597432615  </pose>
      <inertial>
        <mass>0.018</mass>
        <inertia>
          <ixx>8.82e-6</ixx>
          <ixy>0</ixy>
          <ixz>0</ixz>
          <iyy>8.82e-6</iyy>
          <iyz>0</iyz>
          <izz>8.82e-6</izz>
        </inertia>
      </inertial>
      <visual name="visual">
        <geometry>
          <mesh>
            <uri>model://random_strawberry_plant/meshes/leaf5.dae</uri>
            <scale> 0.5838859176595098 0.5838859176595098 0.5838859176595098</scale>
          </mesh>
        </geometry>
      </visual>
    </link>

    <link name= leaf_link_2_2 >
      <pose> -0.13596987313349743
             -0.14993675364731884
             0.09123222374053801 0
             0 -0.5725914842445783  </pose>
      <inertial>
        <mass>0.018</mass>
        <inertia>
          <ixx>8.82e-6</ixx>
          <ixy>0</ixy>
          <ixz>0</ixz>
          <iyy>8.82e-6</iyy>
          <iyz>0</iyz>
          <izz>8.82e-6</izz>
        </inertia>
      </inertial>
      <visual name="visual">
        <geometry>
          <mesh>
            <uri>model://random_strawberry_plant/meshes/leaf2.dae</uri>
            <scale> 0.5838859176595098 0.5838859176595098 0.5838859176595098</scale>
          </mesh>
        </geometry>
      </visual>
    </link>


    <joint name=leaf_dirt_joint_2 type="revolute">
      <parent>dirt_link</parent>
      <child>leaf_stem_link_2</child>
      <axis>
        <xyz>0 1 0</xyz>
      </axis>
    </joint>

    <link name= leaf_stem_link_3 >
      <pose>0 0 0 0 -0.49792743779417437 -2.021912433093122 </pose>
      <inertial>
        <mass>1</mass>
        <inertia> <!-- Modeled as slender rod -->
          <ixx>1e-3</ixx>
          <ixy>0</ixy>
          <ixz>0</ixz>
          <iyy>8.333e-2</iyy>
          <iyz>0</iyz>
          <izz>8.333e-2</izz>
        </inertia>
      </inertial>
      <visual name="visual">
        <geometry>
          <mesh>
            <uri>model://random_strawberry_plant/meshes/leaf_stem1.stl</uri>
            <scale> 0.23849589403302113 0.23849589403302113 0.23849589403302113</scale>
          </mesh>
        </geometry>
        <material> <!-- Green -->
          <ambient>0.0 0.5 0.0 1.0</ambient>
          <diffuse>0.0 0.5 0.0 1.0</diffuse>
          <specular>0.1 0.1 0.1 1.0</specular>
        </material>
      </visual>
    </link>

    <link name= leaf_link_3_0 >
      <pose> -0.054810974313814875
             -0.11314474424376905
             0.06834419415138374 0
             0 -3.67450883064503  </pose>
      <inertial>
        <mass>0.018</mass>
        <inertia>
          <ixx>8.82e-6</ixx>
          <ixy>0</ixy>
          <ixz>0</ixz>
          <iyy>8.82e-6</iyy>
          <iyz>0</iyz>
          <izz>8.82e-6</izz>
        </inertia>
      </inertial>
      <visual name="visual">
        <geometry>
          <mesh>
            <uri>model://random_strawberry_plant/meshes/leaf1.dae</uri>
            <scale> 0.6045813127276993 0.6045813127276993 0.6045813127276993</scale>
          </mesh>
        </geometry>
      </visual>
    </link>

    <link name= leaf_link_3_1 >
      <pose> -0.054810974313814875
             -0.11314474424376905
             0.06834419415138374 0
             0 -1.9219492211339029  </pose>
      <inertial>
        <mass>0.018</mass>
        <inertia>
          <ixx>8.82e-6</ixx>
          <ixy>0</ixy>
          <ixz>0</ixz>
          <iyy>8.82e-6</iyy>
          <iyz>0</iyz>
          <izz>8.82e-6</izz>
        </inertia>
      </inertial>
      <visual name="visual">
        <geometry>
          <mesh>
            <uri>model://random_strawberry_plant/meshes/leaf1.dae</uri>
            <scale> 0.6045813127276993 0.6045813127276993 0.6045813127276993</scale>
          </mesh>
        </geometry>
      </visual>
    </link>

    <link name= leaf_link_3_2 >
      <pose> -0.054810974313814875
             -0.11314474424376905
             0.06834419415138374 0
             0 -0.3167705218248069  </pose>
      <inertial>
        <mass>0.018</mass>
        <inertia>
          <ixx>8.82e-6</ixx>
          <ixy>0</ixy>
          <ixz>0</ixz>
          <iyy>8.82e-6</iyy>
          <iyz>0</iyz>
          <izz>8.82e-6</izz>
        </inertia>
      </inertial>
      <visual name="visual">
        <geometry>
          <mesh>
            <uri>model://random_strawberry_plant/meshes/leaf1.dae</uri>
            <scale> 0.6045813127276993 0.6045813127276993 0.6045813127276993</scale>
          </mesh>
        </geometry>
      </visual>
    </link>


    <joint name=leaf_dirt_joint_3 type="revolute">
      <parent>dirt_link</parent>
      <child>leaf_stem_link_3</child>
      <axis>
        <xyz>0 1 0</xyz>
      </axis>
    </joint>

    <link name= leaf_stem_link_4 >
      <pose>0 0 0 0 -0.9501565327077497 -2.9358760446474466 </pose>
      <inertial>
        <mass>1</mass>
        <inertia> <!-- Modeled as slender rod -->
          <ixx>1e-3</ixx>
          <ixy>0</ixy>
          <ixz>0</ixz>
          <iyy>8.333e-2</iyy>
          <iyz>0</iyz>
          <izz>8.333e-2</izz>
        </inertia>
      </inertial>
      <visual name="visual">
        <geometry>
          <mesh>
            <uri>model://random_strawberry_plant/meshes/leaf_stem2.stl</uri>
            <scale> 0.2940763458695784 0.2940763458695784 0.2940763458695784</scale>
          </mesh>
        </geometry>
        <material> <!-- Green -->
          <ambient>0.0 0.5 0.0 1.0</ambient>
          <diffuse>0.0 0.5 0.0 1.0</diffuse>
          <specular>0.1 0.1 0.1 1.0</specular>
        </material>
      </visual>
    </link>

    <link name= leaf_link_4_0 >
      <pose> -0.10044946346699564
             -0.02096064061104015
             0.14353981965423018 0
             0 -4.575518410111249  </pose>
      <inertial>
        <mass>0.018</mass>
        <inertia>
          <ixx>8.82e-6</ixx>
          <ixy>0</ixy>
          <ixz>0</ixz>
          <iyy>8.82e-6</iyy>
          <iyz>0</iyz>
          <izz>8.82e-6</izz>
        </inertia>
      </inertial>
      <visual name="visual">
        <geometry>
          <mesh>
            <uri>model://random_strawberry_plant/meshes/leaf4.dae</uri>
            <scale> 0.30136177571028133 0.30136177571028133 0.30136177571028133</scale>
          </mesh>
        </geometry>
      </visual>
    </link>

    <link name= leaf_link_4_1 >
      <pose> -0.10044946346699564
             -0.02096064061104015
             0.14353981965423018 0
             0 -3.0267064186967945  </pose>
      <inertial>
        <mass>0.018</mass>
        <inertia>
          <ixx>8.82e-6</ixx>
          <ixy>0</ixy>
          <ixz>0</ixz>
          <iyy>8.82e-6</iyy>
          <iyz>0</iyz>
          <izz>8.82e-6</izz>
        </inertia>
      </inertial>
      <visual name="visual">
        <geometry>
          <mesh>
            <uri>model://random_strawberry_plant/meshes/leaf5.dae</uri>
            <scale> 0.30136177571028133 0.30136177571028133 0.30136177571028133</scale>
          </mesh>
        </geometry>
      </visual>
    </link>

    <link name= leaf_link_4_2 >
      <pose> -0.10044946346699564
             -0.02096064061104015
             0.14353981965423018 0
             0 -1.2685680200449974  </pose>
      <inertial>
        <mass>0.018</mass>
        <inertia>
          <ixx>8.82e-6</ixx>
          <ixy>0</ixy>
          <ixz>0</ixz>
          <iyy>8.82e-6</iyy>
          <iyz>0</iyz>
          <izz>8.82e-6</izz>
        </inertia>
      </inertial>
      <visual name="visual">
        <geometry>
          <mesh>
            <uri>model://random_strawberry_plant/meshes/leaf5.dae</uri>
            <scale> 0.30136177571028133 0.30136177571028133 0.30136177571028133</scale>
          </mesh>
        </geometry>
      </visual>
    </link>


    <joint name=leaf_dirt_joint_4 type="revolute">
      <parent>dirt_link</parent>
      <child>leaf_stem_link_4</child>
      <axis>
        <xyz>0 1 0</xyz>
      </axis>
    </joint>

    <link name= leaf_stem_link_5 >
      <pose>0 0 0 0 -1.1084828038877352 -0.6369232017183597 </pose>
      <inertial>
        <mass>1</mass>
        <inertia> <!-- Modeled as slender rod -->
          <ixx>1e-3</ixx>
          <ixy>0</ixy>
          <ixz>0</ixz>
          <iyy>8.333e-2</iyy>
          <iyz>0</iyz>
          <izz>8.333e-2</izz>
        </inertia>
      </inertial>
      <visual name="visual">
        <geometry>
          <mesh>
            <uri>model://random_strawberry_plant/meshes/leaf_stem2.stl</uri>
            <scale> 0.36698817096350506 0.36698817096350506 0.36698817096350506</scale>
          </mesh>
        </geometry>
        <material> <!-- Green -->
          <ambient>0.0 0.5 0.0 1.0</ambient>
          <diffuse>0.0 0.5 0.0 1.0</diffuse>
          <specular>0.1 0.1 0.1 1.0</specular>
        </material>
      </visual>
    </link>

    <link name= leaf_link_5_0 >
      <pose> 0.07895425167314685
             -0.05840817073770855
             0.19707771583712363 0
             0 -2.2622277254442276  </pose>
      <inertial>
        <mass>0.018</mass>
        <inertia>
          <ixx>8.82e-6</ixx>
          <ixy>0</ixy>
          <ixz>0</ixz>
          <iyy>8.82e-6</iyy>
          <iyz>0</iyz>
          <izz>8.82e-6</izz>
        </inertia>
      </inertial>
      <visual name="visual">
        <geometry>
          <mesh>
            <uri>model://random_strawberry_plant/meshes/leaf4.dae</uri>
            <scale> 0.5970063025495251 0.5970063025495251 0.5970063025495251</scale>
          </mesh>
        </geometry>
      </visual>
    </link>

    <link name= leaf_link_5_1 >
      <pose> 0.07895425167314685
             -0.05840817073770855
             0.19707771583712363 0
             0 -0.6010443310501402  </pose>
      <inertial>
        <mass>0.018</mass>
        <inertia>
          <ixx>8.82e-6</ixx>
          <ixy>0</ixy>
          <ixz>0</ixz>
          <iyy>8.82e-6</iyy>
          <iyz>0</iyz>
          <izz>8.82e-6</izz>
        </inertia>
      </inertial>
      <visual name="visual">
        <geometry>
          <mesh>
            <uri>model://random_strawberry_plant/meshes/leaf5.dae</uri>
            <scale> 0.5970063025495251 0.5970063025495251 0.5970063025495251</scale>
          </mesh>
        </geometry>
      </visual>
    </link>

    <link name= leaf_link_5_2 >
      <pose> 0.07895425167314685
             -0.05840817073770855
             0.19707771583712363 0
             0 0.832823228539789  </pose>
      <inertial>
        <mass>0.018</mass>
        <inertia>
          <ixx>8.82e-6</ixx>
          <ixy>0</ixy>
          <ixz>0</ixz>
          <iyy>8.82e-6</iyy>
          <iyz>0</iyz>
          <izz>8.82e-6</izz>
        </inertia>
      </inertial>
      <visual name="visual">
        <geometry>
          <mesh>
            <uri>model://random_strawberry_plant/meshes/leaf2.dae</uri>
            <scale> 0.5970063025495251 0.5970063025495251 0.5970063025495251</scale>
          </mesh>
        </geometry>
      </visual>
    </link>


    <joint name=leaf_dirt_joint_5 type="revolute">
      <parent>dirt_link</parent>
      <child>leaf_stem_link_5</child>
      <axis>
        <xyz>0 1 0</xyz>
      </axis>
    </joint>

    <link name= leaf_stem_link_6 >
      <pose>0 0 0 0 -0.6429743457725329 2.526807067471517 </pose>
      <inertial>
        <mass>1</mass>
        <inertia> <!-- Modeled as slender rod -->
          <ixx>1e-3</ixx>
          <ixy>0</ixy>
          <ixz>0</ixz>
          <iyy>8.333e-2</iyy>
          <iyz>0</iyz>
          <izz>8.333e-2</izz>
        </inertia>
      </inertial>
      <visual name="visual">
        <geometry>
          <mesh>
            <uri>model://random_strawberry_plant/meshes/leaf_stem1.stl</uri>
            <scale> 0.32851200015589266 0.32851200015589266 0.32851200015589266</scale>
          </mesh>
        </geometry>
        <material> <!-- Green -->
          <ambient>0.0 0.5 0.0 1.0</ambient>
          <diffuse>0.0 0.5 0.0 1.0</diffuse>
          <specular>0.1 0.1 0.1 1.0</specular>
        </material>
      </visual>
    </link>

    <link name= leaf_link_6_0 >
      <pose> -0.12886391838763897
             0.09098644531413456
             0.1181812406247074 0
             0 1.0245111706705567  </pose>
      <inertial>
        <mass>0.018</mass>
        <inertia>
          <ixx>8.82e-6</ixx>
          <ixy>0</ixy>
          <ixz>0</ixz>
          <iyy>8.82e-6</iyy>
          <iyz>0</iyz>
          <izz>8.82e-6</izz>
        </inertia>
      </inertial>
      <visual name="visual">
        <geometry>
          <mesh>
            <uri>model://random_strawberry_plant/meshes/leaf4.dae</uri>
            <scale> 0.6788379719534017 0.6788379719534017 0.6788379719534017</scale>
          </mesh>
        </geometry>
      </visual>
    </link>

    <link name= leaf_link_6_1 >
      <pose> -0.12886391838763897
             0.09098644531413456
             0.1181812406247074 0
             0 2.6333706822064467  </pose>
      <inertial>
        <mass>0.018</mass>
        <inertia>
          <ixx>8.82e-6</ixx>
          <ixy>0</ixy>
          <ixz>0</ixz>
          <iyy>8.82e-6</iyy>
          <iyz>0</iyz>
          <izz>8.82e-6</izz>
        </inertia>
      </inertial>
      <visual name="visual">
        <geometry>
          <mesh>
            <uri>model://random_strawberry_plant/meshes/leaf3.dae</uri>
            <scale> 0.6788379719534017 0.6788379719534017 0.6788379719534017</scale>
          </mesh>
        </geometry>
      </visual>
    </link>

    <link name= leaf_link_6_2 >
      <pose> -0.12886391838763897
             0.09098644531413456
             0.1181812406247074 0
             0 4.0893943501322525  </pose>
      <inertial>
        <mass>0.018</mass>
        <inertia>
          <ixx>8.82e-6</ixx>
          <ixy>0</ixy>
          <ixz>0</ixz>
          <iyy>8.82e-6</iyy>
          <iyz>0</iyz>
          <izz>8.82e-6</izz>
        </inertia>
      </inertial>
      <visual name="visual">
        <geometry>
          <mesh>
            <uri>model://random_strawberry_plant/meshes/leaf5.dae</uri>
            <scale> 0.6788379719534017 0.6788379719534017 0.6788379719534017</scale>
          </mesh>
        </geometry>
      </visual>
    </link>


    <joint name=leaf_dirt_joint_6 type="revolute">
      <parent>dirt_link</parent>
      <child>leaf_stem_link_6</child>
      <axis>
        <xyz>0 1 0</xyz>
      </axis>
    </joint>

    <link name= leaf_stem_link_7 >
      <pose>0 0 0 0 -1.0715230451446973 -1.84837611774404 </pose>
      <inertial>
        <mass>1</mass>
        <inertia> <!-- Modeled as slender rod -->
          <ixx>1e-3</ixx>
          <ixy>0</ixy>
          <ixz>0</ixz>
          <iyy>8.333e-2</iyy>
          <iyz>0</iyz>
          <izz>8.333e-2</izz>
        </inertia>
      </inertial>
      <visual name="visual">
        <geometry>
          <mesh>
            <uri>model://random_strawberry_plant/meshes/leaf_stem2.stl</uri>
            <scale> 0.17478117474583785 0.17478117474583785 0.17478117474583785</scale>
          </mesh>
        </geometry>
        <material> <!-- Green -->
          <ambient>0.0 0.5 0.0 1.0</ambient>
          <diffuse>0.0 0.5 0.0 1.0</diffuse>
          <specular>0.1 0.1 0.1 1.0</specular>
        </material>
      </visual>
    </link>

    <link name= leaf_link_7_0 >
      <pose> -0.01375894694064022
             -0.048287882104715026
             0.09206745938342399 0
             0 -3.329457094784024  </pose>
      <inertial>
        <mass>0.018</mass>
        <inertia>
          <ixx>8.82e-6</ixx>
          <ixy>0</ixy>
          <ixz>0</ixz>
          <iyy>8.82e-6</iyy>
          <iyz>0</iyz>
          <izz>8.82e-6</izz>
        </inertia>
      </inertial>
      <visual name="visual">
        <geometry>
          <mesh>
            <uri>model://random_strawberry_plant/meshes/leaf4.dae</uri>
            <scale> 0.6198932199066706 0.6198932199066706 0.6198932199066706</scale>
          </mesh>
        </geometry>
      </visual>
    </link>

    <link name= leaf_link_7_1 >
      <pose> -0.01375894694064022
             -0.048287882104715026
             0.09206745938342399 0
             0 -1.8102800141609097  </pose>
      <inertial>
        <mass>0.018</mass>
        <inertia>
          <ixx>8.82e-6</ixx>
          <ixy>0</ixy>
          <ixz>0</ixz>
          <iyy>8.82e-6</iyy>
          <iyz>0</iyz>
          <izz>8.82e-6</izz>
        </inertia>
      </inertial>
      <visual name="visual">
        <geometry>
          <mesh>
            <uri>model://random_strawberry_plant/meshes/leaf2.dae</uri>
            <scale> 0.6198932199066706 0.6198932199066706 0.6198932199066706</scale>
          </mesh>
        </geometry>
      </visual>
    </link>

    <link name= leaf_link_7_2 >
      <pose> -0.01375894694064022
             -0.048287882104715026
             0.09206745938342399 0
             0 -0.27452307488094374  </pose>
      <inertial>
        <mass>0.018</mass>
        <inertia>
          <ixx>8.82e-6</ixx>
          <ixy>0</ixy>
          <ixz>0</ixz>
          <iyy>8.82e-6</iyy>
          <iyz>0</iyz>
          <izz>8.82e-6</izz>
        </inertia>
      </inertial>
      <visual name="visual">
        <geometry>
          <mesh>
            <uri>model://random_strawberry_plant/meshes/leaf1.dae</uri>
            <scale> 0.6198932199066706 0.6198932199066706 0.6198932199066706</scale>
          </mesh>
        </geometry>
      </visual>
    </link>


    <joint name=leaf_dirt_joint_7 type="revolute">
      <parent>dirt_link</parent>
      <child>leaf_stem_link_7</child>
      <axis>
        <xyz>0 1 0</xyz>
      </axis>
    </joint>

    <link name= leaf_stem_link_8 >
      <pose>0 0 0 0 -0.3200551412288214 1.013612608335925 </pose>
      <inertial>
        <mass>1</mass>
        <inertia> <!-- Modeled as slender rod -->
          <ixx>1e-3</ixx>
          <ixy>0</ixy>
          <ixz>0</ixz>
          <iyy>8.333e-2</iyy>
          <iyz>0</iyz>
          <izz>8.333e-2</izz>
        </inertia>
      </inertial>
      <visual name="visual">
        <geometry>
          <mesh>
            <uri>model://random_strawberry_plant/meshes/leaf_stem1.stl</uri>
            <scale> 0.32676993834136137 0.32676993834136137 0.32676993834136137</scale>
          </mesh>
        </geometry>
        <material> <!-- Green -->
          <ambient>0.0 0.5 0.0 1.0</ambient>
          <diffuse>0.0 0.5 0.0 1.0</diffuse>
          <specular>0.1 0.1 0.1 1.0</specular>
        </material>
      </visual>
    </link>

    <link name= leaf_link_8_0 >
      <pose> 0.09841224435596337
             0.15795666811574666
             0.061684799553019386 0
             0 -0.6886854565354414  </pose>
      <inertial>
        <mass>0.018</mass>
        <inertia>
          <ixx>8.82e-6</ixx>
          <ixy>0</ixy>
          <ixz>0</ixz>
          <iyy>8.82e-6</iyy>
          <iyz>0</iyz>
          <izz>8.82e-6</izz>
        </inertia>
      </inertial>
      <visual name="visual">
        <geometry>
          <mesh>
            <uri>model://random_strawberry_plant/meshes/leaf2.dae</uri>
            <scale> 0.5503118245826185 0.5503118245826185 0.5503118245826185</scale>
          </mesh>
        </geometry>
      </visual>
    </link>

    <link name= leaf_link_8_1 >
      <pose> 0.09841224435596337
             0.15795666811574666
             0.061684799553019386 0
             0 0.8744525746638081  </pose>
      <inertial>
        <mass>0.018</mass>
        <inertia>
          <ixx>8.82e-6</ixx>
          <ixy>0</ixy>
          <ixz>0</ixz>
          <iyy>8.82e-6</iyy>
          <iyz>0</iyz>
          <izz>8.82e-6</izz>
        </inertia>
      </inertial>
      <visual name="visual">
        <geometry>
          <mesh>
            <uri>model://random_strawberry_plant/meshes/leaf1.dae</uri>
            <scale> 0.5503118245826185 0.5503118245826185 0.5503118245826185</scale>
          </mesh>
        </geometry>
      </visual>
    </link>

    <link name= leaf_link_8_2 >
      <pose> 0.09841224435596337
             0.15795666811574666
             0.061684799553019386 0
             0 2.6314233387352832  </pose>
      <inertial>
        <mass>0.018</mass>
        <inertia>
          <ixx>8.82e-6</ixx>
          <ixy>0</ixy>
          <ixz>0</ixz>
          <iyy>8.82e-6</iyy>
          <iyz>0</iyz>
          <izz>8.82e-6</izz>
        </inertia>
      </inertial>
      <visual name="visual">
        <geometry>
          <mesh>
            <uri>model://random_strawberry_plant/meshes/leaf3.dae</uri>
            <scale> 0.5503118245826185 0.5503118245826185 0.5503118245826185</scale>
          </mesh>
        </geometry>
      </visual>
    </link>


    <joint name=leaf_dirt_joint_8 type="revolute">
      <parent>dirt_link</parent>
      <child>leaf_stem_link_8</child>
      <axis>
        <xyz>0 1 0</xyz>
      </axis>
    </joint>

    <link name= leaf_stem_link_9 >
      <pose>0 0 0 0 -0.3883182199402252 -2.6144592113616367 </pose>
      <inertial>
        <mass>1</mass>
        <inertia> <!-- Modeled as slender rod -->
          <ixx>1e-3</ixx>
          <ixy>0</ixy>
          <ixz>0</ixz>
          <iyy>8.333e-2</iyy>
          <iyz>0</iyz>
          <izz>8.333e-2</izz>
        </inertia>
      </inertial>
      <visual name="visual">
        <geometry>
          <mesh>
            <uri>model://random_strawberry_plant/meshes/leaf_stem1.stl</uri>
            <scale> 0.24874441422713697 0.24874441422713697 0.24874441422713697</scale>
          </mesh>
        </geometry>
        <material> <!-- Green -->
          <ambient>0.0 0.5 0.0 1.0</ambient>
          <diffuse>0.0 0.5 0.0 1.0</diffuse>
          <specular>0.1 0.1 0.1 1.0</specular>
        </material>
      </visual>
    </link>

    <link name= leaf_link_9_0 >
      <pose> -0.1193833770633276
             -0.0694898183740265
             0.0565096144263318 0
             0 -4.1422387760167325  </pose>
      <inertial>
        <mass>0.018</mass>
        <inertia>
          <ixx>8.82e-6</ixx>
          <ixy>0</ixy>
          <ixz>0</ixz>
          <iyy>8.82e-6</iyy>
          <iyz>0</iyz>
          <izz>8.82e-6</izz>
        </inertia>
      </inertial>
      <visual name="visual">
        <geometry>
          <mesh>
            <uri>model://random_strawberry_plant/meshes/leaf2.dae</uri>
            <scale> 0.5114060222581749 0.5114060222581749 0.5114060222581749</scale>
          </mesh>
        </geometry>
      </visual>
    </link>

    <link name= leaf_link_9_1 >
      <pose> -0.1193833770633276
             -0.0694898183740265
             0.0565096144263318 0
             0 -2.5589588200929323  </pose>
      <inertial>
        <mass>0.018</mass>
        <inertia>
          <ixx>8.82e-6</ixx>
          <ixy>0</ixy>
          <ixz>0</ixz>
          <iyy>8.82e-6</iyy>
          <iyz>0</iyz>
          <izz>8.82e-6</izz>
        </inertia>
      </inertial>
      <visual name="visual">
        <geometry>
          <mesh>
            <uri>model://random_strawberry_plant/meshes/leaf1.dae</uri>
            <scale> 0.5114060222581749 0.5114060222581749 0.5114060222581749</scale>
          </mesh>
        </geometry>
      </visual>
    </link>

    <link name= leaf_link_9_2 >
      <pose> -0.1193833770633276
             -0.0694898183740265
             0.0565096144263318 0
             0 -1.0883341157866875  </pose>
      <inertial>
        <mass>0.018</mass>
        <inertia>
          <ixx>8.82e-6</ixx>
          <ixy>0</ixy>
          <ixz>0</ixz>
          <iyy>8.82e-6</iyy>
          <iyz>0</iyz>
          <izz>8.82e-6</izz>
        </inertia>
      </inertial>
      <visual name="visual">
        <geometry>
          <mesh>
            <uri>model://random_strawberry_plant/meshes/leaf2.dae</uri>
            <scale> 0.5114060222581749 0.5114060222581749 0.5114060222581749</scale>
          </mesh>
        </geometry>
      </visual>
    </link>


    <joint name=leaf_dirt_joint_9 type="revolute">
      <parent>dirt_link</parent>
      <child>leaf_stem_link_9</child>
      <axis>
        <xyz>0 1 0</xyz>
      </axis>
    </joint>

    <link name= leaf_stem_link_10 >
      <pose>0 0 0 0 -0.8721516785752499 -1.3106201297003166 </pose>
      <inertial>
        <mass>1</mass>
        <inertia> <!-- Modeled as slender rod -->
          <ixx>1e-3</ixx>
          <ixy>0</ixy>
          <ixz>0</ixz>
          <iyy>8.333e-2</iyy>
          <iyz>0</iyz>
          <izz>8.333e-2</izz>
        </inertia>
      </inertial>
      <visual name="visual">
        <geometry>
          <mesh>
            <uri>model://random_strawberry_plant/meshes/leaf_stem2.stl</uri>
            <scale> 0.298029871739489 0.298029871739489 0.298029871739489</scale>
          </mesh>
        </geometry>
        <material> <!-- Green -->
          <ambient>0.0 0.5 0.0 1.0</ambient>
          <diffuse>0.0 0.5 0.0 1.0</diffuse>
          <specular>0.1 0.1 0.1 1.0</specular>
        </material>
      </visual>
    </link>

    <link name= leaf_link_10_0 >
      <pose> 0.029586981821107233
             -0.11114142120192604
             0.13692349908468524 0
             0 -3.021645453351236  </pose>
      <inertial>
        <mass>0.018</mass>
        <inertia>
          <ixx>8.82e-6</ixx>
          <ixy>0</ixy>
          <ixz>0</ixz>
          <iyy>8.82e-6</iyy>
          <iyz>0</iyz>
          <izz>8.82e-6</izz>
        </inertia>
      </inertial>
      <visual name="visual">
        <geometry>
          <mesh>
            <uri>model://random_strawberry_plant/meshes/leaf1.dae</uri>
            <scale> 0.6062909838084345 0.6062909838084345 0.6062909838084345</scale>
          </mesh>
        </geometry>
      </visual>
    </link>

    <link name= leaf_link_10_1 >
      <pose> 0.029586981821107233
             -0.11114142120192604
             0.13692349908468524 0
             0 -1.0507942632198342  </pose>
      <inertial>
        <mass>0.018</mass>
        <inertia>
          <ixx>8.82e-6</ixx>
          <ixy>0</ixy>
          <ixz>0</ixz>
          <iyy>8.82e-6</iyy>
          <iyz>0</iyz>
          <izz>8.82e-6</izz>
        </inertia>
      </inertial>
      <visual name="visual">
        <geometry>
          <mesh>
            <uri>model://random_strawberry_plant/meshes/leaf1.dae</uri>
            <scale> 0.6062909838084345 0.6062909838084345 0.6062909838084345</scale>
          </mesh>
        </geometry>
      </visual>
    </link>

    <link name= leaf_link_10_2 >
      <pose> 0.029586981821107233
             -0.11114142120192604
             0.13692349908468524 0
             0 0.250063500810638  </pose>
      <inertial>
        <mass>0.018</mass>
        <inertia>
          <ixx>8.82e-6</ixx>
          <ixy>0</ixy>
          <ixz>0</ixz>
          <iyy>8.82e-6</iyy>
          <iyz>0</iyz>
          <izz>8.82e-6</izz>
        </inertia>
      </inertial>
      <visual name="visual">
        <geometry>
          <mesh>
            <uri>model://random_strawberry_plant/meshes/leaf2.dae</uri>
            <scale> 0.6062909838084345 0.6062909838084345 0.6062909838084345</scale>
          </mesh>
        </geometry>
      </visual>
    </link>


    <joint name=leaf_dirt_joint_10 type="revolute">
      <parent>dirt_link</parent>
      <child>leaf_stem_link_10</child>
      <axis>
        <xyz>0 1 0</xyz>
      </axis>
    </joint>

    <link name= leaf_stem_link_11 >
      <pose>0 0 0 0 -1.0439800459873145 2.2478350490045242 </pose>
      <inertial>
        <mass>1</mass>
        <inertia> <!-- Modeled as slender rod -->
          <ixx>1e-3</ixx>
          <ixy>0</ixy>
          <ixz>0</ixz>
          <iyy>8.333e-2</iyy>
          <iyz>0</iyz>
          <izz>8.333e-2</izz>
        </inertia>
      </inertial>
      <visual name="visual">
        <geometry>
          <mesh>
            <uri>model://random_strawberry_plant/meshes/leaf_stem2.stl</uri>
            <scale> 0.29841483254404017 0.29841483254404017 0.29841483254404017</scale>
          </mesh>
        </geometry>
        <material> <!-- Green -->
          <ambient>0.0 0.5 0.0 1.0</ambient>
          <diffuse>0.0 0.5 0.0 1.0</diffuse>
          <specular>0.1 0.1 0.1 1.0</specular>
        </material>
      </visual>
    </link>

    <link name= leaf_link_11_0 >
      <pose> -0.05639823281832793
             0.07016666526062443
             0.1547720480022044 0
             0 0.591685731150916  </pose>
      <inertial>
        <mass>0.018</mass>
        <inertia>
          <ixx>8.82e-6</ixx>
          <ixy>0</ixy>
          <ixz>0</ixz>
          <iyy>8.82e-6</iyy>
          <iyz>0</iyz>
          <izz>8.82e-6</izz>
        </inertia>
      </inertial>
      <visual name="visual">
        <geometry>
          <mesh>
            <uri>model://random_strawberry_plant/meshes/leaf1.dae</uri>
            <scale> 0.7456166393248976 0.7456166393248976 0.7456166393248976</scale>
          </mesh>
        </geometry>
      </visual>
    </link>

    <link name= leaf_link_11_1 >
      <pose> -0.05639823281832793
             0.07016666526062443
             0.1547720480022044 0
             0 2.2044765619832125  </pose>
      <inertial>
        <mass>0.018</mass>
        <inertia>
          <ixx>8.82e-6</ixx>
          <ixy>0</ixy>
          <ixz>0</ixz>
          <iyy>8.82e-6</iyy>
          <iyz>0</iyz>
          <izz>8.82e-6</izz>
        </inertia>
      </inertial>
      <visual name="visual">
        <geometry>
          <mesh>
            <uri>model://random_strawberry_plant/meshes/leaf4.dae</uri>
            <scale> 0.7456166393248976 0.7456166393248976 0.7456166393248976</scale>
          </mesh>
        </geometry>
      </visual>
    </link>

    <link name= leaf_link_11_2 >
      <pose> -0.05639823281832793
             0.07016666526062443
             0.1547720480022044 0
             0 3.7310587625470815  </pose>
      <inertial>
        <mass>0.018</mass>
        <inertia>
          <ixx>8.82e-6</ixx>
          <ixy>0</ixy>
          <ixz>0</ixz>
          <iyy>8.82e-6</iyy>
          <iyz>0</iyz>
          <izz>8.82e-6</izz>
        </inertia>
      </inertial>
      <visual name="visual">
        <geometry>
          <mesh>
            <uri>model://random_strawberry_plant/meshes/leaf3.dae</uri>
            <scale> 0.7456166393248976 0.7456166393248976 0.7456166393248976</scale>
          </mesh>
        </geometry>
      </visual>
    </link>


    <joint name=leaf_dirt_joint_11 type="revolute">
      <parent>dirt_link</parent>
      <child>leaf_stem_link_11</child>
      <axis>
        <xyz>0 1 0</xyz>
      </axis>
    </joint>

    <link name= leaf_stem_link_12 >
      <pose>0 0 0 0 -0.5996507170122732 -1.7107910484880213 </pose>
      <inertial>
        <mass>1</mass>
        <inertia> <!-- Modeled as slender rod -->
          <ixx>1e-3</ixx>
          <ixy>0</ixy>
          <ixz>0</ixz>
          <iyy>8.333e-2</iyy>
          <iyz>0</iyz>
          <izz>8.333e-2</izz>
        </inertia>
      </inertial>
      <visual name="visual">
        <geometry>
          <mesh>
            <uri>model://random_strawberry_plant/meshes/leaf_stem1.stl</uri>
            <scale> 0.23797975031876442 0.23797975031876442 0.23797975031876442</scale>
          </mesh>
        </geometry>
        <material> <!-- Green -->
          <ambient>0.0 0.5 0.0 1.0</ambient>
          <diffuse>0.0 0.5 0.0 1.0</diffuse>
          <specular>0.1 0.1 0.1 1.0</specular>
        </material>
      </visual>
    </link>

    <link name= leaf_link_12_0 >
      <pose> -0.01644817527948825
             -0.11672283865640877
             0.0805829177196167 0
             0 -3.2305255721216337  </pose>
      <inertial>
        <mass>0.018</mass>
        <inertia>
          <ixx>8.82e-6</ixx>
          <ixy>0</ixy>
          <ixz>0</ixz>
          <iyy>8.82e-6</iyy>
          <iyz>0</iyz>
          <izz>8.82e-6</izz>
        </inertia>
      </inertial>
      <visual name="visual">
        <geometry>
          <mesh>
            <uri>model://random_strawberry_plant/meshes/leaf5.dae</uri>
            <scale> 0.5660856841460996 0.5660856841460996 0.5660856841460996</scale>
          </mesh>
        </geometry>
      </visual>
    </link>

    <link name= leaf_link_12_1 >
      <pose> -0.01644817527948825
             -0.11672283865640877
             0.0805829177196167 0
             0 -1.7332302831377742  </pose>
      <inertial>
        <mass>0.018</mass>
        <inertia>
          <ixx>8.82e-6</ixx>
          <ixy>0</ixy>
          <ixz>0</ixz>
          <iyy>8.82e-6</iyy>
          <iyz>0</iyz>
          <izz>8.82e-6</izz>
        </inertia>
      </inertial>
      <visual name="visual">
        <geometry>
          <mesh>
            <uri>model://random_strawberry_plant/meshes/leaf5.dae</uri>
            <scale> 0.5660856841460996 0.5660856841460996 0.5660856841460996</scale>
          </mesh>
        </geometry>
      </visual>
    </link>

    <link name= leaf_link_12_2 >
      <pose> -0.01644817527948825
             -0.11672283865640877
             0.0805829177196167 0
             0 -0.0898150733300993  </pose>
      <inertial>
        <mass>0.018</mass>
        <inertia>
          <ixx>8.82e-6</ixx>
          <ixy>0</ixy>
          <ixz>0</ixz>
          <iyy>8.82e-6</iyy>
          <iyz>0</iyz>
          <izz>8.82e-6</izz>
        </inertia>
      </inertial>
      <visual name="visual">
        <geometry>
          <mesh>
            <uri>model://random_strawberry_plant/meshes/leaf3.dae</uri>
            <scale> 0.5660856841460996 0.5660856841460996 0.5660856841460996</scale>
          </mesh>
        </geometry>
      </visual>
    </link>


    <joint name=leaf_dirt_joint_12 type="revolute">
      <parent>dirt_link</parent>
      <child>leaf_stem_link_12</child>
      <axis>
        <xyz>0 1 0</xyz>
      </axis>
    </joint>

    <link name= leaf_stem_link_13 >
      <pose>0 0 0 0 -0.4752124891888788 0.5670608463876983 </pose>
      <inertial>
        <mass>1</mass>
        <inertia> <!-- Modeled as slender rod -->
          <ixx>1e-3</ixx>
          <ixy>0</ixy>
          <ixz>0</ixz>
          <iyy>8.333e-2</iyy>
          <iyz>0</iyz>
          <izz>8.333e-2</izz>
        </inertia>
      </inertial>
      <visual name="visual">
        <geometry>
          <mesh>
            <uri>model://random_strawberry_plant/meshes/leaf_stem1.stl</uri>
            <scale> 0.2573792592575402 0.2573792592575402 0.2573792592575402</scale>
          </mesh>
        </geometry>
        <material> <!-- Green -->
          <ambient>0.0 0.5 0.0 1.0</ambient>
          <diffuse>0.0 0.5 0.0 1.0</diffuse>
          <specular>0.1 0.1 0.1 1.0</specular>
        </material>
      </visual>
    </link>

    <link name= leaf_link_13_0 >
      <pose> 0.1158240116261192
             0.07376016589495527
             0.07065483828108951 0
             0 -0.8186035766774107  </pose>
      <inertial>
        <mass>0.018</mass>
        <inertia>
          <ixx>8.82e-6</ixx>
          <ixy>0</ixy>
          <ixz>0</ixz>
          <iyy>8.82e-6</iyy>
          <iyz>0</iyz>
          <izz>8.82e-6</izz>
        </inertia>
      </inertial>
      <visual name="visual">
        <geometry>
          <mesh>
            <uri>model://random_strawberry_plant/meshes/leaf5.dae</uri>
            <scale> 0.5130359999466103 0.5130359999466103 0.5130359999466103</scale>
          </mesh>
        </geometry>
      </visual>
    </link>

    <link name= leaf_link_13_1 >
      <pose> 0.1158240116261192
             0.07376016589495527
             0.07065483828108951 0
             0 0.6282924329266574  </pose>
      <inertial>
        <mass>0.018</mass>
        <inertia>
          <ixx>8.82e-6</ixx>
          <ixy>0</ixy>
          <ixz>0</ixz>
          <iyy>8.82e-6</iyy>
          <iyz>0</iyz>
          <izz>8.82e-6</izz>
        </inertia>
      </inertial>
      <visual name="visual">
        <geometry>
          <mesh>
            <uri>model://random_strawberry_plant/meshes/leaf5.dae</uri>
            <scale> 0.5130359999466103 0.5130359999466103 0.5130359999466103</scale>
          </mesh>
        </geometry>
      </visual>
    </link>

    <link name= leaf_link_13_2 >
      <pose> 0.1158240116261192
             0.07376016589495527
             0.07065483828108951 0
             0 2.050634415435204  </pose>
      <inertial>
        <mass>0.018</mass>
        <inertia>
          <ixx>8.82e-6</ixx>
          <ixy>0</ixy>
          <ixz>0</ixz>
          <iyy>8.82e-6</iyy>
          <iyz>0</iyz>
          <izz>8.82e-6</izz>
        </inertia>
      </inertial>
      <visual name="visual">
        <geometry>
          <mesh>
            <uri>model://random_strawberry_plant/meshes/leaf1.dae</uri>
            <scale> 0.5130359999466103 0.5130359999466103 0.5130359999466103</scale>
          </mesh>
        </geometry>
      </visual>
    </link>


    <joint name=leaf_dirt_joint_13 type="revolute">
      <parent>dirt_link</parent>
      <child>leaf_stem_link_13</child>
      <axis>
        <xyz>0 1 0</xyz>
      </axis>
    </joint>

    <link name= leaf_stem_link_14 >
      <pose>0 0 0 0 -1.2134624572311141 2.7464306450696157 </pose>
      <inertial>
        <mass>1</mass>
        <inertia> <!-- Modeled as slender rod -->
          <ixx>1e-3</ixx>
          <ixy>0</ixy>
          <ixz>0</ixz>
          <iyy>8.333e-2</iyy>
          <iyz>0</iyz>
          <izz>8.333e-2</izz>
        </inertia>
      </inertial>
      <visual name="visual">
        <geometry>
          <mesh>
            <uri>model://random_strawberry_plant/meshes/leaf_stem2.stl</uri>
            <scale> 0.27057113078422595 0.27057113078422595 0.27057113078422595</scale>
          </mesh>
        </geometry>
        <material> <!-- Green -->
          <ambient>0.0 0.5 0.0 1.0</ambient>
          <diffuse>0.0 0.5 0.0 1.0</diffuse>
          <specular>0.1 0.1 0.1 1.0</specular>
        </material>
      </visual>
    </link>

    <link name= leaf_link_14_0 >
      <pose> -0.05240776570094594
             0.02185938458140944
             0.15208793066165535 0
             0 1.1178672399761567  </pose>
      <inertial>
        <mass>0.018</mass>
        <inertia>
          <ixx>8.82e-6</ixx>
          <ixy>0</ixy>
          <ixz>0</ixz>
          <iyy>8.82e-6</iyy>
          <iyz>0</iyz>
          <izz>8.82e-6</izz>
        </inertia>
      </inertial>
      <visual name="visual">
        <geometry>
          <mesh>
            <uri>model://random_strawberry_plant/meshes/leaf4.dae</uri>
            <scale> 0.6313730486965123 0.6313730486965123 0.6313730486965123</scale>
          </mesh>
        </geometry>
      </visual>
    </link>

    <link name= leaf_link_14_1 >
      <pose> -0.05240776570094594
             0.02185938458140944
             0.15208793066165535 0
             0 2.800363641722689  </pose>
      <inertial>
        <mass>0.018</mass>
        <inertia>
          <ixx>8.82e-6</ixx>
          <ixy>0</ixy>
          <ixz>0</ixz>
          <iyy>8.82e-6</iyy>
          <iyz>0</iyz>
          <izz>8.82e-6</izz>
        </inertia>
      </inertial>
      <visual name="visual">
        <geometry>
          <mesh>
            <uri>model://random_strawberry_plant/meshes/leaf1.dae</uri>
            <scale> 0.6313730486965123 0.6313730486965123 0.6313730486965123</scale>
          </mesh>
        </geometry>
      </visual>
    </link>

    <link name= leaf_link_14_2 >
      <pose> -0.05240776570094594
             0.02185938458140944
             0.15208793066165535 0
             0 4.220626365873701  </pose>
      <inertial>
        <mass>0.018</mass>
        <inertia>
          <ixx>8.82e-6</ixx>
          <ixy>0</ixy>
          <ixz>0</ixz>
          <iyy>8.82e-6</iyy>
          <iyz>0</iyz>
          <izz>8.82e-6</izz>
        </inertia>
      </inertial>
      <visual name="visual">
        <geometry>
          <mesh>
            <uri>model://random_strawberry_plant/meshes/leaf5.dae</uri>
            <scale> 0.6313730486965123 0.6313730486965123 0.6313730486965123</scale>
          </mesh>
        </geometry>
      </visual>
    </link>


    <joint name=leaf_dirt_joint_14 type="revolute">
      <parent>dirt_link</parent>
      <child>leaf_stem_link_14</child>
      <axis>
        <xyz>0 1 0</xyz>
      </axis>
    </joint>

    <link name= leaf_stem_link_15 >
      <pose>0 0 0 0 -0.3706066647679592 -2.6810928858327396 </pose>
      <inertial>
        <mass>1</mass>
        <inertia> <!-- Modeled as slender rod -->
          <ixx>1e-3</ixx>
          <ixy>0</ixy>
          <ixz>0</ixz>
          <iyy>8.333e-2</iyy>
          <iyz>0</iyz>
          <izz>8.333e-2</izz>
        </inertia>
      </inertial>
      <visual name="visual">
        <geometry>
          <mesh>
            <uri>model://random_strawberry_plant/meshes/leaf_stem1.stl</uri>
            <scale> 0.37776727580574676 0.37776727580574676 0.37776727580574676</scale>
          </mesh>
        </geometry>
        <material> <!-- Green -->
          <ambient>0.0 0.5 0.0 1.0</ambient>
          <diffuse>0.0 0.5 0.0 1.0</diffuse>
          <specular>0.1 0.1 0.1 1.0</specular>
        </material>
      </visual>
    </link>

    <link name= leaf_link_15_0 >
      <pose> -0.1892638090193456
             -0.0938883568088405
             0.08209207228663894 0
             0 -4.1621650980070415  </pose>
      <inertial>
        <mass>0.018</mass>
        <inertia>
          <ixx>8.82e-6</ixx>
          <ixy>0</ixy>
          <ixz>0</ixz>
          <iyy>8.82e-6</iyy>
          <iyz>0</iyz>
          <izz>8.82e-6</izz>
        </inertia>
      </inertial>
      <visual name="visual">
        <geometry>
          <mesh>
            <uri>model://random_strawberry_plant/meshes/leaf3.dae</uri>
            <scale> 0.6990633607226373 0.6990633607226373 0.6990633607226373</scale>
          </mesh>
        </geometry>
      </visual>
    </link>

    <link name= leaf_link_15_1 >
      <pose> -0.1892638090193456
             -0.0938883568088405
             0.08209207228663894 0
             0 -2.6242793193403293  </pose>
      <inertial>
        <mass>0.018</mass>
        <inertia>
          <ixx>8.82e-6</ixx>
          <ixy>0</ixy>
          <ixz>0</ixz>
          <iyy>8.82e-6</iyy>
          <iyz>0</iyz>
          <izz>8.82e-6</izz>
        </inertia>
      </inertial>
      <visual name="visual">
        <geometry>
          <mesh>
            <uri>model://random_strawberry_plant/meshes/leaf3.dae</uri>
            <scale> 0.6990633607226373 0.6990633607226373 0.6990633607226373</scale>
          </mesh>
        </geometry>
      </visual>
    </link>

    <link name= leaf_link_15_2 >
      <pose> -0.1892638090193456
             -0.0938883568088405
             0.08209207228663894 0
             0 -1.1803849663431214  </pose>
      <inertial>
        <mass>0.018</mass>
        <inertia>
          <ixx>8.82e-6</ixx>
          <ixy>0</ixy>
          <ixz>0</ixz>
          <iyy>8.82e-6</iyy>
          <iyz>0</iyz>
          <izz>8.82e-6</izz>
        </inertia>
      </inertial>
      <visual name="visual">
        <geometry>
          <mesh>
            <uri>model://random_strawberry_plant/meshes/leaf2.dae</uri>
            <scale> 0.6990633607226373 0.6990633607226373 0.6990633607226373</scale>
          </mesh>
        </geometry>
      </visual>
    </link>


    <joint name=leaf_dirt_joint_15 type="revolute">
      <parent>dirt_link</parent>
      <child>leaf_stem_link_15</child>
      <axis>
        <xyz>0 1 0</xyz>
      </axis>
    </joint>

    <link name= leaf_stem_link_16 >
      <pose>0 0 0 0 -1.234959781768946 0.27308885233672076 </pose>
      <inertial>
        <mass>1</mass>
        <inertia> <!-- Modeled as slender rod -->
          <ixx>1e-3</ixx>
          <ixy>0</ixy>
          <ixz>0</ixz>
          <iyy>8.333e-2</iyy>
          <iyz>0</iyz>
          <izz>8.333e-2</izz>
        </inertia>
      </inertial>
      <visual name="visual">
        <geometry>
          <mesh>
            <uri>model://random_strawberry_plant/meshes/leaf_stem2.stl</uri>
            <scale> 0.26026277272846554 0.26026277272846554 0.26026277272846554</scale>
          </mesh>
        </geometry>
        <material> <!-- Green -->
          <ambient>0.0 0.5 0.0 1.0</ambient>
          <diffuse>0.0 0.5 0.0 1.0</diffuse>
          <specular>0.1 0.1 0.1 1.0</specular>
        </material>
      </visual>
    </link>

    <link name= leaf_link_16_0 >
      <pose> 0.049556076961404204
             0.013879984923311144
             0.14743390779367965 0
             0 -1.2652514522106617  </pose>
      <inertial>
        <mass>0.018</mass>
        <inertia>
          <ixx>8.82e-6</ixx>
          <ixy>0</ixy>
          <ixz>0</ixz>
          <iyy>8.82e-6</iyy>
          <iyz>0</iyz>
          <izz>8.82e-6</izz>
        </inertia>
      </inertial>
      <visual name="visual">
        <geometry>
          <mesh>
            <uri>model://random_strawberry_plant/meshes/leaf4.dae</uri>
            <scale> 0.5547438681053365 0.5547438681053365 0.5547438681053365</scale>
          </mesh>
        </geometry>
      </visual>
    </link>

    <link name= leaf_link_16_1 >
      <pose> 0.049556076961404204
             0.013879984923311144
             0.14743390779367965 0
             0 0.23913765961305353  </pose>
      <inertial>
        <mass>0.018</mass>
        <inertia>
          <ixx>8.82e-6</ixx>
          <ixy>0</ixy>
          <ixz>0</ixz>
          <iyy>8.82e-6</iyy>
          <iyz>0</iyz>
          <izz>8.82e-6</izz>
        </inertia>
      </inertial>
      <visual name="visual">
        <geometry>
          <mesh>
            <uri>model://random_strawberry_plant/meshes/leaf5.dae</uri>
            <scale> 0.5547438681053365 0.5547438681053365 0.5547438681053365</scale>
          </mesh>
        </geometry>
      </visual>
    </link>

    <link name= leaf_link_16_2 >
      <pose> 0.049556076961404204
             0.013879984923311144
             0.14743390779367965 0
             0 1.860061838486471  </pose>
      <inertial>
        <mass>0.018</mass>
        <inertia>
          <ixx>8.82e-6</ixx>
          <ixy>0</ixy>
          <ixz>0</ixz>
          <iyy>8.82e-6</iyy>
          <iyz>0</iyz>
          <izz>8.82e-6</izz>
        </inertia>
      </inertial>
      <visual name="visual">
        <geometry>
          <mesh>
            <uri>model://random_strawberry_plant/meshes/leaf5.dae</uri>
            <scale> 0.5547438681053365 0.5547438681053365 0.5547438681053365</scale>
          </mesh>
        </geometry>
      </visual>
    </link>


    <joint name=leaf_dirt_joint_16 type="revolute">
      <parent>dirt_link</parent>
      <child>leaf_stem_link_16</child>
      <axis>
        <xyz>0 1 0</xyz>
      </axis>
    </joint>

    <link name= leaf_stem_link_17 >
      <pose>0 0 0 0 -0.9792628153071783 0.700760515798474 </pose>
      <inertial>
        <mass>1</mass>
        <inertia> <!-- Modeled as slender rod -->
          <ixx>1e-3</ixx>
          <ixy>0</ixy>
          <ixz>0</ixz>
          <iyy>8.333e-2</iyy>
          <iyz>0</iyz>
          <izz>8.333e-2</izz>
        </inertia>
      </inertial>
      <visual name="visual">
        <geometry>
          <mesh>
            <uri>model://random_strawberry_plant/meshes/leaf_stem2.stl</uri>
            <scale> 0.38076005443179267 0.38076005443179267 0.38076005443179267</scale>
          </mesh>
        </geometry>
        <material> <!-- Green -->
          <ambient>0.0 0.5 0.0 1.0</ambient>
          <diffuse>0.0 0.5 0.0 1.0</diffuse>
          <specular>0.1 0.1 0.1 1.0</specular>
        </material>
      </visual>
    </link>

    <link name= leaf_link_17_0 >
      <pose> 0.09737462220438405
             0.08214418719708619
             0.18963827229388103 0
             0 -0.891352846190195  </pose>
      <inertial>
        <mass>0.018</mass>
        <inertia>
          <ixx>8.82e-6</ixx>
          <ixy>0</ixy>
          <ixz>0</ixz>
          <iyy>8.82e-6</iyy>
          <iyz>0</iyz>
          <izz>8.82e-6</izz>
        </inertia>
      </inertial>
      <visual name="visual">
        <geometry>
          <mesh>
            <uri>model://random_strawberry_plant/meshes/leaf5.dae</uri>
            <scale> 0.6203192745348903 0.6203192745348903 0.6203192745348903</scale>
          </mesh>
        </geometry>
      </visual>
    </link>

    <link name= leaf_link_17_1 >
      <pose> 0.09737462220438405
             0.08214418719708619
             0.18963827229388103 0
             0 0.729345515902136  </pose>
      <inertial>
        <mass>0.018</mass>
        <inertia>
          <ixx>8.82e-6</ixx>
          <ixy>0</ixy>
          <ixz>0</ixz>
          <iyy>8.82e-6</iyy>
          <iyz>0</iyz>
          <izz>8.82e-6</izz>
        </inertia>
      </inertial>
      <visual name="visual">
        <geometry>
          <mesh>
            <uri>model://random_strawberry_plant/meshes/leaf1.dae</uri>
            <scale> 0.6203192745348903 0.6203192745348903 0.6203192745348903</scale>
          </mesh>
        </geometry>
      </visual>
    </link>

    <link name= leaf_link_17_2 >
      <pose> 0.09737462220438405
             0.08214418719708619
             0.18963827229388103 0
             0 2.4044823904650685  </pose>
      <inertial>
        <mass>0.018</mass>
        <inertia>
          <ixx>8.82e-6</ixx>
          <ixy>0</ixy>
          <ixz>0</ixz>
          <iyy>8.82e-6</iyy>
          <iyz>0</iyz>
          <izz>8.82e-6</izz>
        </inertia>
      </inertial>
      <visual name="visual">
        <geometry>
          <mesh>
            <uri>model://random_strawberry_plant/meshes/leaf3.dae</uri>
            <scale> 0.6203192745348903 0.6203192745348903 0.6203192745348903</scale>
          </mesh>
        </geometry>
      </visual>
    </link>


    <joint name=leaf_dirt_joint_17 type="revolute">
      <parent>dirt_link</parent>
      <child>leaf_stem_link_17</child>
      <axis>
        <xyz>0 1 0</xyz>
      </axis>
    </joint>

    <link name= leaf_stem_link_18 >
      <pose>0 0 0 0 -0.9214116292556023 -0.8473545387620933 </pose>
      <inertial>
        <mass>1</mass>
        <inertia> <!-- Modeled as slender rod -->
          <ixx>1e-3</ixx>
          <ixy>0</ixy>
          <ixz>0</ixz>
          <iyy>8.333e-2</iyy>
          <iyz>0</iyz>
          <izz>8.333e-2</izz>
        </inertia>
      </inertial>
      <visual name="visual">
        <geometry>
          <mesh>
            <uri>model://random_strawberry_plant/meshes/leaf_stem2.stl</uri>
            <scale> 0.20111470619804345 0.20111470619804345 0.20111470619804345</scale>
          </mesh>
        </geometry>
        <material> <!-- Green -->
          <ambient>0.0 0.5 0.0 1.0</ambient>
          <diffuse>0.0 0.5 0.0 1.0</diffuse>
          <specular>0.1 0.1 0.1 1.0</specular>
        </material>
      </visual>
    </link>

    <link name= leaf_link_18_0 >
      <pose> 0.048302511063442154
             -0.05469184552382726
             0.09610741113904267 0
             0 -2.4921065177870787  </pose>
      <inertial>
        <mass>0.018</mass>
        <inertia>
          <ixx>8.82e-6</ixx>
          <ixy>0</ixy>
          <ixz>0</ixz>
          <iyy>8.82e-6</iyy>
          <iyz>0</iyz>
          <izz>8.82e-6</izz>
        </inertia>
      </inertial>
      <visual name="visual">
        <geometry>
          <mesh>
            <uri>model://random_strawberry_plant/meshes/leaf5.dae</uri>
            <scale> 0.4489198851757893 0.4489198851757893 0.4489198851757893</scale>
          </mesh>
        </geometry>
      </visual>
    </link>

    <link name= leaf_link_18_1 >
      <pose> 0.048302511063442154
             -0.05469184552382726
             0.09610741113904267 0
             0 -0.8957599786436267  </pose>
      <inertial>
        <mass>0.018</mass>
        <inertia>
          <ixx>8.82e-6</ixx>
          <ixy>0</ixy>
          <ixz>0</ixz>
          <iyy>8.82e-6</iyy>
          <iyz>0</iyz>
          <izz>8.82e-6</izz>
        </inertia>
      </inertial>
      <visual name="visual">
        <geometry>
          <mesh>
            <uri>model://random_strawberry_plant/meshes/leaf1.dae</uri>
            <scale> 0.4489198851757893 0.4489198851757893 0.4489198851757893</scale>
          </mesh>
        </geometry>
      </visual>
    </link>

    <link name= leaf_link_18_2 >
      <pose> 0.048302511063442154
             -0.05469184552382726
             0.09610741113904267 0
             0 0.8097113008278423  </pose>
      <inertial>
        <mass>0.018</mass>
        <inertia>
          <ixx>8.82e-6</ixx>
          <ixy>0</ixy>
          <ixz>0</ixz>
          <iyy>8.82e-6</iyy>
          <iyz>0</iyz>
          <izz>8.82e-6</izz>
        </inertia>
      </inertial>
      <visual name="visual">
        <geometry>
          <mesh>
            <uri>model://random_strawberry_plant/meshes/leaf3.dae</uri>
            <scale> 0.4489198851757893 0.4489198851757893 0.4489198851757893</scale>
          </mesh>
        </geometry>
      </visual>
    </link>


    <joint name=leaf_dirt_joint_18 type="revolute">
      <parent>dirt_link</parent>
      <child>leaf_stem_link_18</child>
      <axis>
        <xyz>0 1 0</xyz>
      </axis>
    </joint>

    <link name= leaf_stem_link_19 >
      <pose>0 0 0 0 -0.38140558966686244 -1.2939409049354844 </pose>
      <inertial>
        <mass>1</mass>
        <inertia> <!-- Modeled as slender rod -->
          <ixx>1e-3</ixx>
          <ixy>0</ixy>
          <ixz>0</ixz>
          <iyy>8.333e-2</iyy>
          <iyz>0</iyz>
          <izz>8.333e-2</izz>
        </inertia>
      </inertial>
      <visual name="visual">
        <geometry>
          <mesh>
            <uri>model://random_strawberry_plant/meshes/leaf_stem1.stl</uri>
            <scale> 0.21816728476048297 0.21816728476048297 0.21816728476048297</scale>
          </mesh>
        </geometry>
        <material> <!-- Green -->
          <ambient>0.0 0.5 0.0 1.0</ambient>
          <diffuse>0.0 0.5 0.0 1.0</diffuse>
          <specular>0.1 0.1 0.1 1.0</specular>
        </material>
      </visual>
    </link>

    <link name= leaf_link_19_0 >
      <pose> 0.03320826789258184
             -0.11686764476007258
             0.04872444604223017 0
             0 -2.743299517293412  </pose>
      <inertial>
        <mass>0.018</mass>
        <inertia>
          <ixx>8.82e-6</ixx>
          <ixy>0</ixy>
          <ixz>0</ixz>
          <iyy>8.82e-6</iyy>
          <iyz>0</iyz>
          <izz>8.82e-6</izz>
        </inertia>
      </inertial>
      <visual name="visual">
        <geometry>
          <mesh>
            <uri>model://random_strawberry_plant/meshes/leaf2.dae</uri>
            <scale> 0.6518313910201294 0.6518313910201294 0.6518313910201294</scale>
          </mesh>
        </geometry>
      </visual>
    </link>

    <link name= leaf_link_19_1 >
      <pose> 0.03320826789258184
             -0.11686764476007258
             0.04872444604223017 0
             0 -1.309910241921824  </pose>
      <inertial>
        <mass>0.018</mass>
        <inertia>
          <ixx>8.82e-6</ixx>
          <ixy>0</ixy>
          <ixz>0</ixz>
          <iyy>8.82e-6</iyy>
          <iyz>0</iyz>
          <izz>8.82e-6</izz>
        </inertia>
      </inertial>
      <visual name="visual">
        <geometry>
          <mesh>
            <uri>model://random_strawberry_plant/meshes/leaf2.dae</uri>
            <scale> 0.6518313910201294 0.6518313910201294 0.6518313910201294</scale>
          </mesh>
        </geometry>
      </visual>
    </link>

    <link name= leaf_link_19_2 >
      <pose> 0.03320826789258184
             -0.11686764476007258
             0.04872444604223017 0
             0 0.20712545253751502  </pose>
      <inertial>
        <mass>0.018</mass>
        <inertia>
          <ixx>8.82e-6</ixx>
          <ixy>0</ixy>
          <ixz>0</ixz>
          <iyy>8.82e-6</iyy>
          <iyz>0</iyz>
          <izz>8.82e-6</izz>
        </inertia>
      </inertial>
      <visual name="visual">
        <geometry>
          <mesh>
            <uri>model://random_strawberry_plant/meshes/leaf4.dae</uri>
            <scale> 0.6518313910201294 0.6518313910201294 0.6518313910201294</scale>
          </mesh>
        </geometry>
      </visual>
    </link>


    <joint name=leaf_dirt_joint_19 type="revolute">
      <parent>dirt_link</parent>
      <child>leaf_stem_link_19</child>
      <axis>
        <xyz>0 1 0</xyz>
      </axis>
    </joint>

    <link name= leaf_stem_link_20 >
      <pose>0 0 0 0 -1.1101081705919942 2.657818427929163 </pose>
      <inertial>
        <mass>1</mass>
        <inertia> <!-- Modeled as slender rod -->
          <ixx>1e-3</ixx>
          <ixy>0</ixy>
          <ixz>0</ixz>
          <iyy>8.333e-2</iyy>
          <iyz>0</iyz>
          <izz>8.333e-2</izz>
        </inertia>
      </inertial>
      <visual name="visual">
        <geometry>
          <mesh>
            <uri>model://random_strawberry_plant/meshes/leaf_stem2.stl</uri>
            <scale> 0.3048044927570605 0.3048044927570605 0.3048044927570605</scale>
          </mesh>
        </geometry>
        <material> <!-- Green -->
          <ambient>0.0 0.5 0.0 1.0</ambient>
          <diffuse>0.0 0.5 0.0 1.0</diffuse>
          <specular>0.1 0.1 0.1 1.0</specular>
        </material>
      </visual>
    </link>

    <link name= leaf_link_20_0 >
      <pose> -0.07197329210257941
             0.03781602626551493
             0.16381658570231125 0
             0 1.1255115654364158  </pose>
      <inertial>
        <mass>0.018</mass>
        <inertia>
          <ixx>8.82e-6</ixx>
          <ixy>0</ixy>
          <ixz>0</ixz>
          <iyy>8.82e-6</iyy>
          <iyz>0</iyz>
          <izz>8.82e-6</izz>
        </inertia>
      </inertial>
      <visual name="visual">
        <geometry>
          <mesh>
            <uri>model://random_strawberry_plant/meshes/leaf5.dae</uri>
            <scale> 0.3886721909613676 0.3886721909613676 0.3886721909613676</scale>
          </mesh>
        </geometry>
      </visual>
    </link>

    <link name= leaf_link_20_1 >
      <pose> -0.07197329210257941
             0.03781602626551493
             0.16381658570231125 0
             0 2.611327316814711  </pose>
      <inertial>
        <mass>0.018</mass>
        <inertia>
          <ixx>8.82e-6</ixx>
          <ixy>0</ixy>
          <ixz>0</ixz>
          <iyy>8.82e-6</iyy>
          <iyz>0</iyz>
          <izz>8.82e-6</izz>
        </inertia>
      </inertial>
      <visual name="visual">
        <geometry>
          <mesh>
            <uri>model://random_strawberry_plant/meshes/leaf5.dae</uri>
            <scale> 0.3886721909613676 0.3886721909613676 0.3886721909613676</scale>
          </mesh>
        </geometry>
      </visual>
    </link>

    <link name= leaf_link_20_2 >
      <pose> -0.07197329210257941
             0.03781602626551493
             0.16381658570231125 0
             0 4.159114008344328  </pose>
      <inertial>
        <mass>0.018</mass>
        <inertia>
          <ixx>8.82e-6</ixx>
          <ixy>0</ixy>
          <ixz>0</ixz>
          <iyy>8.82e-6</iyy>
          <iyz>0</iyz>
          <izz>8.82e-6</izz>
        </inertia>
      </inertial>
      <visual name="visual">
        <geometry>
          <mesh>
            <uri>model://random_strawberry_plant/meshes/leaf3.dae</uri>
            <scale> 0.3886721909613676 0.3886721909613676 0.3886721909613676</scale>
          </mesh>
        </geometry>
      </visual>
    </link>


    <joint name=leaf_dirt_joint_20 type="revolute">
      <parent>dirt_link</parent>
      <child>leaf_stem_link_20</child>
      <axis>
        <xyz>0 1 0</xyz>
      </axis>
    </joint>

    <link name= leaf_stem_link_21 >
      <pose>0 0 0 0 -1.1210588560405068 0.04847105565842158 </pose>
      <inertial>
        <mass>1</mass>
        <inertia> <!-- Modeled as slender rod -->
          <ixx>1e-3</ixx>
          <ixy>0</ixy>
          <ixz>0</ixz>
          <iyy>8.333e-2</iyy>
          <iyz>0</iyz>
          <izz>8.333e-2</izz>
        </inertia>
      </inertial>
      <visual name="visual">
        <geometry>
          <mesh>
            <uri>model://random_strawberry_plant/meshes/leaf_stem2.stl</uri>
            <scale> 0.41506293630583235 0.41506293630583235 0.41506293630583235</scale>
          </mesh>
        </geometry>
        <material> <!-- Green -->
          <ambient>0.0 0.5 0.0 1.0</ambient>
          <diffuse>0.0 0.5 0.0 1.0</diffuse>
          <specular>0.1 0.1 0.1 1.0</specular>
        </material>
      </visual>
    </link>

    <link name= leaf_link_21_0 >
      <pose> 0.10813681325233519
             0.005245614228427728
             0.22427376116062062 0
             0 -1.3945844998256316  </pose>
      <inertial>
        <mass>0.018</mass>
        <inertia>
          <ixx>8.82e-6</ixx>
          <ixy>0</ixy>
          <ixz>0</ixz>
          <iyy>8.82e-6</iyy>
          <iyz>0</iyz>
          <izz>8.82e-6</izz>
        </inertia>
      </inertial>
      <visual name="visual">
        <geometry>
          <mesh>
            <uri>model://random_strawberry_plant/meshes/leaf2.dae</uri>
            <scale> 0.6035249783366081 0.6035249783366081 0.6035249783366081</scale>
          </mesh>
        </geometry>
      </visual>
    </link>

    <link name= leaf_link_21_1 >
      <pose> 0.10813681325233519
             0.005245614228427728
             0.22427376116062062 0
             0 0.058713797256561014  </pose>
      <inertial>
        <mass>0.018</mass>
        <inertia>
          <ixx>8.82e-6</ixx>
          <ixy>0</ixy>
          <ixz>0</ixz>
          <iyy>8.82e-6</iyy>
          <iyz>0</iyz>
          <izz>8.82e-6</izz>
        </inertia>
      </inertial>
      <visual name="visual">
        <geometry>
          <mesh>
            <uri>model://random_strawberry_plant/meshes/leaf2.dae</uri>
            <scale> 0.6035249783366081 0.6035249783366081 0.6035249783366081</scale>
          </mesh>
        </geometry>
      </visual>
    </link>

    <link name= leaf_link_21_2 >
      <pose> 0.10813681325233519
             0.005245614228427728
             0.22427376116062062 0
             0 1.5317241180853194  </pose>
      <inertial>
        <mass>0.018</mass>
        <inertia>
          <ixx>8.82e-6</ixx>
          <ixy>0</ixy>
          <ixz>0</ixz>
          <iyy>8.82e-6</iyy>
          <iyz>0</iyz>
          <izz>8.82e-6</izz>
        </inertia>
      </inertial>
      <visual name="visual">
        <geometry>
          <mesh>
            <uri>model://random_strawberry_plant/meshes/leaf1.dae</uri>
            <scale> 0.6035249783366081 0.6035249783366081 0.6035249783366081</scale>
          </mesh>
        </geometry>
      </visual>
    </link>


    <joint name=leaf_dirt_joint_21 type="revolute">
      <parent>dirt_link</parent>
      <child>leaf_stem_link_21</child>
      <axis>
        <xyz>0 1 0</xyz>
      </axis>
    </joint>

    <link name= leaf_stem_link_22 >
      <pose>0 0 0 0 -0.5861537134020575 2.211215868877531 </pose>
      <inertial>
        <mass>1</mass>
        <inertia> <!-- Modeled as slender rod -->
          <ixx>1e-3</ixx>
          <ixy>0</ixy>
          <ixz>0</ixz>
          <iyy>8.333e-2</iyy>
          <iyz>0</iyz>
          <izz>8.333e-2</izz>
        </inertia>
      </inertial>
      <visual name="visual">
        <geometry>
          <mesh>
            <uri>model://random_strawberry_plant/meshes/leaf_stem1.stl</uri>
            <scale> 0.23632831581854502 0.23632831581854502 0.23632831581854502</scale>
          </mesh>
        </geometry>
        <material> <!-- Green -->
          <ambient>0.0 0.5 0.0 1.0</ambient>
          <diffuse>0.0 0.5 0.0 1.0</diffuse>
          <specular>0.1 0.1 0.1 1.0</specular>
        </material>
      </visual>
    </link>

    <link name= leaf_link_22_0 >
      <pose> -0.07058491937906773
             0.09471992090378356
             0.07843654740602927 0
             0 0.7527890553272534  </pose>
      <inertial>
        <mass>0.018</mass>
        <inertia>
          <ixx>8.82e-6</ixx>
          <ixy>0</ixy>
          <ixz>0</ixz>
          <iyy>8.82e-6</iyy>
          <iyz>0</iyz>
          <izz>8.82e-6</izz>
        </inertia>
      </inertial>
      <visual name="visual">
        <geometry>
          <mesh>
            <uri>model://random_strawberry_plant/meshes/leaf3.dae</uri>
            <scale> 0.6244027536803868 0.6244027536803868 0.6244027536803868</scale>
          </mesh>
        </geometry>
      </visual>
    </link>

    <link name= leaf_link_22_1 >
      <pose> -0.07058491937906773
             0.09471992090378356
             0.07843654740602927 0
             0 2.3928494282579136  </pose>
      <inertial>
        <mass>0.018</mass>
        <inertia>
          <ixx>8.82e-6</ixx>
          <ixy>0</ixy>
          <ixz>0</ixz>
          <iyy>8.82e-6</iyy>
          <iyz>0</iyz>
          <izz>8.82e-6</izz>
        </inertia>
      </inertial>
      <visual name="visual">
        <geometry>
          <mesh>
            <uri>model://random_strawberry_plant/meshes/leaf2.dae</uri>
            <scale> 0.6244027536803868 0.6244027536803868 0.6244027536803868</scale>
          </mesh>
        </geometry>
      </visual>
    </link>

    <link name= leaf_link_22_2 >
      <pose> -0.07058491937906773
             0.09471992090378356
             0.07843654740602927 0
             0 3.7461271421518276  </pose>
      <inertial>
        <mass>0.018</mass>
        <inertia>
          <ixx>8.82e-6</ixx>
          <ixy>0</ixy>
          <ixz>0</ixz>
          <iyy>8.82e-6</iyy>
          <iyz>0</iyz>
          <izz>8.82e-6</izz>
        </inertia>
      </inertial>
      <visual name="visual">
        <geometry>
          <mesh>
            <uri>model://random_strawberry_plant/meshes/leaf1.dae</uri>
            <scale> 0.6244027536803868 0.6244027536803868 0.6244027536803868</scale>
          </mesh>
        </geometry>
      </visual>
    </link>


    <joint name=leaf_dirt_joint_22 type="revolute">
      <parent>dirt_link</parent>
      <child>leaf_stem_link_22</child>
      <axis>
        <xyz>0 1 0</xyz>
      </axis>
    </joint>

    <link name= leaf_stem_link_23 >
      <pose>0 0 0 0 -1.2109291362572578 1.195237811146736 </pose>
      <inertial>
        <mass>1</mass>
        <inertia> <!-- Modeled as slender rod -->
          <ixx>1e-3</ixx>
          <ixy>0</ixy>
          <ixz>0</ixz>
          <iyy>8.333e-2</iyy>
          <iyz>0</iyz>
          <izz>8.333e-2</izz>
        </inertia>
      </inertial>
      <visual name="visual">
        <geometry>
          <mesh>
            <uri>model://random_strawberry_plant/meshes/leaf_stem2.stl</uri>
            <scale> 0.2780984613834073 0.2780984613834073 0.2780984613834073</scale>
          </mesh>
        </geometry>
        <material> <!-- Green -->
          <ambient>0.0 0.5 0.0 1.0</ambient>
          <diffuse>0.0 0.5 0.0 1.0</diffuse>
          <specular>0.1 0.1 0.1 1.0</specular>
        </material>
      </visual>
    </link>

    <link name= leaf_link_23_0 >
      <pose> 0.02155249286983612
             0.054664052711412434
             0.15617068519038468 0
             0 -0.5602423447620701  </pose>
      <inertial>
        <mass>0.018</mass>
        <inertia>
          <ixx>8.82e-6</ixx>
          <ixy>0</ixy>
          <ixz>0</ixz>
          <iyy>8.82e-6</iyy>
          <iyz>0</iyz>
          <izz>8.82e-6</izz>
        </inertia>
      </inertial>
      <visual name="visual">
        <geometry>
          <mesh>
            <uri>model://random_strawberry_plant/meshes/leaf3.dae</uri>
            <scale> 0.4933889285351503 0.4933889285351503 0.4933889285351503</scale>
          </mesh>
        </geometry>
      </visual>
    </link>

    <link name= leaf_link_23_1 >
      <pose> 0.02155249286983612
             0.054664052711412434
             0.15617068519038468 0
             0 1.046738529272952  </pose>
      <inertial>
        <mass>0.018</mass>
        <inertia>
          <ixx>8.82e-6</ixx>
          <ixy>0</ixy>
          <ixz>0</ixz>
          <iyy>8.82e-6</iyy>
          <iyz>0</iyz>
          <izz>8.82e-6</izz>
        </inertia>
      </inertial>
      <visual name="visual">
        <geometry>
          <mesh>
            <uri>model://random_strawberry_plant/meshes/leaf2.dae</uri>
            <scale> 0.4933889285351503 0.4933889285351503 0.4933889285351503</scale>
          </mesh>
        </geometry>
      </visual>
    </link>

    <link name= leaf_link_23_2 >
      <pose> 0.02155249286983612
             0.054664052711412434
             0.15617068519038468 0
             0 2.6874747326865815  </pose>
      <inertial>
        <mass>0.018</mass>
        <inertia>
          <ixx>8.82e-6</ixx>
          <ixy>0</ixy>
          <ixz>0</ixz>
          <iyy>8.82e-6</iyy>
          <iyz>0</iyz>
          <izz>8.82e-6</izz>
        </inertia>
      </inertial>
      <visual name="visual">
        <geometry>
          <mesh>
            <uri>model://random_strawberry_plant/meshes/leaf2.dae</uri>
            <scale> 0.4933889285351503 0.4933889285351503 0.4933889285351503</scale>
          </mesh>
        </geometry>
      </visual>
    </link>


    <joint name=leaf_dirt_joint_23 type="revolute">
      <parent>dirt_link</parent>
      <child>leaf_stem_link_23</child>
      <axis>
        <xyz>0 1 0</xyz>
      </axis>
    </joint>

    <link name= leaf_stem_link_24 >
      <pose>0 0 0 0 -0.5407316158405544 0.43651388809695835 </pose>
      <inertial>
        <mass>1</mass>
        <inertia> <!-- Modeled as slender rod -->
          <ixx>1e-3</ixx>
          <ixy>0</ixy>
          <ixz>0</ixz>
          <iyy>8.333e-2</iyy>
          <iyz>0</iyz>
          <izz>8.333e-2</izz>
        </inertia>
      </inertial>
      <visual name="visual">
        <geometry>
          <mesh>
            <uri>model://random_strawberry_plant/meshes/leaf_stem1.stl</uri>
            <scale> 0.24431745612298086 0.24431745612298086 0.24431745612298086</scale>
          </mesh>
        </geometry>
        <material> <!-- Green -->
          <ambient>0.0 0.5 0.0 1.0</ambient>
          <diffuse>0.0 0.5 0.0 1.0</diffuse>
          <specular>0.1 0.1 0.1 1.0</specular>
        </material>
      </visual>
    </link>

    <link name= leaf_link_24_0 >
      <pose> 0.11389216963164232
             0.05313396973102489
             0.07545940583602169 0
             0 -1.2121339084399199  </pose>
      <inertial>
        <mass>0.018</mass>
        <inertia>
          <ixx>8.82e-6</ixx>
          <ixy>0</ixy>
          <ixz>0</ixz>
          <iyy>8.82e-6</iyy>
          <iyz>0</iyz>
          <izz>8.82e-6</izz>
        </inertia>
      </inertial>
      <visual name="visual">
        <geometry>
          <mesh>
            <uri>model://random_strawberry_plant/meshes/leaf5.dae</uri>
            <scale> 0.5585657590759415 0.5585657590759415 0.5585657590759415</scale>
          </mesh>
        </geometry>
      </visual>
    </link>

    <link name= leaf_link_24_1 >
      <pose> 0.11389216963164232
             0.05313396973102489
             0.07545940583602169 0
             0 0.5290811489266485  </pose>
      <inertial>
        <mass>0.018</mass>
        <inertia>
          <ixx>8.82e-6</ixx>
          <ixy>0</ixy>
          <ixz>0</ixz>
          <iyy>8.82e-6</iyy>
          <iyz>0</iyz>
          <izz>8.82e-6</izz>
        </inertia>
      </inertial>
      <visual name="visual">
        <geometry>
          <mesh>
            <uri>model://random_strawberry_plant/meshes/leaf3.dae</uri>
            <scale> 0.5585657590759415 0.5585657590759415 0.5585657590759415</scale>
          </mesh>
        </geometry>
      </visual>
    </link>

    <link name= leaf_link_24_2 >
      <pose> 0.11389216963164232
             0.05313396973102489
             0.07545940583602169 0
             0 1.9553725664707353  </pose>
      <inertial>
        <mass>0.018</mass>
        <inertia>
          <ixx>8.82e-6</ixx>
          <ixy>0</ixy>
          <ixz>0</ixz>
          <iyy>8.82e-6</iyy>
          <iyz>0</iyz>
          <izz>8.82e-6</izz>
        </inertia>
      </inertial>
      <visual name="visual">
        <geometry>
          <mesh>
            <uri>model://random_strawberry_plant/meshes/leaf5.dae</uri>
            <scale> 0.5585657590759415 0.5585657590759415 0.5585657590759415</scale>
          </mesh>
        </geometry>
      </visual>
    </link>


    <joint name=leaf_dirt_joint_24 type="revolute">
      <parent>dirt_link</parent>
      <child>leaf_stem_link_24</child>
      <axis>
        <xyz>0 1 0</xyz>
      </axis>
    </joint>

    <link name= leaf_stem_link_25 >
      <pose>0 0 0 0 -0.708365519343281 1.8273485064628296 </pose>
      <inertial>
        <mass>1</mass>
        <inertia> <!-- Modeled as slender rod -->
          <ixx>1e-3</ixx>
          <ixy>0</ixy>
          <ixz>0</ixz>
          <iyy>8.333e-2</iyy>
          <iyz>0</iyz>
          <izz>8.333e-2</izz>
        </inertia>
      </inertial>
      <visual name="visual">
        <geometry>
          <mesh>
            <uri>model://random_strawberry_plant/meshes/leaf_stem1.stl</uri>
            <scale> 0.27702011879386246 0.27702011879386246 0.27702011879386246</scale>
          </mesh>
        </geometry>
        <material> <!-- Green -->
          <ambient>0.0 0.5 0.0 1.0</ambient>
          <diffuse>0.0 0.5 0.0 1.0</diffuse>
          <specular>0.1 0.1 0.1 1.0</specular>
        </material>
      </visual>
    </link>

    <link name= leaf_link_25_0 >
      <pose> -0.03202943309031037
             0.12209451853669627
             0.1081364720950767 0
             0 0.30199084676464105  </pose>
      <inertial>
        <mass>0.018</mass>
        <inertia>
          <ixx>8.82e-6</ixx>
          <ixy>0</ixy>
          <ixz>0</ixz>
          <iyy>8.82e-6</iyy>
          <iyz>0</iyz>
          <izz>8.82e-6</izz>
        </inertia>
      </inertial>
      <visual name="visual">
        <geometry>
          <mesh>
            <uri>model://random_strawberry_plant/meshes/leaf2.dae</uri>
            <scale> 0.5627950217139198 0.5627950217139198 0.5627950217139198</scale>
          </mesh>
        </geometry>
      </visual>
    </link>

    <link name= leaf_link_25_1 >
      <pose> -0.03202943309031037
             0.12209451853669627
             0.1081364720950767 0
             0 1.9158845108014864  </pose>
      <inertial>
        <mass>0.018</mass>
        <inertia>
          <ixx>8.82e-6</ixx>
          <ixy>0</ixy>
          <ixz>0</ixz>
          <iyy>8.82e-6</iyy>
          <iyz>0</iyz>
          <izz>8.82e-6</izz>
        </inertia>
      </inertial>
      <visual name="visual">
        <geometry>
          <mesh>
            <uri>model://random_strawberry_plant/meshes/leaf3.dae</uri>
            <scale> 0.5627950217139198 0.5627950217139198 0.5627950217139198</scale>
          </mesh>
        </geometry>
      </visual>
    </link>

    <link name= leaf_link_25_2 >
      <pose> -0.03202943309031037
             0.12209451853669627
             0.1081364720950767 0
             0 3.457897988497717  </pose>
      <inertial>
        <mass>0.018</mass>
        <inertia>
          <ixx>8.82e-6</ixx>
          <ixy>0</ixy>
          <ixz>0</ixz>
          <iyy>8.82e-6</iyy>
          <iyz>0</iyz>
          <izz>8.82e-6</izz>
        </inertia>
      </inertial>
      <visual name="visual">
        <geometry>
          <mesh>
            <uri>model://random_strawberry_plant/meshes/leaf5.dae</uri>
            <scale> 0.5627950217139198 0.5627950217139198 0.5627950217139198</scale>
          </mesh>
        </geometry>
      </visual>
    </link>


    <joint name=leaf_dirt_joint_25 type="revolute">
      <parent>dirt_link</parent>
      <child>leaf_stem_link_25</child>
      <axis>
        <xyz>0 1 0</xyz>
      </axis>
    </joint>

    <link name= leaf_stem_link_26 >
      <pose>0 0 0 0 -1.1046773179134899 -0.17065060949899458 </pose>
      <inertial>
        <mass>1</mass>
        <inertia> <!-- Modeled as slender rod -->
          <ixx>1e-3</ixx>
          <ixy>0</ixy>
          <ixz>0</ixz>
          <iyy>8.333e-2</iyy>
          <iyz>0</iyz>
          <izz>8.333e-2</izz>
        </inertia>
      </inertial>
      <visual name="visual">
        <geometry>
          <mesh>
            <uri>model://random_strawberry_plant/meshes/leaf_stem2.stl</uri>
            <scale> 0.3218047675528255 0.3218047675528255 0.3218047675528255</scale>
          </mesh>
        </geometry>
        <material> <!-- Green -->
          <ambient>0.0 0.5 0.0 1.0</ambient>
          <diffuse>0.0 0.5 0.0 1.0</diffuse>
          <specular>0.1 0.1 0.1 1.0</specular>
        </material>
      </visual>
    </link>

    <link name= leaf_link_26_0 >
      <pose> 0.08551535997453419
             -0.01473657785754671
             0.17248462978647228 0
             0 -1.7537092316526959  </pose>
      <inertial>
        <mass>0.018</mass>
        <inertia>
          <ixx>8.82e-6</ixx>
          <ixy>0</ixy>
          <ixz>0</ixz>
          <iyy>8.82e-6</iyy>
          <iyz>0</iyz>
          <izz>8.82e-6</izz>
        </inertia>
      </inertial>
      <visual name="visual">
        <geometry>
          <mesh>
            <uri>model://random_strawberry_plant/meshes/leaf3.dae</uri>
            <scale> 0.5530124582560997 0.5530124582560997 0.5530124582560997</scale>
          </mesh>
        </geometry>
      </visual>
    </link>

    <link name= leaf_link_26_1 >
      <pose> 0.08551535997453419
             -0.01473657785754671
             0.17248462978647228 0
             0 -0.13641395194613157  </pose>
      <inertial>
        <mass>0.018</mass>
        <inertia>
          <ixx>8.82e-6</ixx>
          <ixy>0</ixy>
          <ixz>0</ixz>
          <iyy>8.82e-6</iyy>
          <iyz>0</iyz>
          <izz>8.82e-6</izz>
        </inertia>
      </inertial>
      <visual name="visual">
        <geometry>
          <mesh>
            <uri>model://random_strawberry_plant/meshes/leaf5.dae</uri>
            <scale> 0.5530124582560997 0.5530124582560997 0.5530124582560997</scale>
          </mesh>
        </geometry>
      </visual>
    </link>

    <link name= leaf_link_26_2 >
      <pose> 0.08551535997453419
             -0.01473657785754671
             0.17248462978647228 0
             0 1.6439564743494708  </pose>
      <inertial>
        <mass>0.018</mass>
        <inertia>
          <ixx>8.82e-6</ixx>
          <ixy>0</ixy>
          <ixz>0</ixz>
          <iyy>8.82e-6</iyy>
          <iyz>0</iyz>
          <izz>8.82e-6</izz>
        </inertia>
      </inertial>
      <visual name="visual">
        <geometry>
          <mesh>
            <uri>model://random_strawberry_plant/meshes/leaf2.dae</uri>
            <scale> 0.5530124582560997 0.5530124582560997 0.5530124582560997</scale>
          </mesh>
        </geometry>
      </visual>
    </link>


    <joint name=leaf_dirt_joint_26 type="revolute">
      <parent>dirt_link</parent>
      <child>leaf_stem_link_26</child>
      <axis>
        <xyz>0 1 0</xyz>
      </axis>
    </joint>

    <link name= leaf_stem_link_27 >
      <pose>0 0 0 0 -0.5408337315865355 0.14110617180215534 </pose>
      <inertial>
        <mass>1</mass>
        <inertia> <!-- Modeled as slender rod -->
          <ixx>1e-3</ixx>
          <ixy>0</ixy>
          <ixz>0</ixz>
          <iyy>8.333e-2</iyy>
          <iyz>0</iyz>
          <izz>8.333e-2</izz>
        </inertia>
      </inertial>
      <visual name="visual">
        <geometry>
          <mesh>
            <uri>model://random_strawberry_plant/meshes/leaf_stem1.stl</uri>
            <scale> 0.30924842575634104 0.30924842575634104 0.30924842575634104</scale>
          </mesh>
        </geometry>
        <material> <!-- Green -->
          <ambient>0.0 0.5 0.0 1.0</ambient>
          <diffuse>0.0 0.5 0.0 1.0</diffuse>
          <specular>0.1 0.1 0.1 1.0</specular>
        </material>
      </visual>
    </link>

    <link name= leaf_link_27_0 >
      <pose> 0.15748647823474365
             0.022370987398539946
             0.09553010036544 0
             0 -1.3180108961645818  </pose>
      <inertial>
        <mass>0.018</mass>
        <inertia>
          <ixx>8.82e-6</ixx>
          <ixy>0</ixy>
          <ixz>0</ixz>
          <iyy>8.82e-6</iyy>
          <iyz>0</iyz>
          <izz>8.82e-6</izz>
        </inertia>
      </inertial>
      <visual name="visual">
        <geometry>
          <mesh>
            <uri>model://random_strawberry_plant/meshes/leaf3.dae</uri>
            <scale> 0.46114736851637483 0.46114736851637483 0.46114736851637483</scale>
          </mesh>
        </geometry>
      </visual>
    </link>

    <link name= leaf_link_27_1 >
      <pose> 0.15748647823474365
             0.022370987398539946
             0.09553010036544 0
             0 0.1936211072721329  </pose>
      <inertial>
        <mass>0.018</mass>
        <inertia>
          <ixx>8.82e-6</ixx>
          <ixy>0</ixy>
          <ixz>0</ixz>
          <iyy>8.82e-6</iyy>
          <iyz>0</iyz>
          <izz>8.82e-6</izz>
        </inertia>
      </inertial>
      <visual name="visual">
        <geometry>
          <mesh>
            <uri>model://random_strawberry_plant/meshes/leaf1.dae</uri>
            <scale> 0.46114736851637483 0.46114736851637483 0.46114736851637483</scale>
          </mesh>
        </geometry>
      </visual>
    </link>

    <link name= leaf_link_27_2 >
      <pose> 0.15748647823474365
             0.022370987398539946
             0.09553010036544 0
             0 1.5763228906075104  </pose>
      <inertial>
        <mass>0.018</mass>
        <inertia>
          <ixx>8.82e-6</ixx>
          <ixy>0</ixy>
          <ixz>0</ixz>
          <iyy>8.82e-6</iyy>
          <iyz>0</iyz>
          <izz>8.82e-6</izz>
        </inertia>
      </inertial>
      <visual name="visual">
        <geometry>
          <mesh>
            <uri>model://random_strawberry_plant/meshes/leaf4.dae</uri>
            <scale> 0.46114736851637483 0.46114736851637483 0.46114736851637483</scale>
          </mesh>
        </geometry>
      </visual>
    </link>


    <joint name=leaf_dirt_joint_27 type="revolute">
      <parent>dirt_link</parent>
      <child>leaf_stem_link_27</child>
      <axis>
        <xyz>0 1 0</xyz>
      </axis>
    </joint>

    <link name= leaf_stem_link_28 >
      <pose>0 0 0 0 -0.3027376357005773 0.6591581819668737 </pose>
      <inertial>
        <mass>1</mass>
        <inertia> <!-- Modeled as slender rod -->
          <ixx>1e-3</ixx>
          <ixy>0</ixy>
          <ixz>0</ixz>
          <iyy>8.333e-2</iyy>
          <iyz>0</iyz>
          <izz>8.333e-2</izz>
        </inertia>
      </inertial>
      <visual name="visual">
        <geometry>
          <mesh>
            <uri>model://random_strawberry_plant/meshes/leaf_stem1.stl</uri>
            <scale> 0.22715634078144598 0.22715634078144598 0.22715634078144598</scale>
          </mesh>
        </geometry>
        <material> <!-- Green -->
          <ambient>0.0 0.5 0.0 1.0</ambient>
          <diffuse>0.0 0.5 0.0 1.0</diffuse>
          <specular>0.1 0.1 0.1 1.0</specular>
        </material>
      </visual>
    </link>

    <link name= leaf_link_28_0 >
      <pose> 0.10284169590087265
             0.07967731510069445
             0.04063387969631974 0
             0 -1.062009857866641  </pose>
      <inertial>
        <mass>0.018</mass>
        <inertia>
          <ixx>8.82e-6</ixx>
          <ixy>0</ixy>
          <ixz>0</ixz>
          <iyy>8.82e-6</iyy>
          <iyz>0</iyz>
          <izz>8.82e-6</izz>
        </inertia>
      </inertial>
      <visual name="visual">
        <geometry>
          <mesh>
            <uri>model://random_strawberry_plant/meshes/leaf3.dae</uri>
            <scale> 0.4362862986842482 0.4362862986842482 0.4362862986842482</scale>
          </mesh>
        </geometry>
      </visual>
    </link>

    <link name= leaf_link_28_1 >
      <pose> 0.10284169590087265
             0.07967731510069445
             0.04063387969631974 0
             0 0.6864737360431188  </pose>
      <inertial>
        <mass>0.018</mass>
        <inertia>
          <ixx>8.82e-6</ixx>
          <ixy>0</ixy>
          <ixz>0</ixz>
          <iyy>8.82e-6</iyy>
          <iyz>0</iyz>
          <izz>8.82e-6</izz>
        </inertia>
      </inertial>
      <visual name="visual">
        <geometry>
          <mesh>
            <uri>model://random_strawberry_plant/meshes/leaf2.dae</uri>
            <scale> 0.4362862986842482 0.4362862986842482 0.4362862986842482</scale>
          </mesh>
        </geometry>
      </visual>
    </link>

    <link name= leaf_link_28_2 >
      <pose> 0.10284169590087265
             0.07967731510069445
             0.04063387969631974 0
             0 2.146113588161488  </pose>
      <inertial>
        <mass>0.018</mass>
        <inertia>
          <ixx>8.82e-6</ixx>
          <ixy>0</ixy>
          <ixz>0</ixz>
          <iyy>8.82e-6</iyy>
          <iyz>0</iyz>
          <izz>8.82e-6</izz>
        </inertia>
      </inertial>
      <visual name="visual">
        <geometry>
          <mesh>
            <uri>model://random_strawberry_plant/meshes/leaf4.dae</uri>
            <scale> 0.4362862986842482 0.4362862986842482 0.4362862986842482</scale>
          </mesh>
        </geometry>
      </visual>
    </link>


    <joint name=leaf_dirt_joint_28 type="revolute">
      <parent>dirt_link</parent>
      <child>leaf_stem_link_28</child>
      <axis>
        <xyz>0 1 0</xyz>
      </axis>
    </joint>

    <link name= leaf_stem_link_29 >
      <pose>0 0 0 0 -0.6130706953367941 0.9697683560499639 </pose>
      <inertial>
        <mass>1</mass>
        <inertia> <!-- Modeled as slender rod -->
          <ixx>1e-3</ixx>
          <ixy>0</ixy>
          <ixz>0</ixz>
          <iyy>8.333e-2</iyy>
          <iyz>0</iyz>
          <izz>8.333e-2</izz>
        </inertia>
      </inertial>
      <visual name="visual">
        <geometry>
          <mesh>
            <uri>model://random_strawberry_plant/meshes/leaf_stem1.stl</uri>
            <scale> 0.28873998235338555 0.28873998235338555 0.28873998235338555</scale>
          </mesh>
        </geometry>
        <material> <!-- Green -->
          <ambient>0.0 0.5 0.0 1.0</ambient>
          <diffuse>0.0 0.5 0.0 1.0</diffuse>
          <specular>0.1 0.1 0.1 1.0</specular>
        </material>
      </visual>
    </link>

    <link name= leaf_link_29_0 >
      <pose> 0.08012643774563159
             0.11686252620871855
             0.0996814115555554 0
             0 -0.5003624718563138  </pose>
      <inertial>
        <mass>0.018</mass>
        <inertia>
          <ixx>8.82e-6</ixx>
          <ixy>0</ixy>
          <ixz>0</ixz>
          <iyy>8.82e-6</iyy>
          <iyz>0</iyz>
          <izz>8.82e-6</izz>
        </inertia>
      </inertial>
      <visual name="visual">
        <geometry>
          <mesh>
            <uri>model://random_strawberry_plant/meshes/leaf3.dae</uri>
            <scale> 0.41510429531332727 0.41510429531332727 0.41510429531332727</scale>
          </mesh>
        </geometry>
      </visual>
    </link>

    <link name= leaf_link_29_1 >
      <pose> 0.08012643774563159
             0.11686252620871855
             0.0996814115555554 0
             0 0.8974351649386423  </pose>
      <inertial>
        <mass>0.018</mass>
        <inertia>
          <ixx>8.82e-6</ixx>
          <ixy>0</ixy>
          <ixz>0</ixz>
          <iyy>8.82e-6</iyy>
          <iyz>0</iyz>
          <izz>8.82e-6</izz>
        </inertia>
      </inertial>
      <visual name="visual">
        <geometry>
          <mesh>
            <uri>model://random_strawberry_plant/meshes/leaf2.dae</uri>
            <scale> 0.41510429531332727 0.41510429531332727 0.41510429531332727</scale>
          </mesh>
        </geometry>
      </visual>
    </link>

    <link name= leaf_link_29_2 >
      <pose> 0.08012643774563159
             0.11686252620871855
             0.0996814115555554 0
             0 2.497942644324487  </pose>
      <inertial>
        <mass>0.018</mass>
        <inertia>
          <ixx>8.82e-6</ixx>
          <ixy>0</ixy>
          <ixz>0</ixz>
          <iyy>8.82e-6</iyy>
          <iyz>0</iyz>
          <izz>8.82e-6</izz>
        </inertia>
      </inertial>
      <visual name="visual">
        <geometry>
          <mesh>
            <uri>model://random_strawberry_plant/meshes/leaf2.dae</uri>
            <scale> 0.41510429531332727 0.41510429531332727 0.41510429531332727</scale>
          </mesh>
        </geometry>
      </visual>
    </link>


    <joint name=leaf_dirt_joint_29 type="revolute">
      <parent>dirt_link</parent>
      <child>leaf_stem_link_29</child>
      <axis>
        <xyz>0 1 0</xyz>
      </axis>
    </joint>

    <link name= leaf_stem_link_30 >
      <pose>0 0 0 0 -0.37176187563186125 -2.0527798316298496 </pose>
      <inertial>
        <mass>1</mass>
        <inertia> <!-- Modeled as slender rod -->
          <ixx>1e-3</ixx>
          <ixy>0</ixy>
          <ixz>0</ixz>
          <iyy>8.333e-2</iyy>
          <iyz>0</iyz>
          <izz>8.333e-2</izz>
        </inertia>
      </inertial>
      <visual name="visual">
        <geometry>
          <mesh>
            <uri>model://random_strawberry_plant/meshes/leaf_stem1.stl</uri>
            <scale> 0.3269375107424964 0.3269375107424964 0.3269375107424964</scale>
          </mesh>
        </geometry>
        <material> <!-- Green -->
          <ambient>0.0 0.5 0.0 1.0</ambient>
          <diffuse>0.0 0.5 0.0 1.0</diffuse>
          <specular>0.1 0.1 0.1 1.0</specular>
        </material>
      </visual>
    </link>

    <link name= leaf_link_30_0 >
      <pose> -0.0847172514779607
             -0.16194160762491366
             0.07125750456519257 0
             0 -3.5667038913558278  </pose>
      <inertial>
        <mass>0.018</mass>
        <inertia>
          <ixx>8.82e-6</ixx>
          <ixy>0</ixy>
          <ixz>0</ixz>
          <iyy>8.82e-6</iyy>
          <iyz>0</iyz>
          <izz>8.82e-6</izz>
        </inertia>
      </inertial>
      <visual name="visual">
        <geometry>
          <mesh>
            <uri>model://random_strawberry_plant/meshes/leaf1.dae</uri>
            <scale> 0.5825073146442721 0.5825073146442721 0.5825073146442721</scale>
          </mesh>
        </geometry>
      </visual>
    </link>

    <link name= leaf_link_30_1 >
      <pose> -0.0847172514779607
             -0.16194160762491366
             0.07125750456519257 0
             0 -1.9479374352484746  </pose>
      <inertial>
        <mass>0.018</mass>
        <inertia>
          <ixx>8.82e-6</ixx>
          <ixy>0</ixy>
          <ixz>0</ixz>
          <iyy>8.82e-6</iyy>
          <iyz>0</iyz>
          <izz>8.82e-6</izz>
        </inertia>
      </inertial>
      <visual name="visual">
        <geometry>
          <mesh>
            <uri>model://random_strawberry_plant/meshes/leaf2.dae</uri>
            <scale> 0.5825073146442721 0.5825073146442721 0.5825073146442721</scale>
          </mesh>
        </geometry>
      </visual>
    </link>

    <link name= leaf_link_30_2 >
      <pose> -0.0847172514779607
             -0.16194160762491366
             0.07125750456519257 0
             0 -0.5089325925309027  </pose>
      <inertial>
        <mass>0.018</mass>
        <inertia>
          <ixx>8.82e-6</ixx>
          <ixy>0</ixy>
          <ixz>0</ixz>
          <iyy>8.82e-6</iyy>
          <iyz>0</iyz>
          <izz>8.82e-6</izz>
        </inertia>
      </inertial>
      <visual name="visual">
        <geometry>
          <mesh>
            <uri>model://random_strawberry_plant/meshes/leaf3.dae</uri>
            <scale> 0.5825073146442721 0.5825073146442721 0.5825073146442721</scale>
          </mesh>
        </geometry>
      </visual>
    </link>


    <joint name=leaf_dirt_joint_30 type="revolute">
      <parent>dirt_link</parent>
      <child>leaf_stem_link_30</child>
      <axis>
        <xyz>0 1 0</xyz>
      </axis>
    </joint>

    <link name= leaf_stem_link_31 >
      <pose>0 0 0 0 -0.8019964839532892 -1.5629369495078855 </pose>
      <inertial>
        <mass>1</mass>
        <inertia> <!-- Modeled as slender rod -->
          <ixx>1e-3</ixx>
          <ixy>0</ixy>
          <ixz>0</ixz>
          <iyy>8.333e-2</iyy>
          <iyz>0</iyz>
          <izz>8.333e-2</izz>
        </inertia>
      </inertial>
      <visual name="visual">
        <geometry>
          <mesh>
            <uri>model://random_strawberry_plant/meshes/leaf_stem2.stl</uri>
            <scale> 0.23260163234531822 0.23260163234531822 0.23260163234531822</scale>
          </mesh>
        </geometry>
        <material> <!-- Green -->
          <ambient>0.0 0.5 0.0 1.0</ambient>
          <diffuse>0.0 0.5 0.0 1.0</diffuse>
          <specular>0.1 0.1 0.1 1.0</specular>
        </material>
      </visual>
    </link>

    <link name= leaf_link_31_0 >
      <pose> 0.0007626110991829647
             -0.09703000239777818
             0.10030884323973102 0
             0 -3.150200682682016  </pose>
      <inertial>
        <mass>0.018</mass>
        <inertia>
          <ixx>8.82e-6</ixx>
          <ixy>0</ixy>
          <ixz>0</ixz>
          <iyy>8.82e-6</iyy>
          <iyz>0</iyz>
          <izz>8.82e-6</izz>
        </inertia>
      </inertial>
      <visual name="visual">
        <geometry>
          <mesh>
            <uri>model://random_strawberry_plant/meshes/leaf5.dae</uri>
            <scale> 0.6419042922916253 0.6419042922916253 0.6419042922916253</scale>
          </mesh>
        </geometry>
      </visual>
    </link>

    <link name= leaf_link_31_1 >
      <pose> 0.0007626110991829647
             -0.09703000239777818
             0.10030884323973102 0
             0 -1.5051401326702591  </pose>
      <inertial>
        <mass>0.018</mass>
        <inertia>
          <ixx>8.82e-6</ixx>
          <ixy>0</ixy>
          <ixz>0</ixz>
          <iyy>8.82e-6</iyy>
          <iyz>0</iyz>
          <izz>8.82e-6</izz>
        </inertia>
      </inertial>
      <visual name="visual">
        <geometry>
          <mesh>
            <uri>model://random_strawberry_plant/meshes/leaf2.dae</uri>
            <scale> 0.6419042922916253 0.6419042922916253 0.6419042922916253</scale>
          </mesh>
        </geometry>
      </visual>
    </link>

    <link name= leaf_link_31_2 >
      <pose> 0.0007626110991829647
             -0.09703000239777818
             0.10030884323973102 0
             0 -0.02428904800526932  </pose>
      <inertial>
        <mass>0.018</mass>
        <inertia>
          <ixx>8.82e-6</ixx>
          <ixy>0</ixy>
          <ixz>0</ixz>
          <iyy>8.82e-6</iyy>
          <iyz>0</iyz>
          <izz>8.82e-6</izz>
        </inertia>
      </inertial>
      <visual name="visual">
        <geometry>
          <mesh>
            <uri>model://random_strawberry_plant/meshes/leaf3.dae</uri>
            <scale> 0.6419042922916253 0.6419042922916253 0.6419042922916253</scale>
          </mesh>
        </geometry>
      </visual>
    </link>


    <joint name=leaf_dirt_joint_31 type="revolute">
      <parent>dirt_link</parent>
      <child>leaf_stem_link_31</child>
      <axis>
        <xyz>0 1 0</xyz>
      </axis>
    </joint>

    <link name= leaf_stem_link_32 >
      <pose>0 0 0 0 -0.4907438483359109 -1.200863991278774 </pose>
      <inertial>
        <mass>1</mass>
        <inertia> <!-- Modeled as slender rod -->
          <ixx>1e-3</ixx>
          <ixy>0</ixy>
          <ixz>0</ixz>
          <iyy>8.333e-2</iyy>
          <iyz>0</iyz>
          <izz>8.333e-2</izz>
        </inertia>
      </inertial>
      <visual name="visual">
        <geometry>
          <mesh>
            <uri>model://random_strawberry_plant/meshes/leaf_stem1.stl</uri>
            <scale> 0.3037870560936171 0.3037870560936171 0.3037870560936171</scale>
          </mesh>
        </geometry>
        <material> <!-- Green -->
          <ambient>0.0 0.5 0.0 1.0</ambient>
          <diffuse>0.0 0.5 0.0 1.0</diffuse>
          <specular>0.1 0.1 0.1 1.0</specular>
        </material>
      </visual>
    </link>

    <link name= leaf_link_32_0 >
      <pose> 0.05812349048993643
             -0.14988574219996526
             0.08590163735599776 0
             0 -2.920935183324724  </pose>
      <inertial>
        <mass>0.018</mass>
        <inertia>
          <ixx>8.82e-6</ixx>
          <ixy>0</ixy>
          <ixz>0</ixz>
          <iyy>8.82e-6</iyy>
          <iyz>0</iyz>
          <izz>8.82e-6</izz>
        </inertia>
      </inertial>
      <visual name="visual">
        <geometry>
          <mesh>
            <uri>model://random_strawberry_plant/meshes/leaf5.dae</uri>
            <scale> 0.632068393168298 0.632068393168298 0.632068393168298</scale>
          </mesh>
        </geometry>
      </visual>
    </link>

    <link name= leaf_link_32_1 >
      <pose> 0.05812349048993643
             -0.14988574219996526
             0.08590163735599776 0
             0 -1.1881810540873805  </pose>
      <inertial>
        <mass>0.018</mass>
        <inertia>
          <ixx>8.82e-6</ixx>
          <ixy>0</ixy>
          <ixz>0</ixz>
          <iyy>8.82e-6</iyy>
          <iyz>0</iyz>
          <izz>8.82e-6</izz>
        </inertia>
      </inertial>
      <visual name="visual">
        <geometry>
          <mesh>
            <uri>model://random_strawberry_plant/meshes/leaf4.dae</uri>
            <scale> 0.632068393168298 0.632068393168298 0.632068393168298</scale>
          </mesh>
        </geometry>
      </visual>
    </link>

    <link name= leaf_link_32_2 >
      <pose> 0.05812349048993643
             -0.14988574219996526
             0.08590163735599776 0
             0 0.21914383787420721  </pose>
      <inertial>
        <mass>0.018</mass>
        <inertia>
          <ixx>8.82e-6</ixx>
          <ixy>0</ixy>
          <ixz>0</ixz>
          <iyy>8.82e-6</iyy>
          <iyz>0</iyz>
          <izz>8.82e-6</izz>
        </inertia>
      </inertial>
      <visual name="visual">
        <geometry>
          <mesh>
            <uri>model://random_strawberry_plant/meshes/leaf3.dae</uri>
            <scale> 0.632068393168298 0.632068393168298 0.632068393168298</scale>
          </mesh>
        </geometry>
      </visual>
    </link>


    <joint name=leaf_dirt_joint_32 type="revolute">
      <parent>dirt_link</parent>
      <child>leaf_stem_link_32</child>
      <axis>
        <xyz>0 1 0</xyz>
      </axis>
    </joint>

    <link name= leaf_stem_link_33 >
      <pose>0 0 0 0 -0.45574767896819623 -1.3257981472009517 </pose>
      <inertial>
        <mass>1</mass>
        <inertia> <!-- Modeled as slender rod -->
          <ixx>1e-3</ixx>
          <ixy>0</ixy>
          <ixz>0</ixz>
          <iyy>8.333e-2</iyy>
          <iyz>0</iyz>
          <izz>8.333e-2</izz>
        </inertia>
      </inertial>
      <visual name="visual">
        <geometry>
          <mesh>
            <uri>model://random_strawberry_plant/meshes/leaf_stem1.stl</uri>
            <scale> 0.2127407238671395 0.2127407238671395 0.2127407238671395</scale>
          </mesh>
        </geometry>
        <material> <!-- Green -->
          <ambient>0.0 0.5 0.0 1.0</ambient>
          <diffuse>0.0 0.5 0.0 1.0</diffuse>
          <specular>0.1 0.1 0.1 1.0</specular>
        </material>
      </visual>
    </link>

    <link name= leaf_link_33_0 >
      <pose> 0.027800644893975913
             -0.11119335659959685
             0.056180630154343734 0
             0 -3.0656835429456883  </pose>
      <inertial>
        <mass>0.018</mass>
        <inertia>
          <ixx>8.82e-6</ixx>
          <ixy>0</ixy>
          <ixz>0</ixz>
          <iyy>8.82e-6</iyy>
          <iyz>0</iyz>
          <izz>8.82e-6</izz>
        </inertia>
      </inertial>
      <visual name="visual">
        <geometry>
          <mesh>
            <uri>model://random_strawberry_plant/meshes/leaf4.dae</uri>
            <scale> 0.581672388951972 0.581672388951972 0.581672388951972</scale>
          </mesh>
        </geometry>
      </visual>
    </link>

    <link name= leaf_link_33_1 >
      <pose> 0.027800644893975913
             -0.11119335659959685
             0.056180630154343734 0
             0 -1.499384216993706  </pose>
      <inertial>
        <mass>0.018</mass>
        <inertia>
          <ixx>8.82e-6</ixx>
          <ixy>0</ixy>
          <ixz>0</ixz>
          <iyy>8.82e-6</iyy>
          <iyz>0</iyz>
          <izz>8.82e-6</izz>
        </inertia>
      </inertial>
      <visual name="visual">
        <geometry>
          <mesh>
            <uri>model://random_strawberry_plant/meshes/leaf5.dae</uri>
            <scale> 0.581672388951972 0.581672388951972 0.581672388951972</scale>
          </mesh>
        </geometry>
      </visual>
    </link>

    <link name= leaf_link_33_2 >
      <pose> 0.027800644893975913
             -0.11119335659959685
             0.056180630154343734 0
             0 0.3386202298429004  </pose>
      <inertial>
        <mass>0.018</mass>
        <inertia>
          <ixx>8.82e-6</ixx>
          <ixy>0</ixy>
          <ixz>0</ixz>
          <iyy>8.82e-6</iyy>
          <iyz>0</iyz>
          <izz>8.82e-6</izz>
        </inertia>
      </inertial>
      <visual name="visual">
        <geometry>
          <mesh>
            <uri>model://random_strawberry_plant/meshes/leaf3.dae</uri>
            <scale> 0.581672388951972 0.581672388951972 0.581672388951972</scale>
          </mesh>
        </geometry>
      </visual>
    </link>


    <joint name=leaf_dirt_joint_33 type="revolute">
      <parent>dirt_link</parent>
      <child>leaf_stem_link_33</child>
      <axis>
        <xyz>0 1 0</xyz>
      </axis>
    </joint>

    <link name= leaf_stem_link_34 >
      <pose>0 0 0 0 -0.7087634687633108 -2.466173486206568 </pose>
      <inertial>
        <mass>1</mass>
        <inertia> <!-- Modeled as slender rod -->
          <ixx>1e-3</ixx>
          <ixy>0</ixy>
          <ixz>0</ixz>
          <iyy>8.333e-2</iyy>
          <iyz>0</iyz>
          <izz>8.333e-2</izz>
        </inertia>
      </inertial>
      <visual name="visual">
        <geometry>
          <mesh>
            <uri>model://random_strawberry_plant/meshes/leaf_stem1.stl</uri>
            <scale> 0.3392788259317036 0.3392788259317036 0.3392788259317036</scale>
          </mesh>
        </geometry>
        <material> <!-- Green -->
          <ambient>0.0 0.5 0.0 1.0</ambient>
          <diffuse>0.0 0.5 0.0 1.0</diffuse>
          <specular>0.1 0.1 0.1 1.0</specular>
        </material>
      </visual>
    </link>

    <link name= leaf_link_34_0 >
      <pose> -0.1206112387099119
             -0.0966232184033267
             0.13250104370705146 0
             0 -3.953486235274636  </pose>
      <inertial>
        <mass>0.018</mass>
        <inertia>
          <ixx>8.82e-6</ixx>
          <ixy>0</ixy>
          <ixz>0</ixz>
          <iyy>8.82e-6</iyy>
          <iyz>0</iyz>
          <izz>8.82e-6</izz>
        </inertia>
      </inertial>
      <visual name="visual">
        <geometry>
          <mesh>
            <uri>model://random_strawberry_plant/meshes/leaf1.dae</uri>
            <scale> 0.46238529392091077 0.46238529392091077 0.46238529392091077</scale>
          </mesh>
        </geometry>
      </visual>
    </link>

    <link name= leaf_link_34_1 >
      <pose> -0.1206112387099119
             -0.0966232184033267
             0.13250104370705146 0
             0 -2.496277001664616  </pose>
      <inertial>
        <mass>0.018</mass>
        <inertia>
          <ixx>8.82e-6</ixx>
          <ixy>0</ixy>
          <ixz>0</ixz>
          <iyy>8.82e-6</iyy>
          <iyz>0</iyz>
          <izz>8.82e-6</izz>
        </inertia>
      </inertial>
      <visual name="visual">
        <geometry>
          <mesh>
            <uri>model://random_strawberry_plant/meshes/leaf1.dae</uri>
            <scale> 0.46238529392091077 0.46238529392091077 0.46238529392091077</scale>
          </mesh>
        </geometry>
      </visual>
    </link>

    <link name= leaf_link_34_2 >
      <pose> -0.1206112387099119
             -0.0966232184033267
             0.13250104370705146 0
             0 -0.7914033823862923  </pose>
      <inertial>
        <mass>0.018</mass>
        <inertia>
          <ixx>8.82e-6</ixx>
          <ixy>0</ixy>
          <ixz>0</ixz>
          <iyy>8.82e-6</iyy>
          <iyz>0</iyz>
          <izz>8.82e-6</izz>
        </inertia>
      </inertial>
      <visual name="visual">
        <geometry>
          <mesh>
            <uri>model://random_strawberry_plant/meshes/leaf5.dae</uri>
            <scale> 0.46238529392091077 0.46238529392091077 0.46238529392091077</scale>
          </mesh>
        </geometry>
      </visual>
    </link>


    <joint name=leaf_dirt_joint_34 type="revolute">
      <parent>dirt_link</parent>
      <child>leaf_stem_link_34</child>
      <axis>
        <xyz>0 1 0</xyz>
      </axis>
    </joint>

    <link name= leaf_stem_link_35 >
      <pose>0 0 0 0 -1.0760756369864724 -1.8817348922282728 </pose>
      <inertial>
        <mass>1</mass>
        <inertia> <!-- Modeled as slender rod -->
          <ixx>1e-3</ixx>
          <ixy>0</ixy>
          <ixz>0</ixz>
          <iyy>8.333e-2</iyy>
          <iyz>0</iyz>
          <izz>8.333e-2</izz>
        </inertia>
      </inertial>
      <visual name="visual">
        <geometry>
          <mesh>
            <uri>model://random_strawberry_plant/meshes/leaf_stem2.stl</uri>
            <scale> 0.3196526765008985 0.3196526765008985 0.3196526765008985</scale>
          </mesh>
        </geometry>
        <material> <!-- Green -->
          <ambient>0.0 0.5 0.0 1.0</ambient>
          <diffuse>0.0 0.5 0.0 1.0</diffuse>
          <specular>0.1 0.1 0.1 1.0</specular>
        </material>
      </visual>
    </link>

    <link name= leaf_link_35_0 >
      <pose> -0.027860000856323196
             -0.08669332781731783
             0.16879605255500627 0
             0 -3.4344182698142465  </pose>
      <inertial>
        <mass>0.018</mass>
        <inertia>
          <ixx>8.82e-6</ixx>
          <ixy>0</ixy>
          <ixz>0</ixz>
          <iyy>8.82e-6</iyy>
          <iyz>0</iyz>
          <izz>8.82e-6</izz>
        </inertia>
      </inertial>
      <visual name="visual">
        <geometry>
          <mesh>
            <uri>model://random_strawberry_plant/meshes/leaf5.dae</uri>
            <scale> 0.5566418041174138 0.5566418041174138 0.5566418041174138</scale>
          </mesh>
        </geometry>
      </visual>
    </link>

    <link name= leaf_link_35_1 >
      <pose> -0.027860000856323196
             -0.08669332781731783
             0.16879605255500627 0
             0 -2.0357599014969905  </pose>
      <inertial>
        <mass>0.018</mass>
        <inertia>
          <ixx>8.82e-6</ixx>
          <ixy>0</ixy>
          <ixz>0</ixz>
          <iyy>8.82e-6</iyy>
          <iyz>0</iyz>
          <izz>8.82e-6</izz>
        </inertia>
      </inertial>
      <visual name="visual">
        <geometry>
          <mesh>
            <uri>model://random_strawberry_plant/meshes/leaf2.dae</uri>
            <scale> 0.5566418041174138 0.5566418041174138 0.5566418041174138</scale>
          </mesh>
        </geometry>
      </visual>
    </link>

    <link name= leaf_link_35_2 >
      <pose> -0.027860000856323196
             -0.08669332781731783
             0.16879605255500627 0
             0 -0.3071527014584423  </pose>
      <inertial>
        <mass>0.018</mass>
        <inertia>
          <ixx>8.82e-6</ixx>
          <ixy>0</ixy>
          <ixz>0</ixz>
          <iyy>8.82e-6</iyy>
          <iyz>0</iyz>
          <izz>8.82e-6</izz>
        </inertia>
      </inertial>
      <visual name="visual">
        <geometry>
          <mesh>
            <uri>model://random_strawberry_plant/meshes/leaf4.dae</uri>
            <scale> 0.5566418041174138 0.5566418041174138 0.5566418041174138</scale>
          </mesh>
        </geometry>
      </visual>
    </link>


    <joint name=leaf_dirt_joint_35 type="revolute">
      <parent>dirt_link</parent>
      <child>leaf_stem_link_35</child>
      <axis>
        <xyz>0 1 0</xyz>
      </axis>
    </joint>


    <link name= berry_stem_link_1 >
      <pose>0 0 0 0 -0.1328464100541297 0.3133164848868284</pose>
      <inertial>
        <mass>1</mass>
        <inertia> <!-- Modeled as slender rod -->
          <ixx>1e-3</ixx>
          <ixy>0</ixy>
          <ixz>0</ixz>
          <iyy>8.333e-2</iyy>
          <iyz>0</iyz>
          <izz>8.333e-2</izz>
        </inertia>
      </inertial>
      <visual name="visual">
        <geometry>
          <mesh>
            <uri>model://random_strawberry_plant/meshes/strawb_stem1.stl</uri>
            <scale>0.19869053480863563 0.19869053480863563 0.19869053480863563</scale>
          </mesh>
        </geometry>
        <material> <!-- Green -->
          <ambient>0.0 0.5 0.0 1.0</ambient>
          <diffuse>0.0 0.5 0.0 1.0</diffuse>
          <specular>0.1 0.1 0.1 1.0</specular>
        </material>
      </visual>
    </link>

    <link name= berry_link_1 >
      <pose> 0.12389829009428883 0.040141583484812046 0.017230331448292245
             0 -1.5607963267948965  0.3133164848868284</pose>
      <inertial>
        <mass>0.018</mass>
        <inertia>
          <ixx>8.82e-6</ixx>
          <ixy>0</ixy>
          <ixz>0</ixz>
          <iyy>8.82e-6</iyy>
          <iyz>0</iyz>
          <izz>8.82e-6</izz>
        </inertia>
      </inertial>
      <collision name="collision">
        <geometry>
          <sphere>
            <radius>0.017404372270280844</radius>
          </sphere>
        </geometry>
      </collision>
      <visual name="visual">
        <geometry>
          <mesh>
            <uri>model://random_strawberry_plant/meshes/1001r1.dae</uri>
            <scale>0.34808744540561687 0.34808744540561687 0.34808744540561687</scale>
          </mesh>
        </geometry>
      </visual>
    </link>

    <link name= calyx_link_1 >
      <pose> 0.12389829009428883 0.040141583484812046 0.017230331448292245
             0 -1.5607963267948965 0.3133164848868284 </pose>
      <inertial>
        <mass>0.018</mass>
        <inertia>
          <ixx>8.82e-6</ixx>
          <ixy>0</ixy>
          <ixz>0</ixz>
          <iyy>8.82e-6</iyy>
          <iyz>0</iyz>
          <izz>8.82e-6</izz>
        </inertia>
      </inertial>
      <visual name="visual">
        <geometry>
          <mesh>
            <uri>model://random_strawberry_plant/meshes/calyx6_1001.dae</uri>
            <scale>0.34808744540561687 0.34808744540561687 0.34808744540561687</scale>
          </mesh>
        </geometry>
      </visual>
    </link>

    <joint name=berry_dirt_joint_1 type="revolute">
      <parent>dirt_link</parent>
      <child>berry_stem_link_1</child>
      <axis>
        <xyz>0 1 0</xyz>
      </axis>
    </joint>

    <joint name=stem_to_calyx_joint_1 type="ball">
      <parent> berry_link_1 </parent>
      <child> calyx_link_1 </child>
    </joint>

    <joint name=stem_to_berry_joint_1 type="ball">
      <parent> berry_stem_link_1 </parent>
      <child> berry_link_1 </child>
    </joint>

    <link name= berry_stem_link_2 >
      <pose>0 0 0 0 -0.10636919937131045 0.03038366711637508</pose>
      <inertial>
        <mass>1</mass>
        <inertia> <!-- Modeled as slender rod -->
          <ixx>1e-3</ixx>
          <ixy>0</ixy>
          <ixz>0</ixz>
          <iyy>8.333e-2</iyy>
          <iyz>0</iyz>
          <izz>8.333e-2</izz>
        </inertia>
      </inertial>
      <visual name="visual">
        <geometry>
          <mesh>
            <uri>model://random_strawberry_plant/meshes/strawb_stem2.stl</uri>
            <scale>0.23820619854162772 0.23820619854162772 0.23820619854162772</scale>
          </mesh>
        </geometry>
        <material> <!-- Green -->
          <ambient>0.0 0.5 0.0 1.0</ambient>
          <diffuse>0.0 0.5 0.0 1.0</diffuse>
          <specular>0.1 0.1 0.1 1.0</specular>
        </material>
      </visual>
    </link>

    <link name= berry_link_2 >
      <pose> 0.15185979218948278 0.004615477747597441 0.014290775108865079
             0 -1.4342483644732187  0.03038366711637508</pose>
      <inertial>
        <mass>0.018</mass>
        <inertia>
          <ixx>8.82e-6</ixx>
          <ixy>0</ixy>
          <ixz>0</ixz>
          <iyy>8.82e-6</iyy>
          <iyz>0</iyz>
          <izz>8.82e-6</izz>
        </inertia>
      </inertial>
      <collision name="collision">
        <geometry>
          <sphere>
            <radius>0.014290775108865079</radius>
          </sphere>
        </geometry>
      </collision>
      <visual name="visual">
        <geometry>
          <mesh>
            <uri>model://random_strawberry_plant/meshes/1000r1.dae</uri>
            <scale>0.28581550217730156 0.28581550217730156 0.28581550217730156</scale>
          </mesh>
        </geometry>
      </visual>
    </link>

    <link name= calyx_link_2 >
      <pose> 0.15185979218948278 0.004615477747597441 0.014290775108865079
             0 -1.4342483644732187 0.03038366711637508 </pose>
      <inertial>
        <mass>0.018</mass>
        <inertia>
          <ixx>8.82e-6</ixx>
          <ixy>0</ixy>
          <ixz>0</ixz>
          <iyy>8.82e-6</iyy>
          <iyz>0</iyz>
          <izz>8.82e-6</izz>
        </inertia>
      </inertial>
      <visual name="visual">
        <geometry>
          <mesh>
            <uri>model://random_strawberry_plant/meshes/calyx3_1000.dae</uri>
            <scale>0.28581550217730156 0.28581550217730156 0.28581550217730156</scale>
          </mesh>
        </geometry>
      </visual>
    </link>

    <joint name=berry_dirt_joint_2 type="revolute">
      <parent>dirt_link</parent>
      <child>berry_stem_link_2</child>
      <axis>
        <xyz>0 1 0</xyz>
      </axis>
    </joint>

    <joint name=stem_to_calyx_joint_2 type="ball">
      <parent> berry_link_2 </parent>
      <child> calyx_link_2 </child>
    </joint>

    <joint name=stem_to_berry_joint_2 type="ball">
      <parent> berry_stem_link_2 </parent>
      <child> berry_link_2 </child>
    </joint>

    <link name= berry_stem_link_3 >
      <pose>0 0 0 0 -0.07701028149834396 -2.6436516777095975</pose>
      <inertial>
        <mass>1</mass>
        <inertia> <!-- Modeled as slender rod -->
          <ixx>1e-3</ixx>
          <ixy>0</ixy>
          <ixz>0</ixz>
          <iyy>8.333e-2</iyy>
          <iyz>0</iyz>
          <izz>8.333e-2</izz>
        </inertia>
      </inertial>
      <visual name="visual">
        <geometry>
          <mesh>
            <uri>model://random_strawberry_plant/meshes/strawb_stem2.stl</uri>
            <scale>0.3382354937695584 0.3382354937695584 0.3382354937695584</scale>
          </mesh>
        </geometry>
        <material> <!-- Green -->
          <ambient>0.0 0.5 0.0 1.0</ambient>
          <diffuse>0.0 0.5 0.0 1.0</diffuse>
          <specular>0.1 0.1 0.1 1.0</specular>
        </material>
      </visual>
    </link>

    <link name= berry_link_3 >
      <pose> -0.1867639135407159 -0.10153083191611527 0.014795566103058717
             0 -1.4614678348174532  -2.6436516777095975</pose>
      <inertial>
        <mass>0.018</mass>
        <inertia>
          <ixx>8.82e-6</ixx>
          <ixy>0</ixy>
          <ixz>0</ixz>
          <iyy>8.82e-6</iyy>
          <iyz>0</iyz>
          <izz>8.82e-6</izz>
        </inertia>
      </inertial>
      <collision name="collision">
        <geometry>
          <sphere>
            <radius>0.014795566103058717</radius>
          </sphere>
        </geometry>
      </collision>
      <visual name="visual">
        <geometry>
          <mesh>
            <uri>model://random_strawberry_plant/meshes/1004r1.dae</uri>
            <scale>0.2959113220611743 0.2959113220611743 0.2959113220611743</scale>
          </mesh>
        </geometry>
      </visual>
    </link>

    <link name= calyx_link_3 >
      <pose> -0.1867639135407159 -0.10153083191611527 0.014795566103058717
             0 -1.4614678348174532 -2.6436516777095975 </pose>
      <inertial>
        <mass>0.018</mass>
        <inertia>
          <ixx>8.82e-6</ixx>
          <ixy>0</ixy>
          <ixz>0</ixz>
          <iyy>8.82e-6</iyy>
          <iyz>0</iyz>
          <izz>8.82e-6</izz>
        </inertia>
      </inertial>
      <visual name="visual">
        <geometry>
          <mesh>
            <uri>model://random_strawberry_plant/meshes/calyx3_1004.dae</uri>
            <scale>0.2959113220611743 0.2959113220611743 0.2959113220611743</scale>
          </mesh>
        </geometry>
      </visual>
    </link>

    <joint name=berry_dirt_joint_3 type="revolute">
      <parent>dirt_link</parent>
      <child>berry_stem_link_3</child>
      <axis>
        <xyz>0 1 0</xyz>
      </axis>
    </joint>

    <joint name=stem_to_calyx_joint_3 type="ball">
      <parent> berry_link_3 </parent>
      <child> calyx_link_3 </child>
    </joint>

    <joint name=stem_to_berry_joint_3 type="ball">
      <parent> berry_stem_link_3 </parent>
      <child> berry_link_3 </child>
    </joint>

    <link name= berry_stem_link_4 >
      <pose>0 0 0 0 -0.0795545997678469 2.3960784943700535</pose>
      <inertial>
        <mass>1</mass>
        <inertia> <!-- Modeled as slender rod -->
          <ixx>1e-3</ixx>
          <ixy>0</ixy>
          <ixz>0</ixz>
          <iyy>8.333e-2</iyy>
          <iyz>0</iyz>
          <izz>8.333e-2</izz>
        </inertia>
      </inertial>
      <visual name="visual">
        <geometry>
          <mesh>
            <uri>model://random_strawberry_plant/meshes/strawb_stem2.stl</uri>
            <scale>0.32398724566818193 0.32398724566818193 0.32398724566818193</scale>
          </mesh>
        </geometry>
        <material> <!-- Green -->
          <ambient>0.0 0.5 0.0 1.0</ambient>
          <diffuse>0.0 0.5 0.0 1.0</diffuse>
          <specular>0.1 0.1 0.1 1.0</specular>
        </material>
      </visual>
    </link>

    <link name= berry_link_4 >
      <pose> -0.14751085063446048 0.13618973181985333 0.011432971293776387
             0 -1.1517900859369965  2.3960784943700535</pose>
      <inertial>
        <mass>0.018</mass>
        <inertia>
          <ixx>8.82e-6</ixx>
          <ixy>0</ixy>
          <ixz>0</ixz>
          <iyy>8.82e-6</iyy>
          <iyz>0</iyz>
          <izz>8.82e-6</izz>
        </inertia>
      </inertial>
      <collision name="collision">
        <geometry>
          <sphere>
            <radius>0.011432971293776387</radius>
          </sphere>
        </geometry>
      </collision>
      <visual name="visual">
        <geometry>
          <mesh>
            <uri>model://random_strawberry_plant/meshes/1004u2.dae</uri>
            <scale>0.22865942587552773 0.22865942587552773 0.22865942587552773</scale>
          </mesh>
        </geometry>
      </visual>
    </link>

    <link name= calyx_link_4 >
      <pose> -0.14751085063446048 0.13618973181985333 0.011432971293776387
             0 -1.1517900859369965 2.3960784943700535 </pose>
      <inertial>
        <mass>0.018</mass>
        <inertia>
          <ixx>8.82e-6</ixx>
          <ixy>0</ixy>
          <ixz>0</ixz>
          <iyy>8.82e-6</iyy>
          <iyz>0</iyz>
          <izz>8.82e-6</izz>
        </inertia>
      </inertial>
      <visual name="visual">
        <geometry>
          <mesh>
            <uri>model://random_strawberry_plant/meshes/calyx5_1004.dae</uri>
            <scale>0.22865942587552773 0.22865942587552773 0.22865942587552773</scale>
          </mesh>
        </geometry>
      </visual>
    </link>

    <joint name=berry_dirt_joint_4 type="revolute">
      <parent>dirt_link</parent>
      <child>berry_stem_link_4</child>
      <axis>
        <xyz>0 1 0</xyz>
      </axis>
    </joint>

    <joint name=stem_to_calyx_joint_4 type="ball">
      <parent> berry_link_4 </parent>
      <child> calyx_link_4 </child>
    </joint>

    <joint name=stem_to_berry_joint_4 type="ball">
      <parent> berry_stem_link_4 </parent>
      <child> berry_link_4 </child>
    </joint>

    <link name= berry_stem_link_5 >
      <pose>0 0 0 0 -0.0948625101544902 -0.026855845936136546</pose>
      <inertial>
        <mass>1</mass>
        <inertia> <!-- Modeled as slender rod -->
          <ixx>1e-3</ixx>
          <ixy>0</ixy>
          <ixz>0</ixz>
          <iyy>8.333e-2</iyy>
          <iyz>0</iyz>
          <izz>8.333e-2</izz>
        </inertia>
      </inertial>
      <visual name="visual">
        <geometry>
          <mesh>
            <uri>model://random_strawberry_plant/meshes/strawb_stem2.stl</uri>
            <scale>0.2915969772942581 0.2915969772942581 0.2915969772942581</scale>
          </mesh>
        </geometry>
        <material> <!-- Green -->
          <ambient>0.0 0.5 0.0 1.0</ambient>
          <diffuse>0.0 0.5 0.0 1.0</diffuse>
          <specular>0.1 0.1 0.1 1.0</specular>
        </material>
      </visual>
    </link>

    <link name= berry_link_5 >
      <pose> 0.18493208434788627 -0.0049677019192411265 0.015704440205858955
             0 -1.4489419935357393  -0.026855845936136546</pose>
      <inertial>
        <mass>0.018</mass>
        <inertia>
          <ixx>8.82e-6</ixx>
          <ixy>0</ixy>
          <ixz>0</ixz>
          <iyy>8.82e-6</iyy>
          <iyz>0</iyz>
          <izz>8.82e-6</izz>
        </inertia>
      </inertial>
      <collision name="collision">
        <geometry>
          <sphere>
            <radius>0.015704440205858955</radius>
          </sphere>
        </geometry>
      </collision>
      <visual name="visual">
        <geometry>
          <mesh>
            <uri>model://random_strawberry_plant/meshes/1002u1.dae</uri>
            <scale>0.3140888041171791 0.3140888041171791 0.3140888041171791</scale>
          </mesh>
        </geometry>
      </visual>
    </link>

    <link name= calyx_link_5 >
      <pose> 0.18493208434788627 -0.0049677019192411265 0.015704440205858955
             0 -1.4489419935357393 -0.026855845936136546 </pose>
      <inertial>
        <mass>0.018</mass>
        <inertia>
          <ixx>8.82e-6</ixx>
          <ixy>0</ixy>
          <ixz>0</ixz>
          <iyy>8.82e-6</iyy>
          <iyz>0</iyz>
          <izz>8.82e-6</izz>
        </inertia>
      </inertial>
      <visual name="visual">
        <geometry>
          <mesh>
            <uri>model://random_strawberry_plant/meshes/calyx5_1002.dae</uri>
            <scale>0.3140888041171791 0.3140888041171791 0.3140888041171791</scale>
          </mesh>
        </geometry>
      </visual>
    </link>

    <joint name=berry_dirt_joint_5 type="revolute">
      <parent>dirt_link</parent>
      <child>berry_stem_link_5</child>
      <axis>
        <xyz>0 1 0</xyz>
      </axis>
    </joint>

    <joint name=stem_to_calyx_joint_5 type="ball">
      <parent> berry_link_5 </parent>
      <child> calyx_link_5 </child>
    </joint>

    <joint name=stem_to_berry_joint_5 type="ball">
      <parent> berry_stem_link_5 </parent>
      <child> berry_link_5 </child>
    </joint>

    <link name= berry_stem_link_6 >
      <pose>0 0 0 0 -0.07147853853848712 -2.583337192847404</pose>
      <inertial>
        <mass>1</mass>
        <inertia> <!-- Modeled as slender rod -->
          <ixx>1e-3</ixx>
          <ixy>0</ixy>
          <ixz>0</ixz>
          <iyy>8.333e-2</iyy>
          <iyz>0</iyz>
          <izz>8.333e-2</izz>
        </inertia>
      </inertial>
      <visual name="visual">
        <geometry>
          <mesh>
            <uri>model://random_strawberry_plant/meshes/strawb_stem2.stl</uri>
            <scale>0.17573569224869173 0.17573569224869173 0.17573569224869173</scale>
          </mesh>
        </geometry>
        <material> <!-- Green -->
          <ambient>0.0 0.5 0.0 1.0</ambient>
          <diffuse>0.0 0.5 0.0 1.0</diffuse>
          <specular>0.1 0.1 0.1 1.0</specular>
        </material>
      </visual>
    </link>

    <link name= berry_link_6 >
      <pose> -0.08846491113816789 -0.055248277034035204 0.004783677799359674
             0 0.0  -2.583337192847404</pose>
      <inertial>
        <mass>0.018</mass>
        <inertia>
          <ixx>8.82e-6</ixx>
          <ixy>0</ixy>
          <ixz>0</ixz>
          <iyy>8.82e-6</iyy>
          <iyz>0</iyz>
          <izz>8.82e-6</izz>
        </inertia>
      </inertial>
      <collision name="collision">
        <geometry>
          <sphere>
            <radius>0.005000000000000001</radius>
          </sphere>
        </geometry>
      </collision>
      <visual name="visual">
        <geometry>
          <mesh>
            <uri>model://random_strawberry_plant/meshes/1002g.dae</uri>
            <scale>0.1 0.1 0.1</scale>
          </mesh>
        </geometry>
      </visual>
    </link>

    <link name= calyx_link_6 >
      <pose> -0.08846491113816789 -0.055248277034035204 0.004783677799359674
             0 0.0 -2.583337192847404 </pose>
      <inertial>
        <mass>0.018</mass>
        <inertia>
          <ixx>8.82e-6</ixx>
          <ixy>0</ixy>
          <ixz>0</ixz>
          <iyy>8.82e-6</iyy>
          <iyz>0</iyz>
          <izz>8.82e-6</izz>
        </inertia>
      </inertial>
      <visual name="visual">
        <geometry>
          <mesh>
            <uri>model://random_strawberry_plant/meshes/calyx7_1002.dae</uri>
            <scale>0.1 0.1 0.1</scale>
          </mesh>
        </geometry>
      </visual>
    </link>

    <joint name=berry_dirt_joint_6 type="revolute">
      <parent>dirt_link</parent>
      <child>berry_stem_link_6</child>
      <axis>
        <xyz>0 1 0</xyz>
      </axis>
    </joint>

    <joint name=stem_to_calyx_joint_6 type="ball">
      <parent> berry_link_6 </parent>
      <child> calyx_link_6 </child>
    </joint>

    <joint name=stem_to_berry_joint_6 type="ball">
      <parent> berry_stem_link_6 </parent>
      <child> berry_link_6 </child>
    </joint>

    <link name= berry_stem_link_7 >
      <pose>0 0 0 0 -0.10699675954949384 -2.6001223208885884</pose>
      <inertial>
        <mass>1</mass>
        <inertia> <!-- Modeled as slender rod -->
          <ixx>1e-3</ixx>
          <ixy>0</ixy>
          <ixz>0</ixz>
          <iyy>8.333e-2</iyy>
          <iyz>0</iyz>
          <izz>8.333e-2</izz>
        </inertia>
      </inertial>
      <visual name="visual">
        <geometry>
          <mesh>
            <uri>model://random_strawberry_plant/meshes/strawb_stem3.stl</uri>
            <scale>0.31072961592037635 0.31072961592037635 0.31072961592037635</scale>
          </mesh>
        </geometry>
        <material> <!-- Green -->
          <ambient>0.0 0.5 0.0 1.0</ambient>
          <diffuse>0.0 0.5 0.0 1.0</diffuse>
          <specular>0.1 0.1 0.1 1.0</specular>
        </material>
      </visual>
    </link>

    <link name= berry_link_7 >
      <pose> -0.15746131918299788 -0.09470196659209076 0.014962132475464567
             0 0.0  -2.6001223208885884</pose>
      <inertial>
        <mass>0.018</mass>
        <inertia>
          <ixx>8.82e-6</ixx>
          <ixy>0</ixy>
          <ixz>0</ixz>
          <iyy>8.82e-6</iyy>
          <iyz>0</iyz>
          <izz>8.82e-6</izz>
        </inertia>
      </inertial>
      <collision name="collision">
        <geometry>
          <sphere>
            <radius>0.00534784164266526</radius>
          </sphere>
        </geometry>
      </collision>
      <visual name="visual">
        <geometry>
          <mesh>
            <uri>model://random_strawberry_plant/meshes/1003g.dae</uri>
            <scale>0.1069568328533052 0.1069568328533052 0.1069568328533052</scale>
          </mesh>
        </geometry>
      </visual>
    </link>

    <link name= calyx_link_7 >
      <pose> -0.15746131918299788 -0.09470196659209076 0.014962132475464567
             0 0.0 -2.6001223208885884 </pose>
      <inertial>
        <mass>0.018</mass>
        <inertia>
          <ixx>8.82e-6</ixx>
          <ixy>0</ixy>
          <ixz>0</ixz>
          <iyy>8.82e-6</iyy>
          <iyz>0</iyz>
          <izz>8.82e-6</izz>
        </inertia>
      </inertial>
      <visual name="visual">
        <geometry>
          <mesh>
            <uri>model://random_strawberry_plant/meshes/calyx10_1003.dae</uri>
            <scale>0.1069568328533052 0.1069568328533052 0.1069568328533052</scale>
          </mesh>
        </geometry>
      </visual>
    </link>

    <joint name=berry_dirt_joint_7 type="revolute">
      <parent>dirt_link</parent>
      <child>berry_stem_link_7</child>
      <axis>
        <xyz>0 1 0</xyz>
      </axis>
    </joint>

    <joint name=stem_to_calyx_joint_7 type="ball">
      <parent> berry_link_7 </parent>
      <child> calyx_link_7 </child>
    </joint>

    <joint name=stem_to_berry_joint_7 type="ball">
      <parent> berry_stem_link_7 </parent>
      <child> berry_link_7 </child>
    </joint>

    <link name= berry_stem_link_8 >
      <pose>0 0 0 0 -0.10269111682416654 1.1902065828883837</pose>
      <inertial>
        <mass>1</mass>
        <inertia> <!-- Modeled as slender rod -->
          <ixx>1e-3</ixx>
          <ixy>0</ixy>
          <ixz>0</ixz>
          <iyy>8.333e-2</iyy>
          <iyz>0</iyz>
          <izz>8.333e-2</izz>
        </inertia>
      </inertial>
      <visual name="visual">
        <geometry>
          <mesh>
            <uri>model://random_strawberry_plant/meshes/strawb_stem3.stl</uri>
            <scale>0.34742820855522405 0.34742820855522405 0.34742820855522405</scale>
          </mesh>
        </geometry>
        <material> <!-- Green -->
          <ambient>0.0 0.5 0.0 1.0</ambient>
          <diffuse>0.0 0.5 0.0 1.0</diffuse>
          <specular>0.1 0.1 0.1 1.0</specular>
        </material>
      </visual>
    </link>

    <link name= berry_link_8 >
      <pose> 0.07639356095465244 0.19093773903229128 0.016155614282276194
             0 0.0  1.1902065828883837</pose>
      <inertial>
        <mass>0.018</mass>
        <inertia>
          <ixx>8.82e-6</ixx>
          <ixy>0</ixy>
          <ixz>0</ixz>
          <iyy>8.82e-6</iyy>
          <iyz>0</iyz>
          <izz>8.82e-6</izz>
        </inertia>
      </inertial>
      <collision name="collision">
        <geometry>
          <sphere>
            <radius>0.005616480769869114</radius>
          </sphere>
        </geometry>
      </collision>
      <visual name="visual">
        <geometry>
          <mesh>
            <uri>model://random_strawberry_plant/meshes/1002g.dae</uri>
            <scale>0.11232961539738227 0.11232961539738227 0.11232961539738227</scale>
          </mesh>
        </geometry>
      </visual>
    </link>

    <link name= calyx_link_8 >
      <pose> 0.07639356095465244 0.19093773903229128 0.016155614282276194
             0 0.0 1.1902065828883837 </pose>
      <inertial>
        <mass>0.018</mass>
        <inertia>
          <ixx>8.82e-6</ixx>
          <ixy>0</ixy>
          <ixz>0</ixz>
          <iyy>8.82e-6</iyy>
          <iyz>0</iyz>
          <izz>8.82e-6</izz>
        </inertia>
      </inertial>
      <visual name="visual">
        <geometry>
          <mesh>
            <uri>model://random_strawberry_plant/meshes/calyx7_1002.dae</uri>
            <scale>0.11232961539738227 0.11232961539738227 0.11232961539738227</scale>
          </mesh>
        </geometry>
      </visual>
    </link>

    <joint name=berry_dirt_joint_8 type="revolute">
      <parent>dirt_link</parent>
      <child>berry_stem_link_8</child>
      <axis>
        <xyz>0 1 0</xyz>
      </axis>
    </joint>

    <joint name=stem_to_calyx_joint_8 type="ball">
      <parent> berry_link_8 </parent>
      <child> calyx_link_8 </child>
    </joint>

    <joint name=stem_to_berry_joint_8 type="ball">
      <parent> berry_stem_link_8 </parent>
      <child> berry_link_8 </child>
    </joint>

    <link name= berry_stem_link_9 >
      <pose>0 0 0 0 -0.06855839972903574 2.187846637271657</pose>
      <inertial>
        <mass>1</mass>
        <inertia> <!-- Modeled as slender rod -->
          <ixx>1e-3</ixx>
          <ixy>0</ixy>
          <ixz>0</ixz>
          <iyy>8.333e-2</iyy>
          <iyz>0</iyz>
          <izz>8.333e-2</izz>
        </inertia>
      </inertial>
      <visual name="visual">
        <geometry>
          <mesh>
            <uri>model://random_strawberry_plant/meshes/strawb_stem3.stl</uri>
            <scale>0.2007140223680398 0.2007140223680398 0.2007140223680398</scale>
          </mesh>
        </geometry>
        <material> <!-- Green -->
          <ambient>0.0 0.5 0.0 1.0</ambient>
          <diffuse>0.0 0.5 0.0 1.0</diffuse>
          <specular>0.1 0.1 0.1 1.0</specular>
        </material>
      </visual>
    </link>

    <link name= berry_link_9 >
      <pose> -0.06934379124650393 0.09774091945150358 0.00728862862743107
             0 0.0  2.187846637271657</pose>
      <inertial>
        <mass>0.018</mass>
        <inertia>
          <ixx>8.82e-6</ixx>
          <ixy>0</ixy>
          <ixz>0</ixz>
          <iyy>8.82e-6</iyy>
          <iyz>0</iyz>
          <izz>8.82e-6</izz>
        </inertia>
      </inertial>
      <collision name="collision">
        <geometry>
          <sphere>
            <radius>0.005000000000000001</radius>
          </sphere>
        </geometry>
      </collision>
      <visual name="visual">
        <geometry>
          <mesh>
            <uri>model://random_strawberry_plant/meshes/1002g.dae</uri>
            <scale>0.1 0.1 0.1</scale>
          </mesh>
        </geometry>
      </visual>
    </link>

    <link name= calyx_link_9 >
      <pose> -0.06934379124650393 0.09774091945150358 0.00728862862743107
             0 0.0 2.187846637271657 </pose>
      <inertial>
        <mass>0.018</mass>
        <inertia>
          <ixx>8.82e-6</ixx>
          <ixy>0</ixy>
          <ixz>0</ixz>
          <iyy>8.82e-6</iyy>
          <iyz>0</iyz>
          <izz>8.82e-6</izz>
        </inertia>
      </inertial>
      <visual name="visual">
        <geometry>
          <mesh>
            <uri>model://random_strawberry_plant/meshes/calyx7_1002.dae</uri>
            <scale>0.1 0.1 0.1</scale>
          </mesh>
        </geometry>
      </visual>
    </link>

    <joint name=berry_dirt_joint_9 type="revolute">
      <parent>dirt_link</parent>
      <child>berry_stem_link_9</child>
      <axis>
        <xyz>0 1 0</xyz>
      </axis>
    </joint>

    <joint name=stem_to_calyx_joint_9 type="ball">
      <parent> berry_link_9 </parent>
      <child> calyx_link_9 </child>
    </joint>

    <joint name=stem_to_berry_joint_9 type="ball">
      <parent> berry_stem_link_9 </parent>
      <child> berry_link_9 </child>
    </joint>

  </model>
</sdf>
