<?xml version="1.0" ?>


<sdf version="1.6">
  <model name="strawb_plant">
    <static>true</static>

    <link name="dirt_link">
      <inertial>
        <mass>10</mass>
        <inertia>
          <ixx>1</ixx>
          <ixy>0</ixy>
          <ixz>0</ixz>
          <iyy>1</iyy>
          <iyz>0</iyz>
          <izz>1</izz>
        </inertia>
      </inertial>
    </link>

    <joint name="fixed to ground" type="revolute">
      <parent>world</parent>
      <child>dirt_link</child>
      <axis>
        <xyz>0 1 0</xyz>
      </axis>
    </joint>


    <link name= leaf_stem_link_1 >
      <pose>0 0 0 0 -0.738457700472178 2.0364313881355978 </pose>
      <inertial>
        <mass>1</mass>
        <inertia> <!-- Modeled as slender rod -->
          <ixx>1e-3</ixx>
          <ixy>0</ixy>
          <ixz>0</ixz>
          <iyy>8.333e-2</iyy>
          <iyz>0</iyz>
          <izz>8.333e-2</izz>
        </inertia>
      </inertial>
      <visual name="visual">
        <geometry>
          <mesh>
            <uri>model://random_strawberry_plant/meshes/leaf_stem1.stl</uri>
            <scale> 0.389048948284289 0.389048948284289 0.389048948284289</scale>
          </mesh>
        </geometry>
        <material> <!-- Green -->
          <ambient>0.0 0.5 0.0 1.0</ambient>
          <diffuse>0.0 0.5 0.0 1.0</diffuse>
          <specular>0.1 0.1 0.1 1.0</specular>
        </material>
      </visual>
    </link>

    <link name= leaf_link_1_0 >
      <pose> -0.07750597024974695
             0.15424479172304106
             0.15713255264254158 0
             0 0.452608293872778  </pose>
      <inertial>
        <mass>0.018</mass>
        <inertia>
          <ixx>8.82e-6</ixx>
          <ixy>0</ixy>
          <ixz>0</ixz>
          <iyy>8.82e-6</iyy>
          <iyz>0</iyz>
          <izz>8.82e-6</izz>
        </inertia>
      </inertial>
      <visual name="visual">
        <geometry>
          <mesh>
            <uri>model://random_strawberry_plant/meshes/leaf4.dae</uri>
            <scale> 0.48195249472801105 0.48195249472801105 0.48195249472801105</scale>
          </mesh>
        </geometry>
      </visual>
    </link>

    <link name= leaf_link_1_1 >
      <pose> -0.07750597024974695
             0.15424479172304106
             0.15713255264254158 0
             0 2.1775335865434933  </pose>
      <inertial>
        <mass>0.018</mass>
        <inertia>
          <ixx>8.82e-6</ixx>
          <ixy>0</ixy>
          <ixz>0</ixz>
          <iyy>8.82e-6</iyy>
          <iyz>0</iyz>
          <izz>8.82e-6</izz>
        </inertia>
      </inertial>
      <visual name="visual">
        <geometry>
          <mesh>
            <uri>model://random_strawberry_plant/meshes/leaf5.dae</uri>
            <scale> 0.48195249472801105 0.48195249472801105 0.48195249472801105</scale>
          </mesh>
        </geometry>
      </visual>
    </link>

    <link name= leaf_link_1_2 >
      <pose> -0.07750597024974695
             0.15424479172304106
             0.15713255264254158 0
             0 3.5856679667021827  </pose>
      <inertial>
        <mass>0.018</mass>
        <inertia>
          <ixx>8.82e-6</ixx>
          <ixy>0</ixy>
          <ixz>0</ixz>
          <iyy>8.82e-6</iyy>
          <iyz>0</iyz>
          <izz>8.82e-6</izz>
        </inertia>
      </inertial>
      <visual name="visual">
        <geometry>
          <mesh>
            <uri>model://random_strawberry_plant/meshes/leaf5.dae</uri>
            <scale> 0.48195249472801105 0.48195249472801105 0.48195249472801105</scale>
          </mesh>
        </geometry>
      </visual>
    </link>


    <joint name=leaf_dirt_joint_1 type="revolute">
      <parent>dirt_link</parent>
      <child>leaf_stem_link_1</child>
      <axis>
        <xyz>0 1 0</xyz>
      </axis>
    </joint>

    <link name= leaf_stem_link_2 >
      <pose>0 0 0 0 -1.1545969932887916 -0.5715342285045386 </pose>
      <inertial>
        <mass>1</mass>
        <inertia> <!-- Modeled as slender rod -->
          <ixx>1e-3</ixx>
          <ixy>0</ixy>
          <ixz>0</ixz>
          <iyy>8.333e-2</iyy>
          <iyz>0</iyz>
          <izz>8.333e-2</izz>
        </inertia>
      </inertial>
      <visual name="visual">
        <geometry>
          <mesh>
            <uri>model://random_strawberry_plant/meshes/leaf_stem2.stl</uri>
            <scale> 0.2864522396352877 0.2864522396352877 0.2864522396352877</scale>
          </mesh>
        </geometry>
        <material> <!-- Green -->
          <ambient>0.0 0.5 0.0 1.0</ambient>
          <diffuse>0.0 0.5 0.0 1.0</diffuse>
          <specular>0.1 0.1 0.1 1.0</specular>
        </material>
      </visual>
    </link>

    <link name= leaf_link_2_0 >
      <pose> 0.05844221138114108
             -0.0375862454151055
             0.15719904865368461 0
             0 -2.112233581042781  </pose>
      <inertial>
        <mass>0.018</mass>
        <inertia>
          <ixx>8.82e-6</ixx>
          <ixy>0</ixy>
          <ixz>0</ixz>
          <iyy>8.82e-6</iyy>
          <iyz>0</iyz>
          <izz>8.82e-6</izz>
        </inertia>
      </inertial>
      <visual name="visual">
        <geometry>
          <mesh>
            <uri>model://random_strawberry_plant/meshes/leaf3.dae</uri>
            <scale> 0.5460212352741229 0.5460212352741229 0.5460212352741229</scale>
          </mesh>
        </geometry>
      </visual>
    </link>

    <link name= leaf_link_2_1 >
      <pose> 0.05844221138114108
             -0.0375862454151055
             0.15719904865368461 0
             0 -0.6921401176907302  </pose>
      <inertial>
        <mass>0.018</mass>
        <inertia>
          <ixx>8.82e-6</ixx>
          <ixy>0</ixy>
          <ixz>0</ixz>
          <iyy>8.82e-6</iyy>
          <iyz>0</iyz>
          <izz>8.82e-6</izz>
        </inertia>
      </inertial>
      <visual name="visual">
        <geometry>
          <mesh>
            <uri>model://random_strawberry_plant/meshes/leaf1.dae</uri>
            <scale> 0.5460212352741229 0.5460212352741229 0.5460212352741229</scale>
          </mesh>
        </geometry>
      </visual>
    </link>

    <link name= leaf_link_2_2 >
      <pose> 0.05844221138114108
             -0.0375862454151055
             0.15719904865368461 0
             0 0.9071904333576601  </pose>
      <inertial>
        <mass>0.018</mass>
        <inertia>
          <ixx>8.82e-6</ixx>
          <ixy>0</ixy>
          <ixz>0</ixz>
          <iyy>8.82e-6</iyy>
          <iyz>0</iyz>
          <izz>8.82e-6</izz>
        </inertia>
      </inertial>
      <visual name="visual">
        <geometry>
          <mesh>
            <uri>model://random_strawberry_plant/meshes/leaf4.dae</uri>
            <scale> 0.5460212352741229 0.5460212352741229 0.5460212352741229</scale>
          </mesh>
        </geometry>
      </visual>
    </link>


    <joint name=leaf_dirt_joint_2 type="revolute">
      <parent>dirt_link</parent>
      <child>leaf_stem_link_2</child>
      <axis>
        <xyz>0 1 0</xyz>
      </axis>
    </joint>

    <link name= leaf_stem_link_3 >
      <pose>0 0 0 0 -0.8088676511528925 -2.2419288478964488 </pose>
      <inertial>
        <mass>1</mass>
        <inertia> <!-- Modeled as slender rod -->
          <ixx>1e-3</ixx>
          <ixy>0</ixy>
          <ixz>0</ixz>
          <iyy>8.333e-2</iyy>
          <iyz>0</iyz>
          <izz>8.333e-2</izz>
        </inertia>
      </inertial>
      <visual name="visual">
        <geometry>
          <mesh>
            <uri>model://random_strawberry_plant/meshes/leaf_stem2.stl</uri>
            <scale> 0.31243511558983955 0.31243511558983955 0.31243511558983955</scale>
          </mesh>
        </geometry>
        <material> <!-- Green -->
          <ambient>0.0 0.5 0.0 1.0</ambient>
          <diffuse>0.0 0.5 0.0 1.0</diffuse>
          <specular>0.1 0.1 0.1 1.0</specular>
        </material>
      </visual>
    </link>

    <link name= leaf_link_3_0 >
      <pose> -0.0804752385674106
             -0.10134154371280316
             0.13562920046484625 0
             0 -3.7449607818585884  </pose>
      <inertial>
        <mass>0.018</mass>
        <inertia>
          <ixx>8.82e-6</ixx>
          <ixy>0</ixy>
          <ixz>0</ixz>
          <iyy>8.82e-6</iyy>
          <iyz>0</iyz>
          <izz>8.82e-6</izz>
        </inertia>
      </inertial>
      <visual name="visual">
        <geometry>
          <mesh>
            <uri>model://random_strawberry_plant/meshes/leaf5.dae</uri>
            <scale> 0.5260478477007304 0.5260478477007304 0.5260478477007304</scale>
          </mesh>
        </geometry>
      </visual>
    </link>

    <link name= leaf_link_3_1 >
      <pose> -0.0804752385674106
             -0.10134154371280316
             0.13562920046484625 0
             0 -2.4157357284736443  </pose>
      <inertial>
        <mass>0.018</mass>
        <inertia>
          <ixx>8.82e-6</ixx>
          <ixy>0</ixy>
          <ixz>0</ixz>
          <iyy>8.82e-6</iyy>
          <iyz>0</iyz>
          <izz>8.82e-6</izz>
        </inertia>
      </inertial>
      <visual name="visual">
        <geometry>
          <mesh>
            <uri>model://random_strawberry_plant/meshes/leaf2.dae</uri>
            <scale> 0.5260478477007304 0.5260478477007304 0.5260478477007304</scale>
          </mesh>
        </geometry>
      </visual>
    </link>

    <link name= leaf_link_3_2 >
      <pose> -0.0804752385674106
             -0.10134154371280316
             0.13562920046484625 0
             0 -0.5730381120061758  </pose>
      <inertial>
        <mass>0.018</mass>
        <inertia>
          <ixx>8.82e-6</ixx>
          <ixy>0</ixy>
          <ixz>0</ixz>
          <iyy>8.82e-6</iyy>
          <iyz>0</iyz>
          <izz>8.82e-6</izz>
        </inertia>
      </inertial>
      <visual name="visual">
        <geometry>
          <mesh>
            <uri>model://random_strawberry_plant/meshes/leaf1.dae</uri>
            <scale> 0.5260478477007304 0.5260478477007304 0.5260478477007304</scale>
          </mesh>
        </geometry>
      </visual>
    </link>


    <joint name=leaf_dirt_joint_3 type="revolute">
      <parent>dirt_link</parent>
      <child>leaf_stem_link_3</child>
      <axis>
        <xyz>0 1 0</xyz>
      </axis>
    </joint>

    <link name= leaf_stem_link_4 >
      <pose>0 0 0 0 -0.9083614320076889 1.925708006705352 </pose>
      <inertial>
        <mass>1</mass>
        <inertia> <!-- Modeled as slender rod -->
          <ixx>1e-3</ixx>
          <ixy>0</ixy>
          <ixz>0</ixz>
          <iyy>8.333e-2</iyy>
          <iyz>0</iyz>
          <izz>8.333e-2</izz>
        </inertia>
      </inertial>
      <visual name="visual">
        <geometry>
          <mesh>
            <uri>model://random_strawberry_plant/meshes/leaf_stem2.stl</uri>
            <scale> 0.33332495397165435 0.33332495397165435 0.33332495397165435</scale>
          </mesh>
        </geometry>
        <material> <!-- Green -->
          <ambient>0.0 0.5 0.0 1.0</ambient>
          <diffuse>0.0 0.5 0.0 1.0</diffuse>
          <specular>0.1 0.1 0.1 1.0</specular>
        </material>
      </visual>
    </link>

    <link name= leaf_link_4_0 >
      <pose> -0.04274503560624411
             0.11533862943192805
             0.1576954389646678 0
             0 0.3687294133181169  </pose>
      <inertial>
        <mass>0.018</mass>
        <inertia>
          <ixx>8.82e-6</ixx>
          <ixy>0</ixy>
          <ixz>0</ixz>
          <iyy>8.82e-6</iyy>
          <iyz>0</iyz>
          <izz>8.82e-6</izz>
        </inertia>
      </inertial>
      <visual name="visual">
        <geometry>
          <mesh>
            <uri>model://random_strawberry_plant/meshes/leaf5.dae</uri>
            <scale> 0.49784076840105085 0.49784076840105085 0.49784076840105085</scale>
          </mesh>
        </geometry>
      </visual>
    </link>

    <link name= leaf_link_4_1 >
      <pose> -0.04274503560624411
             0.11533862943192805
             0.1576954389646678 0
             0 2.191307094787475  </pose>
      <inertial>
        <mass>0.018</mass>
        <inertia>
          <ixx>8.82e-6</ixx>
          <ixy>0</ixy>
          <ixz>0</ixz>
          <iyy>8.82e-6</iyy>
          <iyz>0</iyz>
          <izz>8.82e-6</izz>
        </inertia>
      </inertial>
      <visual name="visual">
        <geometry>
          <mesh>
            <uri>model://random_strawberry_plant/meshes/leaf4.dae</uri>
            <scale> 0.49784076840105085 0.49784076840105085 0.49784076840105085</scale>
          </mesh>
        </geometry>
      </visual>
    </link>

    <link name= leaf_link_4_2 >
      <pose> -0.04274503560624411
             0.11533862943192805
             0.1576954389646678 0
             0 3.6282014851314317  </pose>
      <inertial>
        <mass>0.018</mass>
        <inertia>
          <ixx>8.82e-6</ixx>
          <ixy>0</ixy>
          <ixz>0</ixz>
          <iyy>8.82e-6</iyy>
          <iyz>0</iyz>
          <izz>8.82e-6</izz>
        </inertia>
      </inertial>
      <visual name="visual">
        <geometry>
          <mesh>
            <uri>model://random_strawberry_plant/meshes/leaf5.dae</uri>
            <scale> 0.49784076840105085 0.49784076840105085 0.49784076840105085</scale>
          </mesh>
        </geometry>
      </visual>
    </link>


    <joint name=leaf_dirt_joint_4 type="revolute">
      <parent>dirt_link</parent>
      <child>leaf_stem_link_4</child>
      <axis>
        <xyz>0 1 0</xyz>
      </axis>
    </joint>


    <link name= berry_stem_link_1 >
      <pose>0 0 0 0 -0.08940217167419043 0.23163968112098265</pose>
      <inertial>
        <mass>1</mass>
        <inertia> <!-- Modeled as slender rod -->
          <ixx>1e-3</ixx>
          <ixy>0</ixy>
          <ixz>0</ixz>
          <iyy>8.333e-2</iyy>
          <iyz>0</iyz>
          <izz>8.333e-2</izz>
        </inertia>
      </inertial>
      <visual name="visual">
        <geometry>
          <mesh>
            <uri>model://random_strawberry_plant/meshes/strawb_stem1.stl</uri>
            <scale>0.338529413677258 0.338529413677258 0.338529413677258</scale>
          </mesh>
        </geometry>
        <material> <!-- Green -->
          <ambient>0.0 0.5 0.0 1.0</ambient>
          <diffuse>0.0 0.5 0.0 1.0</diffuse>
          <specular>0.1 0.1 0.1 1.0</specular>
        </material>
      </visual>
    </link>

    <link name= berry_link_1 >
      <pose> 0.21002863363638294 0.04954021028068576 0.01915050322983867
             0 -1.5607963267948965  0.23163968112098265</pose>
      <inertial>
        <mass>0.018</mass>
        <inertia>
          <ixx>8.82e-6</ixx>
          <ixy>0</ixy>
          <ixz>0</ixz>
          <iyy>8.82e-6</iyy>
          <iyz>0</iyz>
          <izz>8.82e-6</izz>
        </inertia>
      </inertial>
      <collision name="collision">
        <geometry>
          <sphere>
            <radius>0.019343939399863525</radius>
          </sphere>
        </geometry>
      </collision>
      <visual name="visual">
        <geometry>
          <mesh>
            <uri>model://random_strawberry_plant/meshes/1004r0.dae</uri>
            <scale>0.3868787879972705 0.3868787879972705 0.3868787879972705</scale>
          </mesh>
        </geometry>
      </visual>
    </link>

    <link name= calyx_link_1 >
      <pose> 0.21002863363638294 0.04954021028068576 0.01915050322983867
             0 -1.5607963267948965 0.23163968112098265 </pose>
      <inertial>
        <mass>0.018</mass>
        <inertia>
          <ixx>8.82e-6</ixx>
          <ixy>0</ixy>
          <ixz>0</ixz>
          <iyy>8.82e-6</iyy>
          <iyz>0</iyz>
          <izz>8.82e-6</izz>
        </inertia>
      </inertial>
      <visual name="visual">
        <geometry>
          <mesh>
            <uri>model://random_strawberry_plant/meshes/calyx1_1004.dae</uri>
            <scale>0.3868787879972705 0.3868787879972705 0.3868787879972705</scale>
          </mesh>
        </geometry>
      </visual>
    </link>

    <joint name=berry_dirt_joint_1 type="revolute">
      <parent>dirt_link</parent>
      <child>berry_stem_link_1</child>
      <axis>
        <xyz>0 1 0</xyz>
      </axis>
    </joint>

    <joint name=stem_to_calyx_joint_1 type="ball">
      <parent> berry_link_1 </parent>
      <child> calyx_link_1 </child>
    </joint>

    <joint name=stem_to_berry_joint_1 type="ball">
      <parent> berry_stem_link_1 </parent>
      <child> berry_link_1 </child>
    </joint>

    <link name= berry_stem_link_2 >
      <pose>0 0 0 0 -0.09006623570989007 0.13909678443292028</pose>
      <inertial>
        <mass>1</mass>
        <inertia> <!-- Modeled as slender rod -->
          <ixx>1e-3</ixx>
          <ixy>0</ixy>
          <ixz>0</ixz>
          <iyy>8.333e-2</iyy>
          <iyz>0</iyz>
          <izz>8.333e-2</izz>
        </inertia>
      </inertial>
      <visual name="visual">
        <geometry>
          <mesh>
            <uri>model://random_strawberry_plant/meshes/strawb_stem1.stl</uri>
            <scale>0.23993206337170103 0.23993206337170103 0.23993206337170103</scale>
          </mesh>
        </geometry>
        <material> <!-- Green -->
          <ambient>0.0 0.5 0.0 1.0</ambient>
          <diffuse>0.0 0.5 0.0 1.0</diffuse>
          <specular>0.1 0.1 0.1 1.0</specular>
        </material>
      </visual>
    </link>

    <link name= berry_link_2 >
      <pose> 0.15153088248361735 0.02121445378437632 0.013680183010551053
             0 -1.5607963267948965  0.13909678443292028</pose>
      <inertial>
        <mass>0.018</mass>
        <inertia>
          <ixx>8.82e-6</ixx>
          <ixy>0</ixy>
          <ixz>0</ixz>
          <iyy>8.82e-6</iyy>
          <iyz>0</iyz>
          <izz>8.82e-6</izz>
        </inertia>
      </inertial>
      <collision name="collision">
        <geometry>
          <sphere>
            <radius>0.013818364351011964</radius>
          </sphere>
        </geometry>
      </collision>
      <visual name="visual">
        <geometry>
          <mesh>
            <uri>model://random_strawberry_plant/meshes/1000r0.dae</uri>
            <scale>0.27636728702023927 0.27636728702023927 0.27636728702023927</scale>
          </mesh>
        </geometry>
      </visual>
    </link>

    <link name= calyx_link_2 >
      <pose> 0.15153088248361735 0.02121445378437632 0.013680183010551053
             0 -1.5607963267948965 0.13909678443292028 </pose>
      <inertial>
        <mass>0.018</mass>
        <inertia>
          <ixx>8.82e-6</ixx>
          <ixy>0</ixy>
          <ixz>0</ixz>
          <iyy>8.82e-6</iyy>
          <iyz>0</iyz>
          <izz>8.82e-6</izz>
        </inertia>
      </inertial>
      <visual name="visual">
        <geometry>
          <mesh>
            <uri>model://random_strawberry_plant/meshes/calyx5_1000.dae</uri>
            <scale>0.27636728702023927 0.27636728702023927 0.27636728702023927</scale>
          </mesh>
        </geometry>
      </visual>
    </link>

    <joint name=berry_dirt_joint_2 type="revolute">
      <parent>dirt_link</parent>
      <child>berry_stem_link_2</child>
      <axis>
        <xyz>0 1 0</xyz>
      </axis>
    </joint>

    <joint name=stem_to_calyx_joint_2 type="ball">
      <parent> berry_link_2 </parent>
      <child> calyx_link_2 </child>
    </joint>

    <joint name=stem_to_berry_joint_2 type="ball">
      <parent> berry_stem_link_2 </parent>
      <child> berry_link_2 </child>
    </joint>

    <link name= berry_stem_link_3 >
      <pose>0 0 0 0 -0.07006515501128288 -1.6745951674323167</pose>
      <inertial>
        <mass>1</mass>
        <inertia> <!-- Modeled as slender rod -->
          <ixx>1e-3</ixx>
          <ixy>0</ixy>
          <ixz>0</ixz>
          <iyy>8.333e-2</iyy>
          <iyz>0</iyz>
          <izz>8.333e-2</izz>
        </inertia>
      </inertial>
      <visual name="visual">
        <geometry>
          <mesh>
            <uri>model://random_strawberry_plant/meshes/strawb_stem2.stl</uri>
            <scale>0.3860700524235406 0.3860700524235406 0.3860700524235406</scale>
          </mesh>
        </geometry>
        <material> <!-- Green -->
          <ambient>0.0 0.5 0.0 1.0</ambient>
          <diffuse>0.0 0.5 0.0 1.0</diffuse>
          <specular>0.1 0.1 0.1 1.0</specular>
        </material>
      </visual>
    </link>

    <link name= berry_link_3 >
      <pose> -0.024780105147397348 -0.2378740045900668 0.012619997742797762
             0 -1.2302412035553747  -1.6745951674323167</pose>
      <inertial>
        <mass>0.018</mass>
        <inertia>
          <ixx>8.82e-6</ixx>
          <ixy>0</ixy>
          <ixz>0</ixz>
          <iyy>8.82e-6</iyy>
          <iyz>0</iyz>
          <izz>8.82e-6</izz>
        </inertia>
      </inertial>
      <collision name="collision">
        <geometry>
          <sphere>
            <radius>0.012619997742797762</radius>
          </sphere>
        </geometry>
      </collision>
      <visual name="visual">
        <geometry>
          <mesh>
            <uri>model://random_strawberry_plant/meshes/1001r1.dae</uri>
            <scale>0.25239995485595523 0.25239995485595523 0.25239995485595523</scale>
          </mesh>
        </geometry>
      </visual>
    </link>

    <link name= calyx_link_3 >
      <pose> -0.024780105147397348 -0.2378740045900668 0.012619997742797762
             0 -1.2302412035553747 -1.6745951674323167 </pose>
      <inertial>
        <mass>0.018</mass>
        <inertia>
          <ixx>8.82e-6</ixx>
          <ixy>0</ixy>
          <ixz>0</ixz>
          <iyy>8.82e-6</iyy>
          <iyz>0</iyz>
          <izz>8.82e-6</izz>
        </inertia>
      </inertial>
      <visual name="visual">
        <geometry>
          <mesh>
            <uri>model://random_strawberry_plant/meshes/calyx4_1001.dae</uri>
            <scale>0.25239995485595523 0.25239995485595523 0.25239995485595523</scale>
          </mesh>
        </geometry>
      </visual>
    </link>

    <joint name=berry_dirt_joint_3 type="revolute">
      <parent>dirt_link</parent>
      <child>berry_stem_link_3</child>
      <axis>
        <xyz>0 1 0</xyz>
      </axis>
    </joint>

    <joint name=stem_to_calyx_joint_3 type="ball">
      <parent> berry_link_3 </parent>
      <child> calyx_link_3 </child>
    </joint>

    <joint name=stem_to_berry_joint_3 type="ball">
      <parent> berry_stem_link_3 </parent>
      <child> berry_link_3 </child>
    </joint>

    <link name= berry_stem_link_4 >
      <pose>0 0 0 0 -0.06198234235983775 1.3894279635628477</pose>
      <inertial>
        <mass>1</mass>
        <inertia> <!-- Modeled as slender rod -->
          <ixx>1e-3</ixx>
          <ixy>0</ixy>
          <ixz>0</ixz>
          <iyy>8.333e-2</iyy>
          <iyz>0</iyz>
          <izz>8.333e-2</izz>
        </inertia>
      </inertial>
      <visual name="visual">
        <geometry>
          <mesh>
            <uri>model://random_strawberry_plant/meshes/strawb_stem1.stl</uri>
            <scale>0.41333378429886747 0.41333378429886747 0.41333378429886747</scale>
          </mesh>
        </geometry>
        <material> <!-- Green -->
          <ambient>0.0 0.5 0.0 1.0</ambient>
          <diffuse>0.0 0.5 0.0 1.0</diffuse>
          <specular>0.1 0.1 0.1 1.0</specular>
        </material>
      </visual>
    </link>

    <link name= berry_link_4 >
      <pose> 0.046670813529164086 0.2544983564195848 0.015897494882081652
             0 -1.5607963267948965  1.3894279635628477</pose>
      <inertial>
        <mass>0.018</mass>
        <inertia>
          <ixx>8.82e-6</ixx>
          <ixy>0</ixy>
          <ixz>0</ixz>
          <iyy>8.82e-6</iyy>
          <iyz>0</iyz>
          <izz>8.82e-6</izz>
        </inertia>
      </inertial>
      <collision name="collision">
        <geometry>
          <sphere>
            <radius>0.01605807293510055</radius>
          </sphere>
        </geometry>
      </collision>
      <visual name="visual">
        <geometry>
          <mesh>
            <uri>model://random_strawberry_plant/meshes/1000u0.dae</uri>
            <scale>0.32116145870201096 0.32116145870201096 0.32116145870201096</scale>
          </mesh>
        </geometry>
      </visual>
    </link>

    <link name= calyx_link_4 >
      <pose> 0.046670813529164086 0.2544983564195848 0.015897494882081652
             0 -1.5607963267948965 1.3894279635628477 </pose>
      <inertial>
        <mass>0.018</mass>
        <inertia>
          <ixx>8.82e-6</ixx>
          <ixy>0</ixy>
          <ixz>0</ixz>
          <iyy>8.82e-6</iyy>
          <iyz>0</iyz>
          <izz>8.82e-6</izz>
        </inertia>
      </inertial>
      <visual name="visual">
        <geometry>
          <mesh>
            <uri>model://random_strawberry_plant/meshes/calyx4_1000.dae</uri>
            <scale>0.32116145870201096 0.32116145870201096 0.32116145870201096</scale>
          </mesh>
        </geometry>
      </visual>
    </link>

    <joint name=berry_dirt_joint_4 type="revolute">
      <parent>dirt_link</parent>
      <child>berry_stem_link_4</child>
      <axis>
        <xyz>0 1 0</xyz>
      </axis>
    </joint>

    <joint name=stem_to_calyx_joint_4 type="ball">
      <parent> berry_link_4 </parent>
      <child> calyx_link_4 </child>
    </joint>

    <joint name=stem_to_berry_joint_4 type="ball">
      <parent> berry_stem_link_4 </parent>
      <child> berry_link_4 </child>
    </joint>

    <link name= berry_stem_link_5 >
      <pose>0 0 0 0 -0.10751291748071183 -0.1696972647876578</pose>
      <inertial>
        <mass>1</mass>
        <inertia> <!-- Modeled as slender rod -->
          <ixx>1e-3</ixx>
          <ixy>0</ixy>
          <ixz>0</ixz>
          <iyy>8.333e-2</iyy>
          <iyz>0</iyz>
          <izz>8.333e-2</izz>
        </inertia>
      </inertial>
      <visual name="visual">
        <geometry>
          <mesh>
            <uri>model://random_strawberry_plant/meshes/strawb_stem1.stl</uri>
            <scale>0.2016579055069912 0.2016579055069912 0.2016579055069912</scale>
          </mesh>
        </geometry>
        <material> <!-- Green -->
          <ambient>0.0 0.5 0.0 1.0</ambient>
          <diffuse>0.0 0.5 0.0 1.0</diffuse>
          <specular>0.1 0.1 0.1 1.0</specular>
        </material>
      </visual>
    </link>

    <link name= berry_link_5 >
      <pose> 0.12819694858221606 -0.021965929579964707 0.013897519245837106
             0 -1.5607963267948965  -0.1696972647876578</pose>
      <inertial>
        <mass>0.018</mass>
        <inertia>
          <ixx>8.82e-6</ixx>
          <ixy>0</ixy>
          <ixz>0</ixz>
          <iyy>8.82e-6</iyy>
          <iyz>0</iyz>
          <izz>8.82e-6</izz>
        </inertia>
      </inertial>
      <collision name="collision">
        <geometry>
          <sphere>
            <radius>0.014037895864847974</radius>
          </sphere>
        </geometry>
      </collision>
      <visual name="visual">
        <geometry>
          <mesh>
            <uri>model://random_strawberry_plant/meshes/1003u2.dae</uri>
            <scale>0.2807579172969595 0.2807579172969595 0.2807579172969595</scale>
          </mesh>
        </geometry>
      </visual>
    </link>

    <link name= calyx_link_5 >
      <pose> 0.12819694858221606 -0.021965929579964707 0.013897519245837106
             0 -1.5607963267948965 -0.1696972647876578 </pose>
      <inertial>
        <mass>0.018</mass>
        <inertia>
          <ixx>8.82e-6</ixx>
          <ixy>0</ixy>
          <ixz>0</ixz>
          <iyy>8.82e-6</iyy>
          <iyz>0</iyz>
          <izz>8.82e-6</izz>
        </inertia>
      </inertial>
      <visual name="visual">
        <geometry>
          <mesh>
            <uri>model://random_strawberry_plant/meshes/calyx1_1003.dae</uri>
            <scale>0.2807579172969595 0.2807579172969595 0.2807579172969595</scale>
          </mesh>
        </geometry>
      </visual>
    </link>

    <joint name=berry_dirt_joint_5 type="revolute">
      <parent>dirt_link</parent>
      <child>berry_stem_link_5</child>
      <axis>
        <xyz>0 1 0</xyz>
      </axis>
    </joint>

    <joint name=stem_to_calyx_joint_5 type="ball">
      <parent> berry_link_5 </parent>
      <child> calyx_link_5 </child>
    </joint>

    <joint name=stem_to_berry_joint_5 type="ball">
      <parent> berry_stem_link_5 </parent>
      <child> berry_link_5 </child>
    </joint>

    <link name= berry_stem_link_6 >
      <pose>0 0 0 0 -0.13703184364513962 2.612778737163029</pose>
      <inertial>
        <mass>1</mass>
        <inertia> <!-- Modeled as slender rod -->
          <ixx>1e-3</ixx>
          <ixy>0</ixy>
          <ixz>0</ixz>
          <iyy>8.333e-2</iyy>
          <iyz>0</iyz>
          <izz>8.333e-2</izz>
        </inertia>
      </inertial>
      <visual name="visual">
        <geometry>
          <mesh>
            <uri>model://random_strawberry_plant/meshes/strawb_stem1.stl</uri>
            <scale>0.186201798565572 0.186201798565572 0.186201798565572</scale>
          </mesh>
        </geometry>
        <material> <!-- Green -->
          <ambient>0.0 0.5 0.0 1.0</ambient>
          <diffuse>0.0 0.5 0.0 1.0</diffuse>
          <specular>0.1 0.1 0.1 1.0</specular>
        </material>
      </visual>
    </link>

    <link name= berry_link_6 >
      <pose> -0.10565913646836626 0.061739259463277046 0.016706368288116773
             0 -1.5607963267948965  2.612778737163029</pose>
      <inertial>
        <mass>0.018</mass>
        <inertia>
          <ixx>8.82e-6</ixx>
          <ixy>0</ixy>
          <ixz>0</ixz>
          <iyy>8.82e-6</iyy>
          <iyz>0</iyz>
          <izz>8.82e-6</izz>
        </inertia>
      </inertial>
      <collision name="collision">
        <geometry>
          <sphere>
            <radius>0.01687511664203171</radius>
          </sphere>
        </geometry>
      </collision>
      <visual name="visual">
        <geometry>
          <mesh>
            <uri>model://random_strawberry_plant/meshes/1002u3.dae</uri>
            <scale>0.33750233284063424 0.33750233284063424 0.33750233284063424</scale>
          </mesh>
        </geometry>
      </visual>
    </link>

    <link name= calyx_link_6 >
      <pose> -0.10565913646836626 0.061739259463277046 0.016706368288116773
             0 -1.5607963267948965 2.612778737163029 </pose>
      <inertial>
        <mass>0.018</mass>
        <inertia>
          <ixx>8.82e-6</ixx>
          <ixy>0</ixy>
          <ixz>0</ixz>
          <iyy>8.82e-6</iyy>
          <iyz>0</iyz>
          <izz>8.82e-6</izz>
        </inertia>
      </inertial>
      <visual name="visual">
        <geometry>
          <mesh>
            <uri>model://random_strawberry_plant/meshes/calyx2_1002.dae</uri>
            <scale>0.33750233284063424 0.33750233284063424 0.33750233284063424</scale>
          </mesh>
        </geometry>
      </visual>
    </link>

    <joint name=berry_dirt_joint_6 type="revolute">
      <parent>dirt_link</parent>
      <child>berry_stem_link_6</child>
      <axis>
        <xyz>0 1 0</xyz>
      </axis>
    </joint>

    <joint name=stem_to_calyx_joint_6 type="ball">
      <parent> berry_link_6 </parent>
      <child> calyx_link_6 </child>
    </joint>

    <joint name=stem_to_berry_joint_6 type="ball">
      <parent> berry_stem_link_6 </parent>
      <child> berry_link_6 </child>
    </joint>

    <link name= berry_stem_link_7 >
      <pose>0 0 0 0 -0.06470945401238774 -0.029893864048326613</pose>
      <inertial>
        <mass>1</mass>
        <inertia> <!-- Modeled as slender rod -->
          <ixx>1e-3</ixx>
          <ixy>0</ixy>
          <ixz>0</ixz>
          <iyy>8.333e-2</iyy>
          <iyz>0</iyz>
          <izz>8.333e-2</izz>
        </inertia>
      </inertial>
      <visual name="visual">
        <geometry>
          <mesh>
            <uri>model://random_strawberry_plant/meshes/strawb_stem3.stl</uri>
            <scale>0.377693377786781 0.377693377786781 0.377693377786781</scale>
          </mesh>
        </geometry>
        <material> <!-- Green -->
          <ambient>0.0 0.5 0.0 1.0</ambient>
          <diffuse>0.0 0.5 0.0 1.0</diffuse>
          <specular>0.1 0.1 0.1 1.0</specular>
        </material>
      </visual>
    </link>

    <link name= berry_link_7 >
      <pose> 0.22534994506451123 -0.006738588038239149 0.01246538444922917
             0 0.0  -0.029893864048326613</pose>
      <inertial>
        <mass>0.018</mass>
        <inertia>
          <ixx>8.82e-6</ixx>
          <ixy>0</ixy>
          <ixz>0</ixz>
          <iyy>8.82e-6</iyy>
          <iyz>0</iyz>
          <izz>8.82e-6</izz>
        </inertia>
      </inertial>
      <collision name="collision">
        <geometry>
          <sphere>
            <radius>0.005000000000000001</radius>
          </sphere>
        </geometry>
      </collision>
      <visual name="visual">
        <geometry>
          <mesh>
            <uri>model://random_strawberry_plant/meshes/1002g.dae</uri>
            <scale>0.1 0.1 0.1</scale>
          </mesh>
        </geometry>
      </visual>
    </link>

    <link name= calyx_link_7 >
      <pose> 0.22534994506451123 -0.006738588038239149 0.01246538444922917
             0 0.0 -0.029893864048326613 </pose>
      <inertial>
        <mass>0.018</mass>
        <inertia>
          <ixx>8.82e-6</ixx>
          <ixy>0</ixy>
          <ixz>0</ixz>
          <iyy>8.82e-6</iyy>
          <iyz>0</iyz>
          <izz>8.82e-6</izz>
        </inertia>
      </inertial>
      <visual name="visual">
        <geometry>
          <mesh>
            <uri>model://random_strawberry_plant/meshes/calyx9_1002.dae</uri>
            <scale>0.1 0.1 0.1</scale>
          </mesh>
        </geometry>
      </visual>
    </link>

    <joint name=berry_dirt_joint_7 type="revolute">
      <parent>dirt_link</parent>
      <child>berry_stem_link_7</child>
      <axis>
        <xyz>0 1 0</xyz>
      </axis>
    </joint>

    <joint name=stem_to_calyx_joint_7 type="ball">
      <parent> berry_link_7 </parent>
      <child> calyx_link_7 </child>
    </joint>

    <joint name=stem_to_berry_joint_7 type="ball">
      <parent> berry_stem_link_7 </parent>
      <child> berry_link_7 </child>
    </joint>

    <link name= berry_stem_link_8 >
      <pose>0 0 0 0 -0.04417876417895353 1.520668881087821</pose>
      <inertial>
        <mass>1</mass>
        <inertia> <!-- Modeled as slender rod -->
          <ixx>1e-3</ixx>
          <ixy>0</ixy>
          <ixz>0</ixz>
          <iyy>8.333e-2</iyy>
          <iyz>0</iyz>
          <izz>8.333e-2</izz>
        </inertia>
      </inertial>
      <visual name="visual">
        <geometry>
          <mesh>
            <uri>model://random_strawberry_plant/meshes/strawb_stem2.stl</uri>
            <scale>0.20886917044956754 0.20886917044956754 0.20886917044956754</scale>
          </mesh>
        </geometry>
        <material> <!-- Green -->
          <ambient>0.0 0.5 0.0 1.0</ambient>
          <diffuse>0.0 0.5 0.0 1.0</diffuse>
          <specular>0.1 0.1 0.1 1.0</specular>
        </material>
      </visual>
    </link>

    <link name= berry_link_8 >
      <pose> 0.0064481501382847905 0.12852736173006837 0.005048876806902455
             0 -1.4433025628415244  1.520668881087821</pose>
      <inertial>
        <mass>0.018</mass>
        <inertia>
          <ixx>8.82e-6</ixx>
          <ixy>0</ixy>
          <ixz>0</ixz>
          <iyy>8.82e-6</iyy>
          <iyz>0</iyz>
          <izz>8.82e-6</izz>
        </inertia>
      </inertial>
      <collision name="collision">
        <geometry>
          <sphere>
            <radius>0.005048876806902455</radius>
          </sphere>
        </geometry>
      </collision>
      <visual name="visual">
        <geometry>
          <mesh>
            <uri>model://random_strawberry_plant/meshes/1002g.dae</uri>
            <scale>0.1009775361380491 0.1009775361380491 0.1009775361380491</scale>
          </mesh>
        </geometry>
      </visual>
    </link>

    <link name= calyx_link_8 >
      <pose> 0.0064481501382847905 0.12852736173006837 0.005048876806902455
             0 -1.4433025628415244 1.520668881087821 </pose>
      <inertial>
        <mass>0.018</mass>
        <inertia>
          <ixx>8.82e-6</ixx>
          <ixy>0</ixy>
          <ixz>0</ixz>
          <iyy>8.82e-6</iyy>
          <iyz>0</iyz>
          <izz>8.82e-6</izz>
        </inertia>
      </inertial>
      <visual name="visual">
        <geometry>
          <mesh>
            <uri>model://random_strawberry_plant/meshes/calyx7_1002.dae</uri>
            <scale>0.1009775361380491 0.1009775361380491 0.1009775361380491</scale>
          </mesh>
        </geometry>
      </visual>
    </link>

    <joint name=berry_dirt_joint_8 type="revolute">
      <parent>dirt_link</parent>
      <child>berry_stem_link_8</child>
      <axis>
        <xyz>0 1 0</xyz>
      </axis>
    </joint>

    <joint name=stem_to_calyx_joint_8 type="ball">
      <parent> berry_link_8 </parent>
      <child> calyx_link_8 </child>
    </joint>

    <joint name=stem_to_berry_joint_8 type="ball">
      <parent> berry_stem_link_8 </parent>
      <child> berry_link_8 </child>
    </joint>

    <link name= berry_stem_link_9 >
      <pose>0 0 0 0 -0.07010419845451235 0.7743982964004705</pose>
      <inertial>
        <mass>1</mass>
        <inertia> <!-- Modeled as slender rod -->
          <ixx>1e-3</ixx>
          <ixy>0</ixy>
          <ixz>0</ixz>
          <iyy>8.333e-2</iyy>
          <iyz>0</iyz>
          <izz>8.333e-2</izz>
        </inertia>
      </inertial>
      <visual name="visual">
        <geometry>
          <mesh>
            <uri>model://random_strawberry_plant/meshes/strawb_stem2.stl</uri>
            <scale>0.3585277611100466 0.3585277611100466 0.3585277611100466</scale>
          </mesh>
        </geometry>
        <material> <!-- Green -->
          <ambient>0.0 0.5 0.0 1.0</ambient>
          <diffuse>0.0 0.5 0.0 1.0</diffuse>
          <specular>0.1 0.1 0.1 1.0</specular>
        </material>
      </visual>
    </link>

    <link name= berry_link_9 >
      <pose> 0.1545819655922745 0.1512180701960046 0.008297073244697023
             0 -0.5254013661330157  0.7743982964004705</pose>
      <inertial>
        <mass>0.018</mass>
        <inertia>
          <ixx>8.82e-6</ixx>
          <ixy>0</ixy>
          <ixz>0</ixz>
          <iyy>8.82e-6</iyy>
          <iyz>0</iyz>
          <izz>8.82e-6</izz>
        </inertia>
      </inertial>
      <collision name="collision">
        <geometry>
          <sphere>
            <radius>0.008297073244697023</radius>
          </sphere>
        </geometry>
      </collision>
      <visual name="visual">
        <geometry>
          <mesh>
            <uri>model://random_strawberry_plant/meshes/1001g.dae</uri>
            <scale>0.16594146489394046 0.16594146489394046 0.16594146489394046</scale>
          </mesh>
        </geometry>
      </visual>
    </link>

    <link name= calyx_link_9 >
      <pose> 0.1545819655922745 0.1512180701960046 0.008297073244697023
             0 -0.5254013661330157 0.7743982964004705 </pose>
      <inertial>
        <mass>0.018</mass>
        <inertia>
          <ixx>8.82e-6</ixx>
          <ixy>0</ixy>
          <ixz>0</ixz>
          <iyy>8.82e-6</iyy>
          <iyz>0</iyz>
          <izz>8.82e-6</izz>
        </inertia>
      </inertial>
      <visual name="visual">
        <geometry>
          <mesh>
            <uri>model://random_strawberry_plant/meshes/calyx10_1001.dae</uri>
            <scale>0.16594146489394046 0.16594146489394046 0.16594146489394046</scale>
          </mesh>
        </geometry>
      </visual>
    </link>

    <joint name=berry_dirt_joint_9 type="revolute">
      <parent>dirt_link</parent>
      <child>berry_stem_link_9</child>
      <axis>
        <xyz>0 1 0</xyz>
      </axis>
    </joint>

    <joint name=stem_to_calyx_joint_9 type="ball">
      <parent> berry_link_9 </parent>
      <child> calyx_link_9 </child>
    </joint>

    <joint name=stem_to_berry_joint_9 type="ball">
      <parent> berry_stem_link_9 </parent>
      <child> berry_link_9 </child>
    </joint>

  </model>
</sdf>
